{
  "version": 8,
  "blockIdVersion": 11,
  "anchorX": 0,
  "anchorY": 0,
  "anchorZ": 0,
  "blocks": [
    {
      "x": -6,
      "y": 2,
      "z": 0,
      "name": "Furniture_Kweebec_Platform",
      "rotation": 1
    },
    {
      "x": -5,
      "y": 2,
      "z": -1,
      "name": "Wood_Kweebec_Planks"
    },
    {
      "x": -5,
      "y": 3,
      "z": -1,
      "name": "Wood_Kweebec_Planks"
    },
    {
      "x": -5,
      "y": 4,
      "z": -1,
      "name": "Wood_Kweebec_Planks"
    },
    {
      "x": -5,
      "y": 5,
      "z": -1,
      "name": "Wood_Kweebec_Planks"
    },
    {
      "x": -5,
      "y": 2,
      "z": 0,
      "name": "Wood_Kweebec_Planks"
    },
    {
      "x": -5,
      "y": 3,
      "z": 0,
      "name": "*Furniture_Kweebec_Door_State_Definitions_CloseDoorIn",
      "rotation": 3
    },
    {
      "x": -5,
      "y": 4,
      "z": 0,
      "name": "*Furniture_Kweebec_Door_State_Definitions_CloseDoorIn",
      "filler": 1024,
      "rotation": 3
    },
    {
      "x": -5,
      "y": 5,
      "z": 0,
      "name": "Wood_Kweebec_Planks"
    },
    {
      "x": -5,
      "y": 2,
      "z": 1,
      "name": "Wood_Kweebec_Planks"
    },
    {
      "x": -5,
      "y": 3,
      "z": 1,
      "name": "Wood_Kweebec_Planks"
    },
    {
      "x": -5,
      "y": 4,
      "z": 1,
      "name": "Wood_Kweebec_Planks"
    },
    {
      "x": -5,
      "y": 5,
      "z": 1,
      "name": "Wood_Kweebec_Planks"
    },
    {
      "x": -4,
      "y": 3,
      "z": -3,
      "name": "Wood_Kweebec_Planks"
    },
    {
      "x": -4,
      "y": 4,
      "z": -3,
      "name": "Wood_Kweebec_Planks"
    },
    {
      "x": -4,
      "y": 5,
      "z": -3,
      "name": "Wood_Kweebec_Planks"
    },
    {
      "x": -4,
      "y": 2,
      "z": -2,
      "name": "Wood_Kweebec_Planks"
    },
    {
      "x": -4,
      "y": 3,
      "z": -2,
      "name": "Wood_Kweebec_Planks"
    },
    {
      "x": -4,
      "y": 4,
      "z": -2,
      "name": "Wood_Kweebec_Planks"
    },
    {
      "x": -4,
      "y": 5,
      "z": -2,
      "name": "Furniture_Kweebec_Window",
      "rotation": 1
    },
    {
      "x": -4,
      "y": 6,
      "z": -2,
      "name": "Wood_Kweebec_Planks"
    },
    {
      "x": -4,
      "y": 1,
      "z": -1,
      "name": "Wood_Kweebec_Planks"
    },
    {
      "x": -4,
      "y": 2,
      "z": -1,
      "name": "Wood_Kweebec_Planks"
    },
    {
      "x": -4,
      "y": 3,
      "z": -1,
      "name": "Wood_Kweebec_Planks"
    },
    {
      "x": -4,
      "y": 4,
      "z": -1,
      "name": "Wood_Kweebec_Planks"
    },
    {
      "x": -4,
      "y": 5,
      "z": -1,
      "name": "Wood_Kweebec_Planks"
    },
    {
      "x": -4,
      "y": 6,
      "z": -1,
      "name": "Wood_Kweebec_Planks"
    },
    {
      "x": -4,
      "y": 7,
      "z": -1,
      "name": "Wood_Kweebec_Planks"
    },
    {
      "x": -4,
      "y": 1,
      "z": 0,
      "name": "Wood_Kweebec_Planks"
    },
    {
      "x": -4,
      "y": 2,
      "z": 0,
      "name": "Wood_Kweebec_Planks"
    },
    {
      "x": -4,
      "y": 5,
      "z": 0,
      "name": "Wood_Kweebec_Planks"
    },
    {
      "x": -4,
      "y": 6,
      "z": 0,
      "name": "Wood_Kweebec_Planks"
    },
    {
      "x": -4,
      "y": 7,
      "z": 0,
      "name": "Wood_Kweebec_Planks"
    },
    {
      "x": -4,
      "y": 8,
      "z": 0,
      "name": "Deco_Rope"
    },
    {
      "x": -4,
      "y": 1,
      "z": 1,
      "name": "Wood_Kweebec_Planks"
    },
    {
      "x": -4,
      "y": 2,
      "z": 1,
      "name": "Wood_Kweebec_Planks"
    },
    {
      "x": -4,
      "y": 3,
      "z": 1,
      "name": "Wood_Kweebec_Planks"
    },
    {
      "x": -4,
      "y": 4,
      "z": 1,
      "name": "Wood_Kweebec_Planks"
    },
    {
      "x": -4,
      "y": 5,
      "z": 1,
      "name": "Wood_Kweebec_Planks"
    },
    {
      "x": -4,
      "y": 6,
      "z": 1,
      "name": "Wood_Kweebec_Planks"
    },
    {
      "x": -4,
      "y": 7,
      "z": 1,
      "name": "Wood_Kweebec_Planks"
    },
    {
      "x": -4,
      "y": 2,
      "z": 2,
      "name": "Wood_Kweebec_Planks"
    },
    {
      "x": -4,
      "y": 3,
      "z": 2,
      "name": "Wood_Kweebec_Planks"
    },
    {
      "x": -4,
      "y": 4,
      "z": 2,
      "name": "Wood_Kweebec_Planks"
    },
    {
      "x": -4,
      "y": 5,
      "z": 2,
      "name": "Furniture_Kweebec_Window",
      "rotation": 1
    },
    {
      "x": -4,
      "y": 6,
      "z": 2,
      "name": "Wood_Kweebec_Planks"
    },
    {
      "x": -4,
      "y": 3,
      "z": 3,
      "name": "Wood_Kweebec_Planks"
    },
    {
      "x": -4,
      "y": 4,
      "z": 3,
      "name": "Wood_Kweebec_Planks"
    },
    {
      "x": -4,
      "y": 5,
      "z": 3,
      "name": "Wood_Kweebec_Planks"
    },
    {
      "x": -3,
      "y": 2,
      "z": -3,
      "name": "Wood_Kweebec_Planks"
    },
    {
      "x": -3,
      "y": 3,
      "z": -3,
      "name": "Wood_Kweebec_Planks"
    },
    {
      "x": -3,
      "y": 4,
      "z": -3,
      "name": "Wood_Kweebec_Planks"
    },
    {
      "x": -3,
      "y": 5,
      "z": -3,
      "name": "Wood_Kweebec_Planks"
    },
    {
      "x": -3,
      "y": 6,
      "z": -3,
      "name": "Wood_Kweebec_Planks"
    },
    {
      "x": -3,
      "y": 1,
      "z": -2,
      "name": "Wood_Kweebec_Planks"
    },
    {
      "x": -3,
      "y": 2,
      "z": -2,
      "name": "Wood_Kweebec_Planks"
    },
    {
      "x": -3,
      "y": 3,
      "z": -2,
      "name": "Furniture_Kweebec_Shelf",
      "rotation": 1
    },
    {
      "x": -3,
      "y": 4,
      "z": -2,
      "name": "Furniture_Kweebec_Candle"
    },
    {
      "x": -3,
      "y": 7,
      "z": -2,
      "name": "Wood_Kweebec_Planks"
    },
    {
      "x": -3,
      "y": 1,
      "z": -1,
      "name": "Wood_Kweebec_Planks"
    },
    {
      "x": -3,
      "y": 2,
      "z": -1,
      "name": "Wood_Kweebec_Planks"
    },
    {
      "x": -3,
      "y": 7,
      "z": -1,
      "name": "Wood_Kweebec_Planks"
    },
    {
      "x": -3,
      "y": 1,
      "z": 0,
      "name": "Wood_Kweebec_Planks"
    },
    {
      "x": -3,
      "y": 2,
      "z": 0,
      "name": "Furniture_Kweebec_Platform"
    },
    {
      "x": -3,
      "y": 7,
      "z": 0,
      "name": "Wood_Kweebec_Planks"
    },
    {
      "x": -3,
      "y": 1,
      "z": 1,
      "name": "Wood_Kweebec_Planks"
    },
    {
      "x": -3,
      "y": 2,
      "z": 1,
      "name": "Wood_Kweebec_Planks"
    },
    {
      "x": -3,
      "y": 7,
      "z": 1,
      "name": "Wood_Kweebec_Planks"
    },
    {
      "x": -3,
      "y": 1,
      "z": 2,
      "name": "Wood_Kweebec_Planks"
    },
    {
      "x": -3,
      "y": 2,
      "z": 2,
      "name": "Wood_Kweebec_Planks"
    },
    {
      "x": -3,
      "y": 7,
      "z": 2,
      "name": "Wood_Kweebec_Planks"
    },
    {
      "x": -3,
      "y": 2,
      "z": 3,
      "name": "Wood_Kweebec_Planks"
    },
    {
      "x": -3,
      "y": 3,
      "z": 3,
      "name": "Wood_Kweebec_Planks"
    },
    {
      "x": -3,
      "y": 4,
      "z": 3,
      "name": "Wood_Kweebec_Planks"
    },
    {
      "x": -3,
      "y": 5,
      "z": 3,
      "name": "Wood_Kweebec_Planks"
    },
    {
      "x": -3,
      "y": 6,
      "z": 3,
      "name": "Wood_Kweebec_Planks"
    },
    {
      "x": -2,
      "y": 3,
      "z": -4,
      "name": "Wood_Kweebec_Planks"
    },
    {
      "x": -2,
      "y": 4,
      "z": -4,
      "name": "Wood_Kweebec_Planks"
    },
    {
      "x": -2,
      "y": 5,
      "z": -4,
      "name": "Wood_Kweebec_Planks"
    },
    {
      "x": -2,
      "y": 1,
      "z": -3,
      "name": "Wood_Kweebec_Planks"
    },
    {
      "x": -2,
      "y": 2,
      "z": -3,
      "name": "Wood_Kweebec_Planks"
    },
    {
      "x": -2,
      "y": 6,
      "z": -3,
      "name": "Wood_Kweebec_Planks"
    },
    {
      "x": -2,
      "y": 7,
      "z": -3,
      "name": "Wood_Kweebec_Planks"
    },
    {
      "x": -2,
      "y": 1,
      "z": -2,
      "name": "Wood_Kweebec_Planks"
    },
    {
      "x": -2,
      "y": 2,
      "z": -2,
      "name": "Furniture_Kweebec_Platform"
    },
    {
      "x": -2,
      "y": 7,
      "z": -2,
      "name": "Wood_Kweebec_Planks"
    },
    {
      "x": -2,
      "y": 0,
      "z": -1,
      "name": "Wood_Kweebec_Planks"
    },
    {
      "x": -2,
      "y": 2,
      "z": -1,
      "name": "Furniture_Kweebec_Platform"
    },
    {
      "x": -2,
      "y": 7,
      "z": -1,
      "name": "Wood_Kweebec_Planks"
    },
    {
      "x": -2,
      "y": 8,
      "z": -1,
      "name": "Wood_Kweebec_Planks"
    },
    {
      "x": -2,
      "y": 0,
      "z": 0,
      "name": "Wood_Kweebec_Planks"
    },
    {
      "x": -2,
      "y": 2,
      "z": 0,
      "name": "Furniture_Kweebec_Platform"
    },
    {
      "x": -2,
      "y": 7,
      "z": 0,
      "name": "Wood_Kweebec_Planks"
    },
    {
      "x": -2,
      "y": 8,
      "z": 0,
      "name": "Wood_Kweebec_Planks"
    },
    {
      "x": -2,
      "y": 0,
      "z": 1,
      "name": "Wood_Kweebec_Planks"
    },
    {
      "x": -2,
      "y": 2,
      "z": 1,
      "name": "Furniture_Kweebec_Platform"
    },
    {
      "x": -2,
      "y": 7,
      "z": 1,
      "name": "Wood_Kweebec_Planks"
    },
    {
      "x": -2,
      "y": 8,
      "z": 1,
      "name": "Wood_Kweebec_Planks"
    },
    {
      "x": -2,
      "y": 1,
      "z": 2,
      "name": "Wood_Kweebec_Planks"
    },
    {
      "x": -2,
      "y": 2,
      "z": 2,
      "name": "Wood_Kweebec_Planks"
    },
    {
      "x": -2,
      "y": 7,
      "z": 2,
      "name": "Wood_Kweebec_Planks"
    },
    {
      "x": -2,
      "y": 1,
      "z": 3,
      "name": "Wood_Kweebec_Planks"
    },
    {
      "x": -2,
      "y": 2,
      "z": 3,
      "name": "Wood_Kweebec_Planks"
    },
    {
      "x": -2,
      "y": 6,
      "z": 3,
      "name": "Wood_Kweebec_Planks"
    },
    {
      "x": -2,
      "y": 7,
      "z": 3,
      "name": "Wood_Kweebec_Planks"
    },
    {
      "x": -2,
      "y": 3,
      "z": 4,
      "name": "Wood_Kweebec_Planks"
    },
    {
      "x": -2,
      "y": 4,
      "z": 4,
      "name": "Wood_Kweebec_Planks"
    },
    {
      "x": -2,
      "y": 5,
      "z": 4,
      "name": "Wood_Kweebec_Planks"
    },
    {
      "x": -1,
      "y": 2,
      "z": -4,
      "name": "Wood_Kweebec_Planks"
    },
    {
      "x": -1,
      "y": 3,
      "z": -4,
      "name": "Furniture_Kweebec_Window"
    },
    {
      "x": -1,
      "y": 4,
      "z": -4,
      "name": "Furniture_Kweebec_Window"
    },
    {
      "x": -1,
      "y": 5,
      "z": -4,
      "name": "Wood_Kweebec_Planks"
    },
    {
      "x": -1,
      "y": 6,
      "z": -4,
      "name": "Deco_Rope"
    },
    {
      "x": -1,
      "y": 7,
      "z": -4,
      "name": "Deco_Rope"
    },
    {
      "x": -1,
      "y": 8,
      "z": -4,
      "name": "Deco_Rope"
    },
    {
      "x": -1,
      "y": 1,
      "z": -3,
      "name": "Wood_Kweebec_Planks"
    },
    {
      "x": -1,
      "y": 2,
      "z": -3,
      "name": "Wood_Kweebec_Planks"
    },
    {
      "x": -1,
      "y": 3,
      "z": -3,
      "name": "Furniture_Kweebec_Bed",
      "components": {
        "Components": {
          "PlacedByInteraction": {
            "WhoPlacedUuid": {
              "$binary": "Jkzvo0hoTZaBZsSL3nwDMA==",
              "$type": "04"
            }
          },
          "RespawnBlock": {}
        }
      }
    },
    {
      "x": -1,
      "y": 4,
      "z": -3,
      "name": "Furniture_Kweebec_Bed",
      "filler": 1024
    },
    {
      "x": -1,
      "y": 6,
      "z": -3,
      "name": "Wood_Kweebec_Planks"
    },
    {
      "x": -1,
      "y": 7,
      "z": -3,
      "name": "Wood_Kweebec_Planks"
    },
    {
      "x": -1,
      "y": 1,
      "z": -2,
      "name": "Wood_Kweebec_Planks"
    },
    {
      "x": -1,
      "y": 2,
      "z": -2,
      "name": "Furniture_Kweebec_Platform"
    },
    {
      "x": -1,
      "y": 3,
      "z": -2,
      "name": "Furniture_Kweebec_Bed",
      "filler": 32
    },
    {
      "x": -1,
      "y": 4,
      "z": -2,
      "name": "Furniture_Kweebec_Bed",
      "filler": 1056
    },
    {
      "x": -1,
      "y": 7,
      "z": -2,
      "name": "Wood_Kweebec_Planks"
    },
    {
      "x": -1,
      "y": 0,
      "z": -1,
      "name": "Wood_Kweebec_Planks"
    },
    {
      "x": -1,
      "y": 1,
      "z": -1,
      "name": "Furniture_Kweebec_Chest_Small",
      "components": {
        "Components": {
          "PlacedByInteraction": {
            "WhoPlacedUuid": {
              "$binary": "Jkzvo0hoTZaBZsSL3nwDMA==",
              "$type": "04"
            }
          },
          "ItemContainerBlock": {
            "ItemContainer": {
              "Capacity": 18,
              "Items": {}
            },
            "Capacity": 18
          }
        }
      }
    },
    {
      "x": -1,
      "y": 2,
      "z": -1,
      "name": "Furniture_Kweebec_Platform"
    },
    {
      "x": -1,
      "y": 7,
      "z": -1,
      "name": "Wood_Kweebec_Planks"
    },
    {
      "x": -1,
      "y": 8,
      "z": -1,
      "name": "Wood_Kweebec_Planks"
    },
    {
      "x": -1,
      "y": 0,
      "z": 0,
      "name": "Wood_Kweebec_Planks"
    },
    {
      "x": -1,
      "y": 2,
      "z": 0,
      "name": "*Furniture_Kweebec_Trapdoor_State_Definitions_CloseDoorOut",
      "rotation": 2
    },
    {
      "x": -1,
      "y": 8,
      "z": 0,
      "name": "Wood_Kweebec_Planks"
    },
    {
      "x": -1,
      "y": 0,
      "z": 1,
      "name": "Wood_Kweebec_Planks"
    },
    {
      "x": -1,
      "y": 2,
      "z": 1,
      "name": "Furniture_Kweebec_Platform",
      "rotation": 1
    },
    {
      "x": -1,
      "y": 7,
      "z": 1,
      "name": "Wood_Kweebec_Planks"
    },
    {
      "x": -1,
      "y": 8,
      "z": 1,
      "name": "Wood_Kweebec_Planks"
    },
    {
      "x": -1,
      "y": 1,
      "z": 2,
      "name": "Wood_Kweebec_Planks"
    },
    {
      "x": -1,
      "y": 2,
      "z": 2,
      "name": "Furniture_Kweebec_Platform",
      "rotation": 1
    },
    {
      "x": -1,
      "y": 7,
      "z": 2,
      "name": "Wood_Kweebec_Planks"
    },
    {
      "x": -1,
      "y": 1,
      "z": 3,
      "name": "Wood_Kweebec_Planks"
    },
    {
      "x": -1,
      "y": 2,
      "z": 3,
      "name": "Wood_Kweebec_Planks"
    },
    {
      "x": -1,
      "y": 6,
      "z": 3,
      "name": "Wood_Kweebec_Planks"
    },
    {
      "x": -1,
      "y": 7,
      "z": 3,
      "name": "Wood_Kweebec_Planks"
    },
    {
      "x": -1,
      "y": 2,
      "z": 4,
      "name": "Wood_Kweebec_Planks"
    },
    {
      "x": -1,
      "y": 3,
      "z": 4,
      "name": "Furniture_Kweebec_Window"
    },
    {
      "x": -1,
      "y": 4,
      "z": 4,
      "name": "Furniture_Kweebec_Window"
    },
    {
      "x": -1,
      "y": 5,
      "z": 4,
      "name": "Wood_Kweebec_Planks"
    },
    {
      "x": -1,
      "y": 6,
      "z": 4,
      "name": "Deco_Rope"
    },
    {
      "x": -1,
      "y": 7,
      "z": 4,
      "name": "Deco_Rope"
    },
    {
      "x": -1,
      "y": 8,
      "z": 4,
      "name": "Deco_Rope"
    },
    {
      "x": 0,
      "y": 3,
      "z": -4,
      "name": "Wood_Kweebec_Planks"
    },
    {
      "x": 0,
      "y": 4,
      "z": -4,
      "name": "Wood_Kweebec_Planks"
    },
    {
      "x": 0,
      "y": 5,
      "z": -4,
      "name": "Wood_Kweebec_Planks"
    },
    {
      "x": 0,
      "y": 1,
      "z": -3,
      "name": "Wood_Kweebec_Planks"
    },
    {
      "x": 0,
      "y": 2,
      "z": -3,
      "name": "Wood_Kweebec_Planks"
    },
    {
      "x": 0,
      "y": 6,
      "z": -3,
      "name": "Wood_Kweebec_Planks"
    },
    {
      "x": 0,
      "y": 7,
      "z": -3,
      "name": "Wood_Kweebec_Planks"
    },
    {
      "x": 0,
      "y": 1,
      "z": -2,
      "name": "Wood_Kweebec_Planks"
    },
    {
      "x": 0,
      "y": 2,
      "z": -2,
      "name": "Furniture_Kweebec_Platform"
    },
    {
      "x": 0,
      "y": 7,
      "z": -2,
      "name": "Wood_Kweebec_Planks"
    },
    {
      "x": 0,
      "y": 0,
      "z": -1,
      "name": "Wood_Kweebec_Planks"
    },
    {
      "x": 0,
      "y": 2,
      "z": -1,
      "name": "Furniture_Kweebec_Platform"
    },
    {
      "x": 0,
      "y": 7,
      "z": -1,
      "name": "Wood_Kweebec_Planks"
    },
    {
      "x": 0,
      "y": 8,
      "z": -1,
      "name": "Wood_Kweebec_Planks"
    },
    {
      "x": 0,
      "y": 0,
      "z": 0,
      "name": "Wood_Kweebec_Planks"
    },
    {
      "x": 0,
      "y": 2,
      "z": 0,
      "name": "Furniture_Kweebec_Platform"
    },
    {
      "x": 0,
      "y": 7,
      "z": 0,
      "name": "Wood_Kweebec_Planks"
    },
    {
      "x": 0,
      "y": 8,
      "z": 0,
      "name": "Wood_Kweebec_Planks"
    },
    {
      "x": 0,
      "y": 0,
      "z": 1,
      "name": "Wood_Kweebec_Planks"
    },
    {
      "x": 0,
      "y": 2,
      "z": 1,
      "name": "Furniture_Kweebec_Platform"
    },
    {
      "x": 0,
      "y": 3,
      "z": 1,
      "name": "Furniture_Kweebec_Stool",
      "rotation": 3
    },
    {
      "x": 0,
      "y": 7,
      "z": 1,
      "name": "Wood_Kweebec_Planks"
    },
    {
      "x": 0,
      "y": 8,
      "z": 1,
      "name": "Wood_Kweebec_Planks"
    },
    {
      "x": 0,
      "y": 1,
      "z": 2,
      "name": "Wood_Kweebec_Planks"
    },
    {
      "x": 0,
      "y": 2,
      "z": 2,
      "name": "Wood_Kweebec_Planks"
    },
    {
      "x": 0,
      "y": 3,
      "z": 2,
      "name": "Furniture_Kweebec_Stool",
      "rotation": 3
    },
    {
      "x": 0,
      "y": 7,
      "z": 2,
      "name": "Wood_Kweebec_Planks"
    },
    {
      "x": 0,
      "y": 1,
      "z": 3,
      "name": "Wood_Kweebec_Planks"
    },
    {
      "x": 0,
      "y": 2,
      "z": 3,
      "name": "Wood_Kweebec_Planks"
    },
    {
      "x": 0,
      "y": 6,
      "z": 3,
      "name": "Wood_Kweebec_Planks"
    },
    {
      "x": 0,
      "y": 7,
      "z": 3,
      "name": "Wood_Kweebec_Planks"
    },
    {
      "x": 0,
      "y": 3,
      "z": 4,
      "name": "Wood_Kweebec_Planks"
    },
    {
      "x": 0,
      "y": 4,
      "z": 4,
      "name": "Wood_Kweebec_Planks"
    },
    {
      "x": 0,
      "y": 5,
      "z": 4,
      "name": "Wood_Kweebec_Planks"
    },
    {
      "x": 1,
      "y": 2,
      "z": -3,
      "name": "Wood_Kweebec_Planks"
    },
    {
      "x": 1,
      "y": 3,
      "z": -3,
      "name": "Wood_Kweebec_Planks"
    },
    {
      "x": 1,
      "y": 4,
      "z": -3,
      "name": "Wood_Kweebec_Planks"
    },
    {
      "x": 1,
      "y": 5,
      "z": -3,
      "name": "Wood_Kweebec_Planks"
    },
    {
      "x": 1,
      "y": 6,
      "z": -3,
      "name": "Wood_Kweebec_Planks"
    },
    {
      "x": 1,
      "y": 1,
      "z": -2,
      "name": "Wood_Kweebec_Planks"
    },
    {
      "x": 1,
      "y": 2,
      "z": -2,
      "name": "Wood_Kweebec_Planks"
    },
    {
      "x": 1,
      "y": 3,
      "z": -2,
      "name": "Furniture_Kweebec_Wardrobe",
      "filler": 992,
      "rotation": 3
    },
    {
      "x": 1,
      "y": 4,
      "z": -2,
      "name": "Furniture_Kweebec_Wardrobe",
      "filler": 2016,
      "rotation": 3
    },
    {
      "x": 1,
      "y": 7,
      "z": -2,
      "name": "Wood_Kweebec_Planks"
    },
    {
      "x": 1,
      "y": 1,
      "z": -1,
      "name": "Wood_Kweebec_Planks"
    },
    {
      "x": 1,
      "y": 2,
      "z": -1,
      "name": "Wood_Kweebec_Planks"
    },
    {
      "x": 1,
      "y": 3,
      "z": -1,
      "name": "Furniture_Kweebec_Wardrobe",
      "rotation": 3
    },
    {
      "x": 1,
      "y": 4,
      "z": -1,
      "name": "Furniture_Kweebec_Wardrobe",
      "filler": 1024,
      "rotation": 3
    },
    {
      "x": 1,
      "y": 7,
      "z": -1,
      "name": "Wood_Kweebec_Planks"
    },
    {
      "x": 1,
      "y": 1,
      "z": 0,
      "name": "Wood_Kweebec_Planks"
    },
    {
      "x": 1,
      "y": 2,
      "z": 0,
      "name": "Furniture_Kweebec_Platform"
    },
    {
      "x": 1,
      "y": 7,
      "z": 0,
      "name": "Wood_Kweebec_Planks"
    },
    {
      "x": 1,
      "y": 1,
      "z": 1,
      "name": "Wood_Kweebec_Planks"
    },
    {
      "x": 1,
      "y": 2,
      "z": 1,
      "name": "Wood_Kweebec_Planks"
    },
    {
      "x": 1,
      "y": 3,
      "z": 1,
      "name": "Furniture_Kweebec_Platform"
    },
    {
      "x": 1,
      "y": 5,
      "z": 1,
      "name": "Furniture_Kweebec_Painting",
      "rotation": 3
    },
    {
      "x": 1,
      "y": 7,
      "z": 1,
      "name": "Wood_Kweebec_Planks"
    },
    {
      "x": 1,
      "y": 1,
      "z": 2,
      "name": "Wood_Kweebec_Planks"
    },
    {
      "x": 1,
      "y": 2,
      "z": 2,
      "name": "Wood_Kweebec_Planks"
    },
    {
      "x": 1,
      "y": 3,
      "z": 2,
      "name": "Furniture_Kweebec_Platform"
    },
    {
      "x": 1,
      "y": 7,
      "z": 2,
      "name": "Wood_Kweebec_Planks"
    },
    {
      "x": 1,
      "y": 2,
      "z": 3,
      "name": "Wood_Kweebec_Planks"
    },
    {
      "x": 1,
      "y": 3,
      "z": 3,
      "name": "Wood_Kweebec_Planks"
    },
    {
      "x": 1,
      "y": 4,
      "z": 3,
      "name": "Wood_Kweebec_Planks"
    },
    {
      "x": 1,
      "y": 5,
      "z": 3,
      "name": "Wood_Kweebec_Planks"
    },
    {
      "x": 1,
      "y": 6,
      "z": 3,
      "name": "Wood_Kweebec_Planks"
    },
    {
      "x": 2,
      "y": 3,
      "z": -3,
      "name": "Wood_Kweebec_Planks"
    },
    {
      "x": 2,
      "y": 4,
      "z": -3,
      "name": "Wood_Kweebec_Planks"
    },
    {
      "x": 2,
      "y": 5,
      "z": -3,
      "name": "Wood_Kweebec_Planks"
    },
    {
      "x": 2,
      "y": 2,
      "z": -2,
      "name": "Wood_Kweebec_Planks"
    },
    {
      "x": 2,
      "y": 3,
      "z": -2,
      "name": "Wood_Kweebec_Planks"
    },
    {
      "x": 2,
      "y": 4,
      "z": -2,
      "name": "Wood_Kweebec_Planks"
    },
    {
      "x": 2,
      "y": 5,
      "z": -2,
      "name": "Wood_Kweebec_Planks"
    },
    {
      "x": 2,
      "y": 6,
      "z": -2,
      "name": "Wood_Kweebec_Planks"
    },
    {
      "x": 2,
      "y": 1,
      "z": -1,
      "name": "Wood_Kweebec_Planks"
    },
    {
      "x": 2,
      "y": 2,
      "z": -1,
      "name": "Wood_Kweebec_Planks"
    },
    {
      "x": 2,
      "y": 3,
      "z": -1,
      "name": "Wood_Kweebec_Planks"
    },
    {
      "x": 2,
      "y": 4,
      "z": -1,
      "name": "Wood_Kweebec_Planks"
    },
    {
      "x": 2,
      "y": 5,
      "z": -1,
      "name": "Wood_Kweebec_Planks"
    },
    {
      "x": 2,
      "y": 6,
      "z": -1,
      "name": "Wood_Kweebec_Planks"
    },
    {
      "x": 2,
      "y": 7,
      "z": -1,
      "name": "Wood_Kweebec_Planks"
    },
    {
      "x": 2,
      "y": 1,
      "z": 0,
      "name": "Wood_Kweebec_Planks"
    },
    {
      "x": 2,
      "y": 2,
      "z": 0,
      "name": "Wood_Kweebec_Planks"
    },
    {
      "x": 2,
      "y": 6,
      "z": 0,
      "name": "Wood_Kweebec_Planks"
    },
    {
      "x": 2,
      "y": 7,
      "z": 0,
      "name": "Wood_Kweebec_Planks"
    },
    {
      "x": 2,
      "y": 8,
      "z": 0,
      "name": "Deco_Rope"
    },
    {
      "x": 2,
      "y": 1,
      "z": 1,
      "name": "Wood_Kweebec_Planks"
    },
    {
      "x": 2,
      "y": 2,
      "z": 1,
      "name": "Wood_Kweebec_Planks"
    },
    {
      "x": 2,
      "y": 3,
      "z": 1,
      "name": "Wood_Kweebec_Planks"
    },
    {
      "x": 2,
      "y": 4,
      "z": 1,
      "name": "Wood_Kweebec_Planks"
    },
    {
      "x": 2,
      "y": 5,
      "z": 1,
      "name": "Wood_Kweebec_Planks"
    },
    {
      "x": 2,
      "y": 6,
      "z": 1,
      "name": "Wood_Kweebec_Planks"
    },
    {
      "x": 2,
      "y": 7,
      "z": 1,
      "name": "Wood_Kweebec_Planks"
    },
    {
      "x": 2,
      "y": 2,
      "z": 2,
      "name": "Wood_Kweebec_Planks"
    },
    {
      "x": 2,
      "y": 3,
      "z": 2,
      "name": "Wood_Kweebec_Planks"
    },
    {
      "x": 2,
      "y": 4,
      "z": 2,
      "name": "Wood_Kweebec_Planks"
    },
    {
      "x": 2,
      "y": 5,
      "z": 2,
      "name": "Wood_Kweebec_Planks"
    },
    {
      "x": 2,
      "y": 6,
      "z": 2,
      "name": "Wood_Kweebec_Planks"
    },
    {
      "x": 2,
      "y": 3,
      "z": 3,
      "name": "Wood_Kweebec_Planks"
    },
    {
      "x": 2,
      "y": 4,
      "z": 3,
      "name": "Wood_Kweebec_Planks"
    },
    {
      "x": 2,
      "y": 5,
      "z": 3,
      "name": "Wood_Kweebec_Planks"
    },
    {
      "x": 3,
      "y": 3,
      "z": -1,
      "name": "Wood_Kweebec_Planks"
    },
    {
      "x": 3,
      "y": 4,
      "z": -1,
      "name": "Wood_Kweebec_Planks"
    },
    {
      "x": 3,
      "y": 5,
      "z": -1,
      "name": "Wood_Kweebec_Planks"
    },
    {
      "x": 3,
      "y": 2,
      "z": 0,
      "name": "Wood_Kweebec_Planks"
    },
    {
      "x": 3,
      "y": 3,
      "z": 0,
      "name": "Furniture_Kweebec_Window",
      "rotation": 1
    },
    {
      "x": 3,
      "y": 4,
      "z": 0,
      "name": "Furniture_Kweebec_Window",
      "rotation": 1
    },
    {
      "x": 3,
      "y": 5,
      "z": 0,
      "name": "Wood_Kweebec_Planks"
    },
    {
      "x": 3,
      "y": 6,
      "z": 0,
      "name": "Wood_Kweebec_Planks"
    },
    {
      "x": 3,
      "y": 3,
      "z": 1,
      "name": "Wood_Kweebec_Planks"
    },
    {
      "x": 3,
      "y": 4,
      "z": 1,
      "name": "Wood_Kweebec_Planks"
    },
    {
      "x": 3,
      "y": 5,
      "z": 1,
      "name": "Wood_Kweebec_Planks"
    }
  ],
  "fluids": [
    {
      "x": -6,
      "y": 2,
      "z": 0,
      "name": "Empty",
      "level": 0
    },
    {
      "x": -5,
      "y": 2,
      "z": -1,
      "name": "Empty",
      "level": 0
    },
    {
      "x": -5,
      "y": 3,
      "z": -1,
      "name": "Empty",
      "level": 0
    },
    {
      "x": -5,
      "y": 4,
      "z": -1,
      "name": "Empty",
      "level": 0
    },
    {
      "x": -5,
      "y": 5,
      "z": -1,
      "name": "Empty",
      "level": 0
    },
    {
      "x": -5,
      "y": 2,
      "z": 0,
      "name": "Empty",
      "level": 0
    },
    {
      "x": -5,
      "y": 3,
      "z": 0,
      "name": "Empty",
      "level": 0
    },
    {
      "x": -5,
      "y": 4,
      "z": 0,
      "name": "Empty",
      "level": 0
    },
    {
      "x": -5,
      "y": 5,
      "z": 0,
      "name": "Empty",
      "level": 0
    },
    {
      "x": -5,
      "y": 2,
      "z": 1,
      "name": "Empty",
      "level": 0
    },
    {
      "x": -5,
      "y": 3,
      "z": 1,
      "name": "Empty",
      "level": 0
    },
    {
      "x": -5,
      "y": 4,
      "z": 1,
      "name": "Empty",
      "level": 0
    },
    {
      "x": -5,
      "y": 5,
      "z": 1,
      "name": "Empty",
      "level": 0
    },
    {
      "x": -4,
      "y": 3,
      "z": -3,
      "name": "Empty",
      "level": 0
    },
    {
      "x": -4,
      "y": 4,
      "z": -3,
      "name": "Empty",
      "level": 0
    },
    {
      "x": -4,
      "y": 5,
      "z": -3,
      "name": "Empty",
      "level": 0
    },
    {
      "x": -4,
      "y": 2,
      "z": -2,
      "name": "Empty",
      "level": 0
    },
    {
      "x": -4,
      "y": 3,
      "z": -2,
      "name": "Empty",
      "level": 0
    },
    {
      "x": -4,
      "y": 4,
      "z": -2,
      "name": "Empty",
      "level": 0
    },
    {
      "x": -4,
      "y": 5,
      "z": -2,
      "name": "Empty",
      "level": 0
    },
    {
      "x": -4,
      "y": 6,
      "z": -2,
      "name": "Empty",
      "level": 0
    },
    {
      "x": -4,
      "y": 1,
      "z": -1,
      "name": "Empty",
      "level": 0
    },
    {
      "x": -4,
      "y": 2,
      "z": -1,
      "name": "Empty",
      "level": 0
    },
    {
      "x": -4,
      "y": 3,
      "z": -1,
      "name": "Empty",
      "level": 0
    },
    {
      "x": -4,
      "y": 4,
      "z": -1,
      "name": "Empty",
      "level": 0
    },
    {
      "x": -4,
      "y": 5,
      "z": -1,
      "name": "Empty",
      "level": 0
    },
    {
      "x": -4,
      "y": 6,
      "z": -1,
      "name": "Empty",
      "level": 0
    },
    {
      "x": -4,
      "y": 7,
      "z": -1,
      "name": "Empty",
      "level": 0
    },
    {
      "x": -4,
      "y": 1,
      "z": 0,
      "name": "Empty",
      "level": 0
    },
    {
      "x": -4,
      "y": 2,
      "z": 0,
      "name": "Empty",
      "level": 0
    },
    {
      "x": -4,
      "y": 5,
      "z": 0,
      "name": "Empty",
      "level": 0
    },
    {
      "x": -4,
      "y": 6,
      "z": 0,
      "name": "Empty",
      "level": 0
    },
    {
      "x": -4,
      "y": 7,
      "z": 0,
      "name": "Empty",
      "level": 0
    },
    {
      "x": -4,
      "y": 8,
      "z": 0,
      "name": "Empty",
      "level": 0
    },
    {
      "x": -4,
      "y": 1,
      "z": 1,
      "name": "Empty",
      "level": 0
    },
    {
      "x": -4,
      "y": 2,
      "z": 1,
      "name": "Empty",
      "level": 0
    },
    {
      "x": -4,
      "y": 3,
      "z": 1,
      "name": "Empty",
      "level": 0
    },
    {
      "x": -4,
      "y": 4,
      "z": 1,
      "name": "Empty",
      "level": 0
    },
    {
      "x": -4,
      "y": 5,
      "z": 1,
      "name": "Empty",
      "level": 0
    },
    {
      "x": -4,
      "y": 6,
      "z": 1,
      "name": "Empty",
      "level": 0
    },
    {
      "x": -4,
      "y": 7,
      "z": 1,
      "name": "Empty",
      "level": 0
    },
    {
      "x": -4,
      "y": 2,
      "z": 2,
      "name": "Empty",
      "level": 0
    },
    {
      "x": -4,
      "y": 3,
      "z": 2,
      "name": "Empty",
      "level": 0
    },
    {
      "x": -4,
      "y": 4,
      "z": 2,
      "name": "Empty",
      "level": 0
    },
    {
      "x": -4,
      "y": 5,
      "z": 2,
      "name": "Empty",
      "level": 0
    },
    {
      "x": -4,
      "y": 6,
      "z": 2,
      "name": "Empty",
      "level": 0
    },
    {
      "x": -4,
      "y": 3,
      "z": 3,
      "name": "Empty",
      "level": 0
    },
    {
      "x": -4,
      "y": 4,
      "z": 3,
      "name": "Empty",
      "level": 0
    },
    {
      "x": -4,
      "y": 5,
      "z": 3,
      "name": "Empty",
      "level": 0
    },
    {
      "x": -3,
      "y": 2,
      "z": -3,
      "name": "Empty",
      "level": 0
    },
    {
      "x": -3,
      "y": 3,
      "z": -3,
      "name": "Empty",
      "level": 0
    },
    {
      "x": -3,
      "y": 4,
      "z": -3,
      "name": "Empty",
      "level": 0
    },
    {
      "x": -3,
      "y": 5,
      "z": -3,
      "name": "Empty",
      "level": 0
    },
    {
      "x": -3,
      "y": 6,
      "z": -3,
      "name": "Empty",
      "level": 0
    },
    {
      "x": -3,
      "y": 1,
      "z": -2,
      "name": "Empty",
      "level": 0
    },
    {
      "x": -3,
      "y": 2,
      "z": -2,
      "name": "Empty",
      "level": 0
    },
    {
      "x": -3,
      "y": 3,
      "z": -2,
      "name": "Empty",
      "level": 0
    },
    {
      "x": -3,
      "y": 4,
      "z": -2,
      "name": "Empty",
      "level": 0
    },
    {
      "x": -3,
      "y": 7,
      "z": -2,
      "name": "Empty",
      "level": 0
    },
    {
      "x": -3,
      "y": 1,
      "z": -1,
      "name": "Empty",
      "level": 0
    },
    {
      "x": -3,
      "y": 2,
      "z": -1,
      "name": "Empty",
      "level": 0
    },
    {
      "x": -3,
      "y": 7,
      "z": -1,
      "name": "Empty",
      "level": 0
    },
    {
      "x": -3,
      "y": 1,
      "z": 0,
      "name": "Empty",
      "level": 0
    },
    {
      "x": -3,
      "y": 2,
      "z": 0,
      "name": "Empty",
      "level": 0
    },
    {
      "x": -3,
      "y": 7,
      "z": 0,
      "name": "Empty",
      "level": 0
    },
    {
      "x": -3,
      "y": 1,
      "z": 1,
      "name": "Empty",
      "level": 0
    },
    {
      "x": -3,
      "y": 2,
      "z": 1,
      "name": "Empty",
      "level": 0
    },
    {
      "x": -3,
      "y": 7,
      "z": 1,
      "name": "Empty",
      "level": 0
    },
    {
      "x": -3,
      "y": 1,
      "z": 2,
      "name": "Empty",
      "level": 0
    },
    {
      "x": -3,
      "y": 2,
      "z": 2,
      "name": "Empty",
      "level": 0
    },
    {
      "x": -3,
      "y": 7,
      "z": 2,
      "name": "Empty",
      "level": 0
    },
    {
      "x": -3,
      "y": 2,
      "z": 3,
      "name": "Empty",
      "level": 0
    },
    {
      "x": -3,
      "y": 3,
      "z": 3,
      "name": "Empty",
      "level": 0
    },
    {
      "x": -3,
      "y": 4,
      "z": 3,
      "name": "Empty",
      "level": 0
    },
    {
      "x": -3,
      "y": 5,
      "z": 3,
      "name": "Empty",
      "level": 0
    },
    {
      "x": -3,
      "y": 6,
      "z": 3,
      "name": "Empty",
      "level": 0
    },
    {
      "x": -2,
      "y": 3,
      "z": -4,
      "name": "Empty",
      "level": 0
    },
    {
      "x": -2,
      "y": 4,
      "z": -4,
      "name": "Empty",
      "level": 0
    },
    {
      "x": -2,
      "y": 5,
      "z": -4,
      "name": "Empty",
      "level": 0
    },
    {
      "x": -2,
      "y": 1,
      "z": -3,
      "name": "Empty",
      "level": 0
    },
    {
      "x": -2,
      "y": 2,
      "z": -3,
      "name": "Empty",
      "level": 0
    },
    {
      "x": -2,
      "y": 6,
      "z": -3,
      "name": "Empty",
      "level": 0
    },
    {
      "x": -2,
      "y": 7,
      "z": -3,
      "name": "Empty",
      "level": 0
    },
    {
      "x": -2,
      "y": 1,
      "z": -2,
      "name": "Empty",
      "level": 0
    },
    {
      "x": -2,
      "y": 2,
      "z": -2,
      "name": "Empty",
      "level": 0
    },
    {
      "x": -2,
      "y": 7,
      "z": -2,
      "name": "Empty",
      "level": 0
    },
    {
      "x": -2,
      "y": 0,
      "z": -1,
      "name": "Empty",
      "level": 0
    },
    {
      "x": -2,
      "y": 2,
      "z": -1,
      "name": "Empty",
      "level": 0
    },
    {
      "x": -2,
      "y": 7,
      "z": -1,
      "name": "Empty",
      "level": 0
    },
    {
      "x": -2,
      "y": 8,
      "z": -1,
      "name": "Empty",
      "level": 0
    },
    {
      "x": -2,
      "y": 0,
      "z": 0,
      "name": "Empty",
      "level": 0
    },
    {
      "x": -2,
      "y": 2,
      "z": 0,
      "name": "Empty",
      "level": 0
    },
    {
      "x": -2,
      "y": 7,
      "z": 0,
      "name": "Empty",
      "level": 0
    },
    {
      "x": -2,
      "y": 8,
      "z": 0,
      "name": "Empty",
      "level": 0
    },
    {
      "x": -2,
      "y": 0,
      "z": 1,
      "name": "Empty",
      "level": 0
    },
    {
      "x": -2,
      "y": 2,
      "z": 1,
      "name": "Empty",
      "level": 0
    },
    {
      "x": -2,
      "y": 7,
      "z": 1,
      "name": "Empty",
      "level": 0
    },
    {
      "x": -2,
      "y": 8,
      "z": 1,
      "name": "Empty",
      "level": 0
    },
    {
      "x": -2,
      "y": 1,
      "z": 2,
      "name": "Empty",
      "level": 0
    },
    {
      "x": -2,
      "y": 2,
      "z": 2,
      "name": "Empty",
      "level": 0
    },
    {
      "x": -2,
      "y": 7,
      "z": 2,
      "name": "Empty",
      "level": 0
    },
    {
      "x": -2,
      "y": 1,
      "z": 3,
      "name": "Empty",
      "level": 0
    },
    {
      "x": -2,
      "y": 2,
      "z": 3,
      "name": "Empty",
      "level": 0
    },
    {
      "x": -2,
      "y": 6,
      "z": 3,
      "name": "Empty",
      "level": 0
    },
    {
      "x": -2,
      "y": 7,
      "z": 3,
      "name": "Empty",
      "level": 0
    },
    {
      "x": -2,
      "y": 3,
      "z": 4,
      "name": "Empty",
      "level": 0
    },
    {
      "x": -2,
      "y": 4,
      "z": 4,
      "name": "Empty",
      "level": 0
    },
    {
      "x": -2,
      "y": 5,
      "z": 4,
      "name": "Empty",
      "level": 0
    },
    {
      "x": -1,
      "y": 2,
      "z": -4,
      "name": "Empty",
      "level": 0
    },
    {
      "x": -1,
      "y": 3,
      "z": -4,
      "name": "Empty",
      "level": 0
    },
    {
      "x": -1,
      "y": 4,
      "z": -4,
      "name": "Empty",
      "level": 0
    },
    {
      "x": -1,
      "y": 5,
      "z": -4,
      "name": "Empty",
      "level": 0
    },
    {
      "x": -1,
      "y": 6,
      "z": -4,
      "name": "Empty",
      "level": 0
    },
    {
      "x": -1,
      "y": 7,
      "z": -4,
      "name": "Empty",
      "level": 0
    },
    {
      "x": -1,
      "y": 8,
      "z": -4,
      "name": "Empty",
      "level": 0
    },
    {
      "x": -1,
      "y": 1,
      "z": -3,
      "name": "Empty",
      "level": 0
    },
    {
      "x": -1,
      "y": 2,
      "z": -3,
      "name": "Empty",
      "level": 0
    },
    {
      "x": -1,
      "y": 3,
      "z": -3,
      "name": "Empty",
      "level": 0
    },
    {
      "x": -1,
      "y": 4,
      "z": -3,
      "name": "Empty",
      "level": 0
    },
    {
      "x": -1,
      "y": 6,
      "z": -3,
      "name": "Empty",
      "level": 0
    },
    {
      "x": -1,
      "y": 7,
      "z": -3,
      "name": "Empty",
      "level": 0
    },
    {
      "x": -1,
      "y": 1,
      "z": -2,
      "name": "Empty",
      "level": 0
    },
    {
      "x": -1,
      "y": 2,
      "z": -2,
      "name": "Empty",
      "level": 0
    },
    {
      "x": -1,
      "y": 3,
      "z": -2,
      "name": "Empty",
      "level": 0
    },
    {
      "x": -1,
      "y": 4,
      "z": -2,
      "name": "Empty",
      "level": 0
    },
    {
      "x": -1,
      "y": 7,
      "z": -2,
      "name": "Empty",
      "level": 0
    },
    {
      "x": -1,
      "y": 0,
      "z": -1,
      "name": "Empty",
      "level": 0
    },
    {
      "x": -1,
      "y": 1,
      "z": -1,
      "name": "Empty",
      "level": 0
    },
    {
      "x": -1,
      "y": 2,
      "z": -1,
      "name": "Empty",
      "level": 0
    },
    {
      "x": -1,
      "y": 7,
      "z": -1,
      "name": "Empty",
      "level": 0
    },
    {
      "x": -1,
      "y": 8,
      "z": -1,
      "name": "Empty",
      "level": 0
    },
    {
      "x": -1,
      "y": 0,
      "z": 0,
      "name": "Empty",
      "level": 0
    },
    {
      "x": -1,
      "y": 2,
      "z": 0,
      "name": "Empty",
      "level": 0
    },
    {
      "x": -1,
      "y": 8,
      "z": 0,
      "name": "Empty",
      "level": 0
    },
    {
      "x": -1,
      "y": 0,
      "z": 1,
      "name": "Empty",
      "level": 0
    },
    {
      "x": -1,
      "y": 2,
      "z": 1,
      "name": "Empty",
      "level": 0
    },
    {
      "x": -1,
      "y": 7,
      "z": 1,
      "name": "Empty",
      "level": 0
    },
    {
      "x": -1,
      "y": 8,
      "z": 1,
      "name": "Empty",
      "level": 0
    },
    {
      "x": -1,
      "y": 1,
      "z": 2,
      "name": "Empty",
      "level": 0
    },
    {
      "x": -1,
      "y": 2,
      "z": 2,
      "name": "Empty",
      "level": 0
    },
    {
      "x": -1,
      "y": 7,
      "z": 2,
      "name": "Empty",
      "level": 0
    },
    {
      "x": -1,
      "y": 1,
      "z": 3,
      "name": "Empty",
      "level": 0
    },
    {
      "x": -1,
      "y": 2,
      "z": 3,
      "name": "Empty",
      "level": 0
    },
    {
      "x": -1,
      "y": 6,
      "z": 3,
      "name": "Empty",
      "level": 0
    },
    {
      "x": -1,
      "y": 7,
      "z": 3,
      "name": "Empty",
      "level": 0
    },
    {
      "x": -1,
      "y": 2,
      "z": 4,
      "name": "Empty",
      "level": 0
    },
    {
      "x": -1,
      "y": 3,
      "z": 4,
      "name": "Empty",
      "level": 0
    },
    {
      "x": -1,
      "y": 4,
      "z": 4,
      "name": "Empty",
      "level": 0
    },
    {
      "x": -1,
      "y": 5,
      "z": 4,
      "name": "Empty",
      "level": 0
    },
    {
      "x": -1,
      "y": 6,
      "z": 4,
      "name": "Empty",
      "level": 0
    },
    {
      "x": -1,
      "y": 7,
      "z": 4,
      "name": "Empty",
      "level": 0
    },
    {
      "x": -1,
      "y": 8,
      "z": 4,
      "name": "Empty",
      "level": 0
    },
    {
      "x": 0,
      "y": 3,
      "z": -4,
      "name": "Empty",
      "level": 0
    },
    {
      "x": 0,
      "y": 4,
      "z": -4,
      "name": "Empty",
      "level": 0
    },
    {
      "x": 0,
      "y": 5,
      "z": -4,
      "name": "Empty",
      "level": 0
    },
    {
      "x": 0,
      "y": 1,
      "z": -3,
      "name": "Empty",
      "level": 0
    },
    {
      "x": 0,
      "y": 2,
      "z": -3,
      "name": "Empty",
      "level": 0
    },
    {
      "x": 0,
      "y": 6,
      "z": -3,
      "name": "Empty",
      "level": 0
    },
    {
      "x": 0,
      "y": 7,
      "z": -3,
      "name": "Empty",
      "level": 0
    },
    {
      "x": 0,
      "y": 1,
      "z": -2,
      "name": "Empty",
      "level": 0
    },
    {
      "x": 0,
      "y": 2,
      "z": -2,
      "name": "Empty",
      "level": 0
    },
    {
      "x": 0,
      "y": 7,
      "z": -2,
      "name": "Empty",
      "level": 0
    },
    {
      "x": 0,
      "y": 0,
      "z": -1,
      "name": "Empty",
      "level": 0
    },
    {
      "x": 0,
      "y": 2,
      "z": -1,
      "name": "Empty",
      "level": 0
    },
    {
      "x": 0,
      "y": 7,
      "z": -1,
      "name": "Empty",
      "level": 0
    },
    {
      "x": 0,
      "y": 8,
      "z": -1,
      "name": "Empty",
      "level": 0
    },
    {
      "x": 0,
      "y": 0,
      "z": 0,
      "name": "Empty",
      "level": 0
    },
    {
      "x": 0,
      "y": 2,
      "z": 0,
      "name": "Empty",
      "level": 0
    },
    {
      "x": 0,
      "y": 7,
      "z": 0,
      "name": "Empty",
      "level": 0
    },
    {
      "x": 0,
      "y": 8,
      "z": 0,
      "name": "Empty",
      "level": 0
    },
    {
      "x": 0,
      "y": 0,
      "z": 1,
      "name": "Empty",
      "level": 0
    },
    {
      "x": 0,
      "y": 2,
      "z": 1,
      "name": "Empty",
      "level": 0
    },
    {
      "x": 0,
      "y": 3,
      "z": 1,
      "name": "Empty",
      "level": 0
    },
    {
      "x": 0,
      "y": 7,
      "z": 1,
      "name": "Empty",
      "level": 0
    },
    {
      "x": 0,
      "y": 8,
      "z": 1,
      "name": "Empty",
      "level": 0
    },
    {
      "x": 0,
      "y": 1,
      "z": 2,
      "name": "Empty",
      "level": 0
    },
    {
      "x": 0,
      "y": 2,
      "z": 2,
      "name": "Empty",
      "level": 0
    },
    {
      "x": 0,
      "y": 3,
      "z": 2,
      "name": "Empty",
      "level": 0
    },
    {
      "x": 0,
      "y": 7,
      "z": 2,
      "name": "Empty",
      "level": 0
    },
    {
      "x": 0,
      "y": 1,
      "z": 3,
      "name": "Empty",
      "level": 0
    },
    {
      "x": 0,
      "y": 2,
      "z": 3,
      "name": "Empty",
      "level": 0
    },
    {
      "x": 0,
      "y": 6,
      "z": 3,
      "name": "Empty",
      "level": 0
    },
    {
      "x": 0,
      "y": 7,
      "z": 3,
      "name": "Empty",
      "level": 0
    },
    {
      "x": 0,
      "y": 3,
      "z": 4,
      "name": "Empty",
      "level": 0
    },
    {
      "x": 0,
      "y": 4,
      "z": 4,
      "name": "Empty",
      "level": 0
    },
    {
      "x": 0,
      "y": 5,
      "z": 4,
      "name": "Empty",
      "level": 0
    },
    {
      "x": 1,
      "y": 2,
      "z": -3,
      "name": "Empty",
      "level": 0
    },
    {
      "x": 1,
      "y": 3,
      "z": -3,
      "name": "Empty",
      "level": 0
    },
    {
      "x": 1,
      "y": 4,
      "z": -3,
      "name": "Empty",
      "level": 0
    },
    {
      "x": 1,
      "y": 5,
      "z": -3,
      "name": "Empty",
      "level": 0
    },
    {
      "x": 1,
      "y": 6,
      "z": -3,
      "name": "Empty",
      "level": 0
    },
    {
      "x": 1,
      "y": 1,
      "z": -2,
      "name": "Empty",
      "level": 0
    },
    {
      "x": 1,
      "y": 2,
      "z": -2,
      "name": "Empty",
      "level": 0
    },
    {
      "x": 1,
      "y": 3,
      "z": -2,
      "name": "Empty",
      "level": 0
    },
    {
      "x": 1,
      "y": 4,
      "z": -2,
      "name": "Empty",
      "level": 0
    },
    {
      "x": 1,
      "y": 7,
      "z": -2,
      "name": "Empty",
      "level": 0
    },
    {
      "x": 1,
      "y": 1,
      "z": -1,
      "name": "Empty",
      "level": 0
    },
    {
      "x": 1,
      "y": 2,
      "z": -1,
      "name": "Empty",
      "level": 0
    },
    {
      "x": 1,
      "y": 3,
      "z": -1,
      "name": "Empty",
      "level": 0
    },
    {
      "x": 1,
      "y": 4,
      "z": -1,
      "name": "Empty",
      "level": 0
    },
    {
      "x": 1,
      "y": 7,
      "z": -1,
      "name": "Empty",
      "level": 0
    },
    {
      "x": 1,
      "y": 1,
      "z": 0,
      "name": "Empty",
      "level": 0
    },
    {
      "x": 1,
      "y": 2,
      "z": 0,
      "name": "Empty",
      "level": 0
    },
    {
      "x": 1,
      "y": 7,
      "z": 0,
      "name": "Empty",
      "level": 0
    },
    {
      "x": 1,
      "y": 1,
      "z": 1,
      "name": "Empty",
      "level": 0
    },
    {
      "x": 1,
      "y": 2,
      "z": 1,
      "name": "Empty",
      "level": 0
    },
    {
      "x": 1,
      "y": 3,
      "z": 1,
      "name": "Empty",
      "level": 0
    },
    {
      "x": 1,
      "y": 5,
      "z": 1,
      "name": "Empty",
      "level": 0
    },
    {
      "x": 1,
      "y": 7,
      "z": 1,
      "name": "Empty",
      "level": 0
    },
    {
      "x": 1,
      "y": 1,
      "z": 2,
      "name": "Empty",
      "level": 0
    },
    {
      "x": 1,
      "y": 2,
      "z": 2,
      "name": "Empty",
      "level": 0
    },
    {
      "x": 1,
      "y": 3,
      "z": 2,
      "name": "Empty",
      "level": 0
    },
    {
      "x": 1,
      "y": 7,
      "z": 2,
      "name": "Empty",
      "level": 0
    },
    {
      "x": 1,
      "y": 2,
      "z": 3,
      "name": "Empty",
      "level": 0
    },
    {
      "x": 1,
      "y": 3,
      "z": 3,
      "name": "Empty",
      "level": 0
    },
    {
      "x": 1,
      "y": 4,
      "z": 3,
      "name": "Empty",
      "level": 0
    },
    {
      "x": 1,
      "y": 5,
      "z": 3,
      "name": "Empty",
      "level": 0
    },
    {
      "x": 1,
      "y": 6,
      "z": 3,
      "name": "Empty",
      "level": 0
    },
    {
      "x": 2,
      "y": 3,
      "z": -3,
      "name": "Empty",
      "level": 0
    },
    {
      "x": 2,
      "y": 4,
      "z": -3,
      "name": "Empty",
      "level": 0
    },
    {
      "x": 2,
      "y": 5,
      "z": -3,
      "name": "Empty",
      "level": 0
    },
    {
      "x": 2,
      "y": 2,
      "z": -2,
      "name": "Empty",
      "level": 0
    },
    {
      "x": 2,
      "y": 3,
      "z": -2,
      "name": "Empty",
      "level": 0
    },
    {
      "x": 2,
      "y": 4,
      "z": -2,
      "name": "Empty",
      "level": 0
    },
    {
      "x": 2,
      "y": 5,
      "z": -2,
      "name": "Empty",
      "level": 0
    },
    {
      "x": 2,
      "y": 6,
      "z": -2,
      "name": "Empty",
      "level": 0
    },
    {
      "x": 2,
      "y": 1,
      "z": -1,
      "name": "Empty",
      "level": 0
    },
    {
      "x": 2,
      "y": 2,
      "z": -1,
      "name": "Empty",
      "level": 0
    },
    {
      "x": 2,
      "y": 3,
      "z": -1,
      "name": "Empty",
      "level": 0
    },
    {
      "x": 2,
      "y": 4,
      "z": -1,
      "name": "Empty",
      "level": 0
    },
    {
      "x": 2,
      "y": 5,
      "z": -1,
      "name": "Empty",
      "level": 0
    },
    {
      "x": 2,
      "y": 6,
      "z": -1,
      "name": "Empty",
      "level": 0
    },
    {
      "x": 2,
      "y": 7,
      "z": -1,
      "name": "Empty",
      "level": 0
    },
    {
      "x": 2,
      "y": 1,
      "z": 0,
      "name": "Empty",
      "level": 0
    },
    {
      "x": 2,
      "y": 2,
      "z": 0,
      "name": "Empty",
      "level": 0
    },
    {
      "x": 2,
      "y": 6,
      "z": 0,
      "name": "Empty",
      "level": 0
    },
    {
      "x": 2,
      "y": 7,
      "z": 0,
      "name": "Empty",
      "level": 0
    },
    {
      "x": 2,
      "y": 8,
      "z": 0,
      "name": "Empty",
      "level": 0
    },
    {
      "x": 2,
      "y": 1,
      "z": 1,
      "name": "Empty",
      "level": 0
    },
    {
      "x": 2,
      "y": 2,
      "z": 1,
      "name": "Empty",
      "level": 0
    },
    {
      "x": 2,
      "y": 3,
      "z": 1,
      "name": "Empty",
      "level": 0
    },
    {
      "x": 2,
      "y": 4,
      "z": 1,
      "name": "Empty",
      "level": 0
    },
    {
      "x": 2,
      "y": 5,
      "z": 1,
      "name": "Empty",
      "level": 0
    },
    {
      "x": 2,
      "y": 6,
      "z": 1,
      "name": "Empty",
      "level": 0
    },
    {
      "x": 2,
      "y": 7,
      "z": 1,
      "name": "Empty",
      "level": 0
    },
    {
      "x": 2,
      "y": 2,
      "z": 2,
      "name": "Empty",
      "level": 0
    },
    {
      "x": 2,
      "y": 3,
      "z": 2,
      "name": "Empty",
      "level": 0
    },
    {
      "x": 2,
      "y": 4,
      "z": 2,
      "name": "Empty",
      "level": 0
    },
    {
      "x": 2,
      "y": 5,
      "z": 2,
      "name": "Empty",
      "level": 0
    },
    {
      "x": 2,
      "y": 6,
      "z": 2,
      "name": "Empty",
      "level": 0
    },
    {
      "x": 2,
      "y": 3,
      "z": 3,
      "name": "Empty",
      "level": 0
    },
    {
      "x": 2,
      "y": 4,
      "z": 3,
      "name": "Empty",
      "level": 0
    },
    {
      "x": 2,
      "y": 5,
      "z": 3,
      "name": "Empty",
      "level": 0
    },
    {
      "x": 3,
      "y": 3,
      "z": -1,
      "name": "Empty",
      "level": 0
    },
    {
      "x": 3,
      "y": 4,
      "z": -1,
      "name": "Empty",
      "level": 0
    },
    {
      "x": 3,
      "y": 5,
      "z": -1,
      "name": "Empty",
      "level": 0
    },
    {
      "x": 3,
      "y": 2,
      "z": 0,
      "name": "Empty",
      "level": 0
    },
    {
      "x": 3,
      "y": 3,
      "z": 0,
      "name": "Empty",
      "level": 0
    },
    {
      "x": 3,
      "y": 4,
      "z": 0,
      "name": "Empty",
      "level": 0
    },
    {
      "x": 3,
      "y": 5,
      "z": 0,
      "name": "Empty",
      "level": 0
    },
    {
      "x": 3,
      "y": 6,
      "z": 0,
      "name": "Empty",
      "level": 0
    },
    {
      "x": 3,
      "y": 3,
      "z": 1,
      "name": "Empty",
      "level": 0
    },
    {
      "x": 3,
      "y": 4,
      "z": 1,
      "name": "Empty",
      "level": 0
    },
    {
      "x": 3,
      "y": 5,
      "z": 1,
      "name": "Empty",
      "level": 0
    }
  ]
}