{
  "version": 8,
  "blockIdVersion": 11,
  "anchorX": 0,
  "anchorY": 0,
  "anchorZ": 0,
  "blocks": [
    {
      "x": -5,
      "y": 5,
      "z": -1,
      "name": "Rock_Crystal_Yellow_Block",
      "rotation": 7
    },
    {
      "x": -5,
      "y": 6,
      "z": -1,
      "name": "Rock_Crystal_Yellow_Block",
      "rotation": 7
    },
    {
      "x": -5,
      "y": 7,
      "z": -1,
      "name": "Rock_Crystal_Yellow_Block",
      "rotation": 7
    },
    {
      "x": -5,
      "y": 4,
      "z": 0,
      "name": "Rock_Crystal_Yellow_Block",
      "rotation": 7
    },
    {
      "x": -5,
      "y": 7,
      "z": 0,
      "name": "Rock_Crystal_Yellow_Block",
      "rotation": 7
    },
    {
      "x": -5,
      "y": 8,
      "z": 0,
      "name": "Rock_Crystal_Yellow_Block",
      "rotation": 7
    },
    {
      "x": -5,
      "y": 5,
      "z": 1,
      "name": "Rock_Crystal_Yellow_Block",
      "rotation": 7
    },
    {
      "x": -5,
      "y": 6,
      "z": 1,
      "name": "Rock_Crystal_Yellow_Block",
      "rotation": 7
    },
    {
      "x": -5,
      "y": 7,
      "z": 1,
      "name": "Rock_Crystal_Yellow_Block",
      "rotation": 7
    },
    {
      "x": -4,
      "y": 5,
      "z": -3,
      "name": "Rock_Crystal_Yellow_Block",
      "rotation": 7
    },
    {
      "x": -4,
      "y": 6,
      "z": -3,
      "name": "Rock_Crystal_Yellow_Block",
      "rotation": 7
    },
    {
      "x": -4,
      "y": 7,
      "z": -3,
      "name": "Rock_Crystal_Yellow_Block",
      "rotation": 7
    },
    {
      "x": -4,
      "y": 4,
      "z": -2,
      "name": "Rock_Crystal_Yellow_Block",
      "rotation": 7
    },
    {
      "x": -4,
      "y": 5,
      "z": -2,
      "name": "Rock_Crystal_Yellow_Block",
      "rotation": 7
    },
    {
      "x": -4,
      "y": 6,
      "z": -2,
      "name": "Rock_Crystal_Yellow_Block",
      "rotation": 7
    },
    {
      "x": -4,
      "y": 7,
      "z": -2,
      "name": "Rock_Crystal_Yellow_Block",
      "rotation": 7
    },
    {
      "x": -4,
      "y": 8,
      "z": -2,
      "name": "Rock_Crystal_Yellow_Block",
      "rotation": 7
    },
    {
      "x": -4,
      "y": 3,
      "z": -1,
      "name": "Rock_Crystal_Yellow_Block",
      "rotation": 7
    },
    {
      "x": -4,
      "y": 4,
      "z": -1,
      "name": "Rock_Crystal_Yellow_Block",
      "rotation": 7
    },
    {
      "x": -4,
      "y": 5,
      "z": -1,
      "name": "Wood_Kweebec_Planks",
      "rotation": 2
    },
    {
      "x": -4,
      "y": 6,
      "z": -1,
      "name": "Wood_Kweebec_Planks",
      "rotation": 2
    },
    {
      "x": -4,
      "y": 7,
      "z": -1,
      "name": "Wood_Kweebec_Planks",
      "rotation": 2
    },
    {
      "x": -4,
      "y": 8,
      "z": -1,
      "name": "Rock_Crystal_Yellow_Block",
      "rotation": 7
    },
    {
      "x": -4,
      "y": 9,
      "z": -1,
      "name": "Rock_Crystal_Yellow_Block",
      "rotation": 7
    },
    {
      "x": -4,
      "y": 3,
      "z": 0,
      "name": "Rock_Crystal_Yellow_Block",
      "rotation": 7
    },
    {
      "x": -4,
      "y": 4,
      "z": 0,
      "name": "Wood_Kweebec_Planks",
      "rotation": 2
    },
    {
      "x": -4,
      "y": 5,
      "z": 0,
      "name": "Furniture_Crude_Window",
      "rotation": 3
    },
    {
      "x": -4,
      "y": 6,
      "z": 0,
      "name": "Furniture_Crude_Window",
      "rotation": 3
    },
    {
      "x": -4,
      "y": 7,
      "z": 0,
      "name": "Wood_Kweebec_Planks",
      "rotation": 2
    },
    {
      "x": -4,
      "y": 8,
      "z": 0,
      "name": "Wood_Kweebec_Planks",
      "rotation": 2
    },
    {
      "x": -4,
      "y": 9,
      "z": 0,
      "name": "Rock_Crystal_Yellow_Block",
      "rotation": 7
    },
    {
      "x": -4,
      "y": 3,
      "z": 1,
      "name": "Rock_Crystal_Yellow_Block",
      "rotation": 7
    },
    {
      "x": -4,
      "y": 4,
      "z": 1,
      "name": "Rock_Crystal_Yellow_Block",
      "rotation": 7
    },
    {
      "x": -4,
      "y": 5,
      "z": 1,
      "name": "Wood_Kweebec_Planks",
      "rotation": 2
    },
    {
      "x": -4,
      "y": 6,
      "z": 1,
      "name": "Wood_Kweebec_Planks",
      "rotation": 2
    },
    {
      "x": -4,
      "y": 7,
      "z": 1,
      "name": "Wood_Kweebec_Planks",
      "rotation": 2
    },
    {
      "x": -4,
      "y": 8,
      "z": 1,
      "name": "Rock_Crystal_Yellow_Block",
      "rotation": 7
    },
    {
      "x": -4,
      "y": 9,
      "z": 1,
      "name": "Rock_Crystal_Yellow_Block",
      "rotation": 7
    },
    {
      "x": -4,
      "y": 4,
      "z": 2,
      "name": "Rock_Crystal_Yellow_Block",
      "rotation": 7
    },
    {
      "x": -4,
      "y": 5,
      "z": 2,
      "name": "Rock_Crystal_Yellow_Block",
      "rotation": 7
    },
    {
      "x": -4,
      "y": 6,
      "z": 2,
      "name": "Rock_Crystal_Yellow_Block",
      "rotation": 7
    },
    {
      "x": -4,
      "y": 7,
      "z": 2,
      "name": "Rock_Crystal_Yellow_Block",
      "rotation": 7
    },
    {
      "x": -4,
      "y": 8,
      "z": 2,
      "name": "Rock_Crystal_Yellow_Block",
      "rotation": 7
    },
    {
      "x": -4,
      "y": 5,
      "z": 3,
      "name": "Rock_Crystal_Yellow_Block",
      "rotation": 7
    },
    {
      "x": -4,
      "y": 6,
      "z": 3,
      "name": "Rock_Crystal_Yellow_Block",
      "rotation": 7
    },
    {
      "x": -4,
      "y": 7,
      "z": 3,
      "name": "Rock_Crystal_Yellow_Block",
      "rotation": 7
    },
    {
      "x": -3,
      "y": 5,
      "z": -4,
      "name": "Rock_Crystal_Yellow_Block",
      "rotation": 6
    },
    {
      "x": -3,
      "y": 6,
      "z": -4,
      "name": "Rock_Crystal_Yellow_Block",
      "rotation": 6
    },
    {
      "x": -3,
      "y": 7,
      "z": -4,
      "name": "Rock_Crystal_Yellow_Block",
      "rotation": 6
    },
    {
      "x": -3,
      "y": 4,
      "z": -3,
      "name": "Rock_Crystal_Yellow_Block",
      "rotation": 6
    },
    {
      "x": -3,
      "y": 5,
      "z": -3,
      "name": "Wood_Kweebec_Planks",
      "rotation": 2
    },
    {
      "x": -3,
      "y": 6,
      "z": -3,
      "name": "Wood_Kweebec_Planks",
      "rotation": 2
    },
    {
      "x": -3,
      "y": 7,
      "z": -3,
      "name": "Wood_Kweebec_Planks",
      "rotation": 2
    },
    {
      "x": -3,
      "y": 8,
      "z": -3,
      "name": "Rock_Crystal_Yellow_Block",
      "rotation": 2
    },
    {
      "x": -3,
      "y": 3,
      "z": -2,
      "name": "Rock_Crystal_Yellow_Block",
      "rotation": 7
    },
    {
      "x": -3,
      "y": 4,
      "z": -2,
      "name": "Wood_Kweebec_Planks",
      "rotation": 2
    },
    {
      "x": -3,
      "y": 5,
      "z": -2,
      "name": "Wood_Kweebec_Planks",
      "rotation": 2
    },
    {
      "x": -3,
      "y": 6,
      "z": -2,
      "name": "Wood_Kweebec_Planks",
      "rotation": 2
    },
    {
      "x": -3,
      "y": 7,
      "z": -2,
      "name": "Wood_Kweebec_Planks",
      "rotation": 2
    },
    {
      "x": -3,
      "y": 8,
      "z": -2,
      "name": "Wood_Kweebec_Planks",
      "rotation": 2
    },
    {
      "x": -3,
      "y": 9,
      "z": -2,
      "name": "Rock_Crystal_Yellow_Block",
      "rotation": 2
    },
    {
      "x": -3,
      "y": 3,
      "z": -1,
      "name": "Wood_Kweebec_Planks",
      "rotation": 2
    },
    {
      "x": -3,
      "y": 4,
      "z": -1,
      "name": "Wood_Kweebec_Planks",
      "rotation": 2
    },
    {
      "x": -3,
      "y": 5,
      "z": -1,
      "name": "Wood_Kweebec_Planks",
      "rotation": 2
    },
    {
      "x": -3,
      "y": 6,
      "z": -1,
      "name": "Wood_Kweebec_Planks",
      "rotation": 2
    },
    {
      "x": -3,
      "y": 7,
      "z": -1,
      "name": "Wood_Kweebec_Planks",
      "rotation": 2
    },
    {
      "x": -3,
      "y": 8,
      "z": -1,
      "name": "Wood_Kweebec_Planks",
      "rotation": 2
    },
    {
      "x": -3,
      "y": 9,
      "z": -1,
      "name": "Wood_Kweebec_Planks",
      "rotation": 2
    },
    {
      "x": -3,
      "y": 10,
      "z": -1,
      "name": "Rock_Crystal_Yellow_Block",
      "rotation": 2
    },
    {
      "x": -3,
      "y": 3,
      "z": 0,
      "name": "Wood_Kweebec_Planks",
      "rotation": 2
    },
    {
      "x": -3,
      "y": 4,
      "z": 0,
      "name": "Wood_Kweebec_Planks",
      "rotation": 2
    },
    {
      "x": -3,
      "y": 8,
      "z": 0,
      "name": "Wood_Kweebec_Planks",
      "rotation": 2
    },
    {
      "x": -3,
      "y": 9,
      "z": 0,
      "name": "Wood_Kweebec_Planks",
      "rotation": 2
    },
    {
      "x": -3,
      "y": 10,
      "z": 0,
      "name": "Rock_Crystal_Yellow_Block",
      "rotation": 2
    },
    {
      "x": -3,
      "y": 11,
      "z": 0,
      "name": "Deco_Rope",
      "rotation": 2
    },
    {
      "x": -3,
      "y": 12,
      "z": 0,
      "name": "Deco_Rope",
      "rotation": 2
    },
    {
      "x": -3,
      "y": 3,
      "z": 1,
      "name": "Wood_Kweebec_Planks",
      "rotation": 2
    },
    {
      "x": -3,
      "y": 4,
      "z": 1,
      "name": "Wood_Kweebec_Planks",
      "rotation": 2
    },
    {
      "x": -3,
      "y": 5,
      "z": 1,
      "name": "Wood_Kweebec_Planks",
      "rotation": 2
    },
    {
      "x": -3,
      "y": 6,
      "z": 1,
      "name": "Wood_Kweebec_Planks",
      "rotation": 2
    },
    {
      "x": -3,
      "y": 7,
      "z": 1,
      "name": "Wood_Kweebec_Planks",
      "rotation": 2
    },
    {
      "x": -3,
      "y": 8,
      "z": 1,
      "name": "Wood_Kweebec_Planks",
      "rotation": 2
    },
    {
      "x": -3,
      "y": 9,
      "z": 1,
      "name": "Wood_Kweebec_Planks",
      "rotation": 2
    },
    {
      "x": -3,
      "y": 10,
      "z": 1,
      "name": "Rock_Crystal_Yellow_Block",
      "rotation": 2
    },
    {
      "x": -3,
      "y": 3,
      "z": 2,
      "name": "Rock_Crystal_Yellow_Block",
      "rotation": 7
    },
    {
      "x": -3,
      "y": 4,
      "z": 2,
      "name": "Wood_Kweebec_Planks",
      "rotation": 2
    },
    {
      "x": -3,
      "y": 5,
      "z": 2,
      "name": "Wood_Kweebec_Planks",
      "rotation": 2
    },
    {
      "x": -3,
      "y": 6,
      "z": 2,
      "name": "Wood_Kweebec_Planks",
      "rotation": 2
    },
    {
      "x": -3,
      "y": 7,
      "z": 2,
      "name": "Wood_Kweebec_Planks",
      "rotation": 2
    },
    {
      "x": -3,
      "y": 8,
      "z": 2,
      "name": "Wood_Kweebec_Planks",
      "rotation": 2
    },
    {
      "x": -3,
      "y": 9,
      "z": 2,
      "name": "Rock_Crystal_Yellow_Block",
      "rotation": 7
    },
    {
      "x": -3,
      "y": 4,
      "z": 3,
      "name": "Rock_Crystal_Yellow_Block",
      "rotation": 7
    },
    {
      "x": -3,
      "y": 5,
      "z": 3,
      "name": "Wood_Kweebec_Planks",
      "rotation": 2
    },
    {
      "x": -3,
      "y": 6,
      "z": 3,
      "name": "Wood_Kweebec_Planks",
      "rotation": 2
    },
    {
      "x": -3,
      "y": 7,
      "z": 3,
      "name": "Wood_Kweebec_Planks",
      "rotation": 2
    },
    {
      "x": -3,
      "y": 8,
      "z": 3,
      "name": "Rock_Crystal_Yellow_Block",
      "rotation": 7
    },
    {
      "x": -3,
      "y": 5,
      "z": 4,
      "name": "Rock_Crystal_Yellow_Block",
      "rotation": 6
    },
    {
      "x": -3,
      "y": 6,
      "z": 4,
      "name": "Rock_Crystal_Yellow_Block",
      "rotation": 6
    },
    {
      "x": -3,
      "y": 7,
      "z": 4,
      "name": "Rock_Crystal_Yellow_Block",
      "rotation": 6
    },
    {
      "x": -2,
      "y": 4,
      "z": -4,
      "name": "Rock_Crystal_Yellow_Block",
      "rotation": 6
    },
    {
      "x": -2,
      "y": 5,
      "z": -4,
      "name": "Rock_Crystal_Yellow_Block",
      "rotation": 6
    },
    {
      "x": -2,
      "y": 6,
      "z": -4,
      "name": "Rock_Crystal_Yellow_Block",
      "rotation": 6
    },
    {
      "x": -2,
      "y": 7,
      "z": -4,
      "name": "Rock_Crystal_Yellow_Block",
      "rotation": 6
    },
    {
      "x": -2,
      "y": 8,
      "z": -4,
      "name": "Rock_Crystal_Yellow_Block",
      "rotation": 6
    },
    {
      "x": -2,
      "y": 3,
      "z": -3,
      "name": "Rock_Crystal_Yellow_Block",
      "rotation": 6
    },
    {
      "x": -2,
      "y": 4,
      "z": -3,
      "name": "Wood_Kweebec_Planks",
      "rotation": 2
    },
    {
      "x": -2,
      "y": 5,
      "z": -3,
      "name": "Wood_Kweebec_Planks",
      "rotation": 2
    },
    {
      "x": -2,
      "y": 6,
      "z": -3,
      "name": "Wood_Kweebec_Planks",
      "rotation": 2
    },
    {
      "x": -2,
      "y": 7,
      "z": -3,
      "name": "Wood_Kweebec_Planks",
      "rotation": 2
    },
    {
      "x": -2,
      "y": 8,
      "z": -3,
      "name": "Wood_Kweebec_Planks",
      "rotation": 2
    },
    {
      "x": -2,
      "y": 9,
      "z": -3,
      "name": "Rock_Crystal_Yellow_Block",
      "rotation": 2
    },
    {
      "x": -2,
      "y": 2,
      "z": -2,
      "name": "Rock_Crystal_Yellow_Block",
      "rotation": 7
    },
    {
      "x": -2,
      "y": 3,
      "z": -2,
      "name": "Wood_Kweebec_Planks",
      "rotation": 2
    },
    {
      "x": -2,
      "y": 4,
      "z": -2,
      "name": "Wood_Kweebec_Planks",
      "rotation": 2
    },
    {
      "x": -2,
      "y": 5,
      "z": -2,
      "name": "Furniture_Kweebec_Platform",
      "rotation": 2
    },
    {
      "x": -2,
      "y": 9,
      "z": -2,
      "name": "Wood_Kweebec_Planks",
      "rotation": 2
    },
    {
      "x": -2,
      "y": 10,
      "z": -2,
      "name": "Rock_Crystal_Yellow_Block",
      "rotation": 2
    },
    {
      "x": -2,
      "y": 2,
      "z": -1,
      "name": "Rock_Crystal_Yellow_Block",
      "rotation": 7
    },
    {
      "x": -2,
      "y": 3,
      "z": -1,
      "name": "Wood_Kweebec_Planks",
      "rotation": 2
    },
    {
      "x": -2,
      "y": 4,
      "z": -1,
      "name": "Wood_Kweebec_Planks",
      "rotation": 2
    },
    {
      "x": -2,
      "y": 5,
      "z": -1,
      "name": "Furniture_Kweebec_Platform",
      "rotation": 2
    },
    {
      "x": -2,
      "y": 7,
      "z": -1,
      "name": "Furniture_Kweebec_Painting",
      "rotation": 1
    },
    {
      "x": -2,
      "y": 9,
      "z": -1,
      "name": "Wood_Kweebec_Planks",
      "rotation": 2
    },
    {
      "x": -2,
      "y": 10,
      "z": -1,
      "name": "Rock_Crystal_Yellow_Block",
      "rotation": 2
    },
    {
      "x": -2,
      "y": 2,
      "z": 0,
      "name": "Rock_Crystal_Yellow_Block",
      "rotation": 7
    },
    {
      "x": -2,
      "y": 3,
      "z": 0,
      "name": "Wood_Kweebec_Planks",
      "rotation": 2
    },
    {
      "x": -2,
      "y": 4,
      "z": 0,
      "name": "Furniture_Kweebec_Platform",
      "rotation": 2
    },
    {
      "x": -2,
      "y": 9,
      "z": 0,
      "name": "Wood_Kweebec_Planks",
      "rotation": 2
    },
    {
      "x": -2,
      "y": 10,
      "z": 0,
      "name": "Rock_Crystal_Yellow_Block",
      "rotation": 2
    },
    {
      "x": -2,
      "y": 2,
      "z": 1,
      "name": "Rock_Crystal_Yellow_Block",
      "rotation": 7
    },
    {
      "x": -2,
      "y": 3,
      "z": 1,
      "name": "Wood_Kweebec_Planks",
      "rotation": 2
    },
    {
      "x": -2,
      "y": 4,
      "z": 1,
      "name": "Wood_Kweebec_Planks",
      "rotation": 2
    },
    {
      "x": -2,
      "y": 5,
      "z": 1,
      "name": "Furniture_Kweebec_Wardrobe",
      "rotation": 1
    },
    {
      "x": -2,
      "y": 6,
      "z": 1,
      "name": "Furniture_Kweebec_Wardrobe",
      "filler": 1024,
      "rotation": 1
    },
    {
      "x": -2,
      "y": 9,
      "z": 1,
      "name": "Wood_Kweebec_Planks",
      "rotation": 2
    },
    {
      "x": -2,
      "y": 10,
      "z": 1,
      "name": "Rock_Crystal_Yellow_Block",
      "rotation": 2
    },
    {
      "x": -2,
      "y": 3,
      "z": 2,
      "name": "Wood_Kweebec_Planks",
      "rotation": 2
    },
    {
      "x": -2,
      "y": 4,
      "z": 2,
      "name": "Wood_Kweebec_Planks",
      "rotation": 2
    },
    {
      "x": -2,
      "y": 5,
      "z": 2,
      "name": "Furniture_Kweebec_Wardrobe",
      "filler": 32,
      "rotation": 1
    },
    {
      "x": -2,
      "y": 6,
      "z": 2,
      "name": "Furniture_Kweebec_Wardrobe",
      "filler": 1056,
      "rotation": 1
    },
    {
      "x": -2,
      "y": 9,
      "z": 2,
      "name": "Wood_Kweebec_Planks",
      "rotation": 2
    },
    {
      "x": -2,
      "y": 10,
      "z": 2,
      "name": "Rock_Crystal_Yellow_Block",
      "rotation": 2
    },
    {
      "x": -2,
      "y": 3,
      "z": 3,
      "name": "Rock_Crystal_Yellow_Block",
      "rotation": 7
    },
    {
      "x": -2,
      "y": 4,
      "z": 3,
      "name": "Wood_Kweebec_Planks",
      "rotation": 2
    },
    {
      "x": -2,
      "y": 5,
      "z": 3,
      "name": "Wood_Kweebec_Planks",
      "rotation": 2
    },
    {
      "x": -2,
      "y": 6,
      "z": 3,
      "name": "Wood_Kweebec_Planks",
      "rotation": 2
    },
    {
      "x": -2,
      "y": 7,
      "z": 3,
      "name": "Wood_Kweebec_Planks",
      "rotation": 2
    },
    {
      "x": -2,
      "y": 8,
      "z": 3,
      "name": "Wood_Kweebec_Planks",
      "rotation": 2
    },
    {
      "x": -2,
      "y": 9,
      "z": 3,
      "name": "Rock_Crystal_Yellow_Block",
      "rotation": 7
    },
    {
      "x": -2,
      "y": 4,
      "z": 4,
      "name": "Rock_Crystal_Yellow_Block",
      "rotation": 6
    },
    {
      "x": -2,
      "y": 5,
      "z": 4,
      "name": "Rock_Crystal_Yellow_Block",
      "rotation": 6
    },
    {
      "x": -2,
      "y": 6,
      "z": 4,
      "name": "Rock_Crystal_Yellow_Block",
      "rotation": 6
    },
    {
      "x": -2,
      "y": 7,
      "z": 4,
      "name": "Rock_Crystal_Yellow_Block",
      "rotation": 6
    },
    {
      "x": -2,
      "y": 8,
      "z": 4,
      "name": "Rock_Crystal_Yellow_Block",
      "rotation": 2
    },
    {
      "x": -1,
      "y": 5,
      "z": -5,
      "name": "Rock_Crystal_Yellow_Block",
      "rotation": 6
    },
    {
      "x": -1,
      "y": 6,
      "z": -5,
      "name": "Rock_Crystal_Yellow_Block",
      "rotation": 6
    },
    {
      "x": -1,
      "y": 7,
      "z": -5,
      "name": "Rock_Crystal_Yellow_Block",
      "rotation": 6
    },
    {
      "x": -1,
      "y": 3,
      "z": -4,
      "name": "Rock_Crystal_Yellow_Block",
      "rotation": 6
    },
    {
      "x": -1,
      "y": 4,
      "z": -4,
      "name": "Rock_Crystal_Yellow_Block",
      "rotation": 6
    },
    {
      "x": -1,
      "y": 5,
      "z": -4,
      "name": "Wood_Kweebec_Planks",
      "rotation": 2
    },
    {
      "x": -1,
      "y": 6,
      "z": -4,
      "name": "Wood_Kweebec_Planks",
      "rotation": 2
    },
    {
      "x": -1,
      "y": 7,
      "z": -4,
      "name": "Wood_Kweebec_Planks",
      "rotation": 2
    },
    {
      "x": -1,
      "y": 8,
      "z": -4,
      "name": "Rock_Crystal_Yellow_Block",
      "rotation": 6
    },
    {
      "x": -1,
      "y": 9,
      "z": -4,
      "name": "Rock_Crystal_Yellow_Block",
      "rotation": 2
    },
    {
      "x": -1,
      "y": 2,
      "z": -3,
      "name": "Rock_Crystal_Yellow_Block",
      "rotation": 2
    },
    {
      "x": -1,
      "y": 3,
      "z": -3,
      "name": "Wood_Kweebec_Planks",
      "rotation": 2
    },
    {
      "x": -1,
      "y": 4,
      "z": -3,
      "name": "Wood_Kweebec_Planks",
      "rotation": 2
    },
    {
      "x": -1,
      "y": 8,
      "z": -3,
      "name": "Wood_Kweebec_Planks",
      "rotation": 2
    },
    {
      "x": -1,
      "y": 9,
      "z": -3,
      "name": "Wood_Kweebec_Planks",
      "rotation": 2
    },
    {
      "x": -1,
      "y": 10,
      "z": -3,
      "name": "Rock_Crystal_Yellow_Block",
      "rotation": 2
    },
    {
      "x": -1,
      "y": 2,
      "z": -2,
      "name": "Rock_Crystal_Yellow_Block",
      "rotation": 6
    },
    {
      "x": -1,
      "y": 3,
      "z": -2,
      "name": "Wood_Kweebec_Planks",
      "rotation": 2
    },
    {
      "x": -1,
      "y": 4,
      "z": -2,
      "name": "Wood_Kweebec_Planks",
      "rotation": 2
    },
    {
      "x": -1,
      "y": 5,
      "z": -2,
      "name": "Furniture_Kweebec_Stool",
      "rotation": 1
    },
    {
      "x": -1,
      "y": 9,
      "z": -2,
      "name": "Wood_Kweebec_Planks",
      "rotation": 2
    },
    {
      "x": -1,
      "y": 10,
      "z": -2,
      "name": "Rock_Crystal_Yellow_Block",
      "rotation": 2
    },
    {
      "x": -1,
      "y": 1,
      "z": -1,
      "name": "Rock_Crystal_Yellow_Block",
      "rotation": 2
    },
    {
      "x": -1,
      "y": 2,
      "z": -1,
      "name": "Wood_Kweebec_Planks",
      "rotation": 2
    },
    {
      "x": -1,
      "y": 4,
      "z": -1,
      "name": "Furniture_Kweebec_Platform",
      "rotation": 2
    },
    {
      "x": -1,
      "y": 5,
      "z": -1,
      "name": "Furniture_Kweebec_Stool",
      "rotation": 1
    },
    {
      "x": -1,
      "y": 9,
      "z": -1,
      "name": "Wood_Kweebec_Planks",
      "rotation": 2
    },
    {
      "x": -1,
      "y": 10,
      "z": -1,
      "name": "Wood_Kweebec_Planks",
      "rotation": 2
    },
    {
      "x": -1,
      "y": 11,
      "z": -1,
      "name": "Rock_Crystal_Yellow_Block",
      "rotation": 2
    },
    {
      "x": -1,
      "y": 1,
      "z": 0,
      "name": "Rock_Crystal_Yellow_Block",
      "rotation": 2
    },
    {
      "x": -1,
      "y": 2,
      "z": 0,
      "name": "Wood_Kweebec_Planks",
      "rotation": 2
    },
    {
      "x": -1,
      "y": 4,
      "z": 0,
      "name": "Furniture_Kweebec_Platform",
      "rotation": 2
    },
    {
      "x": -1,
      "y": 9,
      "z": 0,
      "name": "Wood_Kweebec_Planks",
      "rotation": 2
    },
    {
      "x": -1,
      "y": 10,
      "z": 0,
      "name": "Wood_Kweebec_Planks",
      "rotation": 2
    },
    {
      "x": -1,
      "y": 11,
      "z": 0,
      "name": "Rock_Crystal_Yellow_Block",
      "rotation": 2
    },
    {
      "x": -1,
      "y": 1,
      "z": 1,
      "name": "Rock_Crystal_Yellow_Block",
      "rotation": 2
    },
    {
      "x": -1,
      "y": 2,
      "z": 1,
      "name": "Wood_Kweebec_Planks",
      "rotation": 2
    },
    {
      "x": -1,
      "y": 4,
      "z": 1,
      "name": "Furniture_Kweebec_Platform",
      "rotation": 2
    },
    {
      "x": -1,
      "y": 9,
      "z": 1,
      "name": "Wood_Kweebec_Planks",
      "rotation": 2
    },
    {
      "x": -1,
      "y": 10,
      "z": 1,
      "name": "Wood_Kweebec_Planks",
      "rotation": 2
    },
    {
      "x": -1,
      "y": 11,
      "z": 1,
      "name": "Rock_Crystal_Yellow_Block",
      "rotation": 2
    },
    {
      "x": -1,
      "y": 2,
      "z": 2,
      "name": "Rock_Crystal_Yellow_Block",
      "rotation": 6
    },
    {
      "x": -1,
      "y": 3,
      "z": 2,
      "name": "Wood_Kweebec_Planks",
      "rotation": 2
    },
    {
      "x": -1,
      "y": 4,
      "z": 2,
      "name": "Furniture_Kweebec_Platform",
      "rotation": 2
    },
    {
      "x": -1,
      "y": 9,
      "z": 2,
      "name": "Wood_Kweebec_Planks",
      "rotation": 2
    },
    {
      "x": -1,
      "y": 10,
      "z": 2,
      "name": "Rock_Crystal_Yellow_Block",
      "rotation": 2
    },
    {
      "x": -1,
      "y": 3,
      "z": 3,
      "name": "Wood_Kweebec_Planks",
      "rotation": 2
    },
    {
      "x": -1,
      "y": 4,
      "z": 3,
      "name": "Wood_Kweebec_Planks",
      "rotation": 2
    },
    {
      "x": -1,
      "y": 8,
      "z": 3,
      "name": "Wood_Kweebec_Planks",
      "rotation": 2
    },
    {
      "x": -1,
      "y": 9,
      "z": 3,
      "name": "Wood_Kweebec_Planks",
      "rotation": 2
    },
    {
      "x": -1,
      "y": 10,
      "z": 3,
      "name": "Rock_Crystal_Yellow_Block",
      "rotation": 2
    },
    {
      "x": -1,
      "y": 3,
      "z": 4,
      "name": "Rock_Crystal_Yellow_Block",
      "rotation": 6
    },
    {
      "x": -1,
      "y": 4,
      "z": 4,
      "name": "Rock_Crystal_Yellow_Block",
      "rotation": 6
    },
    {
      "x": -1,
      "y": 5,
      "z": 4,
      "name": "Wood_Kweebec_Planks",
      "rotation": 2
    },
    {
      "x": -1,
      "y": 6,
      "z": 4,
      "name": "Wood_Kweebec_Planks",
      "rotation": 2
    },
    {
      "x": -1,
      "y": 7,
      "z": 4,
      "name": "Wood_Kweebec_Planks",
      "rotation": 2
    },
    {
      "x": -1,
      "y": 8,
      "z": 4,
      "name": "Rock_Crystal_Yellow_Block",
      "rotation": 2
    },
    {
      "x": -1,
      "y": 9,
      "z": 4,
      "name": "Rock_Crystal_Yellow_Block",
      "rotation": 2
    },
    {
      "x": -1,
      "y": 5,
      "z": 5,
      "name": "Rock_Crystal_Yellow_Block",
      "rotation": 6
    },
    {
      "x": -1,
      "y": 6,
      "z": 5,
      "name": "Rock_Crystal_Yellow_Block",
      "rotation": 6
    },
    {
      "x": -1,
      "y": 7,
      "z": 5,
      "name": "Rock_Crystal_Yellow_Block",
      "rotation": 6
    },
    {
      "x": 0,
      "y": 4,
      "z": -5,
      "name": "Rock_Crystal_Yellow_Block",
      "rotation": 6
    },
    {
      "x": 0,
      "y": 7,
      "z": -5,
      "name": "Rock_Crystal_Yellow_Block",
      "rotation": 6
    },
    {
      "x": 0,
      "y": 3,
      "z": -4,
      "name": "Rock_Crystal_Yellow_Block",
      "rotation": 6
    },
    {
      "x": 0,
      "y": 4,
      "z": -4,
      "name": "Wood_Kweebec_Planks",
      "rotation": 2
    },
    {
      "x": 0,
      "y": 5,
      "z": -4,
      "name": "Furniture_Crude_Window",
      "rotation": 2
    },
    {
      "x": 0,
      "y": 6,
      "z": -4,
      "name": "Furniture_Crude_Window",
      "rotation": 2
    },
    {
      "x": 0,
      "y": 7,
      "z": -4,
      "name": "Wood_Kweebec_Planks",
      "rotation": 2
    },
    {
      "x": 0,
      "y": 8,
      "z": -4,
      "name": "Rock_Crystal_Yellow_Block",
      "rotation": 6
    },
    {
      "x": 0,
      "y": 9,
      "z": -4,
      "name": "Rock_Crystal_Yellow_Block",
      "rotation": 2
    },
    {
      "x": 0,
      "y": 10,
      "z": -4,
      "name": "Deco_Rope",
      "rotation": 2
    },
    {
      "x": 0,
      "y": 11,
      "z": -4,
      "name": "Deco_Rope",
      "rotation": 2
    },
    {
      "x": 0,
      "y": 12,
      "z": -4,
      "name": "Deco_Rope",
      "rotation": 2
    },
    {
      "x": 0,
      "y": 2,
      "z": -3,
      "name": "Rock_Crystal_Yellow_Block",
      "rotation": 2
    },
    {
      "x": 0,
      "y": 3,
      "z": -3,
      "name": "Wood_Kweebec_Planks",
      "rotation": 2
    },
    {
      "x": 0,
      "y": 4,
      "z": -3,
      "name": "Wood_Kweebec_Planks",
      "rotation": 2
    },
    {
      "x": 0,
      "y": 8,
      "z": -3,
      "name": "Wood_Kweebec_Planks",
      "rotation": 2
    },
    {
      "x": 0,
      "y": 9,
      "z": -3,
      "name": "Wood_Kweebec_Planks",
      "rotation": 2
    },
    {
      "x": 0,
      "y": 10,
      "z": -3,
      "name": "Rock_Crystal_Yellow_Block",
      "rotation": 2
    },
    {
      "x": 0,
      "y": 2,
      "z": -2,
      "name": "Rock_Crystal_Yellow_Block",
      "rotation": 6
    },
    {
      "x": 0,
      "y": 3,
      "z": -2,
      "name": "Wood_Kweebec_Planks",
      "rotation": 2
    },
    {
      "x": 0,
      "y": 4,
      "z": -2,
      "name": "Furniture_Kweebec_Platform",
      "rotation": 3
    },
    {
      "x": 0,
      "y": 9,
      "z": -2,
      "name": "Wood_Kweebec_Planks",
      "rotation": 2
    },
    {
      "x": 0,
      "y": 10,
      "z": -2,
      "name": "Rock_Crystal_Yellow_Block",
      "rotation": 2
    },
    {
      "x": 0,
      "y": 1,
      "z": -1,
      "name": "Rock_Crystal_Yellow_Block",
      "rotation": 2
    },
    {
      "x": 0,
      "y": 2,
      "z": -1,
      "name": "Wood_Kweebec_Planks",
      "rotation": 2
    },
    {
      "x": 0,
      "y": 4,
      "z": -1,
      "name": "Furniture_Kweebec_Platform",
      "rotation": 3
    },
    {
      "x": 0,
      "y": 9,
      "z": -1,
      "name": "Wood_Kweebec_Planks",
      "rotation": 2
    },
    {
      "x": 0,
      "y": 10,
      "z": -1,
      "name": "Wood_Kweebec_Planks",
      "rotation": 2
    },
    {
      "x": 0,
      "y": 11,
      "z": -1,
      "name": "Rock_Crystal_Yellow_Block",
      "rotation": 2
    },
    {
      "x": 0,
      "y": 1,
      "z": 0,
      "name": "Rock_Crystal_Yellow_Block",
      "rotation": 2
    },
    {
      "x": 0,
      "y": 2,
      "z": 0,
      "name": "Wood_Kweebec_Planks",
      "rotation": 2
    },
    {
      "x": 0,
      "y": 4,
      "z": 0,
      "name": "*Furniture_Kweebec_Trapdoor_State_Definitions_CloseDoorOut"
    },
    {
      "x": 0,
      "y": 10,
      "z": 0,
      "name": "Wood_Kweebec_Planks",
      "rotation": 2
    },
    {
      "x": 0,
      "y": 11,
      "z": 0,
      "name": "Rock_Crystal_Yellow_Block",
      "rotation": 2
    },
    {
      "x": 0,
      "y": 12,
      "z": 0,
      "name": "Deco_Rope",
      "rotation": 2
    },
    {
      "x": 0,
      "y": 1,
      "z": 1,
      "name": "Rock_Crystal_Yellow_Block",
      "rotation": 2
    },
    {
      "x": 0,
      "y": 2,
      "z": 1,
      "name": "Wood_Kweebec_Planks",
      "rotation": 2
    },
    {
      "x": 0,
      "y": 3,
      "z": 1,
      "name": "Furniture_Kweebec_Chest_Small",
      "components": {
        "Components": {
          "ItemContainerBlock": {
            "ItemContainer": {
              "Capacity": 18,
              "Items": {}
            },
            "Capacity": 18
          }
        }
      },
      "rotation": 2
    },
    {
      "x": 0,
      "y": 4,
      "z": 1,
      "name": "Furniture_Kweebec_Platform",
      "rotation": 2
    },
    {
      "x": 0,
      "y": 9,
      "z": 1,
      "name": "Wood_Kweebec_Planks",
      "rotation": 2
    },
    {
      "x": 0,
      "y": 10,
      "z": 1,
      "name": "Wood_Kweebec_Planks",
      "rotation": 2
    },
    {
      "x": 0,
      "y": 11,
      "z": 1,
      "name": "Rock_Crystal_Yellow_Block",
      "rotation": 2
    },
    {
      "x": 0,
      "y": 2,
      "z": 2,
      "name": "Rock_Crystal_Yellow_Block",
      "rotation": 6
    },
    {
      "x": 0,
      "y": 3,
      "z": 2,
      "name": "Wood_Kweebec_Planks",
      "rotation": 2
    },
    {
      "x": 0,
      "y": 4,
      "z": 2,
      "name": "Furniture_Kweebec_Platform",
      "rotation": 2
    },
    {
      "x": 0,
      "y": 5,
      "z": 2,
      "name": "Furniture_Kweebec_Bed",
      "filler": 992,
      "rotation": 2
    },
    {
      "x": 0,
      "y": 6,
      "z": 2,
      "name": "Furniture_Kweebec_Bed",
      "filler": 2016,
      "rotation": 2
    },
    {
      "x": 0,
      "y": 9,
      "z": 2,
      "name": "Wood_Kweebec_Planks",
      "rotation": 2
    },
    {
      "x": 0,
      "y": 10,
      "z": 2,
      "name": "Rock_Crystal_Yellow_Block",
      "rotation": 2
    },
    {
      "x": 0,
      "y": 3,
      "z": 3,
      "name": "Wood_Kweebec_Planks",
      "rotation": 2
    },
    {
      "x": 0,
      "y": 4,
      "z": 3,
      "name": "Wood_Kweebec_Planks",
      "rotation": 2
    },
    {
      "x": 0,
      "y": 5,
      "z": 3,
      "name": "Furniture_Kweebec_Bed",
      "components": {
        "Components": {
          "PlacedByInteraction": {
            "WhoPlacedUuid": {
              "$binary": "Jkzvo0hoTZaBZsSL3nwDMA==",
              "$type": "04"
            }
          },
          "RespawnBlock": {}
        }
      },
      "rotation": 2
    },
    {
      "x": 0,
      "y": 6,
      "z": 3,
      "name": "Furniture_Kweebec_Bed",
      "filler": 1024,
      "rotation": 2
    },
    {
      "x": 0,
      "y": 8,
      "z": 3,
      "name": "Wood_Kweebec_Planks",
      "rotation": 2
    },
    {
      "x": 0,
      "y": 9,
      "z": 3,
      "name": "Wood_Kweebec_Planks",
      "rotation": 2
    },
    {
      "x": 0,
      "y": 10,
      "z": 3,
      "name": "Rock_Crystal_Yellow_Block",
      "rotation": 2
    },
    {
      "x": 0,
      "y": 3,
      "z": 4,
      "name": "Rock_Crystal_Yellow_Block",
      "rotation": 6
    },
    {
      "x": 0,
      "y": 4,
      "z": 4,
      "name": "Wood_Kweebec_Planks",
      "rotation": 2
    },
    {
      "x": 0,
      "y": 5,
      "z": 4,
      "name": "Furniture_Crude_Window",
      "rotation": 2
    },
    {
      "x": 0,
      "y": 6,
      "z": 4,
      "name": "Furniture_Crude_Window",
      "rotation": 2
    },
    {
      "x": 0,
      "y": 7,
      "z": 4,
      "name": "Wood_Kweebec_Planks",
      "rotation": 2
    },
    {
      "x": 0,
      "y": 8,
      "z": 4,
      "name": "Rock_Crystal_Yellow_Block",
      "rotation": 2
    },
    {
      "x": 0,
      "y": 9,
      "z": 4,
      "name": "Rock_Crystal_Yellow_Block",
      "rotation": 2
    },
    {
      "x": 0,
      "y": 10,
      "z": 4,
      "name": "Deco_Rope",
      "rotation": 2
    },
    {
      "x": 0,
      "y": 4,
      "z": 5,
      "name": "Rock_Crystal_Yellow_Block",
      "rotation": 6
    },
    {
      "x": 0,
      "y": 7,
      "z": 5,
      "name": "Rock_Crystal_Yellow_Block",
      "rotation": 6
    },
    {
      "x": 1,
      "y": 5,
      "z": -5,
      "name": "Rock_Crystal_Yellow_Block",
      "rotation": 6
    },
    {
      "x": 1,
      "y": 6,
      "z": -5,
      "name": "Rock_Crystal_Yellow_Block",
      "rotation": 6
    },
    {
      "x": 1,
      "y": 7,
      "z": -5,
      "name": "Rock_Crystal_Yellow_Block",
      "rotation": 6
    },
    {
      "x": 1,
      "y": 3,
      "z": -4,
      "name": "Rock_Crystal_Yellow_Block",
      "rotation": 6
    },
    {
      "x": 1,
      "y": 4,
      "z": -4,
      "name": "Rock_Crystal_Yellow_Block",
      "rotation": 6
    },
    {
      "x": 1,
      "y": 5,
      "z": -4,
      "name": "Wood_Kweebec_Planks",
      "rotation": 2
    },
    {
      "x": 1,
      "y": 6,
      "z": -4,
      "name": "Wood_Kweebec_Planks",
      "rotation": 2
    },
    {
      "x": 1,
      "y": 7,
      "z": -4,
      "name": "Wood_Kweebec_Planks",
      "rotation": 2
    },
    {
      "x": 1,
      "y": 8,
      "z": -4,
      "name": "Rock_Crystal_Yellow_Block",
      "rotation": 6
    },
    {
      "x": 1,
      "y": 9,
      "z": -4,
      "name": "Rock_Crystal_Yellow_Block",
      "rotation": 2
    },
    {
      "x": 1,
      "y": 2,
      "z": -3,
      "name": "Rock_Crystal_Yellow_Block",
      "rotation": 2
    },
    {
      "x": 1,
      "y": 3,
      "z": -3,
      "name": "Wood_Kweebec_Planks",
      "rotation": 2
    },
    {
      "x": 1,
      "y": 4,
      "z": -3,
      "name": "Wood_Kweebec_Planks",
      "rotation": 2
    },
    {
      "x": 1,
      "y": 8,
      "z": -3,
      "name": "Wood_Kweebec_Planks",
      "rotation": 2
    },
    {
      "x": 1,
      "y": 9,
      "z": -3,
      "name": "Wood_Kweebec_Planks",
      "rotation": 2
    },
    {
      "x": 1,
      "y": 10,
      "z": -3,
      "name": "Rock_Crystal_Yellow_Block",
      "rotation": 2
    },
    {
      "x": 1,
      "y": 2,
      "z": -2,
      "name": "Rock_Crystal_Yellow_Block",
      "rotation": 6
    },
    {
      "x": 1,
      "y": 3,
      "z": -2,
      "name": "Wood_Kweebec_Planks",
      "rotation": 2
    },
    {
      "x": 1,
      "y": 4,
      "z": -2,
      "name": "Wood_Kweebec_Planks",
      "rotation": 2
    },
    {
      "x": 1,
      "y": 9,
      "z": -2,
      "name": "Wood_Kweebec_Planks",
      "rotation": 2
    },
    {
      "x": 1,
      "y": 10,
      "z": -2,
      "name": "Rock_Crystal_Yellow_Block",
      "rotation": 2
    },
    {
      "x": 1,
      "y": 1,
      "z": -1,
      "name": "Rock_Crystal_Yellow_Block",
      "rotation": 2
    },
    {
      "x": 1,
      "y": 2,
      "z": -1,
      "name": "Wood_Kweebec_Planks",
      "rotation": 2
    },
    {
      "x": 1,
      "y": 4,
      "z": -1,
      "name": "Furniture_Kweebec_Platform",
      "rotation": 2
    },
    {
      "x": 1,
      "y": 9,
      "z": -1,
      "name": "Wood_Kweebec_Planks",
      "rotation": 2
    },
    {
      "x": 1,
      "y": 10,
      "z": -1,
      "name": "Wood_Kweebec_Planks",
      "rotation": 2
    },
    {
      "x": 1,
      "y": 11,
      "z": -1,
      "name": "Rock_Crystal_Yellow_Block",
      "rotation": 2
    },
    {
      "x": 1,
      "y": 1,
      "z": 0,
      "name": "Rock_Crystal_Yellow_Block",
      "rotation": 2
    },
    {
      "x": 1,
      "y": 2,
      "z": 0,
      "name": "Wood_Kweebec_Planks",
      "rotation": 2
    },
    {
      "x": 1,
      "y": 4,
      "z": 0,
      "name": "Furniture_Kweebec_Platform",
      "rotation": 2
    },
    {
      "x": 1,
      "y": 9,
      "z": 0,
      "name": "Wood_Kweebec_Planks",
      "rotation": 2
    },
    {
      "x": 1,
      "y": 10,
      "z": 0,
      "name": "Wood_Kweebec_Planks",
      "rotation": 2
    },
    {
      "x": 1,
      "y": 11,
      "z": 0,
      "name": "Rock_Crystal_Yellow_Block",
      "rotation": 2
    },
    {
      "x": 1,
      "y": 1,
      "z": 1,
      "name": "Rock_Crystal_Yellow_Block",
      "rotation": 2
    },
    {
      "x": 1,
      "y": 2,
      "z": 1,
      "name": "Wood_Kweebec_Planks",
      "rotation": 2
    },
    {
      "x": 1,
      "y": 4,
      "z": 1,
      "name": "Furniture_Kweebec_Platform",
      "rotation": 2
    },
    {
      "x": 1,
      "y": 9,
      "z": 1,
      "name": "Wood_Kweebec_Planks",
      "rotation": 2
    },
    {
      "x": 1,
      "y": 10,
      "z": 1,
      "name": "Wood_Kweebec_Planks",
      "rotation": 2
    },
    {
      "x": 1,
      "y": 11,
      "z": 1,
      "name": "Rock_Crystal_Yellow_Block",
      "rotation": 2
    },
    {
      "x": 1,
      "y": 2,
      "z": 2,
      "name": "Rock_Crystal_Yellow_Block",
      "rotation": 6
    },
    {
      "x": 1,
      "y": 3,
      "z": 2,
      "name": "Wood_Kweebec_Planks",
      "rotation": 2
    },
    {
      "x": 1,
      "y": 4,
      "z": 2,
      "name": "Furniture_Kweebec_Platform",
      "rotation": 2
    },
    {
      "x": 1,
      "y": 9,
      "z": 2,
      "name": "Wood_Kweebec_Planks",
      "rotation": 2
    },
    {
      "x": 1,
      "y": 10,
      "z": 2,
      "name": "Rock_Crystal_Yellow_Block",
      "rotation": 2
    },
    {
      "x": 1,
      "y": 3,
      "z": 3,
      "name": "Wood_Kweebec_Planks",
      "rotation": 2
    },
    {
      "x": 1,
      "y": 4,
      "z": 3,
      "name": "Wood_Kweebec_Planks",
      "rotation": 2
    },
    {
      "x": 1,
      "y": 8,
      "z": 3,
      "name": "Wood_Kweebec_Planks",
      "rotation": 2
    },
    {
      "x": 1,
      "y": 9,
      "z": 3,
      "name": "Wood_Kweebec_Planks",
      "rotation": 2
    },
    {
      "x": 1,
      "y": 10,
      "z": 3,
      "name": "Rock_Crystal_Yellow_Block",
      "rotation": 2
    },
    {
      "x": 1,
      "y": 3,
      "z": 4,
      "name": "Rock_Crystal_Yellow_Block",
      "rotation": 6
    },
    {
      "x": 1,
      "y": 4,
      "z": 4,
      "name": "Rock_Crystal_Yellow_Block",
      "rotation": 6
    },
    {
      "x": 1,
      "y": 5,
      "z": 4,
      "name": "Wood_Kweebec_Planks",
      "rotation": 2
    },
    {
      "x": 1,
      "y": 6,
      "z": 4,
      "name": "Wood_Kweebec_Planks",
      "rotation": 2
    },
    {
      "x": 1,
      "y": 7,
      "z": 4,
      "name": "Wood_Kweebec_Planks",
      "rotation": 2
    },
    {
      "x": 1,
      "y": 8,
      "z": 4,
      "name": "Rock_Crystal_Yellow_Block",
      "rotation": 2
    },
    {
      "x": 1,
      "y": 9,
      "z": 4,
      "name": "Rock_Crystal_Yellow_Block",
      "rotation": 2
    },
    {
      "x": 1,
      "y": 5,
      "z": 5,
      "name": "Rock_Crystal_Yellow_Block",
      "rotation": 6
    },
    {
      "x": 1,
      "y": 6,
      "z": 5,
      "name": "Rock_Crystal_Yellow_Block",
      "rotation": 6
    },
    {
      "x": 1,
      "y": 7,
      "z": 5,
      "name": "Rock_Crystal_Yellow_Block",
      "rotation": 6
    },
    {
      "x": 2,
      "y": 4,
      "z": -4,
      "name": "Rock_Crystal_Yellow_Block",
      "rotation": 6
    },
    {
      "x": 2,
      "y": 5,
      "z": -4,
      "name": "Rock_Crystal_Yellow_Block",
      "rotation": 6
    },
    {
      "x": 2,
      "y": 6,
      "z": -4,
      "name": "Rock_Crystal_Yellow_Block",
      "rotation": 6
    },
    {
      "x": 2,
      "y": 7,
      "z": -4,
      "name": "Rock_Crystal_Yellow_Block",
      "rotation": 6
    },
    {
      "x": 2,
      "y": 8,
      "z": -4,
      "name": "Rock_Crystal_Yellow_Block",
      "rotation": 6
    },
    {
      "x": 2,
      "y": 3,
      "z": -3,
      "name": "Rock_Crystal_Yellow_Block",
      "rotation": 6
    },
    {
      "x": 2,
      "y": 4,
      "z": -3,
      "name": "Wood_Kweebec_Planks",
      "rotation": 2
    },
    {
      "x": 2,
      "y": 5,
      "z": -3,
      "name": "Wood_Kweebec_Planks",
      "rotation": 2
    },
    {
      "x": 2,
      "y": 6,
      "z": -3,
      "name": "Wood_Kweebec_Planks",
      "rotation": 2
    },
    {
      "x": 2,
      "y": 7,
      "z": -3,
      "name": "Wood_Kweebec_Planks",
      "rotation": 2
    },
    {
      "x": 2,
      "y": 8,
      "z": -3,
      "name": "Wood_Kweebec_Planks",
      "rotation": 2
    },
    {
      "x": 2,
      "y": 9,
      "z": -3,
      "name": "Rock_Crystal_Yellow_Block",
      "rotation": 7
    },
    {
      "x": 2,
      "y": 2,
      "z": -2,
      "name": "Rock_Crystal_Yellow_Block",
      "rotation": 7
    },
    {
      "x": 2,
      "y": 3,
      "z": -2,
      "name": "Wood_Kweebec_Planks",
      "rotation": 2
    },
    {
      "x": 2,
      "y": 4,
      "z": -2,
      "name": "Wood_Kweebec_Planks",
      "rotation": 2
    },
    {
      "x": 2,
      "y": 9,
      "z": -2,
      "name": "Wood_Kweebec_Planks",
      "rotation": 2
    },
    {
      "x": 2,
      "y": 10,
      "z": -2,
      "name": "Rock_Crystal_Yellow_Block",
      "rotation": 2
    },
    {
      "x": 2,
      "y": 2,
      "z": -1,
      "name": "Rock_Crystal_Yellow_Block",
      "rotation": 7
    },
    {
      "x": 2,
      "y": 3,
      "z": -1,
      "name": "Wood_Kweebec_Planks",
      "rotation": 2
    },
    {
      "x": 2,
      "y": 4,
      "z": -1,
      "name": "Wood_Kweebec_Planks",
      "rotation": 2
    },
    {
      "x": 2,
      "y": 9,
      "z": -1,
      "name": "Wood_Kweebec_Planks",
      "rotation": 2
    },
    {
      "x": 2,
      "y": 10,
      "z": -1,
      "name": "Rock_Crystal_Yellow_Block",
      "rotation": 2
    },
    {
      "x": 2,
      "y": 2,
      "z": 0,
      "name": "Rock_Crystal_Yellow_Block",
      "rotation": 7
    },
    {
      "x": 2,
      "y": 3,
      "z": 0,
      "name": "Wood_Kweebec_Planks",
      "rotation": 2
    },
    {
      "x": 2,
      "y": 4,
      "z": 0,
      "name": "Furniture_Kweebec_Platform",
      "rotation": 2
    },
    {
      "x": 2,
      "y": 9,
      "z": 0,
      "name": "Wood_Kweebec_Planks",
      "rotation": 2
    },
    {
      "x": 2,
      "y": 10,
      "z": 0,
      "name": "Rock_Crystal_Yellow_Block",
      "rotation": 2
    },
    {
      "x": 2,
      "y": 2,
      "z": 1,
      "name": "Rock_Crystal_Yellow_Block",
      "rotation": 7
    },
    {
      "x": 2,
      "y": 3,
      "z": 1,
      "name": "Wood_Kweebec_Planks",
      "rotation": 2
    },
    {
      "x": 2,
      "y": 4,
      "z": 1,
      "name": "Wood_Kweebec_Planks",
      "rotation": 2
    },
    {
      "x": 2,
      "y": 5,
      "z": 1,
      "name": "Furniture_Crude_Window",
      "rotation": 3
    },
    {
      "x": 2,
      "y": 9,
      "z": 1,
      "name": "Wood_Kweebec_Planks",
      "rotation": 2
    },
    {
      "x": 2,
      "y": 10,
      "z": 1,
      "name": "Rock_Crystal_Yellow_Block",
      "rotation": 2
    },
    {
      "x": 2,
      "y": 2,
      "z": 2,
      "name": "Rock_Crystal_Yellow_Block",
      "rotation": 2
    },
    {
      "x": 2,
      "y": 3,
      "z": 2,
      "name": "Wood_Kweebec_Planks",
      "rotation": 2
    },
    {
      "x": 2,
      "y": 4,
      "z": 2,
      "name": "Wood_Kweebec_Planks",
      "rotation": 2
    },
    {
      "x": 2,
      "y": 5,
      "z": 2,
      "name": "Furniture_Kweebec_Shelf",
      "rotation": 3
    },
    {
      "x": 2,
      "y": 6,
      "z": 2,
      "name": "*Furniture_Kweebec_Candle_State_Definitions_Off",
      "rotation": 2
    },
    {
      "x": 2,
      "y": 9,
      "z": 2,
      "name": "Wood_Kweebec_Planks",
      "rotation": 2
    },
    {
      "x": 2,
      "y": 10,
      "z": 2,
      "name": "Rock_Crystal_Yellow_Block",
      "rotation": 2
    },
    {
      "x": 2,
      "y": 3,
      "z": 3,
      "name": "Rock_Crystal_Yellow_Block",
      "rotation": 6
    },
    {
      "x": 2,
      "y": 4,
      "z": 3,
      "name": "Wood_Kweebec_Planks",
      "rotation": 2
    },
    {
      "x": 2,
      "y": 5,
      "z": 3,
      "name": "Wood_Kweebec_Planks",
      "rotation": 2
    },
    {
      "x": 2,
      "y": 6,
      "z": 3,
      "name": "Wood_Kweebec_Planks",
      "rotation": 2
    },
    {
      "x": 2,
      "y": 7,
      "z": 3,
      "name": "Wood_Kweebec_Planks",
      "rotation": 2
    },
    {
      "x": 2,
      "y": 8,
      "z": 3,
      "name": "Wood_Kweebec_Planks",
      "rotation": 2
    },
    {
      "x": 2,
      "y": 9,
      "z": 3,
      "name": "Rock_Crystal_Yellow_Block",
      "rotation": 2
    },
    {
      "x": 2,
      "y": 4,
      "z": 4,
      "name": "Rock_Crystal_Yellow_Block",
      "rotation": 6
    },
    {
      "x": 2,
      "y": 5,
      "z": 4,
      "name": "Rock_Crystal_Yellow_Block",
      "rotation": 6
    },
    {
      "x": 2,
      "y": 6,
      "z": 4,
      "name": "Rock_Crystal_Yellow_Block",
      "rotation": 6
    },
    {
      "x": 2,
      "y": 7,
      "z": 4,
      "name": "Rock_Crystal_Yellow_Block",
      "rotation": 6
    },
    {
      "x": 2,
      "y": 8,
      "z": 4,
      "name": "Rock_Crystal_Yellow_Block",
      "rotation": 4
    },
    {
      "x": 3,
      "y": 5,
      "z": -4,
      "name": "Rock_Crystal_Yellow_Block",
      "rotation": 6
    },
    {
      "x": 3,
      "y": 6,
      "z": -4,
      "name": "Rock_Crystal_Yellow_Block",
      "rotation": 6
    },
    {
      "x": 3,
      "y": 7,
      "z": -4,
      "name": "Rock_Crystal_Yellow_Block",
      "rotation": 6
    },
    {
      "x": 3,
      "y": 4,
      "z": -3,
      "name": "Rock_Crystal_Yellow_Block",
      "rotation": 7
    },
    {
      "x": 3,
      "y": 5,
      "z": -3,
      "name": "Wood_Kweebec_Planks",
      "rotation": 2
    },
    {
      "x": 3,
      "y": 6,
      "z": -3,
      "name": "Wood_Kweebec_Planks",
      "rotation": 2
    },
    {
      "x": 3,
      "y": 7,
      "z": -3,
      "name": "Wood_Kweebec_Planks",
      "rotation": 2
    },
    {
      "x": 3,
      "y": 8,
      "z": -3,
      "name": "Rock_Crystal_Yellow_Block",
      "rotation": 2
    },
    {
      "x": 3,
      "y": 3,
      "z": -2,
      "name": "Rock_Crystal_Yellow_Block",
      "rotation": 7
    },
    {
      "x": 3,
      "y": 4,
      "z": -2,
      "name": "Wood_Kweebec_Planks",
      "rotation": 2
    },
    {
      "x": 3,
      "y": 5,
      "z": -2,
      "name": "Wood_Kweebec_Planks",
      "rotation": 2
    },
    {
      "x": 3,
      "y": 6,
      "z": -2,
      "name": "Wood_Kweebec_Planks",
      "rotation": 2
    },
    {
      "x": 3,
      "y": 7,
      "z": -2,
      "name": "Furniture_Crude_Window",
      "rotation": 3
    },
    {
      "x": 3,
      "y": 8,
      "z": -2,
      "name": "Wood_Kweebec_Planks",
      "rotation": 2
    },
    {
      "x": 3,
      "y": 9,
      "z": -2,
      "name": "Rock_Crystal_Yellow_Block",
      "rotation": 7
    },
    {
      "x": 3,
      "y": 3,
      "z": -1,
      "name": "Wood_Kweebec_Planks",
      "rotation": 2
    },
    {
      "x": 3,
      "y": 4,
      "z": -1,
      "name": "Wood_Kweebec_Planks",
      "rotation": 2
    },
    {
      "x": 3,
      "y": 5,
      "z": -1,
      "name": "Wood_Kweebec_Planks",
      "rotation": 2
    },
    {
      "x": 3,
      "y": 6,
      "z": -1,
      "name": "Wood_Kweebec_Planks",
      "rotation": 2
    },
    {
      "x": 3,
      "y": 7,
      "z": -1,
      "name": "Wood_Kweebec_Planks",
      "rotation": 2
    },
    {
      "x": 3,
      "y": 8,
      "z": -1,
      "name": "Wood_Kweebec_Planks",
      "rotation": 2
    },
    {
      "x": 3,
      "y": 9,
      "z": -1,
      "name": "Wood_Kweebec_Planks",
      "rotation": 2
    },
    {
      "x": 3,
      "y": 10,
      "z": -1,
      "name": "Rock_Crystal_Yellow_Block",
      "rotation": 2
    },
    {
      "x": 3,
      "y": 3,
      "z": 0,
      "name": "Wood_Kweebec_Planks",
      "rotation": 2
    },
    {
      "x": 3,
      "y": 4,
      "z": 0,
      "name": "Wood_Kweebec_Planks",
      "rotation": 2
    },
    {
      "x": 3,
      "y": 5,
      "z": 0,
      "name": "*Furniture_Kweebec_Door_State_Definitions_OpenDoorOut",
      "filler": 31,
      "rotation": 1
    },
    {
      "x": 3,
      "y": 6,
      "z": 0,
      "name": "*Furniture_Kweebec_Door_State_Definitions_OpenDoorOut",
      "filler": 1055,
      "rotation": 1
    },
    {
      "x": 3,
      "y": 7,
      "z": 0,
      "name": "Wood_Kweebec_Planks",
      "rotation": 2
    },
    {
      "x": 3,
      "y": 8,
      "z": 0,
      "name": "Wood_Kweebec_Planks",
      "rotation": 2
    },
    {
      "x": 3,
      "y": 9,
      "z": 0,
      "name": "Wood_Kweebec_Planks",
      "rotation": 2
    },
    {
      "x": 3,
      "y": 10,
      "z": 0,
      "name": "Rock_Crystal_Yellow_Block",
      "rotation": 2
    },
    {
      "x": 3,
      "y": 11,
      "z": 0,
      "name": "Deco_Rope",
      "rotation": 2
    },
    {
      "x": 3,
      "y": 12,
      "z": 0,
      "name": "Deco_Rope",
      "rotation": 2
    },
    {
      "x": 3,
      "y": 3,
      "z": 1,
      "name": "Wood_Kweebec_Planks",
      "rotation": 2
    },
    {
      "x": 3,
      "y": 4,
      "z": 1,
      "name": "Wood_Kweebec_Planks",
      "rotation": 2
    },
    {
      "x": 3,
      "y": 5,
      "z": 1,
      "name": "Wood_Kweebec_Planks",
      "rotation": 2
    },
    {
      "x": 3,
      "y": 6,
      "z": 1,
      "name": "Wood_Kweebec_Planks",
      "rotation": 2
    },
    {
      "x": 3,
      "y": 7,
      "z": 1,
      "name": "Wood_Kweebec_Planks",
      "rotation": 2
    },
    {
      "x": 3,
      "y": 8,
      "z": 1,
      "name": "Wood_Kweebec_Planks",
      "rotation": 2
    },
    {
      "x": 3,
      "y": 9,
      "z": 1,
      "name": "Wood_Kweebec_Planks",
      "rotation": 2
    },
    {
      "x": 3,
      "y": 10,
      "z": 1,
      "name": "Rock_Crystal_Yellow_Block",
      "rotation": 2
    },
    {
      "x": 3,
      "y": 3,
      "z": 2,
      "name": "Rock_Crystal_Yellow_Block",
      "rotation": 6
    },
    {
      "x": 3,
      "y": 4,
      "z": 2,
      "name": "Wood_Kweebec_Planks",
      "rotation": 2
    },
    {
      "x": 3,
      "y": 5,
      "z": 2,
      "name": "Wood_Kweebec_Planks",
      "rotation": 2
    },
    {
      "x": 3,
      "y": 6,
      "z": 2,
      "name": "Wood_Kweebec_Planks",
      "rotation": 2
    },
    {
      "x": 3,
      "y": 7,
      "z": 2,
      "name": "Furniture_Crude_Window",
      "rotation": 3
    },
    {
      "x": 3,
      "y": 8,
      "z": 2,
      "name": "Wood_Kweebec_Planks",
      "rotation": 2
    },
    {
      "x": 3,
      "y": 9,
      "z": 2,
      "name": "Rock_Crystal_Yellow_Block",
      "rotation": 2
    },
    {
      "x": 3,
      "y": 4,
      "z": 3,
      "name": "Rock_Crystal_Yellow_Block",
      "rotation": 6
    },
    {
      "x": 3,
      "y": 5,
      "z": 3,
      "name": "Wood_Kweebec_Planks",
      "rotation": 2
    },
    {
      "x": 3,
      "y": 6,
      "z": 3,
      "name": "Wood_Kweebec_Planks",
      "rotation": 2
    },
    {
      "x": 3,
      "y": 7,
      "z": 3,
      "name": "Wood_Kweebec_Planks",
      "rotation": 2
    },
    {
      "x": 3,
      "y": 8,
      "z": 3,
      "name": "Rock_Crystal_Yellow_Block",
      "rotation": 2
    },
    {
      "x": 3,
      "y": 5,
      "z": 4,
      "name": "Rock_Crystal_Yellow_Block",
      "rotation": 6
    },
    {
      "x": 3,
      "y": 6,
      "z": 4,
      "name": "Rock_Crystal_Yellow_Block",
      "rotation": 6
    },
    {
      "x": 3,
      "y": 7,
      "z": 4,
      "name": "Rock_Crystal_Yellow_Block",
      "rotation": 6
    },
    {
      "x": 4,
      "y": 5,
      "z": -3,
      "name": "Rock_Crystal_Yellow_Block",
      "rotation": 7
    },
    {
      "x": 4,
      "y": 6,
      "z": -3,
      "name": "Rock_Crystal_Yellow_Block",
      "rotation": 7
    },
    {
      "x": 4,
      "y": 7,
      "z": -3,
      "name": "Rock_Crystal_Yellow_Block",
      "rotation": 7
    },
    {
      "x": 4,
      "y": 4,
      "z": -2,
      "name": "Rock_Crystal_Yellow_Block",
      "rotation": 6
    },
    {
      "x": 4,
      "y": 5,
      "z": -2,
      "name": "Rock_Crystal_Yellow_Block",
      "rotation": 6
    },
    {
      "x": 4,
      "y": 6,
      "z": -2,
      "name": "Rock_Crystal_Yellow_Block",
      "rotation": 6
    },
    {
      "x": 4,
      "y": 8,
      "z": -2,
      "name": "Rock_Crystal_Yellow_Block",
      "rotation": 7
    },
    {
      "x": 4,
      "y": 3,
      "z": -1,
      "name": "Rock_Crystal_Yellow_Block",
      "rotation": 7
    },
    {
      "x": 4,
      "y": 4,
      "z": -1,
      "name": "Wood_Kweebec_Planks",
      "rotation": 2
    },
    {
      "x": 4,
      "y": 5,
      "z": -1,
      "name": "Wood_Kweebec_Planks",
      "rotation": 2
    },
    {
      "x": 4,
      "y": 6,
      "z": -1,
      "name": "Wood_Kweebec_Planks",
      "rotation": 2
    },
    {
      "x": 4,
      "y": 7,
      "z": -1,
      "name": "Wood_Kweebec_Planks",
      "rotation": 2
    },
    {
      "x": 4,
      "y": 8,
      "z": -1,
      "name": "Rock_Crystal_Yellow_Block",
      "rotation": 7
    },
    {
      "x": 4,
      "y": 9,
      "z": -1,
      "name": "Rock_Crystal_Yellow_Block",
      "rotation": 7
    },
    {
      "x": 4,
      "y": 3,
      "z": 0,
      "name": "Rock_Crystal_Yellow_Block",
      "rotation": 7
    },
    {
      "x": 4,
      "y": 4,
      "z": 0,
      "name": "Wood_Kweebec_Planks",
      "rotation": 2
    },
    {
      "x": 4,
      "y": 5,
      "z": 0,
      "name": "*Furniture_Kweebec_Door_State_Definitions_OpenDoorOut",
      "rotation": 1
    },
    {
      "x": 4,
      "y": 6,
      "z": 0,
      "name": "*Furniture_Kweebec_Door_State_Definitions_OpenDoorOut",
      "filler": 1024,
      "rotation": 1
    },
    {
      "x": 4,
      "y": 7,
      "z": 0,
      "name": "Wood_Kweebec_Planks",
      "rotation": 2
    },
    {
      "x": 4,
      "y": 8,
      "z": 0,
      "name": "Rock_Crystal_Yellow_Block",
      "rotation": 7
    },
    {
      "x": 4,
      "y": 9,
      "z": 0,
      "name": "Rock_Crystal_Yellow_Block",
      "rotation": 7
    },
    {
      "x": 4,
      "y": 3,
      "z": 1,
      "name": "Rock_Crystal_Yellow_Block",
      "rotation": 7
    },
    {
      "x": 4,
      "y": 4,
      "z": 1,
      "name": "Wood_Kweebec_Planks",
      "rotation": 2
    },
    {
      "x": 4,
      "y": 5,
      "z": 1,
      "name": "Wood_Kweebec_Planks",
      "rotation": 2
    },
    {
      "x": 4,
      "y": 6,
      "z": 1,
      "name": "Wood_Kweebec_Planks",
      "rotation": 2
    },
    {
      "x": 4,
      "y": 7,
      "z": 1,
      "name": "Wood_Kweebec_Planks",
      "rotation": 2
    },
    {
      "x": 4,
      "y": 8,
      "z": 1,
      "name": "Rock_Crystal_Yellow_Block",
      "rotation": 7
    },
    {
      "x": 4,
      "y": 9,
      "z": 1,
      "name": "Rock_Crystal_Yellow_Block",
      "rotation": 7
    },
    {
      "x": 4,
      "y": 4,
      "z": 2,
      "name": "Rock_Crystal_Yellow_Block",
      "rotation": 7
    },
    {
      "x": 4,
      "y": 5,
      "z": 2,
      "name": "Rock_Crystal_Yellow_Block",
      "rotation": 7
    },
    {
      "x": 4,
      "y": 6,
      "z": 2,
      "name": "Rock_Crystal_Yellow_Block",
      "rotation": 2
    },
    {
      "x": 4,
      "y": 8,
      "z": 2,
      "name": "Rock_Crystal_Yellow_Block",
      "rotation": 7
    },
    {
      "x": 4,
      "y": 5,
      "z": 3,
      "name": "Rock_Crystal_Yellow_Block",
      "rotation": 7
    },
    {
      "x": 4,
      "y": 6,
      "z": 3,
      "name": "Rock_Crystal_Yellow_Block",
      "rotation": 7
    },
    {
      "x": 4,
      "y": 7,
      "z": 3,
      "name": "Rock_Crystal_Yellow_Block",
      "rotation": 7
    },
    {
      "x": 5,
      "y": 4,
      "z": -1,
      "name": "Rock_Crystal_Yellow_Block",
      "rotation": 7
    },
    {
      "x": 5,
      "y": 5,
      "z": -1,
      "name": "Rock_Crystal_Yellow_Block",
      "rotation": 7
    },
    {
      "x": 5,
      "y": 6,
      "z": -1,
      "name": "Rock_Crystal_Yellow_Block",
      "rotation": 7
    },
    {
      "x": 5,
      "y": 7,
      "z": -1,
      "name": "Rock_Crystal_Yellow_Block",
      "rotation": 7
    },
    {
      "x": 5,
      "y": 4,
      "z": 0,
      "name": "Rock_Crystal_Yellow_Block",
      "rotation": 7
    },
    {
      "x": 5,
      "y": 7,
      "z": 0,
      "name": "Rock_Crystal_Yellow_Block",
      "rotation": 7
    },
    {
      "x": 5,
      "y": 4,
      "z": 1,
      "name": "Rock_Crystal_Yellow_Block",
      "rotation": 7
    },
    {
      "x": 5,
      "y": 5,
      "z": 1,
      "name": "Rock_Crystal_Yellow_Block",
      "rotation": 7
    },
    {
      "x": 5,
      "y": 6,
      "z": 1,
      "name": "Rock_Crystal_Yellow_Block",
      "rotation": 7
    },
    {
      "x": 5,
      "y": 7,
      "z": 1,
      "name": "Rock_Crystal_Yellow_Block",
      "rotation": 7
    },
    {
      "x": 6,
      "y": 4,
      "z": 0,
      "name": "Furniture_Kweebec_Platform",
      "rotation": 3
    }
  ],
  "fluids": [
    {
      "x": -5,
      "y": 5,
      "z": -1,
      "name": "Empty",
      "level": 0
    },
    {
      "x": -5,
      "y": 6,
      "z": -1,
      "name": "Empty",
      "level": 0
    },
    {
      "x": -5,
      "y": 7,
      "z": -1,
      "name": "Empty",
      "level": 0
    },
    {
      "x": -5,
      "y": 4,
      "z": 0,
      "name": "Empty",
      "level": 0
    },
    {
      "x": -5,
      "y": 7,
      "z": 0,
      "name": "Empty",
      "level": 0
    },
    {
      "x": -5,
      "y": 8,
      "z": 0,
      "name": "Empty",
      "level": 0
    },
    {
      "x": -5,
      "y": 5,
      "z": 1,
      "name": "Empty",
      "level": 0
    },
    {
      "x": -5,
      "y": 6,
      "z": 1,
      "name": "Empty",
      "level": 0
    },
    {
      "x": -5,
      "y": 7,
      "z": 1,
      "name": "Empty",
      "level": 0
    },
    {
      "x": -4,
      "y": 5,
      "z": -3,
      "name": "Empty",
      "level": 0
    },
    {
      "x": -4,
      "y": 6,
      "z": -3,
      "name": "Empty",
      "level": 0
    },
    {
      "x": -4,
      "y": 7,
      "z": -3,
      "name": "Empty",
      "level": 0
    },
    {
      "x": -4,
      "y": 4,
      "z": -2,
      "name": "Empty",
      "level": 0
    },
    {
      "x": -4,
      "y": 5,
      "z": -2,
      "name": "Empty",
      "level": 0
    },
    {
      "x": -4,
      "y": 6,
      "z": -2,
      "name": "Empty",
      "level": 0
    },
    {
      "x": -4,
      "y": 7,
      "z": -2,
      "name": "Empty",
      "level": 0
    },
    {
      "x": -4,
      "y": 8,
      "z": -2,
      "name": "Empty",
      "level": 0
    },
    {
      "x": -4,
      "y": 3,
      "z": -1,
      "name": "Empty",
      "level": 0
    },
    {
      "x": -4,
      "y": 4,
      "z": -1,
      "name": "Empty",
      "level": 0
    },
    {
      "x": -4,
      "y": 5,
      "z": -1,
      "name": "Empty",
      "level": 0
    },
    {
      "x": -4,
      "y": 6,
      "z": -1,
      "name": "Empty",
      "level": 0
    },
    {
      "x": -4,
      "y": 7,
      "z": -1,
      "name": "Empty",
      "level": 0
    },
    {
      "x": -4,
      "y": 8,
      "z": -1,
      "name": "Empty",
      "level": 0
    },
    {
      "x": -4,
      "y": 9,
      "z": -1,
      "name": "Empty",
      "level": 0
    },
    {
      "x": -4,
      "y": 3,
      "z": 0,
      "name": "Empty",
      "level": 0
    },
    {
      "x": -4,
      "y": 4,
      "z": 0,
      "name": "Empty",
      "level": 0
    },
    {
      "x": -4,
      "y": 5,
      "z": 0,
      "name": "Empty",
      "level": 0
    },
    {
      "x": -4,
      "y": 6,
      "z": 0,
      "name": "Empty",
      "level": 0
    },
    {
      "x": -4,
      "y": 7,
      "z": 0,
      "name": "Empty",
      "level": 0
    },
    {
      "x": -4,
      "y": 8,
      "z": 0,
      "name": "Empty",
      "level": 0
    },
    {
      "x": -4,
      "y": 9,
      "z": 0,
      "name": "Empty",
      "level": 0
    },
    {
      "x": -4,
      "y": 3,
      "z": 1,
      "name": "Empty",
      "level": 0
    },
    {
      "x": -4,
      "y": 4,
      "z": 1,
      "name": "Empty",
      "level": 0
    },
    {
      "x": -4,
      "y": 5,
      "z": 1,
      "name": "Empty",
      "level": 0
    },
    {
      "x": -4,
      "y": 6,
      "z": 1,
      "name": "Empty",
      "level": 0
    },
    {
      "x": -4,
      "y": 7,
      "z": 1,
      "name": "Empty",
      "level": 0
    },
    {
      "x": -4,
      "y": 8,
      "z": 1,
      "name": "Empty",
      "level": 0
    },
    {
      "x": -4,
      "y": 9,
      "z": 1,
      "name": "Empty",
      "level": 0
    },
    {
      "x": -4,
      "y": 4,
      "z": 2,
      "name": "Empty",
      "level": 0
    },
    {
      "x": -4,
      "y": 5,
      "z": 2,
      "name": "Empty",
      "level": 0
    },
    {
      "x": -4,
      "y": 6,
      "z": 2,
      "name": "Empty",
      "level": 0
    },
    {
      "x": -4,
      "y": 7,
      "z": 2,
      "name": "Empty",
      "level": 0
    },
    {
      "x": -4,
      "y": 8,
      "z": 2,
      "name": "Empty",
      "level": 0
    },
    {
      "x": -4,
      "y": 5,
      "z": 3,
      "name": "Empty",
      "level": 0
    },
    {
      "x": -4,
      "y": 6,
      "z": 3,
      "name": "Empty",
      "level": 0
    },
    {
      "x": -4,
      "y": 7,
      "z": 3,
      "name": "Empty",
      "level": 0
    },
    {
      "x": -3,
      "y": 5,
      "z": -4,
      "name": "Empty",
      "level": 0
    },
    {
      "x": -3,
      "y": 6,
      "z": -4,
      "name": "Empty",
      "level": 0
    },
    {
      "x": -3,
      "y": 7,
      "z": -4,
      "name": "Empty",
      "level": 0
    },
    {
      "x": -3,
      "y": 4,
      "z": -3,
      "name": "Empty",
      "level": 0
    },
    {
      "x": -3,
      "y": 5,
      "z": -3,
      "name": "Empty",
      "level": 0
    },
    {
      "x": -3,
      "y": 6,
      "z": -3,
      "name": "Empty",
      "level": 0
    },
    {
      "x": -3,
      "y": 7,
      "z": -3,
      "name": "Empty",
      "level": 0
    },
    {
      "x": -3,
      "y": 8,
      "z": -3,
      "name": "Empty",
      "level": 0
    },
    {
      "x": -3,
      "y": 3,
      "z": -2,
      "name": "Empty",
      "level": 0
    },
    {
      "x": -3,
      "y": 4,
      "z": -2,
      "name": "Empty",
      "level": 0
    },
    {
      "x": -3,
      "y": 5,
      "z": -2,
      "name": "Empty",
      "level": 0
    },
    {
      "x": -3,
      "y": 6,
      "z": -2,
      "name": "Empty",
      "level": 0
    },
    {
      "x": -3,
      "y": 7,
      "z": -2,
      "name": "Empty",
      "level": 0
    },
    {
      "x": -3,
      "y": 8,
      "z": -2,
      "name": "Empty",
      "level": 0
    },
    {
      "x": -3,
      "y": 9,
      "z": -2,
      "name": "Empty",
      "level": 0
    },
    {
      "x": -3,
      "y": 3,
      "z": -1,
      "name": "Empty",
      "level": 0
    },
    {
      "x": -3,
      "y": 4,
      "z": -1,
      "name": "Empty",
      "level": 0
    },
    {
      "x": -3,
      "y": 5,
      "z": -1,
      "name": "Empty",
      "level": 0
    },
    {
      "x": -3,
      "y": 6,
      "z": -1,
      "name": "Empty",
      "level": 0
    },
    {
      "x": -3,
      "y": 7,
      "z": -1,
      "name": "Empty",
      "level": 0
    },
    {
      "x": -3,
      "y": 8,
      "z": -1,
      "name": "Empty",
      "level": 0
    },
    {
      "x": -3,
      "y": 9,
      "z": -1,
      "name": "Empty",
      "level": 0
    },
    {
      "x": -3,
      "y": 10,
      "z": -1,
      "name": "Empty",
      "level": 0
    },
    {
      "x": -3,
      "y": 3,
      "z": 0,
      "name": "Empty",
      "level": 0
    },
    {
      "x": -3,
      "y": 4,
      "z": 0,
      "name": "Empty",
      "level": 0
    },
    {
      "x": -3,
      "y": 8,
      "z": 0,
      "name": "Empty",
      "level": 0
    },
    {
      "x": -3,
      "y": 9,
      "z": 0,
      "name": "Empty",
      "level": 0
    },
    {
      "x": -3,
      "y": 10,
      "z": 0,
      "name": "Empty",
      "level": 0
    },
    {
      "x": -3,
      "y": 11,
      "z": 0,
      "name": "Empty",
      "level": 0
    },
    {
      "x": -3,
      "y": 12,
      "z": 0,
      "name": "Empty",
      "level": 0
    },
    {
      "x": -3,
      "y": 3,
      "z": 1,
      "name": "Empty",
      "level": 0
    },
    {
      "x": -3,
      "y": 4,
      "z": 1,
      "name": "Empty",
      "level": 0
    },
    {
      "x": -3,
      "y": 5,
      "z": 1,
      "name": "Empty",
      "level": 0
    },
    {
      "x": -3,
      "y": 6,
      "z": 1,
      "name": "Empty",
      "level": 0
    },
    {
      "x": -3,
      "y": 7,
      "z": 1,
      "name": "Empty",
      "level": 0
    },
    {
      "x": -3,
      "y": 8,
      "z": 1,
      "name": "Empty",
      "level": 0
    },
    {
      "x": -3,
      "y": 9,
      "z": 1,
      "name": "Empty",
      "level": 0
    },
    {
      "x": -3,
      "y": 10,
      "z": 1,
      "name": "Empty",
      "level": 0
    },
    {
      "x": -3,
      "y": 3,
      "z": 2,
      "name": "Empty",
      "level": 0
    },
    {
      "x": -3,
      "y": 4,
      "z": 2,
      "name": "Empty",
      "level": 0
    },
    {
      "x": -3,
      "y": 5,
      "z": 2,
      "name": "Empty",
      "level": 0
    },
    {
      "x": -3,
      "y": 6,
      "z": 2,
      "name": "Empty",
      "level": 0
    },
    {
      "x": -3,
      "y": 7,
      "z": 2,
      "name": "Empty",
      "level": 0
    },
    {
      "x": -3,
      "y": 8,
      "z": 2,
      "name": "Empty",
      "level": 0
    },
    {
      "x": -3,
      "y": 9,
      "z": 2,
      "name": "Empty",
      "level": 0
    },
    {
      "x": -3,
      "y": 4,
      "z": 3,
      "name": "Empty",
      "level": 0
    },
    {
      "x": -3,
      "y": 5,
      "z": 3,
      "name": "Empty",
      "level": 0
    },
    {
      "x": -3,
      "y": 6,
      "z": 3,
      "name": "Empty",
      "level": 0
    },
    {
      "x": -3,
      "y": 7,
      "z": 3,
      "name": "Empty",
      "level": 0
    },
    {
      "x": -3,
      "y": 8,
      "z": 3,
      "name": "Empty",
      "level": 0
    },
    {
      "x": -3,
      "y": 5,
      "z": 4,
      "name": "Empty",
      "level": 0
    },
    {
      "x": -3,
      "y": 6,
      "z": 4,
      "name": "Empty",
      "level": 0
    },
    {
      "x": -3,
      "y": 7,
      "z": 4,
      "name": "Empty",
      "level": 0
    },
    {
      "x": -2,
      "y": 4,
      "z": -4,
      "name": "Empty",
      "level": 0
    },
    {
      "x": -2,
      "y": 5,
      "z": -4,
      "name": "Empty",
      "level": 0
    },
    {
      "x": -2,
      "y": 6,
      "z": -4,
      "name": "Empty",
      "level": 0
    },
    {
      "x": -2,
      "y": 7,
      "z": -4,
      "name": "Empty",
      "level": 0
    },
    {
      "x": -2,
      "y": 8,
      "z": -4,
      "name": "Empty",
      "level": 0
    },
    {
      "x": -2,
      "y": 3,
      "z": -3,
      "name": "Empty",
      "level": 0
    },
    {
      "x": -2,
      "y": 4,
      "z": -3,
      "name": "Empty",
      "level": 0
    },
    {
      "x": -2,
      "y": 5,
      "z": -3,
      "name": "Empty",
      "level": 0
    },
    {
      "x": -2,
      "y": 6,
      "z": -3,
      "name": "Empty",
      "level": 0
    },
    {
      "x": -2,
      "y": 7,
      "z": -3,
      "name": "Empty",
      "level": 0
    },
    {
      "x": -2,
      "y": 8,
      "z": -3,
      "name": "Empty",
      "level": 0
    },
    {
      "x": -2,
      "y": 9,
      "z": -3,
      "name": "Empty",
      "level": 0
    },
    {
      "x": -2,
      "y": 2,
      "z": -2,
      "name": "Empty",
      "level": 0
    },
    {
      "x": -2,
      "y": 3,
      "z": -2,
      "name": "Empty",
      "level": 0
    },
    {
      "x": -2,
      "y": 4,
      "z": -2,
      "name": "Empty",
      "level": 0
    },
    {
      "x": -2,
      "y": 5,
      "z": -2,
      "name": "Empty",
      "level": 0
    },
    {
      "x": -2,
      "y": 9,
      "z": -2,
      "name": "Empty",
      "level": 0
    },
    {
      "x": -2,
      "y": 10,
      "z": -2,
      "name": "Empty",
      "level": 0
    },
    {
      "x": -2,
      "y": 2,
      "z": -1,
      "name": "Empty",
      "level": 0
    },
    {
      "x": -2,
      "y": 3,
      "z": -1,
      "name": "Empty",
      "level": 0
    },
    {
      "x": -2,
      "y": 4,
      "z": -1,
      "name": "Empty",
      "level": 0
    },
    {
      "x": -2,
      "y": 5,
      "z": -1,
      "name": "Empty",
      "level": 0
    },
    {
      "x": -2,
      "y": 7,
      "z": -1,
      "name": "Empty",
      "level": 0
    },
    {
      "x": -2,
      "y": 9,
      "z": -1,
      "name": "Empty",
      "level": 0
    },
    {
      "x": -2,
      "y": 10,
      "z": -1,
      "name": "Empty",
      "level": 0
    },
    {
      "x": -2,
      "y": 2,
      "z": 0,
      "name": "Empty",
      "level": 0
    },
    {
      "x": -2,
      "y": 3,
      "z": 0,
      "name": "Empty",
      "level": 0
    },
    {
      "x": -2,
      "y": 4,
      "z": 0,
      "name": "Empty",
      "level": 0
    },
    {
      "x": -2,
      "y": 9,
      "z": 0,
      "name": "Empty",
      "level": 0
    },
    {
      "x": -2,
      "y": 10,
      "z": 0,
      "name": "Empty",
      "level": 0
    },
    {
      "x": -2,
      "y": 2,
      "z": 1,
      "name": "Empty",
      "level": 0
    },
    {
      "x": -2,
      "y": 3,
      "z": 1,
      "name": "Empty",
      "level": 0
    },
    {
      "x": -2,
      "y": 4,
      "z": 1,
      "name": "Empty",
      "level": 0
    },
    {
      "x": -2,
      "y": 5,
      "z": 1,
      "name": "Empty",
      "level": 0
    },
    {
      "x": -2,
      "y": 6,
      "z": 1,
      "name": "Empty",
      "level": 0
    },
    {
      "x": -2,
      "y": 9,
      "z": 1,
      "name": "Empty",
      "level": 0
    },
    {
      "x": -2,
      "y": 10,
      "z": 1,
      "name": "Empty",
      "level": 0
    },
    {
      "x": -2,
      "y": 3,
      "z": 2,
      "name": "Empty",
      "level": 0
    },
    {
      "x": -2,
      "y": 4,
      "z": 2,
      "name": "Empty",
      "level": 0
    },
    {
      "x": -2,
      "y": 5,
      "z": 2,
      "name": "Empty",
      "level": 0
    },
    {
      "x": -2,
      "y": 6,
      "z": 2,
      "name": "Empty",
      "level": 0
    },
    {
      "x": -2,
      "y": 9,
      "z": 2,
      "name": "Empty",
      "level": 0
    },
    {
      "x": -2,
      "y": 10,
      "z": 2,
      "name": "Empty",
      "level": 0
    },
    {
      "x": -2,
      "y": 3,
      "z": 3,
      "name": "Empty",
      "level": 0
    },
    {
      "x": -2,
      "y": 4,
      "z": 3,
      "name": "Empty",
      "level": 0
    },
    {
      "x": -2,
      "y": 5,
      "z": 3,
      "name": "Empty",
      "level": 0
    },
    {
      "x": -2,
      "y": 6,
      "z": 3,
      "name": "Empty",
      "level": 0
    },
    {
      "x": -2,
      "y": 7,
      "z": 3,
      "name": "Empty",
      "level": 0
    },
    {
      "x": -2,
      "y": 8,
      "z": 3,
      "name": "Empty",
      "level": 0
    },
    {
      "x": -2,
      "y": 9,
      "z": 3,
      "name": "Empty",
      "level": 0
    },
    {
      "x": -2,
      "y": 4,
      "z": 4,
      "name": "Empty",
      "level": 0
    },
    {
      "x": -2,
      "y": 5,
      "z": 4,
      "name": "Empty",
      "level": 0
    },
    {
      "x": -2,
      "y": 6,
      "z": 4,
      "name": "Empty",
      "level": 0
    },
    {
      "x": -2,
      "y": 7,
      "z": 4,
      "name": "Empty",
      "level": 0
    },
    {
      "x": -2,
      "y": 8,
      "z": 4,
      "name": "Empty",
      "level": 0
    },
    {
      "x": -1,
      "y": 5,
      "z": -5,
      "name": "Empty",
      "level": 0
    },
    {
      "x": -1,
      "y": 6,
      "z": -5,
      "name": "Empty",
      "level": 0
    },
    {
      "x": -1,
      "y": 7,
      "z": -5,
      "name": "Empty",
      "level": 0
    },
    {
      "x": -1,
      "y": 3,
      "z": -4,
      "name": "Empty",
      "level": 0
    },
    {
      "x": -1,
      "y": 4,
      "z": -4,
      "name": "Empty",
      "level": 0
    },
    {
      "x": -1,
      "y": 5,
      "z": -4,
      "name": "Empty",
      "level": 0
    },
    {
      "x": -1,
      "y": 6,
      "z": -4,
      "name": "Empty",
      "level": 0
    },
    {
      "x": -1,
      "y": 7,
      "z": -4,
      "name": "Empty",
      "level": 0
    },
    {
      "x": -1,
      "y": 8,
      "z": -4,
      "name": "Empty",
      "level": 0
    },
    {
      "x": -1,
      "y": 9,
      "z": -4,
      "name": "Empty",
      "level": 0
    },
    {
      "x": -1,
      "y": 2,
      "z": -3,
      "name": "Empty",
      "level": 0
    },
    {
      "x": -1,
      "y": 3,
      "z": -3,
      "name": "Empty",
      "level": 0
    },
    {
      "x": -1,
      "y": 4,
      "z": -3,
      "name": "Empty",
      "level": 0
    },
    {
      "x": -1,
      "y": 8,
      "z": -3,
      "name": "Empty",
      "level": 0
    },
    {
      "x": -1,
      "y": 9,
      "z": -3,
      "name": "Empty",
      "level": 0
    },
    {
      "x": -1,
      "y": 10,
      "z": -3,
      "name": "Empty",
      "level": 0
    },
    {
      "x": -1,
      "y": 2,
      "z": -2,
      "name": "Empty",
      "level": 0
    },
    {
      "x": -1,
      "y": 3,
      "z": -2,
      "name": "Empty",
      "level": 0
    },
    {
      "x": -1,
      "y": 4,
      "z": -2,
      "name": "Empty",
      "level": 0
    },
    {
      "x": -1,
      "y": 5,
      "z": -2,
      "name": "Empty",
      "level": 0
    },
    {
      "x": -1,
      "y": 9,
      "z": -2,
      "name": "Empty",
      "level": 0
    },
    {
      "x": -1,
      "y": 10,
      "z": -2,
      "name": "Empty",
      "level": 0
    },
    {
      "x": -1,
      "y": 1,
      "z": -1,
      "name": "Empty",
      "level": 0
    },
    {
      "x": -1,
      "y": 2,
      "z": -1,
      "name": "Empty",
      "level": 0
    },
    {
      "x": -1,
      "y": 4,
      "z": -1,
      "name": "Empty",
      "level": 0
    },
    {
      "x": -1,
      "y": 5,
      "z": -1,
      "name": "Empty",
      "level": 0
    },
    {
      "x": -1,
      "y": 9,
      "z": -1,
      "name": "Empty",
      "level": 0
    },
    {
      "x": -1,
      "y": 10,
      "z": -1,
      "name": "Empty",
      "level": 0
    },
    {
      "x": -1,
      "y": 11,
      "z": -1,
      "name": "Empty",
      "level": 0
    },
    {
      "x": -1,
      "y": 1,
      "z": 0,
      "name": "Empty",
      "level": 0
    },
    {
      "x": -1,
      "y": 2,
      "z": 0,
      "name": "Empty",
      "level": 0
    },
    {
      "x": -1,
      "y": 4,
      "z": 0,
      "name": "Empty",
      "level": 0
    },
    {
      "x": -1,
      "y": 9,
      "z": 0,
      "name": "Empty",
      "level": 0
    },
    {
      "x": -1,
      "y": 10,
      "z": 0,
      "name": "Empty",
      "level": 0
    },
    {
      "x": -1,
      "y": 11,
      "z": 0,
      "name": "Empty",
      "level": 0
    },
    {
      "x": -1,
      "y": 1,
      "z": 1,
      "name": "Empty",
      "level": 0
    },
    {
      "x": -1,
      "y": 2,
      "z": 1,
      "name": "Empty",
      "level": 0
    },
    {
      "x": -1,
      "y": 4,
      "z": 1,
      "name": "Empty",
      "level": 0
    },
    {
      "x": -1,
      "y": 9,
      "z": 1,
      "name": "Empty",
      "level": 0
    },
    {
      "x": -1,
      "y": 10,
      "z": 1,
      "name": "Empty",
      "level": 0
    },
    {
      "x": -1,
      "y": 11,
      "z": 1,
      "name": "Empty",
      "level": 0
    },
    {
      "x": -1,
      "y": 2,
      "z": 2,
      "name": "Empty",
      "level": 0
    },
    {
      "x": -1,
      "y": 3,
      "z": 2,
      "name": "Empty",
      "level": 0
    },
    {
      "x": -1,
      "y": 4,
      "z": 2,
      "name": "Empty",
      "level": 0
    },
    {
      "x": -1,
      "y": 9,
      "z": 2,
      "name": "Empty",
      "level": 0
    },
    {
      "x": -1,
      "y": 10,
      "z": 2,
      "name": "Empty",
      "level": 0
    },
    {
      "x": -1,
      "y": 3,
      "z": 3,
      "name": "Empty",
      "level": 0
    },
    {
      "x": -1,
      "y": 4,
      "z": 3,
      "name": "Empty",
      "level": 0
    },
    {
      "x": -1,
      "y": 8,
      "z": 3,
      "name": "Empty",
      "level": 0
    },
    {
      "x": -1,
      "y": 9,
      "z": 3,
      "name": "Empty",
      "level": 0
    },
    {
      "x": -1,
      "y": 10,
      "z": 3,
      "name": "Empty",
      "level": 0
    },
    {
      "x": -1,
      "y": 3,
      "z": 4,
      "name": "Empty",
      "level": 0
    },
    {
      "x": -1,
      "y": 4,
      "z": 4,
      "name": "Empty",
      "level": 0
    },
    {
      "x": -1,
      "y": 5,
      "z": 4,
      "name": "Empty",
      "level": 0
    },
    {
      "x": -1,
      "y": 6,
      "z": 4,
      "name": "Empty",
      "level": 0
    },
    {
      "x": -1,
      "y": 7,
      "z": 4,
      "name": "Empty",
      "level": 0
    },
    {
      "x": -1,
      "y": 8,
      "z": 4,
      "name": "Empty",
      "level": 0
    },
    {
      "x": -1,
      "y": 9,
      "z": 4,
      "name": "Empty",
      "level": 0
    },
    {
      "x": -1,
      "y": 5,
      "z": 5,
      "name": "Empty",
      "level": 0
    },
    {
      "x": -1,
      "y": 6,
      "z": 5,
      "name": "Empty",
      "level": 0
    },
    {
      "x": -1,
      "y": 7,
      "z": 5,
      "name": "Empty",
      "level": 0
    },
    {
      "x": 0,
      "y": 4,
      "z": -5,
      "name": "Empty",
      "level": 0
    },
    {
      "x": 0,
      "y": 7,
      "z": -5,
      "name": "Empty",
      "level": 0
    },
    {
      "x": 0,
      "y": 3,
      "z": -4,
      "name": "Empty",
      "level": 0
    },
    {
      "x": 0,
      "y": 4,
      "z": -4,
      "name": "Empty",
      "level": 0
    },
    {
      "x": 0,
      "y": 5,
      "z": -4,
      "name": "Empty",
      "level": 0
    },
    {
      "x": 0,
      "y": 6,
      "z": -4,
      "name": "Empty",
      "level": 0
    },
    {
      "x": 0,
      "y": 7,
      "z": -4,
      "name": "Empty",
      "level": 0
    },
    {
      "x": 0,
      "y": 8,
      "z": -4,
      "name": "Empty",
      "level": 0
    },
    {
      "x": 0,
      "y": 9,
      "z": -4,
      "name": "Empty",
      "level": 0
    },
    {
      "x": 0,
      "y": 10,
      "z": -4,
      "name": "Empty",
      "level": 0
    },
    {
      "x": 0,
      "y": 11,
      "z": -4,
      "name": "Empty",
      "level": 0
    },
    {
      "x": 0,
      "y": 12,
      "z": -4,
      "name": "Empty",
      "level": 0
    },
    {
      "x": 0,
      "y": 2,
      "z": -3,
      "name": "Empty",
      "level": 0
    },
    {
      "x": 0,
      "y": 3,
      "z": -3,
      "name": "Empty",
      "level": 0
    },
    {
      "x": 0,
      "y": 4,
      "z": -3,
      "name": "Empty",
      "level": 0
    },
    {
      "x": 0,
      "y": 8,
      "z": -3,
      "name": "Empty",
      "level": 0
    },
    {
      "x": 0,
      "y": 9,
      "z": -3,
      "name": "Empty",
      "level": 0
    },
    {
      "x": 0,
      "y": 10,
      "z": -3,
      "name": "Empty",
      "level": 0
    },
    {
      "x": 0,
      "y": 2,
      "z": -2,
      "name": "Empty",
      "level": 0
    },
    {
      "x": 0,
      "y": 3,
      "z": -2,
      "name": "Empty",
      "level": 0
    },
    {
      "x": 0,
      "y": 4,
      "z": -2,
      "name": "Empty",
      "level": 0
    },
    {
      "x": 0,
      "y": 9,
      "z": -2,
      "name": "Empty",
      "level": 0
    },
    {
      "x": 0,
      "y": 10,
      "z": -2,
      "name": "Empty",
      "level": 0
    },
    {
      "x": 0,
      "y": 1,
      "z": -1,
      "name": "Empty",
      "level": 0
    },
    {
      "x": 0,
      "y": 2,
      "z": -1,
      "name": "Empty",
      "level": 0
    },
    {
      "x": 0,
      "y": 4,
      "z": -1,
      "name": "Empty",
      "level": 0
    },
    {
      "x": 0,
      "y": 9,
      "z": -1,
      "name": "Empty",
      "level": 0
    },
    {
      "x": 0,
      "y": 10,
      "z": -1,
      "name": "Empty",
      "level": 0
    },
    {
      "x": 0,
      "y": 11,
      "z": -1,
      "name": "Empty",
      "level": 0
    },
    {
      "x": 0,
      "y": 1,
      "z": 0,
      "name": "Empty",
      "level": 0
    },
    {
      "x": 0,
      "y": 2,
      "z": 0,
      "name": "Empty",
      "level": 0
    },
    {
      "x": 0,
      "y": 4,
      "z": 0,
      "name": "Empty",
      "level": 0
    },
    {
      "x": 0,
      "y": 10,
      "z": 0,
      "name": "Empty",
      "level": 0
    },
    {
      "x": 0,
      "y": 11,
      "z": 0,
      "name": "Empty",
      "level": 0
    },
    {
      "x": 0,
      "y": 12,
      "z": 0,
      "name": "Empty",
      "level": 0
    },
    {
      "x": 0,
      "y": 1,
      "z": 1,
      "name": "Empty",
      "level": 0
    },
    {
      "x": 0,
      "y": 2,
      "z": 1,
      "name": "Empty",
      "level": 0
    },
    {
      "x": 0,
      "y": 3,
      "z": 1,
      "name": "Empty",
      "level": 0
    },
    {
      "x": 0,
      "y": 4,
      "z": 1,
      "name": "Empty",
      "level": 0
    },
    {
      "x": 0,
      "y": 9,
      "z": 1,
      "name": "Empty",
      "level": 0
    },
    {
      "x": 0,
      "y": 10,
      "z": 1,
      "name": "Empty",
      "level": 0
    },
    {
      "x": 0,
      "y": 11,
      "z": 1,
      "name": "Empty",
      "level": 0
    },
    {
      "x": 0,
      "y": 2,
      "z": 2,
      "name": "Empty",
      "level": 0
    },
    {
      "x": 0,
      "y": 3,
      "z": 2,
      "name": "Empty",
      "level": 0
    },
    {
      "x": 0,
      "y": 4,
      "z": 2,
      "name": "Empty",
      "level": 0
    },
    {
      "x": 0,
      "y": 5,
      "z": 2,
      "name": "Empty",
      "level": 0
    },
    {
      "x": 0,
      "y": 6,
      "z": 2,
      "name": "Empty",
      "level": 0
    },
    {
      "x": 0,
      "y": 9,
      "z": 2,
      "name": "Empty",
      "level": 0
    },
    {
      "x": 0,
      "y": 10,
      "z": 2,
      "name": "Empty",
      "level": 0
    },
    {
      "x": 0,
      "y": 3,
      "z": 3,
      "name": "Empty",
      "level": 0
    },
    {
      "x": 0,
      "y": 4,
      "z": 3,
      "name": "Empty",
      "level": 0
    },
    {
      "x": 0,
      "y": 5,
      "z": 3,
      "name": "Empty",
      "level": 0
    },
    {
      "x": 0,
      "y": 6,
      "z": 3,
      "name": "Empty",
      "level": 0
    },
    {
      "x": 0,
      "y": 8,
      "z": 3,
      "name": "Empty",
      "level": 0
    },
    {
      "x": 0,
      "y": 9,
      "z": 3,
      "name": "Empty",
      "level": 0
    },
    {
      "x": 0,
      "y": 10,
      "z": 3,
      "name": "Empty",
      "level": 0
    },
    {
      "x": 0,
      "y": 3,
      "z": 4,
      "name": "Empty",
      "level": 0
    },
    {
      "x": 0,
      "y": 4,
      "z": 4,
      "name": "Empty",
      "level": 0
    },
    {
      "x": 0,
      "y": 5,
      "z": 4,
      "name": "Empty",
      "level": 0
    },
    {
      "x": 0,
      "y": 6,
      "z": 4,
      "name": "Empty",
      "level": 0
    },
    {
      "x": 0,
      "y": 7,
      "z": 4,
      "name": "Empty",
      "level": 0
    },
    {
      "x": 0,
      "y": 8,
      "z": 4,
      "name": "Empty",
      "level": 0
    },
    {
      "x": 0,
      "y": 9,
      "z": 4,
      "name": "Empty",
      "level": 0
    },
    {
      "x": 0,
      "y": 10,
      "z": 4,
      "name": "Empty",
      "level": 0
    },
    {
      "x": 0,
      "y": 4,
      "z": 5,
      "name": "Empty",
      "level": 0
    },
    {
      "x": 0,
      "y": 7,
      "z": 5,
      "name": "Empty",
      "level": 0
    },
    {
      "x": 1,
      "y": 5,
      "z": -5,
      "name": "Empty",
      "level": 0
    },
    {
      "x": 1,
      "y": 6,
      "z": -5,
      "name": "Empty",
      "level": 0
    },
    {
      "x": 1,
      "y": 7,
      "z": -5,
      "name": "Empty",
      "level": 0
    },
    {
      "x": 1,
      "y": 3,
      "z": -4,
      "name": "Empty",
      "level": 0
    },
    {
      "x": 1,
      "y": 4,
      "z": -4,
      "name": "Empty",
      "level": 0
    },
    {
      "x": 1,
      "y": 5,
      "z": -4,
      "name": "Empty",
      "level": 0
    },
    {
      "x": 1,
      "y": 6,
      "z": -4,
      "name": "Empty",
      "level": 0
    },
    {
      "x": 1,
      "y": 7,
      "z": -4,
      "name": "Empty",
      "level": 0
    },
    {
      "x": 1,
      "y": 8,
      "z": -4,
      "name": "Empty",
      "level": 0
    },
    {
      "x": 1,
      "y": 9,
      "z": -4,
      "name": "Empty",
      "level": 0
    },
    {
      "x": 1,
      "y": 2,
      "z": -3,
      "name": "Empty",
      "level": 0
    },
    {
      "x": 1,
      "y": 3,
      "z": -3,
      "name": "Empty",
      "level": 0
    },
    {
      "x": 1,
      "y": 4,
      "z": -3,
      "name": "Empty",
      "level": 0
    },
    {
      "x": 1,
      "y": 8,
      "z": -3,
      "name": "Empty",
      "level": 0
    },
    {
      "x": 1,
      "y": 9,
      "z": -3,
      "name": "Empty",
      "level": 0
    },
    {
      "x": 1,
      "y": 10,
      "z": -3,
      "name": "Empty",
      "level": 0
    },
    {
      "x": 1,
      "y": 2,
      "z": -2,
      "name": "Empty",
      "level": 0
    },
    {
      "x": 1,
      "y": 3,
      "z": -2,
      "name": "Empty",
      "level": 0
    },
    {
      "x": 1,
      "y": 4,
      "z": -2,
      "name": "Empty",
      "level": 0
    },
    {
      "x": 1,
      "y": 9,
      "z": -2,
      "name": "Empty",
      "level": 0
    },
    {
      "x": 1,
      "y": 10,
      "z": -2,
      "name": "Empty",
      "level": 0
    },
    {
      "x": 1,
      "y": 1,
      "z": -1,
      "name": "Empty",
      "level": 0
    },
    {
      "x": 1,
      "y": 2,
      "z": -1,
      "name": "Empty",
      "level": 0
    },
    {
      "x": 1,
      "y": 4,
      "z": -1,
      "name": "Empty",
      "level": 0
    },
    {
      "x": 1,
      "y": 9,
      "z": -1,
      "name": "Empty",
      "level": 0
    },
    {
      "x": 1,
      "y": 10,
      "z": -1,
      "name": "Empty",
      "level": 0
    },
    {
      "x": 1,
      "y": 11,
      "z": -1,
      "name": "Empty",
      "level": 0
    },
    {
      "x": 1,
      "y": 1,
      "z": 0,
      "name": "Empty",
      "level": 0
    },
    {
      "x": 1,
      "y": 2,
      "z": 0,
      "name": "Empty",
      "level": 0
    },
    {
      "x": 1,
      "y": 4,
      "z": 0,
      "name": "Empty",
      "level": 0
    },
    {
      "x": 1,
      "y": 9,
      "z": 0,
      "name": "Empty",
      "level": 0
    },
    {
      "x": 1,
      "y": 10,
      "z": 0,
      "name": "Empty",
      "level": 0
    },
    {
      "x": 1,
      "y": 11,
      "z": 0,
      "name": "Empty",
      "level": 0
    },
    {
      "x": 1,
      "y": 1,
      "z": 1,
      "name": "Empty",
      "level": 0
    },
    {
      "x": 1,
      "y": 2,
      "z": 1,
      "name": "Empty",
      "level": 0
    },
    {
      "x": 1,
      "y": 4,
      "z": 1,
      "name": "Empty",
      "level": 0
    },
    {
      "x": 1,
      "y": 9,
      "z": 1,
      "name": "Empty",
      "level": 0
    },
    {
      "x": 1,
      "y": 10,
      "z": 1,
      "name": "Empty",
      "level": 0
    },
    {
      "x": 1,
      "y": 11,
      "z": 1,
      "name": "Empty",
      "level": 0
    },
    {
      "x": 1,
      "y": 2,
      "z": 2,
      "name": "Empty",
      "level": 0
    },
    {
      "x": 1,
      "y": 3,
      "z": 2,
      "name": "Empty",
      "level": 0
    },
    {
      "x": 1,
      "y": 4,
      "z": 2,
      "name": "Empty",
      "level": 0
    },
    {
      "x": 1,
      "y": 9,
      "z": 2,
      "name": "Empty",
      "level": 0
    },
    {
      "x": 1,
      "y": 10,
      "z": 2,
      "name": "Empty",
      "level": 0
    },
    {
      "x": 1,
      "y": 3,
      "z": 3,
      "name": "Empty",
      "level": 0
    },
    {
      "x": 1,
      "y": 4,
      "z": 3,
      "name": "Empty",
      "level": 0
    },
    {
      "x": 1,
      "y": 8,
      "z": 3,
      "name": "Empty",
      "level": 0
    },
    {
      "x": 1,
      "y": 9,
      "z": 3,
      "name": "Empty",
      "level": 0
    },
    {
      "x": 1,
      "y": 10,
      "z": 3,
      "name": "Empty",
      "level": 0
    },
    {
      "x": 1,
      "y": 3,
      "z": 4,
      "name": "Empty",
      "level": 0
    },
    {
      "x": 1,
      "y": 4,
      "z": 4,
      "name": "Empty",
      "level": 0
    },
    {
      "x": 1,
      "y": 5,
      "z": 4,
      "name": "Empty",
      "level": 0
    },
    {
      "x": 1,
      "y": 6,
      "z": 4,
      "name": "Empty",
      "level": 0
    },
    {
      "x": 1,
      "y": 7,
      "z": 4,
      "name": "Empty",
      "level": 0
    },
    {
      "x": 1,
      "y": 8,
      "z": 4,
      "name": "Empty",
      "level": 0
    },
    {
      "x": 1,
      "y": 9,
      "z": 4,
      "name": "Empty",
      "level": 0
    },
    {
      "x": 1,
      "y": 5,
      "z": 5,
      "name": "Empty",
      "level": 0
    },
    {
      "x": 1,
      "y": 6,
      "z": 5,
      "name": "Empty",
      "level": 0
    },
    {
      "x": 1,
      "y": 7,
      "z": 5,
      "name": "Empty",
      "level": 0
    },
    {
      "x": 2,
      "y": 4,
      "z": -4,
      "name": "Empty",
      "level": 0
    },
    {
      "x": 2,
      "y": 5,
      "z": -4,
      "name": "Empty",
      "level": 0
    },
    {
      "x": 2,
      "y": 6,
      "z": -4,
      "name": "Empty",
      "level": 0
    },
    {
      "x": 2,
      "y": 7,
      "z": -4,
      "name": "Empty",
      "level": 0
    },
    {
      "x": 2,
      "y": 8,
      "z": -4,
      "name": "Empty",
      "level": 0
    },
    {
      "x": 2,
      "y": 3,
      "z": -3,
      "name": "Empty",
      "level": 0
    },
    {
      "x": 2,
      "y": 4,
      "z": -3,
      "name": "Empty",
      "level": 0
    },
    {
      "x": 2,
      "y": 5,
      "z": -3,
      "name": "Empty",
      "level": 0
    },
    {
      "x": 2,
      "y": 6,
      "z": -3,
      "name": "Empty",
      "level": 0
    },
    {
      "x": 2,
      "y": 7,
      "z": -3,
      "name": "Empty",
      "level": 0
    },
    {
      "x": 2,
      "y": 8,
      "z": -3,
      "name": "Empty",
      "level": 0
    },
    {
      "x": 2,
      "y": 9,
      "z": -3,
      "name": "Empty",
      "level": 0
    },
    {
      "x": 2,
      "y": 2,
      "z": -2,
      "name": "Empty",
      "level": 0
    },
    {
      "x": 2,
      "y": 3,
      "z": -2,
      "name": "Empty",
      "level": 0
    },
    {
      "x": 2,
      "y": 4,
      "z": -2,
      "name": "Empty",
      "level": 0
    },
    {
      "x": 2,
      "y": 9,
      "z": -2,
      "name": "Empty",
      "level": 0
    },
    {
      "x": 2,
      "y": 10,
      "z": -2,
      "name": "Empty",
      "level": 0
    },
    {
      "x": 2,
      "y": 2,
      "z": -1,
      "name": "Empty",
      "level": 0
    },
    {
      "x": 2,
      "y": 3,
      "z": -1,
      "name": "Empty",
      "level": 0
    },
    {
      "x": 2,
      "y": 4,
      "z": -1,
      "name": "Empty",
      "level": 0
    },
    {
      "x": 2,
      "y": 9,
      "z": -1,
      "name": "Empty",
      "level": 0
    },
    {
      "x": 2,
      "y": 10,
      "z": -1,
      "name": "Empty",
      "level": 0
    },
    {
      "x": 2,
      "y": 2,
      "z": 0,
      "name": "Empty",
      "level": 0
    },
    {
      "x": 2,
      "y": 3,
      "z": 0,
      "name": "Empty",
      "level": 0
    },
    {
      "x": 2,
      "y": 4,
      "z": 0,
      "name": "Empty",
      "level": 0
    },
    {
      "x": 2,
      "y": 9,
      "z": 0,
      "name": "Empty",
      "level": 0
    },
    {
      "x": 2,
      "y": 10,
      "z": 0,
      "name": "Empty",
      "level": 0
    },
    {
      "x": 2,
      "y": 2,
      "z": 1,
      "name": "Empty",
      "level": 0
    },
    {
      "x": 2,
      "y": 3,
      "z": 1,
      "name": "Empty",
      "level": 0
    },
    {
      "x": 2,
      "y": 4,
      "z": 1,
      "name": "Empty",
      "level": 0
    },
    {
      "x": 2,
      "y": 5,
      "z": 1,
      "name": "Empty",
      "level": 0
    },
    {
      "x": 2,
      "y": 9,
      "z": 1,
      "name": "Empty",
      "level": 0
    },
    {
      "x": 2,
      "y": 10,
      "z": 1,
      "name": "Empty",
      "level": 0
    },
    {
      "x": 2,
      "y": 2,
      "z": 2,
      "name": "Empty",
      "level": 0
    },
    {
      "x": 2,
      "y": 3,
      "z": 2,
      "name": "Empty",
      "level": 0
    },
    {
      "x": 2,
      "y": 4,
      "z": 2,
      "name": "Empty",
      "level": 0
    },
    {
      "x": 2,
      "y": 5,
      "z": 2,
      "name": "Empty",
      "level": 0
    },
    {
      "x": 2,
      "y": 6,
      "z": 2,
      "name": "Empty",
      "level": 0
    },
    {
      "x": 2,
      "y": 9,
      "z": 2,
      "name": "Empty",
      "level": 0
    },
    {
      "x": 2,
      "y": 10,
      "z": 2,
      "name": "Empty",
      "level": 0
    },
    {
      "x": 2,
      "y": 3,
      "z": 3,
      "name": "Empty",
      "level": 0
    },
    {
      "x": 2,
      "y": 4,
      "z": 3,
      "name": "Empty",
      "level": 0
    },
    {
      "x": 2,
      "y": 5,
      "z": 3,
      "name": "Empty",
      "level": 0
    },
    {
      "x": 2,
      "y": 6,
      "z": 3,
      "name": "Empty",
      "level": 0
    },
    {
      "x": 2,
      "y": 7,
      "z": 3,
      "name": "Empty",
      "level": 0
    },
    {
      "x": 2,
      "y": 8,
      "z": 3,
      "name": "Empty",
      "level": 0
    },
    {
      "x": 2,
      "y": 9,
      "z": 3,
      "name": "Empty",
      "level": 0
    },
    {
      "x": 2,
      "y": 4,
      "z": 4,
      "name": "Empty",
      "level": 0
    },
    {
      "x": 2,
      "y": 5,
      "z": 4,
      "name": "Empty",
      "level": 0
    },
    {
      "x": 2,
      "y": 6,
      "z": 4,
      "name": "Empty",
      "level": 0
    },
    {
      "x": 2,
      "y": 7,
      "z": 4,
      "name": "Empty",
      "level": 0
    },
    {
      "x": 2,
      "y": 8,
      "z": 4,
      "name": "Empty",
      "level": 0
    },
    {
      "x": 3,
      "y": 5,
      "z": -4,
      "name": "Empty",
      "level": 0
    },
    {
      "x": 3,
      "y": 6,
      "z": -4,
      "name": "Empty",
      "level": 0
    },
    {
      "x": 3,
      "y": 7,
      "z": -4,
      "name": "Empty",
      "level": 0
    },
    {
      "x": 3,
      "y": 4,
      "z": -3,
      "name": "Empty",
      "level": 0
    },
    {
      "x": 3,
      "y": 5,
      "z": -3,
      "name": "Empty",
      "level": 0
    },
    {
      "x": 3,
      "y": 6,
      "z": -3,
      "name": "Empty",
      "level": 0
    },
    {
      "x": 3,
      "y": 7,
      "z": -3,
      "name": "Empty",
      "level": 0
    },
    {
      "x": 3,
      "y": 8,
      "z": -3,
      "name": "Empty",
      "level": 0
    },
    {
      "x": 3,
      "y": 3,
      "z": -2,
      "name": "Empty",
      "level": 0
    },
    {
      "x": 3,
      "y": 4,
      "z": -2,
      "name": "Empty",
      "level": 0
    },
    {
      "x": 3,
      "y": 5,
      "z": -2,
      "name": "Empty",
      "level": 0
    },
    {
      "x": 3,
      "y": 6,
      "z": -2,
      "name": "Empty",
      "level": 0
    },
    {
      "x": 3,
      "y": 7,
      "z": -2,
      "name": "Empty",
      "level": 0
    },
    {
      "x": 3,
      "y": 8,
      "z": -2,
      "name": "Empty",
      "level": 0
    },
    {
      "x": 3,
      "y": 9,
      "z": -2,
      "name": "Empty",
      "level": 0
    },
    {
      "x": 3,
      "y": 3,
      "z": -1,
      "name": "Empty",
      "level": 0
    },
    {
      "x": 3,
      "y": 4,
      "z": -1,
      "name": "Empty",
      "level": 0
    },
    {
      "x": 3,
      "y": 5,
      "z": -1,
      "name": "Empty",
      "level": 0
    },
    {
      "x": 3,
      "y": 6,
      "z": -1,
      "name": "Empty",
      "level": 0
    },
    {
      "x": 3,
      "y": 7,
      "z": -1,
      "name": "Empty",
      "level": 0
    },
    {
      "x": 3,
      "y": 8,
      "z": -1,
      "name": "Empty",
      "level": 0
    },
    {
      "x": 3,
      "y": 9,
      "z": -1,
      "name": "Empty",
      "level": 0
    },
    {
      "x": 3,
      "y": 10,
      "z": -1,
      "name": "Empty",
      "level": 0
    },
    {
      "x": 3,
      "y": 3,
      "z": 0,
      "name": "Empty",
      "level": 0
    },
    {
      "x": 3,
      "y": 4,
      "z": 0,
      "name": "Empty",
      "level": 0
    },
    {
      "x": 3,
      "y": 5,
      "z": 0,
      "name": "Empty",
      "level": 0
    },
    {
      "x": 3,
      "y": 6,
      "z": 0,
      "name": "Empty",
      "level": 0
    },
    {
      "x": 3,
      "y": 7,
      "z": 0,
      "name": "Empty",
      "level": 0
    },
    {
      "x": 3,
      "y": 8,
      "z": 0,
      "name": "Empty",
      "level": 0
    },
    {
      "x": 3,
      "y": 9,
      "z": 0,
      "name": "Empty",
      "level": 0
    },
    {
      "x": 3,
      "y": 10,
      "z": 0,
      "name": "Empty",
      "level": 0
    },
    {
      "x": 3,
      "y": 11,
      "z": 0,
      "name": "Empty",
      "level": 0
    },
    {
      "x": 3,
      "y": 12,
      "z": 0,
      "name": "Empty",
      "level": 0
    },
    {
      "x": 3,
      "y": 3,
      "z": 1,
      "name": "Empty",
      "level": 0
    },
    {
      "x": 3,
      "y": 4,
      "z": 1,
      "name": "Empty",
      "level": 0
    },
    {
      "x": 3,
      "y": 5,
      "z": 1,
      "name": "Empty",
      "level": 0
    },
    {
      "x": 3,
      "y": 6,
      "z": 1,
      "name": "Empty",
      "level": 0
    },
    {
      "x": 3,
      "y": 7,
      "z": 1,
      "name": "Empty",
      "level": 0
    },
    {
      "x": 3,
      "y": 8,
      "z": 1,
      "name": "Empty",
      "level": 0
    },
    {
      "x": 3,
      "y": 9,
      "z": 1,
      "name": "Empty",
      "level": 0
    },
    {
      "x": 3,
      "y": 10,
      "z": 1,
      "name": "Empty",
      "level": 0
    },
    {
      "x": 3,
      "y": 3,
      "z": 2,
      "name": "Empty",
      "level": 0
    },
    {
