{
  "version": 8,
  "blockIdVersion": 11,
  "anchorX": 0,
  "anchorY": 0,
  "anchorZ": 0,
  "blocks": [
    {
      "x": -24,
      "y": 3,
      "z": 5,
      "name": "Wood_Beastwood_Bark",
      "rotation": 5
    },
    {
      "x": -24,
      "y": 4,
      "z": 5,
      "name": "Wood_Beastwood_Bark",
      "rotation": 5
    },
    {
      "x": -24,
      "y": 2,
      "z": 6,
      "name": "Wood_Beastwood_Bark",
      "rotation": 5
    },
    {
      "x": -24,
      "y": 3,
      "z": 6,
      "name": "Wood_Beastwood_Bark",
      "rotation": 5
    },
    {
      "x": -24,
      "y": 4,
      "z": 6,
      "name": "Wood_Beastwood_Bark",
      "rotation": 5
    },
    {
      "x": -24,
      "y": 5,
      "z": 6,
      "name": "Wood_Beastwood_Bark",
      "rotation": 5
    },
    {
      "x": -24,
      "y": 1,
      "z": 7,
      "name": "Wood_Beastwood_Bark",
      "rotation": 5
    },
    {
      "x": -24,
      "y": 2,
      "z": 7,
      "name": "Wood_Beastwood_Plhoem_Sap"
    },
    {
      "x": -24,
      "y": 3,
      "z": 7,
      "name": "Wood_Beastwood_Plhoem_Sap"
    },
    {
      "x": -24,
      "y": 4,
      "z": 7,
      "name": "Wood_Beastwood_Plhoem_Sap"
    },
    {
      "x": -24,
      "y": 5,
      "z": 7,
      "name": "Wood_Beastwood_Plhoem_Sap"
    },
    {
      "x": -24,
      "y": 6,
      "z": 7,
      "name": "Wood_Beastwood_Bark",
      "rotation": 5
    },
    {
      "x": -24,
      "y": 1,
      "z": 8,
      "name": "Wood_Beastwood_Bark",
      "rotation": 5
    },
    {
      "x": -24,
      "y": 2,
      "z": 8,
      "name": "Wood_Beastwood_Plhoem_Sap"
    },
    {
      "x": -24,
      "y": 3,
      "z": 8,
      "name": "Wood_Beastwood_Sapwood",
      "rotation": 5
    },
    {
      "x": -24,
      "y": 4,
      "z": 8,
      "name": "Wood_Beastwood_Sapwood",
      "rotation": 5
    },
    {
      "x": -24,
      "y": 5,
      "z": 8,
      "name": "Wood_Beastwood_Plhoem_Sap"
    },
    {
      "x": -24,
      "y": 6,
      "z": 8,
      "name": "Wood_Beastwood_Bark",
      "rotation": 5
    },
    {
      "x": -24,
      "y": 1,
      "z": 9,
      "name": "Wood_Beastwood_Bark",
      "rotation": 5
    },
    {
      "x": -24,
      "y": 2,
      "z": 9,
      "name": "Wood_Beastwood_Plhoem_Sap"
    },
    {
      "x": -24,
      "y": 3,
      "z": 9,
      "name": "Wood_Beastwood_Sapwood",
      "rotation": 5
    },
    {
      "x": -24,
      "y": 4,
      "z": 9,
      "name": "Wood_Beastwood_Sapwood",
      "rotation": 5
    },
    {
      "x": -24,
      "y": 5,
      "z": 9,
      "name": "Wood_Beastwood_Plhoem_Sap"
    },
    {
      "x": -24,
      "y": 6,
      "z": 9,
      "name": "Wood_Beastwood_Bark",
      "rotation": 5
    },
    {
      "x": -24,
      "y": 1,
      "z": 10,
      "name": "Wood_Beastwood_Bark",
      "rotation": 5
    },
    {
      "x": -24,
      "y": 2,
      "z": 10,
      "name": "Wood_Beastwood_Plhoem_Sap"
    },
    {
      "x": -24,
      "y": 3,
      "z": 10,
      "name": "Wood_Beastwood_Plhoem_Sap"
    },
    {
      "x": -24,
      "y": 4,
      "z": 10,
      "name": "Wood_Beastwood_Plhoem_Sap"
    },
    {
      "x": -24,
      "y": 5,
      "z": 10,
      "name": "Wood_Beastwood_Plhoem_Sap"
    },
    {
      "x": -24,
      "y": 6,
      "z": 10,
      "name": "Wood_Beastwood_Bark",
      "rotation": 5
    },
    {
      "x": -24,
      "y": 2,
      "z": 11,
      "name": "Wood_Beastwood_Bark",
      "rotation": 5
    },
    {
      "x": -24,
      "y": 3,
      "z": 11,
      "name": "Wood_Beastwood_Bark",
      "rotation": 5
    },
    {
      "x": -24,
      "y": 4,
      "z": 11,
      "name": "Wood_Beastwood_Bark",
      "rotation": 5
    },
    {
      "x": -24,
      "y": 5,
      "z": 11,
      "name": "Wood_Beastwood_Bark",
      "rotation": 5
    },
    {
      "x": -24,
      "y": 3,
      "z": 12,
      "name": "Wood_Beastwood_Bark",
      "rotation": 5
    },
    {
      "x": -24,
      "y": 4,
      "z": 12,
      "name": "Wood_Beastwood_Bark",
      "rotation": 5
    },
    {
      "x": -23,
      "y": 3,
      "z": 5,
      "name": "Wood_Beastwood_Bark",
      "rotation": 5
    },
    {
      "x": -23,
      "y": 4,
      "z": 5,
      "name": "Wood_Beastwood_Bark",
      "rotation": 5
    },
    {
      "x": -23,
      "y": 2,
      "z": 6,
      "name": "Wood_Beastwood_Bark",
      "rotation": 5
    },
    {
      "x": -23,
      "y": 3,
      "z": 6,
      "name": "Wood_Beastwood_Bark",
      "rotation": 5
    },
    {
      "x": -23,
      "y": 4,
      "z": 6,
      "name": "Wood_Beastwood_Bark",
      "rotation": 5
    },
    {
      "x": -23,
      "y": 5,
      "z": 6,
      "name": "Wood_Beastwood_Bark",
      "rotation": 5
    },
    {
      "x": -23,
      "y": 1,
      "z": 7,
      "name": "Wood_Beastwood_Bark",
      "rotation": 5
    },
    {
      "x": -23,
      "y": 2,
      "z": 7,
      "name": "Wood_Beastwood_Plhoem_Sap"
    },
    {
      "x": -23,
      "y": 3,
      "z": 7,
      "name": "Wood_Beastwood_Plhoem_Sap"
    },
    {
      "x": -23,
      "y": 4,
      "z": 7,
      "name": "Wood_Beastwood_Plhoem_Sap"
    },
    {
      "x": -23,
      "y": 5,
      "z": 7,
      "name": "Wood_Beastwood_Plhoem_Sap"
    },
    {
      "x": -23,
      "y": 6,
      "z": 7,
      "name": "Wood_Beastwood_Bark",
      "rotation": 5
    },
    {
      "x": -23,
      "y": 1,
      "z": 8,
      "name": "Wood_Beastwood_Bark",
      "rotation": 5
    },
    {
      "x": -23,
      "y": 2,
      "z": 8,
      "name": "Wood_Beastwood_Plhoem_Sap"
    },
    {
      "x": -23,
      "y": 3,
      "z": 8,
      "name": "Wood_Beastwood_Sapwood",
      "rotation": 5
    },
    {
      "x": -23,
      "y": 4,
      "z": 8,
      "name": "Wood_Beastwood_Sapwood",
      "rotation": 5
    },
    {
      "x": -23,
      "y": 5,
      "z": 8,
      "name": "Wood_Beastwood_Plhoem_Sap"
    },
    {
      "x": -23,
      "y": 6,
      "z": 8,
      "name": "Wood_Beastwood_Bark",
      "rotation": 5
    },
    {
      "x": -23,
      "y": 1,
      "z": 9,
      "name": "Wood_Beastwood_Bark",
      "rotation": 5
    },
    {
      "x": -23,
      "y": 2,
      "z": 9,
      "name": "Wood_Beastwood_Plhoem_Sap"
    },
    {
      "x": -23,
      "y": 3,
      "z": 9,
      "name": "Wood_Beastwood_Sapwood",
      "rotation": 5
    },
    {
      "x": -23,
      "y": 4,
      "z": 9,
      "name": "Wood_Beastwood_Sapwood",
      "rotation": 5
    },
    {
      "x": -23,
      "y": 5,
      "z": 9,
      "name": "Wood_Beastwood_Plhoem_Sap"
    },
    {
      "x": -23,
      "y": 6,
      "z": 9,
      "name": "Wood_Beastwood_Bark",
      "rotation": 5
    },
    {
      "x": -23,
      "y": 1,
      "z": 10,
      "name": "Wood_Beastwood_Bark",
      "rotation": 5
    },
    {
      "x": -23,
      "y": 2,
      "z": 10,
      "name": "Wood_Beastwood_Plhoem_Sap"
    },
    {
      "x": -23,
      "y": 3,
      "z": 10,
      "name": "Wood_Beastwood_Plhoem_Sap"
    },
    {
      "x": -23,
      "y": 4,
      "z": 10,
      "name": "Wood_Beastwood_Plhoem_Sap"
    },
    {
      "x": -23,
      "y": 5,
      "z": 10,
      "name": "Wood_Beastwood_Plhoem_Sap"
    },
    {
      "x": -23,
      "y": 6,
      "z": 10,
      "name": "Wood_Beastwood_Bark",
      "rotation": 5
    },
    {
      "x": -23,
      "y": 2,
      "z": 11,
      "name": "Wood_Beastwood_Bark",
      "rotation": 5
    },
    {
      "x": -23,
      "y": 3,
      "z": 11,
      "name": "Wood_Beastwood_Bark",
      "rotation": 5
    },
    {
      "x": -23,
      "y": 4,
      "z": 11,
      "name": "Wood_Beastwood_Bark",
      "rotation": 5
    },
    {
      "x": -23,
      "y": 5,
      "z": 11,
      "name": "Wood_Beastwood_Bark",
      "rotation": 5
    },
    {
      "x": -23,
      "y": 3,
      "z": 12,
      "name": "Wood_Beastwood_Bark",
      "rotation": 5
    },
    {
      "x": -23,
      "y": 4,
      "z": 12,
      "name": "Wood_Beastwood_Bark",
      "rotation": 5
    },
    {
      "x": -22,
      "y": 3,
      "z": 5,
      "name": "Wood_Beastwood_Bark",
      "rotation": 5
    },
    {
      "x": -22,
      "y": 4,
      "z": 5,
      "name": "Wood_Beastwood_Bark",
      "rotation": 5
    },
    {
      "x": -22,
      "y": 2,
      "z": 6,
      "name": "Wood_Beastwood_Bark",
      "rotation": 5
    },
    {
      "x": -22,
      "y": 3,
      "z": 6,
      "name": "Wood_Beastwood_Bark",
      "rotation": 5
    },
    {
      "x": -22,
      "y": 4,
      "z": 6,
      "name": "Wood_Beastwood_Bark",
      "rotation": 5
    },
    {
      "x": -22,
      "y": 5,
      "z": 6,
      "name": "Wood_Beastwood_Bark",
      "rotation": 5
    },
    {
      "x": -22,
      "y": 1,
      "z": 7,
      "name": "Wood_Beastwood_Bark",
      "rotation": 5
    },
    {
      "x": -22,
      "y": 2,
      "z": 7,
      "name": "Wood_Beastwood_Plhoem_Sap"
    },
    {
      "x": -22,
      "y": 3,
      "z": 7,
      "name": "Wood_Beastwood_Plhoem_Sap"
    },
    {
      "x": -22,
      "y": 4,
      "z": 7,
      "name": "Wood_Beastwood_Plhoem_Sap"
    },
    {
      "x": -22,
      "y": 5,
      "z": 7,
      "name": "Wood_Beastwood_Plhoem_Sap"
    },
    {
      "x": -22,
      "y": 6,
      "z": 7,
      "name": "Wood_Beastwood_Bark",
      "rotation": 5
    },
    {
      "x": -22,
      "y": 1,
      "z": 8,
      "name": "Wood_Beastwood_Bark",
      "rotation": 5
    },
    {
      "x": -22,
      "y": 2,
      "z": 8,
      "name": "Wood_Beastwood_Plhoem_Sap"
    },
    {
      "x": -22,
      "y": 3,
      "z": 8,
      "name": "Wood_Beastwood_Sapwood",
      "rotation": 5
    },
    {
      "x": -22,
      "y": 4,
      "z": 8,
      "name": "Wood_Beastwood_Sapwood",
      "rotation": 5
    },
    {
      "x": -22,
      "y": 5,
      "z": 8,
      "name": "Wood_Beastwood_Plhoem_Sap"
    },
    {
      "x": -22,
      "y": 6,
      "z": 8,
      "name": "Wood_Beastwood_Bark",
      "rotation": 5
    },
    {
      "x": -22,
      "y": 1,
      "z": 9,
      "name": "Wood_Beastwood_Bark",
      "rotation": 5
    },
    {
      "x": -22,
      "y": 2,
      "z": 9,
      "name": "Wood_Beastwood_Plhoem_Sap"
    },
    {
      "x": -22,
      "y": 3,
      "z": 9,
      "name": "Wood_Beastwood_Sapwood",
      "rotation": 5
    },
    {
      "x": -22,
      "y": 4,
      "z": 9,
      "name": "Wood_Beastwood_Sapwood",
      "rotation": 5
    },
    {
      "x": -22,
      "y": 5,
      "z": 9,
      "name": "Wood_Beastwood_Plhoem_Sap"
    },
    {
      "x": -22,
      "y": 6,
      "z": 9,
      "name": "Wood_Beastwood_Bark",
      "rotation": 5
    },
    {
      "x": -22,
      "y": 1,
      "z": 10,
      "name": "Wood_Beastwood_Bark",
      "rotation": 5
    },
    {
      "x": -22,
      "y": 2,
      "z": 10,
      "name": "Wood_Beastwood_Plhoem_Sap"
    },
    {
      "x": -22,
      "y": 3,
      "z": 10,
      "name": "Wood_Beastwood_Plhoem_Sap"
    },
    {
      "x": -22,
      "y": 4,
      "z": 10,
      "name": "Wood_Beastwood_Plhoem_Sap"
    },
    {
      "x": -22,
      "y": 5,
      "z": 10,
      "name": "Wood_Beastwood_Plhoem_Sap"
    },
    {
      "x": -22,
      "y": 6,
      "z": 10,
      "name": "Wood_Beastwood_Bark",
      "rotation": 5
    },
    {
      "x": -22,
      "y": 2,
      "z": 11,
      "name": "Wood_Beastwood_Bark",
      "rotation": 5
    },
    {
      "x": -22,
      "y": 3,
      "z": 11,
      "name": "Wood_Beastwood_Bark",
      "rotation": 5
    },
    {
      "x": -22,
      "y": 4,
      "z": 11,
      "name": "Wood_Beastwood_Bark",
      "rotation": 5
    },
    {
      "x": -22,
      "y": 5,
      "z": 11,
      "name": "Wood_Beastwood_Bark",
      "rotation": 5
    },
    {
      "x": -22,
      "y": 3,
      "z": 12,
      "name": "Wood_Beastwood_Bark",
      "rotation": 5
    },
    {
      "x": -22,
      "y": 4,
      "z": 12,
      "name": "Wood_Beastwood_Bark",
      "rotation": 5
    },
    {
      "x": -21,
      "y": 3,
      "z": 5,
      "name": "Wood_Beastwood_Bark",
      "rotation": 5
    },
    {
      "x": -21,
      "y": 4,
      "z": 5,
      "name": "Wood_Beastwood_Bark",
      "rotation": 5
    },
    {
      "x": -21,
      "y": 2,
      "z": 6,
      "name": "Wood_Beastwood_Bark",
      "rotation": 5
    },
    {
      "x": -21,
      "y": 3,
      "z": 6,
      "name": "Wood_Beastwood_Bark",
      "rotation": 5
    },
    {
      "x": -21,
      "y": 4,
      "z": 6,
      "name": "Wood_Beastwood_Bark",
      "rotation": 5
    },
    {
      "x": -21,
      "y": 5,
      "z": 6,
      "name": "Wood_Beastwood_Bark",
      "rotation": 5
    },
    {
      "x": -21,
      "y": 1,
      "z": 7,
      "name": "Wood_Beastwood_Bark",
      "rotation": 5
    },
    {
      "x": -21,
      "y": 2,
      "z": 7,
      "name": "Wood_Beastwood_Plhoem_Sap"
    },
    {
      "x": -21,
      "y": 3,
      "z": 7,
      "name": "Wood_Beastwood_Plhoem_Sap"
    },
    {
      "x": -21,
      "y": 4,
      "z": 7,
      "name": "Wood_Beastwood_Plhoem_Sap"
    },
    {
      "x": -21,
      "y": 5,
      "z": 7,
      "name": "Wood_Beastwood_Plhoem_Sap"
    },
    {
      "x": -21,
      "y": 6,
      "z": 7,
      "name": "Wood_Beastwood_Bark",
      "rotation": 5
    },
    {
      "x": -21,
      "y": 1,
      "z": 8,
      "name": "Wood_Beastwood_Bark",
      "rotation": 5
    },
    {
      "x": -21,
      "y": 2,
      "z": 8,
      "name": "Wood_Beastwood_Plhoem_Sap"
    },
    {
      "x": -21,
      "y": 3,
      "z": 8,
      "name": "Wood_Beastwood_Sapwood",
      "rotation": 5
    },
    {
      "x": -21,
      "y": 4,
      "z": 8,
      "name": "Wood_Beastwood_Sapwood",
      "rotation": 5
    },
    {
      "x": -21,
      "y": 5,
      "z": 8,
      "name": "Wood_Beastwood_Plhoem_Sap"
    },
    {
      "x": -21,
      "y": 6,
      "z": 8,
      "name": "Wood_Beastwood_Bark",
      "rotation": 5
    },
    {
      "x": -21,
      "y": 1,
      "z": 9,
      "name": "Wood_Beastwood_Bark",
      "rotation": 5
    },
    {
      "x": -21,
      "y": 2,
      "z": 9,
      "name": "Wood_Beastwood_Plhoem_Sap"
    },
    {
      "x": -21,
      "y": 3,
      "z": 9,
      "name": "Wood_Beastwood_Sapwood",
      "rotation": 5
    },
    {
      "x": -21,
      "y": 4,
      "z": 9,
      "name": "Wood_Beastwood_Sapwood",
      "rotation": 5
    },
    {
      "x": -21,
      "y": 5,
      "z": 9,
      "name": "Wood_Beastwood_Plhoem_Sap"
    },
    {
      "x": -21,
      "y": 6,
      "z": 9,
      "name": "Wood_Beastwood_Bark",
      "rotation": 5
    },
    {
      "x": -21,
      "y": 1,
      "z": 10,
      "name": "Wood_Beastwood_Bark",
      "rotation": 5
    },
    {
      "x": -21,
      "y": 2,
      "z": 10,
      "name": "Wood_Beastwood_Plhoem_Sap"
    },
    {
      "x": -21,
      "y": 3,
      "z": 10,
      "name": "Wood_Beastwood_Plhoem_Sap"
    },
    {
      "x": -21,
      "y": 4,
      "z": 10,
      "name": "Wood_Beastwood_Plhoem_Sap"
    },
    {
      "x": -21,
      "y": 5,
      "z": 10,
      "name": "Wood_Beastwood_Plhoem_Sap"
    },
    {
      "x": -21,
      "y": 6,
      "z": 10,
      "name": "Wood_Beastwood_Bark",
      "rotation": 5
    },
    {
      "x": -21,
      "y": 2,
      "z": 11,
      "name": "Wood_Beastwood_Bark",
      "rotation": 5
    },
    {
      "x": -21,
      "y": 3,
      "z": 11,
      "name": "Wood_Beastwood_Bark",
      "rotation": 5
    },
    {
      "x": -21,
      "y": 4,
      "z": 11,
      "name": "Wood_Beastwood_Bark",
      "rotation": 5
    },
    {
      "x": -21,
      "y": 5,
      "z": 11,
      "name": "Wood_Beastwood_Bark",
      "rotation": 5
    },
    {
      "x": -21,
      "y": 3,
      "z": 12,
      "name": "Wood_Beastwood_Bark",
      "rotation": 5
    },
    {
      "x": -21,
      "y": 4,
      "z": 12,
      "name": "Wood_Beastwood_Bark",
      "rotation": 5
    },
    {
      "x": -20,
      "y": 3,
      "z": 5,
      "name": "Wood_Beastwood_Bark",
      "rotation": 5
    },
    {
      "x": -20,
      "y": 4,
      "z": 5,
      "name": "Wood_Beastwood_Bark",
      "rotation": 5
    },
    {
      "x": -20,
      "y": 2,
      "z": 6,
      "name": "Wood_Beastwood_Bark",
      "rotation": 5
    },
    {
      "x": -20,
      "y": 3,
      "z": 6,
      "name": "Wood_Beastwood_Bark",
      "rotation": 5
    },
    {
      "x": -20,
      "y": 4,
      "z": 6,
      "name": "Wood_Beastwood_Bark",
      "rotation": 5
    },
    {
      "x": -20,
      "y": 5,
      "z": 6,
      "name": "Wood_Beastwood_Bark",
      "rotation": 5
    },
    {
      "x": -20,
      "y": 1,
      "z": 7,
      "name": "Wood_Beastwood_Bark",
      "rotation": 5
    },
    {
      "x": -20,
      "y": 2,
      "z": 7,
      "name": "Wood_Beastwood_Plhoem_Sap"
    },
    {
      "x": -20,
      "y": 3,
      "z": 7,
      "name": "Wood_Beastwood_Plhoem_Sap"
    },
    {
      "x": -20,
      "y": 4,
      "z": 7,
      "name": "Wood_Beastwood_Plhoem_Sap"
    },
    {
      "x": -20,
      "y": 5,
      "z": 7,
      "name": "Wood_Beastwood_Plhoem_Sap"
    },
    {
      "x": -20,
      "y": 6,
      "z": 7,
      "name": "Wood_Beastwood_Bark",
      "rotation": 5
    },
    {
      "x": -20,
      "y": 1,
      "z": 8,
      "name": "Wood_Beastwood_Bark",
      "rotation": 5
    },
    {
      "x": -20,
      "y": 2,
      "z": 8,
      "name": "Wood_Beastwood_Plhoem_Sap"
    },
    {
      "x": -20,
      "y": 3,
      "z": 8,
      "name": "Wood_Beastwood_Sapwood",
      "rotation": 5
    },
    {
      "x": -20,
      "y": 4,
      "z": 8,
      "name": "Wood_Beastwood_Sapwood",
      "rotation": 5
    },
    {
      "x": -20,
      "y": 5,
      "z": 8,
      "name": "Wood_Beastwood_Plhoem_Sap"
    },
    {
      "x": -20,
      "y": 6,
      "z": 8,
      "name": "Wood_Beastwood_Bark",
      "rotation": 5
    },
    {
      "x": -20,
      "y": 1,
      "z": 9,
      "name": "Wood_Beastwood_Bark",
      "rotation": 5
    },
    {
      "x": -20,
      "y": 2,
      "z": 9,
      "name": "Wood_Beastwood_Plhoem_Sap"
    },
    {
      "x": -20,
      "y": 3,
      "z": 9,
      "name": "Wood_Beastwood_Sapwood",
      "rotation": 5
    },
    {
      "x": -20,
      "y": 4,
      "z": 9,
      "name": "Wood_Beastwood_Sapwood",
      "rotation": 5
    },
    {
      "x": -20,
      "y": 5,
      "z": 9,
      "name": "Wood_Beastwood_Plhoem_Sap"
    },
    {
      "x": -20,
      "y": 6,
      "z": 9,
      "name": "Wood_Beastwood_Bark",
      "rotation": 5
    },
    {
      "x": -20,
      "y": 1,
      "z": 10,
      "name": "Wood_Beastwood_Bark",
      "rotation": 5
    },
    {
      "x": -20,
      "y": 2,
      "z": 10,
      "name": "Wood_Beastwood_Plhoem_Sap"
    },
    {
      "x": -20,
      "y": 3,
      "z": 10,
      "name": "Wood_Beastwood_Plhoem_Sap"
    },
    {
      "x": -20,
      "y": 4,
      "z": 10,
      "name": "Wood_Beastwood_Plhoem_Sap"
    },
    {
      "x": -20,
      "y": 5,
      "z": 10,
      "name": "Wood_Beastwood_Plhoem_Sap"
    },
    {
      "x": -20,
      "y": 6,
      "z": 10,
      "name": "Wood_Beastwood_Bark",
      "rotation": 5
    },
    {
      "x": -20,
      "y": 2,
      "z": 11,
      "name": "Wood_Beastwood_Bark",
      "rotation": 5
    },
    {
      "x": -20,
      "y": 3,
      "z": 11,
      "name": "Wood_Beastwood_Bark",
      "rotation": 5
    },
    {
      "x": -20,
      "y": 4,
      "z": 11,
      "name": "Wood_Beastwood_Bark",
      "rotation": 5
    },
    {
      "x": -20,
      "y": 5,
      "z": 11,
      "name": "Wood_Beastwood_Bark",
      "rotation": 5
    },
    {
      "x": -20,
      "y": 3,
      "z": 12,
      "name": "Wood_Beastwood_Bark",
      "rotation": 5
    },
    {
      "x": -20,
      "y": 4,
      "z": 12,
      "name": "Wood_Beastwood_Bark",
      "rotation": 5
    },
    {
      "x": -19,
      "y": 3,
      "z": 5,
      "name": "Wood_Beastwood_Bark",
      "rotation": 5
    },
    {
      "x": -19,
      "y": 4,
      "z": 5,
      "name": "Wood_Beastwood_Bark",
      "rotation": 5
    },
    {
      "x": -19,
      "y": 2,
      "z": 6,
      "name": "Wood_Beastwood_Bark",
      "rotation": 5
    },
    {
      "x": -19,
      "y": 3,
      "z": 6,
      "name": "Wood_Beastwood_Bark",
      "rotation": 5
    },
    {
      "x": -19,
      "y": 4,
      "z": 6,
      "name": "Wood_Beastwood_Bark",
      "rotation": 5
    },
    {
      "x": -19,
      "y": 5,
      "z": 6,
      "name": "Wood_Beastwood_Bark",
      "rotation": 5
    },
    {
      "x": -19,
      "y": 1,
      "z": 7,
      "name": "Wood_Beastwood_Bark",
      "rotation": 5
    },
    {
      "x": -19,
      "y": 2,
      "z": 7,
      "name": "Wood_Beastwood_Plhoem_Sap"
    },
    {
      "x": -19,
      "y": 3,
      "z": 7,
      "name": "Wood_Beastwood_Plhoem_Sap"
    },
    {
      "x": -19,
      "y": 4,
      "z": 7,
      "name": "Wood_Beastwood_Plhoem_Sap"
    },
    {
      "x": -19,
      "y": 5,
      "z": 7,
      "name": "Wood_Beastwood_Plhoem_Sap"
    },
    {
      "x": -19,
      "y": 6,
      "z": 7,
      "name": "Wood_Beastwood_Bark",
      "rotation": 5
    },
    {
      "x": -19,
      "y": 1,
      "z": 8,
      "name": "Wood_Beastwood_Bark",
      "rotation": 5
    },
    {
      "x": -19,
      "y": 2,
      "z": 8,
      "name": "Wood_Beastwood_Plhoem_Sap"
    },
    {
      "x": -19,
      "y": 3,
      "z": 8,
      "name": "Wood_Beastwood_Sapwood",
      "rotation": 5
    },
    {
      "x": -19,
      "y": 4,
      "z": 8,
      "name": "Wood_Beastwood_Sapwood",
      "rotation": 5
    },
    {
      "x": -19,
      "y": 5,
      "z": 8,
      "name": "Wood_Beastwood_Plhoem_Sap"
    },
    {
      "x": -19,
      "y": 6,
      "z": 8,
      "name": "Wood_Beastwood_Bark",
      "rotation": 5
    },
    {
      "x": -19,
      "y": 1,
      "z": 9,
      "name": "Wood_Beastwood_Bark",
      "rotation": 5
    },
    {
      "x": -19,
      "y": 2,
      "z": 9,
      "name": "Wood_Beastwood_Plhoem_Sap"
    },
    {
      "x": -19,
      "y": 3,
      "z": 9,
      "name": "Wood_Beastwood_Sapwood",
      "rotation": 5
    },
    {
      "x": -19,
      "y": 4,
      "z": 9,
      "name": "Wood_Beastwood_Sapwood",
      "rotation": 5
    },
    {
      "x": -19,
      "y": 5,
      "z": 9,
      "name": "Wood_Beastwood_Plhoem_Sap"
    },
    {
      "x": -19,
      "y": 6,
      "z": 9,
      "name": "Wood_Beastwood_Bark",
      "rotation": 5
    },
    {
      "x": -19,
      "y": 1,
      "z": 10,
      "name": "Wood_Beastwood_Bark",
      "rotation": 5
    },
    {
      "x": -19,
      "y": 2,
      "z": 10,
      "name": "Wood_Beastwood_Plhoem_Sap"
    },
    {
      "x": -19,
      "y": 3,
      "z": 10,
      "name": "Wood_Beastwood_Plhoem_Sap"
    },
    {
      "x": -19,
      "y": 4,
      "z": 10,
      "name": "Wood_Beastwood_Plhoem_Sap"
    },
    {
      "x": -19,
      "y": 5,
      "z": 10,
      "name": "Wood_Beastwood_Plhoem_Sap"
    },
    {
      "x": -19,
      "y": 6,
      "z": 10,
      "name": "Wood_Beastwood_Bark",
      "rotation": 5
    },
    {
      "x": -19,
      "y": 2,
      "z": 11,
      "name": "Wood_Beastwood_Bark",
      "rotation": 5
    },
    {
      "x": -19,
      "y": 3,
      "z": 11,
      "name": "Wood_Beastwood_Bark",
      "rotation": 5
    },
    {
      "x": -19,
      "y": 4,
      "z": 11,
      "name": "Wood_Beastwood_Bark",
      "rotation": 5
    },
    {
      "x": -19,
      "y": 5,
      "z": 11,
      "name": "Wood_Beastwood_Bark",
      "rotation": 5
    },
    {
      "x": -18,
      "y": 3,
      "z": 5,
      "name": "Wood_Beastwood_Bark",
      "rotation": 5
    },
    {
      "x": -18,
      "y": 4,
      "z": 5,
      "name": "Wood_Beastwood_Bark",
      "rotation": 5
    },
    {
      "x": -18,
      "y": 2,
      "z": 6,
      "name": "Wood_Beastwood_Bark",
      "rotation": 5
    },
    {
      "x": -18,
      "y": 3,
      "z": 6,
      "name": "Wood_Beastwood_Bark",
      "rotation": 5
    },
    {
      "x": -18,
      "y": 4,
      "z": 6,
      "name": "Wood_Beastwood_Bark",
      "rotation": 5
    },
    {
      "x": -18,
      "y": 5,
      "z": 6,
      "name": "Wood_Beastwood_Bark",
      "rotation": 5
    },
    {
      "x": -18,
      "y": 1,
      "z": 7,
      "name": "Wood_Beastwood_Bark",
      "rotation": 5
    },
    {
      "x": -18,
      "y": 2,
      "z": 7,
      "name": "Wood_Beastwood_Plhoem_Sap"
    },
    {
      "x": -18,
      "y": 3,
      "z": 7,
      "name": "Wood_Beastwood_Plhoem_Sap"
    },
    {
      "x": -18,
      "y": 4,
      "z": 7,
      "name": "Wood_Beastwood_Plhoem_Sap"
    },
    {
      "x": -18,
      "y": 5,
      "z": 7,
      "name": "Wood_Beastwood_Plhoem_Sap"
    },
    {
      "x": -18,
      "y": 6,
      "z": 7,
      "name": "Wood_Beastwood_Bark",
      "rotation": 5
    },
    {
      "x": -18,
      "y": 1,
      "z": 8,
      "name": "Wood_Beastwood_Bark",
      "rotation": 5
    },
    {
      "x": -18,
      "y": 2,
      "z": 8,
      "name": "Wood_Beastwood_Plhoem_Sap"
    },
    {
      "x": -18,
      "y": 3,
      "z": 8,
      "name": "Wood_Beastwood_Sapwood",
      "rotation": 5
    },
    {
      "x": -18,
      "y": 4,
      "z": 8,
      "name": "Wood_Beastwood_Sapwood",
      "rotation": 5
    },
    {
      "x": -18,
      "y": 5,
      "z": 8,
      "name": "Wood_Beastwood_Plhoem_Sap"
    },
    {
      "x": -18,
      "y": 6,
      "z": 8,
      "name": "Wood_Beastwood_Bark",
      "rotation": 5
    },
    {
      "x": -18,
      "y": 1,
      "z": 9,
      "name": "Wood_Beastwood_Bark",
      "rotation": 5
    },
    {
      "x": -18,
      "y": 2,
      "z": 9,
      "name": "Wood_Beastwood_Plhoem_Sap"
    },
    {
      "x": -18,
      "y": 3,
      "z": 9,
      "name": "Wood_Beastwood_Sapwood",
      "rotation": 5
    },
    {
      "x": -18,
      "y": 4,
      "z": 9,
      "name": "Wood_Beastwood_Sapwood",
      "rotation": 5
    },
    {
      "x": -18,
      "y": 5,
      "z": 9,
      "name": "Wood_Beastwood_Plhoem_Sap"
    },
    {
      "x": -18,
      "y": 6,
      "z": 9,
      "name": "Wood_Beastwood_Bark",
      "rotation": 5
    },
    {
      "x": -18,
      "y": 1,
      "z": 10,
      "name": "Wood_Beastwood_Bark",
      "rotation": 5
    },
    {
      "x": -18,
      "y": 2,
      "z": 10,
      "name": "Wood_Beastwood_Plhoem_Sap"
    },
    {
      "x": -18,
      "y": 3,
      "z": 10,
      "name": "Wood_Beastwood_Plhoem_Sap"
    },
    {
      "x": -18,
      "y": 4,
      "z": 10,
      "name": "Wood_Beastwood_Plhoem_Sap"
    },
    {
      "x": -18,
      "y": 5,
      "z": 10,
      "name": "Wood_Beastwood_Plhoem_Sap"
    },
    {
      "x": -18,
      "y": 6,
      "z": 10,
      "name": "Wood_Beastwood_Bark",
      "rotation": 5
    },
    {
      "x": -18,
      "y": 2,
      "z": 11,
      "name": "Wood_Beastwood_Bark",
      "rotation": 5
    },
    {
      "x": -18,
      "y": 3,
      "z": 11,
      "name": "Wood_Beastwood_Bark",
      "rotation": 5
    },
    {
      "x": -18,
      "y": 4,
      "z": 11,
      "name": "Wood_Beastwood_Bark",
      "rotation": 5
    },
    {
      "x": -18,
      "y": 5,
      "z": 11,
      "name": "Wood_Beastwood_Bark",
      "rotation": 5
    },
    {
      "x": -17,
      "y": 2,
      "z": 6,
      "name": "Wood_Beastwood_Bark",
      "rotation": 5
    },
    {
      "x": -17,
      "y": 3,
      "z": 6,
      "name": "Wood_Beastwood_Bark",
      "rotation": 5
    },
    {
      "x": -17,
      "y": 4,
      "z": 6,
      "name": "Wood_Beastwood_Bark",
      "rotation": 5
    },
    {
      "x": -17,
      "y": 5,
      "z": 6,
      "name": "Wood_Beastwood_Bark",
      "rotation": 5
    },
    {
      "x": -17,
      "y": 1,
      "z": 7,
      "name": "Wood_Beastwood_Bark",
      "rotation": 5
    },
    {
      "x": -17,
      "y": 2,
      "z": 7,
      "name": "Wood_Beastwood_Plhoem_Sap"
    },
    {
      "x": -17,
      "y": 3,
      "z": 7,
      "name": "Wood_Beastwood_Plhoem_Sap"
    },
    {
      "x": -17,
      "y": 4,
      "z": 7,
      "name": "Wood_Beastwood_Plhoem_Sap"
    },
    {
      "x": -17,
      "y": 5,
      "z": 7,
      "name": "Wood_Beastwood_Plhoem_Sap"
    },
    {
      "x": -17,
      "y": 6,
      "z": 7,
      "name": "Wood_Beastwood_Bark",
      "rotation": 5
    },
    {
      "x": -17,
      "y": 1,
      "z": 8,
      "name": "Wood_Beastwood_Bark",
      "rotation": 5
    },
    {
      "x": -17,
      "y": 2,
      "z": 8,
      "name": "Wood_Beastwood_Plhoem_Sap"
    },
    {
      "x": -17,
      "y": 3,
      "z": 8,
      "name": "Wood_Beastwood_Sapwood",
      "rotation": 5
    },
    {
      "x": -17,
      "y": 4,
      "z": 8,
      "name": "Wood_Beastwood_Sapwood",
      "rotation": 5
    },
    {
      "x": -17,
      "y": 5,
      "z": 8,
      "name": "Wood_Beastwood_Plhoem_Sap"
    },
    {
      "x": -17,
      "y": 6,
      "z": 8,
      "name": "Wood_Beastwood_Bark",
      "rotation": 5
    },
    {
      "x": -17,
      "y": 1,
      "z": 9,
      "name": "Wood_Beastwood_Bark",
      "rotation": 5
    },
    {
      "x": -17,
      "y": 2,
      "z": 9,
      "name": "Wood_Beastwood_Plhoem_Sap"
    },
    {
      "x": -17,
      "y": 3,
      "z": 9,
      "name": "Wood_Beastwood_Sapwood",
      "rotation": 5
    },
    {
      "x": -17,
      "y": 4,
      "z": 9,
      "name": "Wood_Beastwood_Sapwood",
      "rotation": 5
    },
    {
      "x": -17,
      "y": 5,
      "z": 9,
      "name": "Wood_Beastwood_Plhoem_Sap"
    },
    {
      "x": -17,
      "y": 6,
      "z": 9,
      "name": "Wood_Beastwood_Bark",
      "rotation": 5
    },
    {
      "x": -17,
      "y": 1,
      "z": 10,
      "name": "Wood_Beastwood_Bark",
      "rotation": 5
    },
    {
      "x": -17,
      "y": 2,
      "z": 10,
      "name": "Wood_Beastwood_Plhoem_Sap"
    },
    {
      "x": -17,
      "y": 3,
      "z": 10,
      "name": "Wood_Beastwood_Plhoem_Sap"
    },
    {
      "x": -17,
      "y": 4,
      "z": 10,
      "name": "Wood_Beastwood_Plhoem_Sap"
    },
    {
      "x": -17,
      "y": 5,
      "z": 10,
      "name": "Wood_Beastwood_Plhoem_Sap"
    },
    {
      "x": -17,
      "y": 6,
      "z": 10,
      "name": "Wood_Beastwood_Bark",
      "rotation": 5
    },
    {
      "x": -17,
      "y": 2,
      "z": 11,
      "name": "Wood_Beastwood_Bark",
      "rotation": 5
    },
    {
      "x": -17,
      "y": 3,
      "z": 11,
      "name": "Wood_Beastwood_Bark",
      "rotation": 5
    },
    {
      "x": -17,
      "y": 4,
      "z": 11,
      "name": "Wood_Beastwood_Bark",
      "rotation": 5
    },
    {
      "x": -17,
      "y": 5,
      "z": 11,
      "name": "Wood_Beastwood_Bark",
      "rotation": 5
    },
    {
      "x": -16,
      "y": 20,
      "z": -15,
      "name": "Plant_Leaves_Redwood",
      "rotation": 3
    },
    {
      "x": -16,
      "y": 21,
      "z": -15,
      "name": "Plant_Leaves_Redwood",
      "rotation": 3
    },
    {
      "x": -16,
      "y": 22,
      "z": -15,
      "name": "Plant_Leaves_Redwood",
      "rotation": 3
    },
    {
      "x": -16,
      "y": 20,
      "z": -14,
      "name": "Plant_Leaves_Redwood",
      "rotation": 3
    },
    {
      "x": -16,
      "y": 21,
      "z": -14,
      "name": "Plant_Leaves_Redwood",
      "rotation": 3
    },
    {
      "x": -16,
      "y": 22,
      "z": -14,
      "name": "Plant_Leaves_Redwood",
      "rotation": 3
    },
    {
      "x": -16,
      "y": 20,
      "z": -13,
      "name": "Plant_Leaves_Redwood",
      "rotation": 3
    },
    {
      "x": -16,
      "y": 21,
      "z": -13,
      "name": "Plant_Leaves_Redwood",
      "rotation": 3
    },
    {
      "x": -16,
      "y": 22,
      "z": -13,
      "name": "Plant_Leaves_Redwood",
      "rotation": 3
    },
    {
      "x": -16,
      "y": 20,
      "z": -12,
      "name": "Plant_Leaves_Redwood",
      "rotation": 3
    },
    {
      "x": -16,
      "y": 21,
      "z": -12,
      "name": "Plant_Leaves_Redwood",
      "rotation": 3
    },
    {
      "x": -16,
      "y": 22,
      "z": -12,
      "name": "Plant_Leaves_Redwood",
      "rotation": 3
    },
    {
      "x": -16,
      "y": 20,
      "z": -11,
      "name": "Plant_Leaves_Redwood",
      "rotation": 3
    },
    {
      "x": -16,
      "y": 21,
      "z": -11,
      "name": "Plant_Leaves_Redwood",
      "rotation": 3
    },
    {
      "x": -16,
      "y": 22,
      "z": -11,
      "name": "Plant_Leaves_Redwood",
      "rotation": 3
    },
    {
      "x": -16,
      "y": 2,
      "z": 6,
      "name": "Wood_Beastwood_Bark",
      "rotation": 4
    },
    {
      "x": -16,
      "y": 3,
      "z": 6,
      "name": "Wood_Beastwood_Bark",
      "rotation": 7
    },
    {
      "x": -16,
      "y": 4,
      "z": 6,
      "name": "Wood_Beastwood_Bark",
      "rotation": 7
    },
    {
      "x": -16,
      "y": 5,
      "z": 6,
      "name": "Wood_Beastwood_Bark",
      "rotation": 7
    },
    {
      "x": -16,
      "y": 1,
      "z": 7,
      "name": "Wood_Beastwood_Bark",
      "rotation": 4
    },
    {
      "x": -16,
      "y": 2,
      "z": 7,
      "name": "Wood_Beastwood_Plhoem_Sap"
    },
    {
      "x": -16,
      "y": 3,
      "z": 7,
      "name": "Wood_Beastwood_Plhoem_Sap",
      "rotation": 3
    },
    {
      "x": -16,
      "y": 4,
      "z": 7,
      "name": "Wood_Beastwood_Plhoem_Sap",
      "rotation": 3
    },
    {
      "x": -16,
      "y": 5,
      "z": 7,
      "name": "Wood_Beastwood_Plhoem_Sap",
      "rotation": 3
    },
    {
      "x": -16,
      "y": 6,
      "z": 7,
      "name": "Wood_Beastwood_Bark",
      "rotation": 7
    },
    {
      "x": -16,
      "y": 1,
      "z": 8,
      "name": "Wood_Beastwood_Bark",
      "rotation": 4
    },
    {
      "x": -16,
      "y": 2,
      "z": 8,
      "name": "Wood_Beastwood_Plhoem_Sap",
      "rotation": 3
    },
    {
      "x": -16,
      "y": 3,
      "z": 8,
      "name": "Wood_Beastwood_Sapwood",
      "rotation": 7
    },
    {
      "x": -16,
      "y": 4,
      "z": 8,
      "name": "Wood_Beastwood_Sapwood",
      "rotation": 7
    },
    {
      "x": -16,
      "y": 5,
      "z": 8,
      "name": "Wood_Beastwood_Plhoem_Sap",
      "rotation": 3
    },
    {
      "x": -16,
      "y": 6,
      "z": 8,
      "name": "Wood_Beastwood_Bark",
      "rotation": 7
    },
    {
      "x": -16,
      "y": 1,
      "z": 9,
      "name": "Wood_Beastwood_Bark",
      "rotation": 4
    },
    {
      "x": -16,
      "y": 2,
      "z": 9,
      "name": "Wood_Beastwood_Plhoem_Sap",
      "rotation": 3
    },
    {
      "x": -16,
      "y": 3,
      "z": 9,
      "name": "Wood_Beastwood_Sapwood",
      "rotation": 3
    },
    {
      "x": -16,
      "y": 4,
      "z": 9,
      "name": "Wood_Beastwood_Sapwood",
      "rotation": 7
    },
    {
      "x": -16,
      "y": 5,
      "z": 9,
      "name": "Wood_Beastwood_Plhoem_Sap",
      "rotation": 3
    },
    {
      "x": -16,
      "y": 6,
      "z": 9,
      "name": "Wood_Beastwood_Bark",
      "rotation": 7
    },
    {
      "x": -16,
      "y": 1,
      "z": 10,
      "name": "Wood_Beastwood_Bark",
      "rotation": 4
    },
    {
      "x": -16,
      "y": 2,
      "z": 10,
      "name": "Wood_Beastwood_Plhoem_Sap",
      "rotation": 3
    },
    {
      "x": -16,
      "y": 3,
      "z": 10,
      "name": "Wood_Beastwood_Plhoem_Sap",
      "rotation": 3
    },
    {
      "x": -16,
      "y": 4,
      "z": 10,
      "name": "Wood_Beastwood_Plhoem_Sap",
      "rotation": 3
    },
    {
      "x": -16,
      "y": 5,
      "z": 10,
      "name": "Wood_Beastwood_Plhoem_Sap",
      "rotation": 3
    },
    {
      "x": -16,
      "y": 6,
      "z": 10,
      "name": "Wood_Beastwood_Bark",
      "rotation": 7
    },
    {
      "x": -16,
      "y": 2,
      "z": 11,
      "name": "Wood_Beastwood_Bark",
      "rotation": 7
    },
    {
      "x": -16,
      "y": 3,
      "z": 11,
      "name": "Wood_Beastwood_Bark",
      "rotation": 7
    },
    {
      "x": -16,
      "y": 4,
      "z": 11,
      "name": "Wood_Beastwood_Bark",
      "rotation": 7
    },
    {
      "x": -16,
      "y": 5,
      "z": 11,
      "name": "Wood_Beastwood_Bark",
      "rotation": 7
    },
    {
      "x": -15,
      "y": 21,
      "z": -16,
      "name": "Plant_Leaves_Redwood",
      "rotation": 3
    },
    {
      "x": -15,
      "y": 20,
      "z": -15,
      "name": "Plant_Leaves_Redwood",
      "rotation": 3
    },
    {
      "x": -15,
      "y": 21,
      "z": -15,
      "name": "Plant_Leaves_Redwood",
      "rotation": 3
    },
    {
      "x": -15,
      "y": 22,
      "z": -15,
      "name": "Plant_Leaves_Redwood",
      "rotation": 3
    },
    {
      "x": -15,
      "y": 19,
      "z": -14,
      "name": "Plant_Leaves_Redwood",
      "rotation": 3
    },
    {
      "x": -15,
      "y": 20,
      "z": -14,
      "name": "Plant_Leaves_Redwood",
      "rotation": 3
    },
    {
      "x": -15,
      "y": 22,
      "z": -14,
      "name": "Plant_Leaves_Redwood",
      "rotation": 3
    },
    {
      "x": -15,
      "y": 23,
      "z": -14,
      "name": "Plant_Leaves_Redwood",
      "rotation": 3
    },
    {
      "x": -15,
      "y": 19,
      "z": -13,
      "name": "Plant_Leaves_Redwood",
      "rotation": 3
    },
    {
      "x": -15,
      "y": 20,
      "z": -13,
      "name": "Plant_Leaves_Redwood",
      "rotation": 3
    },
    {
      "x": -15,
      "y": 22,
      "z": -13,
      "name": "Plant_Leaves_Redwood",
      "rotation": 3
    },
    {
      "x": -15,
      "y": 23,
      "z": -13,
      "name": "Plant_Leaves_Redwood",
      "rotation": 3
    },
    {
      "x": -15,
      "y": 19,
      "z": -12,
      "name": "Plant_Leaves_Redwood",
      "rotation": 3
    },
    {
      "x": -15,
      "y": 20,
      "z": -12,
      "name": "Plant_Leaves_Redwood",
      "rotation": 3
    },
    {
      "x": -15,
      "y": 22,
      "z": -12,
      "name": "Plant_Leaves_Redwood",
      "rotation": 3
    },
    {
      "x": -15,
      "y": 23,
      "z": -12,
      "name": "Plant_Leaves_Redwood",
      "rotation": 3
    },
    {
      "x": -15,
      "y": 20,
      "z": -11,
      "name": "Plant_Leaves_Redwood",
      "rotation": 3
    },
    {
      "x": -15,
      "y": 21,
      "z": -11,
      "name": "Plant_Leaves_Redwood",
      "rotation": 3
    },
    {
      "x": -15,
      "y": 22,
      "z": -11,
      "name": "Plant_Leaves_Redwood",
      "rotation": 3
    },
    {
      "x": -15,
      "y": 21,
      "z": -10,
      "name": "Plant_Leaves_Redwood",
      "rotation": 3
    },
    {
      "x": -15,
      "y": 2,
      "z": 6,
      "name": "Wood_Beastwood_Bark",
      "rotation": 5
    },
    {
      "x": -15,
      "y": 3,
      "z": 6,
      "name": "Wood_Beastwood_Bark",
      "rotation": 5
    },
    {
      "x": -15,
      "y": 4,
      "z": 6,
      "name": "Wood_Beastwood_Bark",
      "rotation": 5
    },
    {
      "x": -15,
      "y": 5,
      "z": 6,
      "name": "Wood_Beastwood_Bark",
      "rotation": 5
    },
    {
      "x": -15,
      "y": 1,
      "z": 7,
      "name": "Wood_Beastwood_Bark",
      "rotation": 5
    },
    {
      "x": -15,
      "y": 2,
      "z": 7,
      "name": "Wood_Beastwood_Plhoem_Sap",
      "rotation": 1
    },
    {
      "x": -15,
      "y": 3,
      "z": 7,
      "name": "Wood_Beastwood_Plhoem_Sap",
      "rotation": 1
    },
    {
      "x": -15,
      "y": 4,
      "z": 7,
      "name": "Wood_Beastwood_Plhoem_Sap",
      "rotation": 1
    },
    {
      "x": -15,
      "y": 5,
      "z": 7,
      "name": "Wood_Beastwood_Plhoem_Sap",
      "rotation": 1
    },
    {
      "x": -15,
      "y": 6,
      "z": 7,
      "name": "Wood_Beastwood_Bark",
      "rotation": 5
    },
    {
      "x": -15,
      "y": 1,
      "z": 8,
      "name": "Wood_Beastwood_Bark",
      "rotation": 5
    },
    {
      "x": -15,
      "y": 2,
      "z": 8,
      "name": "Wood_Beastwood_Plhoem_Sap",
      "rotation": 1
    },
    {
      "x": -15,
      "y": 3,
      "z": 8,
      "name": "Wood_Beastwood_Sapwood",
      "rotation": 5
    },
    {
      "x": -15,
      "y": 4,
      "z": 8,
      "name": "Wood_Beastwood_Sapwood",
      "rotation": 5
    },
    {
      "x": -15,
      "y": 5,
      "z": 8,
      "name": "Wood_Beastwood_Plhoem_Sap",
      "rotation": 1
    },
    {
      "x": -15,
      "y": 6,
      "z": 8,
      "name": "Wood_Beastwood_Bark",
      "rotation": 5
    },
    {
      "x": -15,
      "y": 1,
      "z": 9,
      "name": "Wood_Beastwood_Bark",
      "rotation": 5
    },
    {
      "x": -15,
      "y": 2,
      "z": 9,
      "name": "Wood_Beastwood_Plhoem_Sap",
      "rotation": 1
    },
    {
      "x": -15,
      "y": 3,
      "z": 9,
      "name": "Wood_Beastwood_Sapwood",
      "rotation": 5
    },
    {
      "x": -15,
      "y": 4,
      "z": 9,
      "name": "Wood_Beastwood_Sapwood",
      "rotation": 5
    },
    {
      "x": -15,
      "y": 5,
      "z": 9,
      "name": "Wood_Beastwood_Plhoem_Sap",
      "rotation": 1
    },
    {
      "x": -15,
      "y": 6,
      "z": 9,
      "name": "Wood_Beastwood_Bark",
      "rotation": 5
    },
    {
      "x": -15,
      "y": 1,
      "z": 10,
      "name": "Wood_Beastwood_Bark",
      "rotation": 5
    },
    {
      "x": -15,
      "y": 2,
      "z": 10,
      "name": "Wood_Beastwood_Plhoem_Sap",
      "rotation": 1
    },
    {
      "x": -15,
      "y": 3,
      "z": 10,
      "name": "Wood_Beastwood_Plhoem_Sap",
      "rotation": 1
    },
    {
      "x": -15,
      "y": 4,
      "z": 10,
      "name": "Wood_Beastwood_Plhoem_Sap",
      "rotation": 1
    },
    {
      "x": -15,
      "y": 5,
      "z": 10,
      "name": "Wood_Beastwood_Plhoem_Sap",
      "rotation": 1
    },
    {
      "x": -15,
      "y": 6,
      "z": 10,
      "name": "Wood_Beastwood_Bark",
      "rotation": 5
    },
    {
      "x": -15,
      "y": 2,
      "z": 11,
      "name": "Wood_Beastwood_Bark",
      "rotation": 5
    },
    {
      "x": -15,
      "y": 3,
      "z": 11,
      "name": "Wood_Beastwood_Bark",
      "rotation": 5
    },
    {
      "x": -15,
      "y": 4,
      "z": 11,
      "name": "Wood_Beastwood_Bark",
      "rotation": 5
    },
    {
      "x": -15,
      "y": 5,
      "z": 11,
      "name": "Wood_Beastwood_Bark",
      "rotation": 5
    },
    {
      "x": -14,
      "y": 20,
      "z": -16,
      "name": "Plant_Leaves_Redwood",
      "rotation": 3
    },
    {
      "x": -14,
      "y": 21,
      "z": -16,
      "name": "Plant_Leaves_Redwood",
      "rotation": 3
    },
    {
      "x": -14,
      "y": 22,
      "z": -16,
      "name": "Plant_Leaves_Redwood",
      "rotation": 3
    },
    {
      "x": -14,
      "y": 20,
      "z": -15,
      "name": "Plant_Leaves_Redwood",
      "rotation": 3
    },
    {
      "x": -14,
      "y": 21,
      "z": -15,
      "name": "Plant_Leaves_Redwood",
      "rotation": 3
    },
    {
      "x": -14,
      "y": 22,
      "z": -15,
      "name": "Plant_Leaves_Redwood",
      "rotation": 3
    },
    {
      "x": -14,
      "y": 19,
      "z": -14,
      "name": "Plant_Leaves_Redwood",
      "rotation": 3
    },
    {
      "x": -14,
      "y": 20,
      "z": -14,
      "name": "Plant_Leaves_Redwood",
      "rotation": 3
    },
    {
      "x": -14,
      "y": 22,
      "z": -14,
      "name": "Plant_Leaves_Redwood",
      "rotation": 3
    },
    {
      "x": -14,
      "y": 23,
      "z": -14,
      "name": "Plant_Leaves_Redwood",
      "rotation": 3
    },
    {
      "x": -14,
      "y": 19,
      "z": -13,
      "name": "Plant_Leaves_Redwood",
      "support": 15,
      "rotation": 3
    },
    {
      "x": -14,
      "y": 20,
      "z": -13,
      "name": "Plant_Leaves_Redwood",
      "support": 15,
      "rotation": 3
    },
    {
      "x": -14,
      "y": 21,
      "z": -13,
      "name": "Plant_Leaves_Redwood",
      "support": 15,
      "rotation": 3
    },
    {
      "x": -14,
      "y": 23,
      "z": -13,
      "name": "Plant_Leaves_Redwood",
      "rotation": 3
    },
    {
      "x": -14,
      "y": 19,
      "z": -12,
      "name": "Plant_Leaves_Redwood",
      "rotation": 3
    },
    {
      "x": -14,
      "y": 20,
      "z": -12,
      "name": "Plant_Leaves_Redwood",
      "support": 15,
      "rotation": 3
    },
    {
      "x": -14,
      "y": 22,
      "z": -12,
      "name": "Plant_Leaves_Redwood",
      "rotation": 3
    },
    {
      "x": -14,
      "y": 23,
      "z": -12,
      "name": "Plant_Leaves_Redwood",
      "rotation": 3
    },
    {
      "x": -14,
      "y": 20,
      "z": -11,
      "name": "Plant_Leaves_Redwood",
      "rotation": 3
    },
    {
      "x": -14,
      "y": 21,
      "z": -11,
      "name": "Plant_Leaves_Redwood",
      "rotation": 3
    },
    {
      "x": -14,
      "y": 22,
      "z": -11,
      "name": "Plant_Leaves_Redwood",
      "rotation": 3
    },
    {
      "x": -14,
      "y": 20,
      "z": -10,
      "name": "Plant_Leaves_Redwood",
      "rotation": 3
    },
    {
      "x": -14,
      "y": 21,
      "z": -10,
      "name": "Plant_Leaves_Redwood",
      "rotation": 3
    },
    {
      "x": -14,
      "y": 22,
      "z": -10,
      "name": "Plant_Leaves_Redwood",
      "rotation": 3
    },
    {
      "x": -14,
      "y": 10,
      "z": 3,
      "name": "Plant_Leaves_Redwood"
    },
    {
      "x": -14,
      "y": 9,
      "z": 4,
      "name": "Plant_Leaves_Redwood"
    },
    {
      "x": -14,
      "y": 10,
      "z": 4,
      "name": "Plant_Leaves_Redwood"
    },
    {
      "x": -14,
      "y": 11,
      "z": 4,
      "name": "Plant_Leaves_Redwood"
    },
    {
      "x": -14,
      "y": 10,
      "z": 5,
      "name": "Plant_Leaves_Redwood"
    },
    {
      "x": -14,
      "y": 3,
      "z": 6,
      "name": "Wood_Beastwood_Bark",
      "rotation": 5
    },
    {
      "x": -14,
      "y": 4,
      "z": 6,
      "name": "Wood_Beastwood_Bark",
      "rotation": 5
    },
    {
      "x": -14,
      "y": 5,
      "z": 6,
      "name": "Wood_Beastwood_Bark",
      "rotation": 5
    },
    {
      "x": -14,
      "y": 2,
      "z": 7,
      "name": "Wood_Beastwood_Bark",
      "rotation": 5
    },
    {
      "x": -14,
      "y": 3,
      "z": 7,
      "name": "Wood_Beastwood_Plhoem_Sap",
      "rotation": 1
    },
    {
      "x": -14,
      "y": 4,
      "z": 7,
      "name": "Wood_Beastwood_Plhoem_Sap",
      "rotation": 1
    },
    {
      "x": -14,
      "y": 5,
      "z": 7,
      "name": "Wood_Beastwood_Bark",
      "rotation": 5
    },
    {
      "x": -14,
      "y": 6,
      "z": 7,
      "name": "Wood_Beastwood_Bark",
      "rotation": 5
    },
    {
      "x": -14,
      "y": 1,
      "z": 8,
      "name": "Wood_Beastwood_Bark",
      "rotation": 5
    },
    {
      "x": -14,
      "y": 2,
      "z": 8,
      "name": "Wood_Beastwood_Plhoem_Sap",
      "rotation": 1
    },
    {
      "x": -14,
      "y": 3,
      "z": 8,
      "name": "Wood_Beastwood_Sapwood",
      "rotation": 5
    },
    {
      "x": -14,
      "y": 4,
      "z": 8,
      "name": "Wood_Beastwood_Sapwood",
      "rotation": 5
    },
    {
      "x": -14,
      "y": 5,
      "z": 8,
      "name": "Wood_Beastwood_Plhoem_Sap",
      "rotation": 1
    },
    {
      "x": -14,
      "y": 6,
      "z": 8,
      "name": "Wood_Beastwood_Bark",
      "rotation": 5
    },
    {
      "x": -14,
      "y": 1,
      "z": 9,
      "name": "Wood_Beastwood_Bark",
      "rotation": 5
    },
    {
      "x": -14,
      "y": 2,
      "z": 9,
      "name": "Wood_Beastwood_Plhoem_Sap",
      "rotation": 1
    },
    {
      "x": -14,
      "y": 3,
      "z": 9,
      "name": "Wood_Beastwood_Sapwood",
      "rotation": 5
    },
    {
      "x": -14,
      "y": 4,
      "z": 9,
      "name": "Wood_Beastwood_Sapwood",
      "rotation": 5
    },
    {
      "x": -14,
      "y": 5,
      "z": 9,
      "name": "Wood_Beastwood_Plhoem_Sap",
      "rotation": 1
    },
    {
      "x": -14,
      "y": 6,
      "z": 9,
      "name": "Wood_Beastwood_Bark",
      "rotation": 5
    },
    {
      "x": -14,
      "y": 2,
      "z": 10,
      "name": "Wood_Beastwood_Bark",
      "rotation": 5
    },
    {
      "x": -14,
      "y": 3,
      "z": 10,
      "name": "Wood_Beastwood_Plhoem_Sap",
      "rotation": 1
    },
    {
      "x": -14,
      "y": 4,
      "z": 10,
      "name": "Wood_Beastwood_Plhoem_Sap",
      "rotation": 1
    },
    {
      "x": -14,
      "y": 5,
      "z": 10,
      "name": "Wood_Beastwood_Bark",
      "rotation": 5
    },
    {
      "x": -14,
      "y": 6,
      "z": 10,
      "name": "Wood_Beastwood_Bark",
      "rotation": 5
    },
    {
      "x": -14,
      "y": 3,
      "z": 11,
      "name": "Wood_Beastwood_Bark",
      "rotation": 5
    },
    {
      "x": -14,
      "y": 4,
      "z": 11,
      "name": "Wood_Beastwood_Bark",
      "rotation": 5
    },
    {
      "x": -14,
      "y": 5,
      "z": 11,
      "name": "Wood_Beastwood_Bark",
      "rotation": 5
    },
    {
      "x": -13,
      "y": 20,
      "z": -16,
      "name": "Plant_Leaves_Redwood",
      "rotation": 3
    },
    {
      "x": -13,
      "y": 21,
      "z": -16,
      "name": "Plant_Leaves_Redwood",
      "rotation": 3
    },
    {
      "x": -13,
      "y": 19,
      "z": -15,
      "name": "Plant_Leaves_Redwood",
      "rotation": 3
    },
    {
      "x": -13,
      "y": 20,
      "z": -15,
      "name": "Plant_Leaves_Redwood",
      "rotation": 3
    },
    {
      "x": -13,
      "y": 21,
      "z": -15,
      "name": "Plant_Leaves_Redwood",
      "rotation": 3
    },
    {
      "x": -13,
      "y": 22,
      "z": -15,
      "name": "Plant_Leaves_Redwood",
      "rotation": 3
    },
    {
      "x": -13,
      "y": 19,
      "z": -14,
      "name": "Plant_Leaves_Redwood",
      "rotation": 3
    },
    {
      "x": -13,
      "y": 20,
      "z": -14,
      "name": "Plant_Leaves_Redwood",
      "support": 15,
      "rotation": 3
    },
    {
      "x": -13,
      "y": 21,
      "z": -14,
      "name": "Plant_Leaves_Redwood",
      "support": 15,
      "rotation": 3
    },
    {
      "x": -13,
      "y": 22,
      "z": -14,
      "name": "Plant_Leaves_Redwood",
      "rotation": 3
    },
    {
      "x": -13,
      "y": 23,
      "z": -14,
      "name": "Plant_Leaves_Redwood",
      "rotation": 3
    },
    {
      "x": -13,
      "y": 19,
      "z": -13,
      "name": "Plant_Leaves_Redwood",
      "support": 15,
      "rotation": 3
    },
    {
      "x": -13,
      "y": 20,
      "z": -13,
      "name": "Plant_Leaves_Redwood",
      "support": 15,
      "rotation": 3
    },
    {
      "x": -13,
      "y": 21,
      "z": -13,
      "name": "Plant_Leaves_Redwood",
      "support": 15,
      "rotation": 3
    },
    {
      "x": -13,
      "y": 22,
      "z": -13,
      "name": "Plant_Leaves_Redwood",
      "rotation": 3
    },
    {
      "x": -13,
      "y": 23,
      "z": -13,
      "name": "Plant_Leaves_Redwood",
      "rotation": 3
    },
    {
      "x": -13,
      "y": 19,
      "z": -12,
      "name": "Plant_Leaves_Redwood",
      "rotation": 3
    },
    {
      "x": -13,
      "y": 20,
      "z": -12,
      "name": "Plant_Leaves_Redwood",
      "support": 15,
      "rotation": 3
    },
    {
      "x": -13,
      "y": 21,
      "z": -12,
      "name": "Plant_Leaves_Redwood",
      "support": 15,
      "rotation": 3
    },
    {
      "x": -13,
      "y": 22,
      "z": -12,
      "name": "Plant_Leaves_Redwood",
      "rotation": 3
    },
    {
      "x": -13,
      "y": 23,
      "z": -12,
      "name": "Plant_Leaves_Redwood",
      "rotation": 3
    },
    {
      "x": -13,
      "y": 20,
      "z": -11,
      "name": "Plant_Leaves_Redwood",
      "rotation": 3
    },
    {
      "x": -13,
      "y": 21,
      "z": -11,
      "name": "Plant_Leaves_Redwood",
      "rotation": 3
    },
    {
      "x": -13,
      "y": 22,
      "z": -11,
      "name": "Plant_Leaves_Redwood",
      "rotation": 3
    },
    {
      "x": -13,
      "y": 21,
      "z": -10,
      "name": "Plant_Leaves_Redwood",
      "rotation": 3
    },
    {
      "x": -13,
      "y": 9,
      "z": 2,
      "name": "Plant_Leaves_Redwood"
    },
    {
      "x": -13,
      "y": 10,
      "z": 2,
      "name": "Plant_Leaves_Redwood"
    },
    {
      "x": -13,
      "y": 11,
      "z": 2,
      "name": "Plant_Leaves_Redwood"
    },
    {
      "x": -13,
      "y": 9,
      "z": 3,
      "name": "Plant_Leaves_Redwood"
    },
    {
      "x": -13,
      "y": 10,
      "z": 3,
      "name": "Plant_Leaves_Redwood"
    },
    {
      "x": -13,
      "y": 11,
      "z": 3,
      "name": "Plant_Leaves_Redwood"
    },
    {
      "x": -13,
      "y": 9,
      "z": 4,
      "name": "Plant_Leaves_Redwood"
    },
    {
      "x": -13,
      "y": 10,
      "z": 4,
      "name": "Plant_Leaves_Redwood"
    },
    {
      "x": -13,
      "y": 11,
      "z": 4,
      "name": "Plant_Leaves_Redwood"
    },
    {
      "x": -13,
      "y": 9,
      "z": 5,
      "name": "Plant_Leaves_Redwood"
    },
    {
      "x": -13,
      "y": 10,
      "z": 5,
      "name": "Plant_Leaves_Redwood"
    },
    {
      "x": -13,
      "y": 11,
      "z": 5,
      "name": "Plant_Leaves_Redwood"
    },
    {
      "x": -13,
      "y": 4,
      "z": 6,
      "name": "Wood_Beastwood_Bark",
      "rotation": 5
    },
    {
      "x": -13,
      "y": 5,
      "z": 6,
      "name": "Wood_Beastwood_Bark",
      "rotation": 5
    },
    {
      "x": -13,
      "y": 6,
      "z": 6,
      "name": "Wood_Beastwood_Bark",
      "rotation": 5
    },
    {
      "x": -13,
      "y": 9,
      "z": 6,
      "name": "Plant_Leaves_Redwood"
    },
    {
      "x": -13,
      "y": 10,
      "z": 6,
      "name": "Plant_Leaves_Redwood"
    },
    {
      "x": -13,
      "y": 11,
      "z": 6,
      "name": "Plant_Leaves_Redwood"
    },
    {
      "x": -13,
      "y": 3,
      "z": 7,
      "name": "Wood_Beastwood_Bark",
      "rotation": 5
    },
    {
      "x": -13,
      "y": 4,
      "z": 7,
      "name": "Wood_Beastwood_Plhoem_Sap",
      "rotation": 1
    },
    {
      "x": -13,
      "y": 5,
      "z": 7,
      "name": "Wood_Beastwood_Plhoem_Sap",
      "rotation": 1
    },
    {
      "x": -13,
      "y": 6,
      "z": 7,
      "name": "Wood_Beastwood_Bark",
      "rotation": 5
    },
    {
      "x": -13,
      "y": 7,
      "z": 7,
      "name": "Wood_Beastwood_Bark",
      "rotation": 5
    },
    {
      "x": -13,
      "y": 2,
      "z": 8,
      "name": "Wood_Beastwood_Bark",
      "rotation": 5
    },
    {
      "x": -13,
      "y": 3,
      "z": 8,
      "name": "Wood_Beastwood_Plhoem_Sap",
      "rotation": 1
    },
    {
      "x": -13,
      "y": 4,
      "z": 8,
      "name": "Wood_Beastwood_Sapwood",
      "rotation": 5
    },
    {
      "x": -13,
      "y": 5,
      "z": 8,
      "name": "Wood_Beastwood_Sapwood",
      "rotation": 1
    },
    {
      "x": -13,
      "y": 6,
      "z": 8,
      "name": "Wood_Beastwood_Plhoem_Sap",
      "rotation": 1
    },
    {
      "x": -13,
      "y": 7,
      "z": 8,
      "name": "Wood_Beastwood_Bark",
      "rotation": 5
    },
    {
      "x": -13,
      "y": 2,
      "z": 9,
      "name": "Wood_Beastwood_Bark",
      "rotation": 5
    },
    {
      "x": -13,
      "y": 3,
      "z": 9,
      "name": "Wood_Beastwood_Plhoem_Sap",
      "rotation": 1
    },
    {
      "x": -13,
      "y": 4,
      "z": 9,
      "name": "Wood_Beastwood_Sapwood",
      "rotation": 5
    },
    {
      "x": -13,
      "y": 5,
      "z": 9,
      "name": "Wood_Beastwood_Sapwood",
      "rotation": 1
    },
    {
      "x": -13,
      "y": 6,
      "z": 9,
      "name": "Wood_Beastwood_Plhoem_Sap",
      "rotation": 1
    },
    {
      "x": -13,
      "y": 7,
      "z": 9,
      "name": "Wood_Beastwood_Bark",
      "rotation": 5
    },
    {
      "x": -13,
      "y": 3,
      "z": 10,
      "name": "Wood_Beastwood_Bark",
      "rotation": 5
    },
    {
      "x": -13,
      "y": 4,
      "z": 10,
      "name": "Wood_Beastwood_Plhoem_Sap",
      "rotation": 1
    },
    {
      "x": -13,
      "y": 5,
      "z": 10,
      "name": "Wood_Beastwood_Plhoem_Sap",
      "rotation": 1
    },
    {
      "x": -13,
      "y": 6,
      "z": 10,
      "name": "Wood_Beastwood_Bark",
      "rotation": 5
    },
    {
      "x": -13,
      "y": 4,
      "z": 11,
      "name": "Wood_Beastwood_Bark",
      "rotation": 5
    },
    {
      "x": -13,
      "y": 5,
      "z": 11,
      "name": "Wood_Beastwood_Bark",
      "rotation": 5
    },
    {
      "x": -13,
      "y": 4,
      "z": 13,
      "name": "Plant_Leaves_Redwood"
    },
    {
      "x": -13,
      "y": 3,
      "z": 14,
      "name": "Plant_Leaves_Redwood"
    },
    {
      "x": -13,
      "y": 4,
      "z": 14,
      "name": "Plant_Leaves_Redwood"
    },
    {
      "x": -13,
      "y": 5,
      "z": 14,
      "name": "Plant_Leaves_Redwood"
    },
    {
      "x": -13,
      "y": 4,
      "z": 15,
      "name": "Plant_Leaves_Redwood"
    },
    {
      "x": -12,
      "y": 19,
      "z": -17,
      "name": "Plant_Leaves_Redwood",
      "rotation": 3
    },
    {
      "x": -12,
      "y": 20,
      "z": -17,
      "name": "Plant_Leaves_Redwood",
      "rotation": 3
    },
    {
      "x": -12,
      "y": 21,
      "z": -17,
      "name": "Plant_Leaves_Redwood",
      "rotation": 3
    },
    {
      "x": -12,
      "y": 19,
      "z": -16,
      "name": "Plant_Leaves_Redwood",
      "rotation": 3
    },
    {
      "x": -12,
      "y": 20,
      "z": -16,
      "name": "Plant_Leaves_Redwood",
      "rotation": 3
    },
    {
      "x": -12,
      "y": 21,
      "z": -16,
      "name": "Plant_Leaves_Redwood",
      "rotation": 3
    },
    {
      "x": -12,
      "y": 19,
      "z": -15,
      "name": "Plant_Leaves_Redwood",
      "rotation": 3
    },
    {
      "x": -12,
      "y": 20,
      "z": -15,
      "name": "Plant_Leaves_Redwood",
      "rotation": 3
    },
    {
      "x": -12,
      "y": 21,
      "z": -15,
      "name": "Plant_Leaves_Redwood",
      "rotation": 3
    },
    {
      "x": -12,
      "y": 22,
      "z": -15,
      "name": "Plant_Leaves_Redwood",
      "rotation": 3
    },
    {
      "x": -12,
      "y": 19,
      "z": -14,
      "name": "Plant_Leaves_Redwood",
      "rotation": 3
    },
    {
      "x": -12,
      "y": 20,
      "z": -14,
      "name": "Plant_Leaves_Redwood",
      "support": 15,
      "rotation": 3
    },
    {
      "x": -12,
      "y": 21,
      "z": -14,
      "name": "Plant_Leaves_Redwood",
      "rotation": 3
    },
    {
      "x": -12,
      "y": 22,
      "z": -14,
      "name": "Plant_Leaves_Redwood",
      "rotation": 3
    },
    {
      "x": -12,
      "y": 19,
      "z": -13,
      "name": "Plant_Leaves_Redwood",
      "support": 15,
      "rotation": 3
    },
    {
      "x": -12,
      "y": 20,
      "z": -13,
      "name": "Plant_Leaves_Redwood",
      "support": 15,
      "rotation": 3
    },
    {
      "x": -12,
      "y": 21,
      "z": -13,
      "name": "Plant_Leaves_Redwood",
      "support": 15,
      "rotation": 3
    },
    {
      "x": -12,
      "y": 22,
      "z": -13,
      "name": "Plant_Leaves_Redwood",
      "rotation": 3
    },
    {
      "x": -12,
      "y": 19,
      "z": -12,
      "name": "Plant_Leaves_Redwood",
      "support": 15,
      "rotation": 3
    },
    {
      "x": -12,
      "y": 20,
      "z": -12,
      "name": "Plant_Leaves_Redwood",
      "support": 15,
      "rotation": 3
    },
    {
      "x": -12,
      "y": 21,
      "z": -12,
      "name": "Plant_Leaves_Redwood",
      "rotation": 3
    },
    {
      "x": -12,
      "y": 22,
      "z": -12,
      "name": "Plant_Leaves_Redwood",
      "rotation": 3
    },
    {
      "x": -12,
      "y": 20,
      "z": -11,
      "name": "Plant_Leaves_Redwood",
      "rotation": 3
    },
    {
      "x": -12,
      "y": 21,
      "z": -11,
      "name": "Plant_Leaves_Redwood",
      "rotation": 3
    },
    {
      "x": -12,
      "y": 22,
      "z": -11,
      "name": "Plant_Leaves_Redwood",
      "rotation": 3
    },
    {
      "x": -12,
      "y": 10,
      "z": 1,
      "name": "Plant_Leaves_Redwood"
    },
    {
      "x": -12,
      "y": 9,
      "z": 2,
      "name": "Plant_Leaves_Redwood"
    },
    {
      "x": -12,
      "y": 10,
      "z": 2,
      "name": "Plant_Leaves_Redwood"
    },
    {
      "x": -12,
      "y": 11,
      "z": 2,
      "name": "Plant_Leaves_Redwood"
    },
    {
      "x": -12,
      "y": 8,
      "z": 3,
      "name": "Plant_Leaves_Redwood"
    },
    {
      "x": -12,
      "y": 9,
      "z": 3,
      "name": "Plant_Leaves_Redwood"
    },
    {
      "x": -12,
      "y": 11,
      "z": 3,
      "name": "Plant_Leaves_Redwood"
    },
    {
      "x": -12,
      "y": 12,
      "z": 3,
      "name": "Plant_Leaves_Redwood"
    },
    {
      "x": -12,
      "y": 8,
      "z": 4,
      "name": "Plant_Leaves_Redwood"
    },
    {
      "x": -12,
      "y": 9,
      "z": 4,
      "name": "Plant_Leaves_Redwood"
    },
    {
      "x": -12,
      "y": 11,
      "z": 4,
      "name": "Plant_Leaves_Redwood"
    },
    {
      "x": -12,
      "y": 12,
      "z": 4,
      "name": "Plant_Leaves_Redwood"
    },
    {
      "x": -12,
      "y": 8,
      "z": 5,
      "name": "Plant_Leaves_Redwood"
    },
    {
      "x": -12,
      "y": 9,
      "z": 5,
      "name": "Plant_Leaves_Redwood"
    },
    {
      "x": -12,
      "y": 11,
      "z": 5,
      "name": "Plant_Leaves_Redwood"
    },
    {
      "x": -12,
      "y": 12,
      "z": 5,
      "name": "Plant_Leaves_Redwood"
    },
    {
      "x": -12,
      "y": 4,
      "z": 6,
      "name": "Wood_Beastwood_Bark",
      "rotation": 5
    },
    {
      "x": -12,
      "y": 5,
      "z": 6,
      "name": "Wood_Beastwood_Bark",
      "rotation": 5
    },
    {
      "x": -12,
      "y": 6,
      "z": 6,
      "name": "Wood_Beastwood_Bark",
      "rotation": 5
    },
    {
      "x": -12,
      "y": 9,
      "z": 6,
      "name": "Plant_Leaves_Redwood"
    },
    {
      "x": -12,
      "y": 10,
      "z": 6,
      "name": "Plant_Leaves_Redwood"
    },
    {
      "x": -12,
      "y": 11,
      "z": 6,
      "name": "Plant_Leaves_Redwood"
    },
    {
      "x": -12,
      "y": 3,
      "z": 7,
      "name": "Wood_Beastwood_Bark",
      "rotation": 5
    },
    {
      "x": -12,
      "y": 4,
      "z": 7,
      "name": "Wood_Beastwood_Plhoem_Sap",
      "rotation": 1
    },
    {
      "x": -12,
      "y": 5,
      "z": 7,
      "name": "Wood_Beastwood_Plhoem_Sap",
      "rotation": 1
    },
    {
      "x": -12,
      "y": 6,
      "z": 7,
      "name": "Wood_Beastwood_Bark",
      "rotation": 5
    },
    {
      "x": -12,
      "y": 7,
      "z": 7,
      "name": "Wood_Beastwood_Bark",
      "rotation": 5
    },
    {
      "x": -12,
      "y": 8,
      "z": 7,
      "name": "Wood_Beastwood_Bark",
      "rotation": 1
    },
    {
      "x": -12,
      "y": 10,
      "z": 7,
      "name": "Plant_Leaves_Redwood"
    },
    {
      "x": -12,
      "y": 2,
      "z": 8,
      "name": "Wood_Beastwood_Bark",
      "rotation": 5
    },
    {
      "x": -12,
      "y": 3,
      "z": 8,
      "name": "Wood_Beastwood_Plhoem_Sap",
      "rotation": 1
    },
    {
      "x": -12,
      "y": 4,
      "z": 8,
      "name": "Wood_Beastwood_Sapwood",
      "rotation": 5
    },
    {
      "x": -12,
      "y": 5,
      "z": 8,
      "name": "Wood_Beastwood_Sapwood",
      "rotation": 5
    },
    {
      "x": -12,
      "y": 6,
      "z": 8,
      "name": "Wood_Beastwood_Plhoem_Sap",
      "rotation": 1
    },
    {
      "x": -12,
      "y": 7,
      "z": 8,
      "name": "Wood_Beastwood_Bark",
      "rotation": 5
    },
    {
      "x": -12,
      "y": 8,
      "z": 8,
      "name": "Wood_Beastwood_Bark",
      "rotation": 1
    },
    {
      "x": -12,
      "y": 2,
      "z": 9,
      "name": "Wood_Beastwood_Bark",
      "rotation": 5
    },
    {
      "x": -12,
      "y": 3,
      "z": 9,
      "name": "Wood_Beastwood_Plhoem_Sap",
      "rotation": 1
    },
    {
      "x": -12,
      "y": 4,
      "z": 9,
      "name": "Wood_Beastwood_Sapwood",
      "rotation": 5
    },
    {
      "x": -12,
      "y": 5,
      "z": 9,
      "name": "Wood_Beastwood_Sapwood",
      "rotation": 5
    },
    {
      "x": -12,
      "y": 6,
      "z": 9,
      "name": "Wood_Beastwood_Plhoem_Sap",
      "rotation": 1
    },
    {
      "x": -12,
      "y": 7,
      "z": 9,
      "name": "Wood_Beastwood_Bark",
      "rotation": 5
    },
    {
      "x": -12,
      "y": 8,
      "z": 9,
      "name": "Wood_Beastwood_Bark",
      "rotation": 1
    },
    {
      "x": -12,
      "y": 3,
      "z": 10,
      "name": "Wood_Beastwood_Bark",
      "rotation": 5
    },
    {
      "x": -12,
      "y": 4,
      "z": 10,
      "name": "Wood_Beastwood_Plhoem_Sap",
      "rotation": 1
    },
    {
      "x": -12,
      "y": 5,
      "z": 10,
      "name": "Wood_Beastwood_Plhoem_Sap",
      "rotation": 1
    },
    {
      "x": -12,
      "y": 6,
      "z": 10,
      "name": "Wood_Beastwood_Bark",
      "rotation": 5
    },
    {
      "x": -12,
      "y": 7,
      "z": 10,
      "name": "Wood_Beastwood_Bark",
      "rotation": 5
    },
    {
      "x": -12,
      "y": 8,
      "z": 10,
      "name": "Wood_Beastwood_Bark",
      "rotation": 1
    },
    {
      "x": -12,
      "y": 4,
      "z": 11,
      "name": "Wood_Beastwood_Bark",
      "rotation": 5
    },
    {
      "x": -12,
      "y": 5,
      "z": 11,
      "name": "Wood_Beastwood_Bark",
      "rotation": 5
    },
    {
      "x": -12,
      "y": 6,
      "z": 11,
      "name": "Wood_Beastwood_Bark",
      "rotation": 5
    },
    {
      "x": -12,
      "y": 3,
      "z": 12,
      "name": "Plant_Leaves_Redwood"
    },
    {
      "x": -12,
      "y": 4,
      "z": 12,
      "name": "Plant_Leaves_Redwood"
    },
    {
      "x": -12,
      "y": 5,
      "z": 12,
      "name": "Plant_Leaves_Redwood"
    },
    {
      "x": -12,
      "y": 3,
      "z": 13,
      "name": "Plant_Leaves_Redwood"
    },
    {
      "x": -12,
      "y": 4,
      "z": 13,
      "name": "Plant_Leaves_Redwood"
    },
    {
      "x": -12,
      "y": 5,
      "z": 13,
      "name": "Plant_Leaves_Redwood"
    },
    {
      "x": -12,
      "y": 3,
      "z": 14,
      "name": "Plant_Leaves_Redwood"
    },
    {
      "x": -12,
      "y": 4,
      "z": 14,
      "name": "Plant_Leaves_Redwood"
    },
    {
      "x": -12,
      "y": 5,
      "z": 14,
      "name": "Plant_Leaves_Redwood"
    },
    {
      "x": -12,
      "y": 3,
      "z": 15,
      "name": "Plant_Leaves_Redwood"
    },
    {
      "x": -12,
      "y": 4,
      "z": 15,
      "name": "Plant_Leaves_Redwood"
    },
    {
      "x": -12,
      "y": 5,
      "z": 15,
      "name": "Plant_Leaves_Redwood"
    },
    {
      "x": -12,
      "y": 3,
      "z": 16,
      "name": "Plant_Leaves_Redwood"
    },
    {
      "x": -12,
      "y": 4,
      "z": 16,
      "name": "Plant_Leaves_Redwood"
    },
    {
      "x": -12,
      "y": 5,
      "z": 16,
      "name": "Plant_Leaves_Redwood"
    },
    {
      "x": -11,
      "y": 20,
      "z": -18,
      "name": "Plant_Leaves_Redwood",
      "rotation": 3
    },
    {
      "x": -11,
      "y": 19,
      "z": -17,
      "name": "Plant_Leaves_Redwood",
      "rotation": 3
    },
    {
      "x": -11,
      "y": 20,
      "z": -17,
      "name": "Plant_Leaves_Redwood",
      "rotation": 3
    },
    {
      "x": -11,
      "y": 21,
      "z": -17,
      "name": "Plant_Leaves_Redwood",
      "rotation": 3
    },
    {
      "x": -11,
      "y": 18,
      "z": -16,
      "name": "Plant_Leaves_Redwood",
      "rotation": 3
    },
    {
      "x": -11,
      "y": 19,
      "z": -16,
      "name": "Plant_Leaves_Redwood",
      "rotation": 3
    },
    {
      "x": -11,
      "y": 21,
      "z": -16,
      "name": "Plant_Leaves_Redwood",
      "rotation": 3
    },
    {
      "x": -11,
      "y": 22,
      "z": -16,
      "name": "Plant_Leaves_Redwood",
      "rotation": 3
    },
    {
      "x": -11,
      "y": 18,
      "z": -15,
      "name": "Plant_Leaves_Redwood",
      "rotation": 3
    },
    {
      "x": -11,
      "y": 19,
      "z": -15,
      "name": "Plant_Leaves_Redwood",
      "rotation": 3
    },
    {
      "x": -11,
      "y": 21,
      "z": -15,
      "name": "Plant_Leaves_Redwood",
      "rotation": 3
    },
    {
      "x": -11,
      "y": 22,
      "z": -15,
      "name": "Plant_Leaves_Redwood",
      "rotation": 3
    },
    {
      "x": -11,
      "y": 18,
      "z": -14,
      "name": "Plant_Leaves_Redwood",
      "rotation": 3
    },
    {
      "x": -11,
      "y": 19,
      "z": -14,
      "name": "Plant_Leaves_Redwood",
      "support": 15,
      "rotation": 3
    },
    {
      "x": -11,
      "y": 20,
      "z": -14,
      "name": "Plant_Leaves_Redwood",
      "support": 15,
      "rotation": 3
    },
    {
      "x": -11,
      "y": 21,
      "z": -14,
      "name": "Plant_Leaves_Redwood",
      "support": 15,
      "rotation": 3
    },
    {
      "x": -11,
      "y": 22,
      "z": -14,
      "name": "Plant_Leaves_Redwood",
      "rotation": 3
    },
    {
      "x": -11,
      "y": 18,
      "z": -13,
      "name": "Wood_Redwood_Branch_Corner",
      "support": 15,
      "rotation": 3
    },
    {
      "x": -11,
      "y": 19,
      "z": -13,
      "name": "Plant_Leaves_Redwood",
      "support": 15,
      "rotation": 3
    },
    {
      "x": -11,
      "y": 20,
      "z": -13,
      "name": "Plant_Leaves_Redwood",
      "support": 15,
      "rotation": 3
    },
    {
      "x": -11,
      "y": 21,
      "z": -13,
      "name": "Plant_Leaves_Redwood",
      "support": 15,
      "rotation": 3
    },
    {
      "x": -11,
      "y": 22,
      "z": -13,
      "name": "Plant_Leaves_Redwood",
      "rotation": 3
    },
    {
      "x": -11,
      "y": 18,
      "z": -12,
      "name": "Plant_Leaves_Redwood",
      "support": 15,
      "rotation": 3
    },
    {
      "x": -11,
      "y": 19,
      "z": -12,
      "name": "Plant_Leaves_Redwood",
      "support": 15,
      "rotation": 3
    },
    {
      "x": -11,
      "y": 20,
      "z": -12,
      "name": "Plant_Leaves_Redwood",
      "support": 15,
      "rotation": 3
    },
    {
      "x": -11,
      "y": 21,
      "z": -12,
      "name": "Plant_Leaves_Redwood",
      "rotation": 3
    },
    {
      "x": -11,
      "y": 9,
      "z": 1,
      "name": "Plant_Leaves_Redwood"
    },
    {
      "x": -11,
      "y": 10,
      "z": 1,
      "name": "Plant_Leaves_Redwood"
    },
    {
      "x": -11,
      "y": 11,
      "z": 1,
      "name": "Plant_Leaves_Redwood"
    },
    {
      "x": -11,
      "y": 9,
      "z": 2,
      "name": "Plant_Leaves_Redwood"
    },
    {
      "x": -11,
      "y": 10,
      "z": 2,
      "name": "Plant_Leaves_Redwood"
    },
    {
      "x": -11,
      "y": 11,
      "z": 2,
      "name": "Plant_Leaves_Redwood"
    },
    {
      "x": -11,
      "y": 8,
      "z": 3,
      "name": "Plant_Leaves_Redwood"
    },
    {
      "x": -11,
      "y": 9,
      "z": 3,
      "name": "Plant_Leaves_Redwood"
    },
    {
      "x": -11,
      "y": 11,
      "z": 3,
      "name": "Plant_Leaves_Redwood"
    },
    {
      "x": -11,
      "y": 12,
      "z": 3,
      "name": "Plant_Leaves_Redwood"
    },
    {
      "x": -11,
      "y": 8,
      "z": 4,
      "name": "Plant_Leaves_Redwood"
    },
    {
      "x": -11,
      "y": 10,
      "z": 4,
      "name": "Plant_Leaves_Redwood",
      "support": 15,
      "rotation": 3
    },
    {
      "x": -11,
      "y": 12,
      "z": 4,
      "name": "Plant_Leaves_Redwood"
    },
    {
      "x": -11,
      "y": 8,
      "z": 5,
      "name": "Plant_Leaves_Redwood"
    },
    {
      "x": -11,
      "y": 9,
      "z": 5,
      "name": "Plant_Leaves_Redwood"
    },
    {
      "x": -11,
      "y": 11,
      "z": 5,
      "name": "Plant_Leaves_Redwood"
    },
    {
      "x": -11,
      "y": 12,
      "z": 5,
      "name": "Plant_Leaves_Redwood"
    },
    {
      "x": -11,
      "y": 4,
      "z": 6,
      "name": "Wood_Redwood_Trunk_Full",
      "support": 15,
      "rotation": 5
    },
    {
      "x": -11,
      "y": 5,
      "z": 6,
      "name": "Wood_Redwood_Trunk_Full",
      "support": 15,
      "rotation": 5
    },
    {
      "x": -11,
      "y": 6,
      "z": 6,
      "name": "Wood_Beastwood_Bark",
      "rotation": 5
    },
    {
      "x": -11,
      "y": 7,
      "z": 6,
      "name": "Wood_Beastwood_Bark",
      "rotation": 5
    },
    {
      "x": -11,
      "y": 9,
      "z": 6,
      "name": "Plant_Leaves_Redwood"
    },
    {
      "x": -11,
      "y": 10,
      "z": 6,
      "name": "Plant_Leaves_Redwood"
    },
    {
      "x": -11,
      "y": 11,
      "z": 6,
      "name": "Plant_Leaves_Redwood"
    },
    {
      "x": -11,
      "y": 3,
      "z": 7,
      "name": "Wood_Redwood_Trunk_Full",
      "support": 15,
      "rotation": 5
    },
    {
      "x": -11,
      "y": 4,
      "z": 7,
      "name": "Wood_Beastwood_Plhoem_Sap",
      "rotation": 1
    },
    {
      "x": -11,
      "y": 5,
      "z": 7,
      "name": "Wood_Beastwood_Plhoem_Sap",
      "rotation": 1
    },
    {
      "x": -11,
      "y": 6,
      "z": 7,
      "name": "Wood_Beastwood_Plhoem_Sap",
      "rotation": 1
    },
    {
      "x": -11,
      "y": 7,
      "z": 7,
      "name": "Wood_Redwood_Trunk_Full",
      "support": 15,
      "rotation": 5
    },
    {
      "x": -11,
      "y": 8,
      "z": 7,
      "name": "Wood_Beastwood_Bark",
      "rotation": 5
    },
    {
      "x": -11,
      "y": 9,
      "z": 7,
      "name": "Plant_Leaves_Redwood"
    },
    {
      "x": -11,
      "y": 10,
      "z": 7,
      "name": "Plant_Leaves_Redwood"
    },
    {
      "x": -11,
      "y": 11,
      "z": 7,
      "name": "Plant_Leaves_Redwood"
    },
    {
      "x": -11,
      "y": 2,
      "z": 8,
      "name": "Wood_Redwood_Trunk_Full",
      "support": 15,
      "rotation": 5
    },
    {
      "x": -11,
      "y": 3,
      "z": 8,
      "name": "Wood_Beastwood_Plhoem_Sap",
      "rotation": 1
    },
    {
      "x": -11,
      "y": 4,
      "z": 8,
      "name": "Wood_Beastwood_Plhoem_Sap",
      "rotation": 1
    },
    {
      "x": -11,
      "y": 5,
      "z": 8,
      "name": "Wood_Beastwood_Sapwood",
      "rotation": 5
    },
    {
      "x": -11,
      "y": 6,
      "z": 8,
      "name": "Wood_Beastwood_Sapwood",
      "rotation": 5
    },
    {
      "x": -11,
      "y": 7,
      "z": 8,
      "name": "Wood_Beastwood_Plhoem_Sap",
      "rotation": 1
    },
    {
      "x": -11,
      "y": 8,
      "z": 8,
      "name": "Wood_Redwood_Trunk_Full",
      "support": 15,
      "rotation": 5
    },
    {
      "x": -11,
      "y": 9,
      "z": 8,
      "name": "Wood_Beastwood_Bark",
      "rotation": 1
    },
    {
      "x": -11,
      "y": 2,
      "z": 9,
      "name": "Wood_Redwood_Trunk_Full",
      "support": 15,
      "rotation": 5
    },
    {
      "x": -11,
      "y": 3,
      "z": 9,
      "name": "Wood_Beastwood_Plhoem_Sap",
      "rotation": 1
    },
    {
      "x": -11,
      "y": 4,
      "z": 9,
      "name": "Wood_Beastwood_Plhoem_Sap",
      "rotation": 1
    },
    {
      "x": -11,
      "y": 5,
      "z": 9,
      "name": "Wood_Beastwood_Sapwood",
      "rotation": 5
    },
    {
      "x": -11,
      "y": 6,
      "z": 9,
      "name": "Wood_Beastwood_Sapwood",
      "rotation": 5
    },
    {
      "x": -11,
      "y": 7,
      "z": 9,
      "name": "Wood_Beastwood_Plhoem_Sap",
      "rotation": 1
    },
    {
      "x": -11,
      "y": 8,
      "z": 9,
      "name": "Wood_Redwood_Trunk_Full",
      "support": 15,
      "rotation": 5
    },
    {
      "x": -11,
      "y": 9,
      "z": 9,
      "name": "Wood_Beastwood_Bark",
      "rotation": 1
    },
    {
      "x": -11,
      "y": 3,
      "z": 10,
      "name": "Wood_Redwood_Trunk_Full",
      "support": 15,
      "rotation": 5
    },
    {
      "x": -11,
      "y": 4,
      "z": 10,
      "name": "Wood_Beastwood_Plhoem_Sap",
      "rotation": 1
    },
    {
      "x": -11,
      "y": 5,
      "z": 10,
      "name": "Wood_Beastwood_Plhoem_Sap",
      "rotation": 1
    },
    {
      "x": -11,
      "y": 6,
      "z": 10,
      "name": "Wood_Beastwood_Plhoem_Sap",
      "rotation": 1
    },
    {
      "x": -11,
      "y": 7,
      "z": 10,
      "name": "Wood_Redwood_Trunk_Full",
      "support": 15,
      "rotation": 5
    },
    {
      "x": -11,
      "y": 8,
      "z": 10,
      "name": "Wood_Beastwood_Bark",
      "rotation": 5
    },
    {
      "x": -11,
      "y": 9,
      "z": 10,
      "name": "Wood_Beastwood_Bark",
      "rotation": 1
    },
    {
      "x": -11,
      "y": 14,
      "z": 10,
      "name": "Plant_Leaves_Redwood"
    },
    {
      "x": -11,
      "y": 4,
      "z": 11,
      "name": "Plant_Leaves_Redwood",
      "support": 15
    },
    {
      "x": -11,
      "y": 5,
      "z": 11,
      "name": "Wood_Redwood_Trunk_Full",
      "support": 15,
      "rotation": 5
    },
    {
      "x": -11,
      "y": 6,
      "z": 11,
      "name": "Wood_Redwood_Trunk_Full",
      "support": 15,
      "rotation": 5
    },
    {
      "x": -11,
      "y": 7,
      "z": 11,
      "name": "Wood_Beastwood_Bark",
      "rotation": 5
    },
    {
      "x": -11,
      "y": 13,
      "z": 11,
      "name": "Plant_Leaves_Redwood"
    },
    {
      "x": -11,
      "y": 14,
      "z": 11,
      "name": "Plant_Leaves_Redwood"
    },
    {
      "x": -11,
      "y": 15,
      "z": 11,
      "name": "Plant_Leaves_Redwood"
    },
    {
      "x": -11,
      "y": 3,
      "z": 12,
      "name": "Plant_Leaves_Redwood"
    },
    {
      "x": -11,
      "y": 4,
      "z": 12,
      "name": "Plant_Leaves_Redwood"
    },
    {
      "x": -11,
      "y": 5,
      "z": 12,
      "name": "Plant_Leaves_Redwood"
    },
    {
      "x": -11,
      "y": 14,
      "z": 12,
      "name": "Plant_Leaves_Redwood"
    },
    {
      "x": -11,
      "y": 2,
      "z": 13,
      "name": "Plant_Leaves_Redwood"
    },
    {
      "x": -11,
      "y": 3,
      "z": 13,
      "name": "Plant_Leaves_Redwood",
      "support": 15
    },
    {
      "x": -11,
      "y": 4,
      "z": 13,
      "name": "Plant_Leaves_Redwood",
      "support": 15,
      "rotation": 3
    },
    {
      "x": -11,
      "y": 5,
      "z": 13,
      "name": "Plant_Leaves_Redwood"
    },
    {
      "x": -11,
      "y": 6,
      "z": 13,
      "name": "Plant_Leaves_Redwood"
    },
    {
      "x": -11,
      "y": 2,
      "z": 14,
      "name": "Plant_Leaves_Redwood"
    },
    {
      "x": -11,
      "y": 3,
      "z": 14,
      "name": "Plant_Leaves_Redwood"
    },
    {
      "x": -11,
      "y": 5,
      "z": 14,
      "name": "Plant_Leaves_Redwood"
    },
    {
      "x": -11,
      "y": 6,
      "z": 14,
      "name": "Plant_Leaves_Redwood"
    },
    {
      "x": -11,
      "y": 2,
      "z": 15,
      "name": "Plant_Leaves_Redwood"
    },
    {
      "x": -11,
      "y": 3,
      "z": 15,
      "name": "Plant_Leaves_Redwood"
    },
    {
      "x": -11,
      "y": 5,
      "z": 15,
      "name": "Plant_Leaves_Redwood"
    },
    {
      "x": -11,
      "y": 6,
      "z": 15,
      "name": "Plant_Leaves_Redwood"
    },
    {
      "x": -11,
      "y": 3,
      "z": 16,
      "name": "Plant_Leaves_Redwood"
    },
    {
      "x": -11,
      "y": 4,
      "z": 16,
      "name": "Plant_Leaves_Redwood"
    },
    {
      "x": -11,
      "y": 5,
      "z": 16,
      "name": "Plant_Leaves_Redwood"
    },
    {
      "x": -11,
      "y": 4,
      "z": 17,
      "name": "Plant_Leaves_Redwood"
    },
    {
      "x": -10,
      "y": 21,
      "z": -22,
      "name": "Plant_Leaves_Redwood",
      "rotation": 3
    },
    {
      "x": -10,
      "y": 19,
      "z": -18,
      "name": "Plant_Leaves_Redwood",
      "rotation": 3
    },
    {
      "x": -10,
      "y": 20,
      "z": -18,
      "name": "Plant_Leaves_Redwood",
      "rotation": 3
    },
    {
      "x": -10,
      "y": 21,
      "z": -18,
      "name": "Plant_Leaves_Redwood",
      "rotation": 3
    },
    {
      "x": -10,
      "y": 19,
      "z": -17,
      "name": "Plant_Leaves_Redwood",
      "rotation": 3
    },
    {
      "x": -10,
      "y": 20,
      "z": -17,
      "name": "Plant_Leaves_Redwood",
      "rotation": 3
    },
    {
      "x": -10,
      "y": 21,
      "z": -17,
      "name": "Plant_Leaves_Redwood",
      "rotation": 3
    },
    {
      "x": -10,
      "y": 18,
      "z": -16,
      "name": "Plant_Leaves_Redwood",
      "rotation": 3
    },
    {
      "x": -10,
      "y": 19,
      "z": -16,
      "name": "Plant_Leaves_Redwood",
      "rotation": 3
    },
    {
      "x": -10,
      "y": 21,
      "z": -16,
      "name": "Plant_Leaves_Redwood",
      "rotation": 3
    },
    {
      "x": -10,
      "y": 22,
      "z": -16,
      "name": "Plant_Leaves_Redwood",
      "rotation": 3
    },
    {
      "x": -10,
      "y": 18,
      "z": -15,
      "name": "Plant_Leaves_Redwood",
      "rotation": 3
    },
    {
      "x": -10,
      "y": 20,
      "z": -15,
      "name": "Plant_Leaves_Redwood",
      "support": 15,
      "rotation": 3
    },
    {
      "x": -10,
      "y": 22,
      "z": -15,
      "name": "Plant_Leaves_Redwood",
      "rotation": 3
    },
    {
      "x": -10,
      "y": 18,
      "z": -14,
      "name": "Plant_Leaves_Redwood",
      "rotation": 3
    },
    {
      "x": -10,
      "y": 19,
      "z": -14,
      "name": "Plant_Leaves_Redwood",
      "rotation": 3
    },
    {
      "x": -10,
      "y": 21,
      "z": -14,
      "name": "Plant_Leaves_Redwood",
      "rotation": 3
    },
    {
      "x": -10,
      "y": 22,
      "z": -14,
      "name": "Plant_Leaves_Redwood",
      "rotation": 3
    },
    {
      "x": -10,
      "y": 18,
      "z": -13,
      "name": "Wood_Redwood_Branch_Long",
      "support": 15,
      "rotation": 7
    },
    {
      "x": -10,
      "y": 19,
      "z": -13,
      "name": "Plant_Leaves_Redwood",
      "support": 15,
      "rotation": 3
    },
    {
      "x": -10,
      "y": 20,
      "z": -13,
      "name": "Plant_Leaves_Redwood",
      "support": 15,
      "rotation": 3
    },
    {
      "x": -10,
      "y": 21,
      "z": -13,
      "name": "Plant_Leaves_Redwood",
      "rotation": 3
    },
    {
      "x": -10,
      "y": 19,
      "z": -12,
      "name": "Plant_Leaves_Redwood",
      "support": 15,
      "rotation": 3
    },
    {
      "x": -10,
      "y": 20,
      "z": -12,
      "name": "Plant_Leaves_Redwood",
      "rotation": 3
    },
    {
      "x": -10,
      "y": 21,
      "z": -12,
      "name": "Plant_Leaves_Redwood",
      "rotation": 3
    },
    {
      "x": -10,
      "y": 16,
      "z": -10,
      "name": "Wood_Redwood_Branch_Short",
      "support": 15,
      "rotation": 3
    },
    {
      "x": -10,
      "y": 10,
      "z": 1,
      "name": "Plant_Leaves_Redwood"
    },
    {
      "x": -10,
      "y": 9,
      "z": 2,
      "name": "Plant_Leaves_Redwood"
    },
    {
      "x": -10,
      "y": 10,
      "z": 2,
      "name": "Plant_Leaves_Redwood"
    },
    {
      "x": -10,
      "y": 11,
      "z": 2,
      "name": "Plant_Leaves_Redwood"
    },
    {
      "x": -10,
      "y": 8,
      "z": 3,
      "name": "Plant_Leaves_Redwood"
    },
    {
      "x": -10,
      "y": 9,
      "z": 3,
      "name": "Plant_Leaves_Redwood"
    },
    {
      "x": -10,
      "y": 10,
      "z": 3,
      "name": "Plant_Leaves_Redwood",
      "support": 15,
      "rotation": 3
    },
    {
      "x": -10,
      "y": 11,
      "z": 3,
      "name": "Plant_Leaves_Redwood"
    },
    {
      "x": -10,
      "y": 12,
      "z": 3,
      "name": "Plant_Leaves_Redwood"
    },
    {
      "x": -10,
      "y": 8,
      "z": 4,
      "name": "Plant_Leaves_Redwood"
    },
    {
      "x": -10,
      "y": 9,
      "z": 4,
      "name": "Plant_Leaves_Redwood",
      "support": 15
    },
    {
      "x": -10,
      "y": 10,
      "z": 4,
      "name": "Wood_Redwood_Branch_Long",
      "support": 15,
      "rotation": 4
    },
    {
      "x": -10,
      "y": 11,
      "z": 4,
      "name": "Plant_Leaves_Redwood",
      "support": 15
    },
    {
      "x": -10,
      "y": 12,
      "z": 4,
      "name": "Plant_Leaves_Redwood"
    },
    {
      "x": -10,
      "y": 8,
      "z": 5,
      "name": "Plant_Leaves_Redwood"
    },
    {
      "x": -10,
      "y": 9,
      "z": 5,
      "name": "Plant_Leaves_Redwood"
    },
    {
      "x": -10,
      "y": 10,
      "z": 5,
      "name": "Wood_Redwood_Branch_Long",
      "support": 15,
      "rotation": 4
    },
    {
      "x": -10,
      "y": 11,
      "z": 5,
      "name": "Plant_Leaves_Redwood"
    },
    {
      "x": -10,
      "y": 12,
      "z": 5,
      "name": "Plant_Leaves_Redwood"
    },
    {
      "x": -10,
      "y": 4,
      "z": 6,
      "name": "Wood_Beastwood_Bark",
      "rotation": 5
    },
    {
      "x": -10,
      "y": 5,
      "z": 6,
      "name": "Wood_Beastwood_Bark",
      "rotation": 5
    },
    {
      "x": -10,
      "y": 6,
      "z": 6,
      "name": "Wood_Beastwood_Bark",
      "rotation": 5
    },
    {
      "x": -10,
      "y": 7,
      "z": 6,
      "name": "Wood_Beastwood_Bark",
      "rotation": 5
    },
    {
      "x": -10,
      "y": 8,
      "z": 6,
      "name": "Wood_Beastwood_Bark",
      "rotation": 5
    },
    {
      "x": -10,
      "y": 9,
      "z": 6,
      "name": "Plant_Leaves_Redwood"
    },
    {
      "x": -10,
      "y": 10,
      "z": 6,
      "name": "Plant_Leaves_Redwood"
    },
    {
      "x": -10,
      "y": 11,
      "z": 6,
      "name": "Plant_Leaves_Redwood"
    },
    {
      "x": -10,
      "y": 3,
      "z": 7,
      "name": "Wood_Beastwood_Bark",
      "rotation": 5
    },
    {
      "x": -10,
      "y": 4,
      "z": 7,
      "name": "Wood_Beastwood_Bark",
      "rotation": 5
    },
    {
      "x": -10,
      "y": 5,
      "z": 7,
      "name": "Wood_Beastwood_Plhoem_Sap",
      "rotation": 1
    },
    {
      "x": -10,
      "y": 6,
      "z": 7,
      "name": "Wood_Beastwood_Plhoem_Sap",
      "rotation": 1
    },
    {
      "x": -10,
      "y": 7,
      "z": 7,
      "name": "Wood_Beastwood_Plhoem_Sap",
      "rotation": 1
    },
    {
      "x": -10,
      "y": 8,
      "z": 7,
      "name": "Wood_Beastwood_Bark",
      "rotation": 5
    },
    {
      "x": -10,
      "y": 9,
      "z": 7,
      "name": "Wood_Beastwood_Bark",
      "rotation": 5
    },
    {
      "x": -10,
      "y": 10,
      "z": 7,
      "name": "Plant_Leaves_Redwood"
    },
    {
      "x": -10,
      "y": 3,
      "z": 8,
      "name": "Wood_Beastwood_Bark",
      "rotation": 5
    },
    {
      "x": -10,
      "y": 4,
      "z": 8,
      "name": "Wood_Beastwood_Bark",
      "rotation": 5
    },
    {
      "x": -10,
      "y": 5,
      "z": 8,
      "name": "Wood_Beastwood_Plhoem_Sap",
      "rotation": 1
    },
    {
      "x": -10,
      "y": 6,
      "z": 8,
      "name": "Wood_Beastwood_Sapwood",
      "rotation": 5
    },
    {
      "x": -10,
      "y": 7,
      "z": 8,
      "name": "Wood_Beastwood_Sapwood",
      "rotation": 5
    },
    {
      "x": -10,
      "y": 8,
      "z": 8,
      "name": "Wood_Beastwood_Plhoem_Sap",
      "rotation": 1
    },
    {
      "x": -10,
      "y": 9,
      "z": 8,
      "name": "Wood_Beastwood_Bark",
      "rotation": 5
    },
    {
      "x": -10,
      "y": 10,
      "z": 8,
      "name": "Wood_Beastwood_Bark",
      "rotation": 5
    },
    {
      "x": -10,
      "y": 3,
      "z": 9,
      "name": "Wood_Beastwood_Bark",
      "rotation": 5
    },
    {
      "x": -10,
      "y": 4,
      "z": 9,
      "name": "Wood_Beastwood_Bark",
      "rotation": 5
    },
    {
      "x": -10,
      "y": 5,
      "z": 9,
      "name": "Wood_Beastwood_Plhoem_Sap",
      "rotation": 1
    },
    {
      "x": -10,
      "y": 6,
      "z": 9,
      "name": "Wood_Beastwood_Sapwood",
      "rotation": 5
    },
    {
      "x": -10,
      "y": 7,
      "z": 9,
      "name": "Wood_Beastwood_Sapwood",
      "rotation": 1
    },
    {
      "x": -10,
      "y": 8,
      "z": 9,
      "name": "Wood_Beastwood_Plhoem_Sap",
      "rotation": 1
    },
    {
      "x": -10,
      "y": 9,
      "z": 9,
      "name": "Wood_Beastwood_Bark",
      "rotation": 5
    },
    {
      "x": -10,
      "y": 10,
      "z": 9,
      "name": "Wood_Beastwood_Bark",
      "rotation": 5
    },
    {
      "x": -10,
      "y": 13,
      "z": 9,
      "name": "Plant_Leaves_Redwood"
    },
    {
      "x": -10,
      "y": 14,
      "z": 9,
      "name": "Plant_Leaves_Redwood"
    },
    {
      "x": -10,
      "y": 15,
      "z": 9,
      "name": "Plant_Leaves_Redwood"
    },
    {
      "x": -10,
      "y": 3,
      "z": 10,
      "name": "Wood_Beastwood_Bark",
      "rotation": 5
    },
    {
      "x": -10,
      "y": 4,
      "z": 10,
      "name": "Wood_Beastwood_Bark",
      "rotation": 5
    },
    {
      "x": -10,
      "y": 5,
      "z": 10,
      "name": "Wood_Beastwood_Plhoem_Sap",
      "rotation": 1
    },
    {
      "x": -10,
      "y": 6,
      "z": 10,
      "name": "Wood_Beastwood_Plhoem_Sap",
      "rotation": 1
    },
    {
      "x": -10,
      "y": 7,
      "z": 10,
      "name": "Wood_Beastwood_Plhoem_Sap",
      "rotation": 1
    },
    {
      "x": -10,
      "y": 8,
      "z": 10,
      "name": "Wood_Beastwood_Bark",
      "rotation": 5
    },
    {
      "x": -10,
      "y": 9,
      "z": 10,
      "name": "Wood_Beastwood_Bark",
      "rotation": 5
    },
    {
      "x": -10,
      "y": 10,
      "z": 10,
      "name": "Wood_Beastwood_Bark",
      "rotation": 5
    },
    {
      "x": -10,
      "y": 13,
      "z": 10,
      "name": "Plant_Leaves_Redwood"
    },
    {
      "x": -10,
      "y": 14,
      "z": 10,
      "name": "Plant_Leaves_Redwood"
    },
    {
      "x": -10,
      "y": 15,
      "z": 10,
      "name": "Plant_Leaves_Redwood"
    },
    {
      "x": -10,
      "y": 3,
      "z": 11,
      "name": "Plant_Leaves_Redwood"
    },
    {
      "x": -10,
      "y": 4,
      "z": 11,
      "name": "Plant_Leaves_Redwood"
    },
    {
      "x": -10,
      "y": 5,
      "z": 11,
      "name": "Plant_Leaves_Redwood"
    },
    {
      "x": -10,
      "y": 6,
      "z": 11,
      "name": "Wood_Beastwood_Bark",
      "rotation": 5
    },
    {
      "x": -10,
      "y": 7,
      "z": 11,
      "name": "Wood_Beastwood_Bark",
      "rotation": 5
    },
    {
      "x": -10,
      "y": 8,
      "z": 11,
      "name": "Wood_Beastwood_Bark",
      "rotation": 5
    },
    {
      "x": -10,
      "y": 9,
      "z": 11,
      "name": "Wood_Beastwood_Bark",
      "rotation": 5
    },
    {
      "x": -10,
      "y": 10,
      "z": 11,
      "name": "Wood_Beastwood_Bark",
      "rotation": 5
    },
    {
      "x": -10,
      "y": 13,
      "z": 11,
      "name": "Plant_Leaves_Redwood"
    },
    {
      "x": -10,
      "y": 14,
      "z": 11,
      "name": "Plant_Leaves_Redwood"
    },
    {
      "x": -10,
      "y": 15,
      "z": 11,
      "name": "Plant_Leaves_Redwood"
    },
    {
      "x": -10,
      "y": 3,
      "z": 12,
      "name": "Plant_Leaves_Redwood"
    },
    {
      "x": -10,
      "y": 4,
      "z": 12,
      "name": "Plant_Leaves_Redwood",
      "support": 15
    },
    {
      "x": -10,
      "y": 5,
      "z": 12,
      "name": "Plant_Leaves_Redwood"
    },
    {
      "x": -10,
      "y": 13,
      "z": 12,
      "name": "Plant_Leaves_Redwood"
    },
    {
      "x": -10,
      "y": 14,
      "z": 12,
      "name": "Plant_Leaves_Redwood"
    },
    {
      "x": -10,
      "y": 15,
      "z": 12,
      "name": "Plant_Leaves_Redwood"
    },
    {
      "x": -10,
      "y": 2,
      "z": 13,
      "name": "Plant_Leaves_Redwood"
    },
    {
      "x": -10,
      "y": 3,
      "z": 13,
      "name": "Plant_Leaves_Redwood",
      "support": 15
    },
    {
      "x": -10,
      "y": 4,
      "z": 13,
      "name": "Wood_Redwood_Branch_Long",
      "support": 15,
      "rotation": 4
    },
    {
      "x": -10,
      "y": 5,
      "z": 13,
      "name": "Plant_Leaves_Redwood",
      "support": 15
    },
    {
      "x": -10,
      "y": 6,
      "z": 13,
      "name": "Plant_Leaves_Redwood"
    },
    {
      "x": -10,
      "y": 13,
      "z": 13,
      "name": "Plant_Leaves_Redwood"
    },
    {
      "x": -10,
      "y": 14,
      "z": 13,
      "name": "Plant_Leaves_Redwood"
    },
    {
      "x": -10,
      "y": 15,
      "z": 13,
      "name": "Plant_Leaves_Redwood"
    },
    {
      "x": -10,
      "y": 2,
      "z": 14,
      "name": "Plant_Leaves_Redwood"
    },
    {
      "x": -10,
      "y": 4,
      "z": 14,
      "name": "Plant_Leaves_Redwood",
      "support": 15,
      "rotation": 3
    },
    {
      "x": -10,
      "y": 5,
      "z": 14,
      "name": "Plant_Leaves_Redwood",
      "support": 15,
      "rotation": 3
    },
    {
      "x": -10,
      "y": 6,
      "z": 14,
      "name": "Plant_Leaves_Redwood"
    },
    {
      "x": -10,
      "y": 2,
      "z": 15,
      "name": "Plant_Leaves_Redwood"
    },
    {
      "x": -10,
      "y": 3,
      "z": 15,
      "name": "Plant_Leaves_Redwood"
    },
    {
      "x": -10,
      "y": 5,
      "z": 15,
      "name": "Plant_Leaves_Redwood"
    },
    {
      "x": -10,
      "y": 6,
      "z": 15,
      "name": "Plant_Leaves_Redwood"
    },
    {
      "x": -10,
      "y": 3,
      "z": 16,
      "name": "Plant_Leaves_Redwood"
    },
    {
      "x": -10,
      "y": 4,
      "z": 16,
      "name": "Plant_Leaves_Redwood"
    },
    {
      "x": -10,
      "y": 5,
      "z": 16,
      "name": "Plant_Leaves_Redwood"
    },
    {
      "x": -10,
      "y": 3,
      "z": 17,
      "name": "Plant_Leaves_Redwood"
    },
    {
      "x": -10,
      "y": 4,
      "z": 17,
      "name": "Plant_Leaves_Redwood"
    },
    {
      "x": -10,
      "y": 5,
      "z": 17,
      "name": "Plant_Leaves_Redwood"
    },
    {
      "x": -9,
      "y": 20,
      "z": -22,
      "name": "Plant_Leaves_Redwood",
      "rotation": 3
    },
    {
      "x": -9,
      "y": 21,
      "z": -22,
      "name": "Plant_Leaves_Redwood",
      "rotation": 3
    },
    {
      "x": -9,
      "y": 22,
      "z": -22,
      "name": "Plant_Leaves_Redwood",
      "rotation": 3
    },
    {
      "x": -9,
      "y": 20,
      "z": -21,
      "name": "Plant_Leaves_Redwood",
      "rotation": 3
    },
    {
      "x": -9,
      "y": 21,
      "z": -21,
      "name": "Plant_Leaves_Redwood",
      "rotation": 3
    },
    {
      "x": -9,
      "y": 22,
      "z": -21,
      "name": "Plant_Leaves_Redwood",
      "rotation": 3
    },
    {
      "x": -9,
      "y": 20,
      "z": -18,
      "name": "Plant_Leaves_Redwood",
      "rotation": 3
    },
    {
      "x": -9,
      "y": 19,
      "z": -17,
      "name": "Plant_Leaves_Redwood",
      "rotation": 3
    },
    {
      "x": -9,
      "y": 20,
      "z": -17,
      "name": "Plant_Leaves_Redwood",
      "rotation": 3
    },
    {
      "x": -9,
      "y": 21,
      "z": -17,
      "name": "Plant_Leaves_Redwood",
      "rotation": 3
    },
    {
      "x": -9,
      "y": 18,
      "z": -16,
      "name": "Plant_Leaves_Redwood",
      "rotation": 3
    },
    {
      "x": -9,
      "y": 19,
      "z": -16,
      "name": "Plant_Leaves_Redwood",
      "support": 15,
      "rotation": 3
    },
    {
      "x": -9,
      "y": 20,
      "z": -16,
      "name": "Plant_Leaves_Redwood",
      "support": 15,
      "rotation": 3
    },
    {
      "x": -9,
      "y": 21,
      "z": -16,
      "name": "Plant_Leaves_Redwood",
      "support": 15,
      "rotation": 3
    },
    {
      "x": -9,
      "y": 22,
      "z": -16,
      "name": "Plant_Leaves_Redwood",
      "rotation": 3
    },
    {
      "x": -9,
      "y": 18,
      "z": -15,
      "name": "Plant_Leaves_Redwood",
      "rotation": 3
    },
    {
      "x": -9,
      "y": 19,
      "z": -15,
      "name": "Plant_Leaves_Redwood",
      "support": 15,
      "rotation": 3
    },
    {
      "x": -9,
      "y": 20,
      "z": -15,
      "name": "Wood_Redwood_Branch_Long",
      "support": 15,
      "rotation": 7
    },
    {
      "x": -9,
      "y": 21,
      "z": -15,
      "name": "Plant_Leaves_Redwood",
      "support": 15,
      "rotation": 3
    },
    {
      "x": -9,
      "y": 22,
      "z": -15,
      "name": "Plant_Leaves_Redwood",
      "rotation": 3
    },
    {
      "x": -9,
      "y": 18,
      "z": -14,
      "name": "Plant_Leaves_Redwood",
      "rotation": 3
    },
    {
      "x": -9,
      "y": 19,
      "z": -14,
      "name": "Plant_Leaves_Redwood",
      "rotation": 3
    },
    {
      "x": -9,
      "y": 20,
      "z": -14,
      "name": "Plant_Leaves_Redwood",
      "support": 15,
      "rotation": 3
    },
    {
      "x": -9,
      "y": 21,
      "z": -14,
      "name": "Plant_Leaves_Redwood",
      "rotation": 3
    },
    {
      "x": -9,
      "y": 22,
      "z": -14,
      "name": "Plant_Leaves_Redwood",
      "rotation": 3
    },
    {
      "x": -9,
      "y": 18,
      "z": -13,
      "name": "Wood_Redwood_Branch_Long",
      "support": 15,
      "rotation": 7
    },
    {
      "x": -9,
      "y": 19,
      "z": -13,
      "name": "Plant_Leaves_Redwood",
      "rotation": 3
    },
    {
      "x": -9,
      "y": 20,
      "z": -13,
      "name": "Plant_Leaves_Redwood",
      "rotation": 3
    },
    {
      "x": -9,
      "y": 21,
      "z": -13,
      "name": "Plant_Leaves_Redwood",
      "rotation": 3
    },
    {
      "x": -9,
      "y": 17,
      "z": -12,
      "name": "Wood_Beastwood_Bark",
      "rotation": 4
    },
    {
      "x": -9,
      "y": 20,
      "z": -12,
      "name": "Plant_Leaves_Redwood",
      "rotation": 3
    },
    {
      "x": -9,
      "y": 16,
      "z": -11,
      "name": "Wood_Beastwood_Bark",
      "rotation": 4
    },
    {
      "x": -9,
      "y": 17,
      "z": -11,
      "name": "Wood_Beastwood_Bark",
      "rotation": 4
    },
    {
      "x": -9,
      "y": 15,
      "z": -10,
      "name": "Wood_Beastwood_Bark",
      "rotation": 4
    },
    {
      "x": -9,
      "y": 16,
      "z": -10,
      "name": "Wood_Beastwood_Bark",
      "rotation": 4
    },
    {
      "x": -9,
      "y": 14,
      "z": -9,
      "name": "Wood_Beastwood_Bark",
      "rotation": 4
    },
    {
      "x": -9,
      "y": 15,
      "z": -9,
      "name": "Wood_Beastwood_Bark",
      "rotation": 4
    },
    {
      "x": -9,
      "y": 13,
      "z": -8,
      "name": "Wood_Beastwood_Bark",
      "rotation": 4
    },
    {
      "x": -9,
      "y": 14,
      "z": -8,
      "name": "Wood_Beastwood_Bark",
      "rotation": 4
    },
    {
      "x": -9,
      "y": 15,
      "z": -8,
      "name": "Wood_Beastwood_Bark",
      "rotation": 4
    },
    {
      "x": -9,
      "y": 13,
      "z": -7,
      "name": "Wood_Beastwood_Bark",
      "rotation": 4
    },
    {
      "x": -9,
      "y": 13,
      "z": -6,
      "name": "Wood_Beastwood_Bark",
      "rotation": 4
    },
    {
      "x": -9,
      "y": 13,
      "z": -5,
      "name": "Wood_Beastwood_Bark",
      "rotation": 4
    },
    {
      "x": -9,
      "y": 13,
      "z": -4,
      "name": "Wood_Beastwood_Bark",
      "rotation": 4
    },
    {
      "x": -9,
      "y": 13,
      "z": -3,
      "name": "Wood_Beastwood_Bark",
      "rotation": 4
    },
    {
      "x": -9,
      "y": 13,
      "z": -2,
      "name": "Wood_Beastwood_Bark",
      "rotation": 4
    },
    {
      "x": -9,
      "y": 12,
      "z": -1,
      "name": "Wood_Beastwood_Bark",
      "rotation": 4
    },
    {
      "x": -9,
      "y": 13,
      "z": -1,
      "name": "Wood_Beastwood_Bark",
      "rotation": 4
    },
    {
      "x": -9,
      "y": 11,
      "z": 0,
      "name": "Wood_Beastwood_Bark",
      "rotation": 4
    },
    {
      "x": -9,
      "y": 12,
      "z": 0,
      "name": "Wood_Beastwood_Bark",
