{
  "version": 8,
  "blockIdVersion": 11,
  "anchorX": 0,
  "anchorY": 1,
  "anchorZ": 0,
  "blocks": [
    {
      "x": -20,
      "y": 1,
      "z": -4,
      "name": "Wood_Beastwood_Bark"
    },
    {
      "x": -20,
      "y": 2,
      "z": -4,
      "name": "Wood_Beastwood_Bark"
    },
    {
      "x": -20,
      "y": 3,
      "z": -4,
      "name": "Wood_Beastwood_Bark"
    },
    {
      "x": -20,
      "y": 4,
      "z": -4,
      "name": "Wood_Beastwood_Bark"
    },
    {
      "x": -20,
      "y": 5,
      "z": -4,
      "name": "Wood_Beastwood_Bark"
    },
    {
      "x": -20,
      "y": 6,
      "z": -4,
      "name": "Wood_Beastwood_Bark"
    },
    {
      "x": -20,
      "y": 7,
      "z": -4,
      "name": "Wood_Beastwood_Bark"
    },
    {
      "x": -20,
      "y": 8,
      "z": -4,
      "name": "Wood_Beastwood_Bark"
    },
    {
      "x": -20,
      "y": 1,
      "z": -3,
      "name": "Wood_Beastwood_Bark"
    },
    {
      "x": -20,
      "y": 2,
      "z": -3,
      "name": "Wood_Beastwood_Bark"
    },
    {
      "x": -20,
      "y": 3,
      "z": -3,
      "name": "Wood_Beastwood_Bark"
    },
    {
      "x": -20,
      "y": 4,
      "z": -3,
      "name": "Wood_Beastwood_Bark"
    },
    {
      "x": -20,
      "y": 5,
      "z": -3,
      "name": "Wood_Beastwood_Bark"
    },
    {
      "x": -20,
      "y": 6,
      "z": -3,
      "name": "Wood_Beastwood_Bark"
    },
    {
      "x": -20,
      "y": 7,
      "z": -3,
      "name": "Wood_Beastwood_Bark"
    },
    {
      "x": -20,
      "y": 8,
      "z": -3,
      "name": "Wood_Beastwood_Bark"
    },
    {
      "x": -20,
      "y": 1,
      "z": -2,
      "name": "Wood_Beastwood_Bark"
    },
    {
      "x": -20,
      "y": 2,
      "z": -2,
      "name": "Wood_Beastwood_Bark"
    },
    {
      "x": -20,
      "y": 3,
      "z": -2,
      "name": "Wood_Beastwood_Bark"
    },
    {
      "x": -20,
      "y": 4,
      "z": -2,
      "name": "Wood_Beastwood_Bark"
    },
    {
      "x": -20,
      "y": 5,
      "z": -2,
      "name": "Wood_Beastwood_Bark"
    },
    {
      "x": -20,
      "y": 6,
      "z": -2,
      "name": "Wood_Beastwood_Bark"
    },
    {
      "x": -20,
      "y": 7,
      "z": -2,
      "name": "Wood_Beastwood_Bark"
    },
    {
      "x": -20,
      "y": 8,
      "z": -2,
      "name": "Wood_Beastwood_Bark"
    },
    {
      "x": -20,
      "y": 1,
      "z": -1,
      "name": "Wood_Beastwood_Bark"
    },
    {
      "x": -20,
      "y": 2,
      "z": -1,
      "name": "Wood_Beastwood_Bark"
    },
    {
      "x": -20,
      "y": 3,
      "z": -1,
      "name": "Wood_Beastwood_Bark"
    },
    {
      "x": -20,
      "y": 4,
      "z": -1,
      "name": "Wood_Beastwood_Bark"
    },
    {
      "x": -20,
      "y": 5,
      "z": -1,
      "name": "Wood_Beastwood_Bark"
    },
    {
      "x": -20,
      "y": 6,
      "z": -1,
      "name": "Wood_Beastwood_Bark"
    },
    {
      "x": -20,
      "y": 7,
      "z": -1,
      "name": "Wood_Beastwood_Bark"
    },
    {
      "x": -20,
      "y": 8,
      "z": -1,
      "name": "Wood_Beastwood_Bark"
    },
    {
      "x": -20,
      "y": 1,
      "z": 0,
      "name": "Wood_Beastwood_Bark"
    },
    {
      "x": -20,
      "y": 2,
      "z": 0,
      "name": "Wood_Beastwood_Bark"
    },
    {
      "x": -20,
      "y": 3,
      "z": 0,
      "name": "Wood_Beastwood_Bark"
    },
    {
      "x": -20,
      "y": 4,
      "z": 0,
      "name": "Wood_Beastwood_Bark"
    },
    {
      "x": -20,
      "y": 5,
      "z": 0,
      "name": "Wood_Beastwood_Bark"
    },
    {
      "x": -20,
      "y": 6,
      "z": 0,
      "name": "Wood_Beastwood_Bark"
    },
    {
      "x": -20,
      "y": 7,
      "z": 0,
      "name": "Wood_Beastwood_Bark"
    },
    {
      "x": -20,
      "y": 8,
      "z": 0,
      "name": "Wood_Beastwood_Bark"
    },
    {
      "x": -20,
      "y": 1,
      "z": 1,
      "name": "Wood_Beastwood_Bark"
    },
    {
      "x": -20,
      "y": 2,
      "z": 1,
      "name": "Wood_Beastwood_Bark"
    },
    {
      "x": -20,
      "y": 3,
      "z": 1,
      "name": "Wood_Beastwood_Bark"
    },
    {
      "x": -20,
      "y": 4,
      "z": 1,
      "name": "Wood_Beastwood_Bark"
    },
    {
      "x": -20,
      "y": 5,
      "z": 1,
      "name": "Wood_Beastwood_Bark"
    },
    {
      "x": -20,
      "y": 6,
      "z": 1,
      "name": "Wood_Beastwood_Bark"
    },
    {
      "x": -20,
      "y": 7,
      "z": 1,
      "name": "Wood_Beastwood_Bark"
    },
    {
      "x": -20,
      "y": 8,
      "z": 1,
      "name": "Wood_Beastwood_Bark"
    },
    {
      "x": -20,
      "y": 1,
      "z": 2,
      "name": "Wood_Beastwood_Bark"
    },
    {
      "x": -20,
      "y": 2,
      "z": 2,
      "name": "Wood_Beastwood_Bark"
    },
    {
      "x": -20,
      "y": 3,
      "z": 2,
      "name": "Wood_Beastwood_Bark"
    },
    {
      "x": -20,
      "y": 4,
      "z": 2,
      "name": "Wood_Beastwood_Bark"
    },
    {
      "x": -20,
      "y": 5,
      "z": 2,
      "name": "Wood_Beastwood_Bark"
    },
    {
      "x": -20,
      "y": 6,
      "z": 2,
      "name": "Wood_Beastwood_Bark"
    },
    {
      "x": -20,
      "y": 7,
      "z": 2,
      "name": "Wood_Beastwood_Bark"
    },
    {
      "x": -20,
      "y": 8,
      "z": 2,
      "name": "Wood_Beastwood_Bark"
    },
    {
      "x": -20,
      "y": 1,
      "z": 3,
      "name": "Wood_Beastwood_Bark"
    },
    {
      "x": -20,
      "y": 2,
      "z": 3,
      "name": "Wood_Beastwood_Bark"
    },
    {
      "x": -20,
      "y": 3,
      "z": 3,
      "name": "Wood_Beastwood_Bark"
    },
    {
      "x": -20,
      "y": 4,
      "z": 3,
      "name": "Wood_Beastwood_Bark"
    },
    {
      "x": -20,
      "y": 5,
      "z": 3,
      "name": "Wood_Beastwood_Bark"
    },
    {
      "x": -20,
      "y": 6,
      "z": 3,
      "name": "Wood_Beastwood_Bark"
    },
    {
      "x": -20,
      "y": 7,
      "z": 3,
      "name": "Wood_Beastwood_Bark"
    },
    {
      "x": -20,
      "y": 8,
      "z": 3,
      "name": "Wood_Beastwood_Bark"
    },
    {
      "x": -20,
      "y": 1,
      "z": 4,
      "name": "Wood_Beastwood_Bark"
    },
    {
      "x": -20,
      "y": 2,
      "z": 4,
      "name": "Wood_Beastwood_Bark"
    },
    {
      "x": -20,
      "y": 3,
      "z": 4,
      "name": "Wood_Beastwood_Bark"
    },
    {
      "x": -20,
      "y": 4,
      "z": 4,
      "name": "Wood_Beastwood_Bark"
    },
    {
      "x": -20,
      "y": 5,
      "z": 4,
      "name": "Wood_Beastwood_Bark"
    },
    {
      "x": -20,
      "y": 6,
      "z": 4,
      "name": "Wood_Beastwood_Bark"
    },
    {
      "x": -20,
      "y": 7,
      "z": 4,
      "name": "Wood_Beastwood_Bark"
    },
    {
      "x": -20,
      "y": 8,
      "z": 4,
      "name": "Wood_Beastwood_Bark"
    },
    {
      "x": -19,
      "y": 1,
      "z": -7,
      "name": "Wood_Beastwood_Bark"
    },
    {
      "x": -19,
      "y": 2,
      "z": -7,
      "name": "Wood_Beastwood_Bark"
    },
    {
      "x": -19,
      "y": 3,
      "z": -7,
      "name": "Wood_Beastwood_Bark"
    },
    {
      "x": -19,
      "y": 4,
      "z": -7,
      "name": "Wood_Beastwood_Bark"
    },
    {
      "x": -19,
      "y": 5,
      "z": -7,
      "name": "Wood_Beastwood_Bark"
    },
    {
      "x": -19,
      "y": 6,
      "z": -7,
      "name": "Wood_Beastwood_Bark"
    },
    {
      "x": -19,
      "y": 7,
      "z": -7,
      "name": "Wood_Beastwood_Bark"
    },
    {
      "x": -19,
      "y": 8,
      "z": -7,
      "name": "Wood_Beastwood_Bark"
    },
    {
      "x": -19,
      "y": 1,
      "z": -6,
      "name": "Wood_Beastwood_Bark"
    },
    {
      "x": -19,
      "y": 2,
      "z": -6,
      "name": "Wood_Beastwood_Bark"
    },
    {
      "x": -19,
      "y": 3,
      "z": -6,
      "name": "Wood_Beastwood_Bark"
    },
    {
      "x": -19,
      "y": 4,
      "z": -6,
      "name": "Wood_Beastwood_Bark"
    },
    {
      "x": -19,
      "y": 5,
      "z": -6,
      "name": "Wood_Beastwood_Bark"
    },
    {
      "x": -19,
      "y": 6,
      "z": -6,
      "name": "Wood_Beastwood_Bark"
    },
    {
      "x": -19,
      "y": 7,
      "z": -6,
      "name": "Wood_Beastwood_Bark"
    },
    {
      "x": -19,
      "y": 8,
      "z": -6,
      "name": "Wood_Beastwood_Bark"
    },
    {
      "x": -19,
      "y": 1,
      "z": -5,
      "name": "Wood_Beastwood_Bark"
    },
    {
      "x": -19,
      "y": 2,
      "z": -5,
      "name": "Wood_Beastwood_Bark"
    },
    {
      "x": -19,
      "y": 3,
      "z": -5,
      "name": "Wood_Beastwood_Bark"
    },
    {
      "x": -19,
      "y": 4,
      "z": -5,
      "name": "Wood_Beastwood_Bark"
    },
    {
      "x": -19,
      "y": 5,
      "z": -5,
      "name": "Wood_Beastwood_Bark"
    },
    {
      "x": -19,
      "y": 6,
      "z": -5,
      "name": "Wood_Beastwood_Bark"
    },
    {
      "x": -19,
      "y": 7,
      "z": -5,
      "name": "Wood_Beastwood_Bark"
    },
    {
      "x": -19,
      "y": 8,
      "z": -5,
      "name": "Wood_Beastwood_Bark"
    },
    {
      "x": -19,
      "y": 1,
      "z": -4,
      "name": "Wood_Beastwood_Bark"
    },
    {
      "x": -19,
      "y": 2,
      "z": -4,
      "name": "Wood_Beastwood_Bark"
    },
    {
      "x": -19,
      "y": 3,
      "z": -4,
      "name": "Wood_Beastwood_Bark"
    },
    {
      "x": -19,
      "y": 4,
      "z": -4,
      "name": "Wood_Beastwood_Bark"
    },
    {
      "x": -19,
      "y": 5,
      "z": -4,
      "name": "Wood_Beastwood_Bark"
    },
    {
      "x": -19,
      "y": 6,
      "z": -4,
      "name": "Wood_Beastwood_Bark"
    },
    {
      "x": -19,
      "y": 7,
      "z": -4,
      "name": "Wood_Beastwood_Bark"
    },
    {
      "x": -19,
      "y": 8,
      "z": -4,
      "name": "Wood_Beastwood_Bark"
    },
    {
      "x": -19,
      "y": 1,
      "z": -3,
      "name": "Wood_Beastwood_Bark"
    },
    {
      "x": -19,
      "y": 2,
      "z": -3,
      "name": "Wood_Beastwood_Bark"
    },
    {
      "x": -19,
      "y": 3,
      "z": -3,
      "name": "Wood_Beastwood_Bark"
    },
    {
      "x": -19,
      "y": 4,
      "z": -3,
      "name": "Wood_Beastwood_Bark"
    },
    {
      "x": -19,
      "y": 5,
      "z": -3,
      "name": "Wood_Beastwood_Bark"
    },
    {
      "x": -19,
      "y": 6,
      "z": -3,
      "name": "Wood_Beastwood_Bark"
    },
    {
      "x": -19,
      "y": 7,
      "z": -3,
      "name": "Wood_Beastwood_Bark"
    },
    {
      "x": -19,
      "y": 8,
      "z": -3,
      "name": "Wood_Beastwood_Bark"
    },
    {
      "x": -19,
      "y": 1,
      "z": -2,
      "name": "Wood_Beastwood_Bark"
    },
    {
      "x": -19,
      "y": 2,
      "z": -2,
      "name": "Wood_Beastwood_Bark"
    },
    {
      "x": -19,
      "y": 3,
      "z": -2,
      "name": "Wood_Beastwood_Bark"
    },
    {
      "x": -19,
      "y": 4,
      "z": -2,
      "name": "Wood_Beastwood_Bark"
    },
    {
      "x": -19,
      "y": 5,
      "z": -2,
      "name": "Wood_Beastwood_Bark"
    },
    {
      "x": -19,
      "y": 6,
      "z": -2,
      "name": "Wood_Beastwood_Bark"
    },
    {
      "x": -19,
      "y": 7,
      "z": -2,
      "name": "Wood_Beastwood_Bark"
    },
    {
      "x": -19,
      "y": 8,
      "z": -2,
      "name": "Wood_Beastwood_Bark"
    },
    {
      "x": -19,
      "y": 1,
      "z": -1,
      "name": "Wood_Beastwood_Bark"
    },
    {
      "x": -19,
      "y": 2,
      "z": -1,
      "name": "Wood_Beastwood_Bark"
    },
    {
      "x": -19,
      "y": 3,
      "z": -1,
      "name": "Wood_Beastwood_Bark"
    },
    {
      "x": -19,
      "y": 4,
      "z": -1,
      "name": "Wood_Beastwood_Bark"
    },
    {
      "x": -19,
      "y": 5,
      "z": -1,
      "name": "Wood_Beastwood_Bark"
    },
    {
      "x": -19,
      "y": 6,
      "z": -1,
      "name": "Wood_Beastwood_Bark"
    },
    {
      "x": -19,
      "y": 7,
      "z": -1,
      "name": "Wood_Beastwood_Bark"
    },
    {
      "x": -19,
      "y": 8,
      "z": -1,
      "name": "Wood_Beastwood_Bark"
    },
    {
      "x": -19,
      "y": 1,
      "z": 0,
      "name": "Wood_Beastwood_Bark"
    },
    {
      "x": -19,
      "y": 2,
      "z": 0,
      "name": "Wood_Beastwood_Bark"
    },
    {
      "x": -19,
      "y": 3,
      "z": 0,
      "name": "Wood_Beastwood_Bark"
    },
    {
      "x": -19,
      "y": 4,
      "z": 0,
      "name": "Wood_Beastwood_Bark"
    },
    {
      "x": -19,
      "y": 5,
      "z": 0,
      "name": "Wood_Beastwood_Bark"
    },
    {
      "x": -19,
      "y": 6,
      "z": 0,
      "name": "Wood_Beastwood_Bark"
    },
    {
      "x": -19,
      "y": 7,
      "z": 0,
      "name": "Wood_Beastwood_Bark"
    },
    {
      "x": -19,
      "y": 8,
      "z": 0,
      "name": "Wood_Beastwood_Bark"
    },
    {
      "x": -19,
      "y": 1,
      "z": 1,
      "name": "Wood_Beastwood_Bark"
    },
    {
      "x": -19,
      "y": 2,
      "z": 1,
      "name": "Wood_Beastwood_Bark"
    },
    {
      "x": -19,
      "y": 3,
      "z": 1,
      "name": "Wood_Beastwood_Bark"
    },
    {
      "x": -19,
      "y": 4,
      "z": 1,
      "name": "Wood_Beastwood_Bark"
    },
    {
      "x": -19,
      "y": 5,
      "z": 1,
      "name": "Wood_Beastwood_Bark"
    },
    {
      "x": -19,
      "y": 6,
      "z": 1,
      "name": "Wood_Beastwood_Bark"
    },
    {
      "x": -19,
      "y": 7,
      "z": 1,
      "name": "Wood_Beastwood_Bark"
    },
    {
      "x": -19,
      "y": 8,
      "z": 1,
      "name": "Wood_Beastwood_Bark"
    },
    {
      "x": -19,
      "y": 1,
      "z": 2,
      "name": "Wood_Beastwood_Bark"
    },
    {
      "x": -19,
      "y": 2,
      "z": 2,
      "name": "Wood_Beastwood_Bark"
    },
    {
      "x": -19,
      "y": 3,
      "z": 2,
      "name": "Wood_Beastwood_Bark"
    },
    {
      "x": -19,
      "y": 4,
      "z": 2,
      "name": "Wood_Beastwood_Bark"
    },
    {
      "x": -19,
      "y": 5,
      "z": 2,
      "name": "Wood_Beastwood_Bark"
    },
    {
      "x": -19,
      "y": 6,
      "z": 2,
      "name": "Wood_Beastwood_Bark"
    },
    {
      "x": -19,
      "y": 7,
      "z": 2,
      "name": "Wood_Beastwood_Bark"
    },
    {
      "x": -19,
      "y": 8,
      "z": 2,
      "name": "Wood_Beastwood_Bark"
    },
    {
      "x": -19,
      "y": 1,
      "z": 3,
      "name": "Wood_Beastwood_Bark"
    },
    {
      "x": -19,
      "y": 2,
      "z": 3,
      "name": "Wood_Beastwood_Bark"
    },
    {
      "x": -19,
      "y": 3,
      "z": 3,
      "name": "Wood_Beastwood_Bark"
    },
    {
      "x": -19,
      "y": 4,
      "z": 3,
      "name": "Wood_Beastwood_Bark"
    },
    {
      "x": -19,
      "y": 5,
      "z": 3,
      "name": "Wood_Beastwood_Bark"
    },
    {
      "x": -19,
      "y": 6,
      "z": 3,
      "name": "Wood_Beastwood_Bark"
    },
    {
      "x": -19,
      "y": 7,
      "z": 3,
      "name": "Wood_Beastwood_Bark"
    },
    {
      "x": -19,
      "y": 8,
      "z": 3,
      "name": "Wood_Beastwood_Bark"
    },
    {
      "x": -19,
      "y": 1,
      "z": 4,
      "name": "Wood_Beastwood_Bark"
    },
    {
      "x": -19,
      "y": 2,
      "z": 4,
      "name": "Wood_Beastwood_Bark"
    },
    {
      "x": -19,
      "y": 3,
      "z": 4,
      "name": "Wood_Beastwood_Bark"
    },
    {
      "x": -19,
      "y": 4,
      "z": 4,
      "name": "Wood_Beastwood_Bark"
    },
    {
      "x": -19,
      "y": 5,
      "z": 4,
      "name": "Wood_Beastwood_Bark"
    },
    {
      "x": -19,
      "y": 6,
      "z": 4,
      "name": "Wood_Beastwood_Bark"
    },
    {
      "x": -19,
      "y": 7,
      "z": 4,
      "name": "Wood_Beastwood_Bark"
    },
    {
      "x": -19,
      "y": 8,
      "z": 4,
      "name": "Wood_Beastwood_Bark"
    },
    {
      "x": -19,
      "y": 1,
      "z": 5,
      "name": "Wood_Beastwood_Bark"
    },
    {
      "x": -19,
      "y": 2,
      "z": 5,
      "name": "Wood_Beastwood_Bark"
    },
    {
      "x": -19,
      "y": 3,
      "z": 5,
      "name": "Wood_Beastwood_Bark"
    },
    {
      "x": -19,
      "y": 4,
      "z": 5,
      "name": "Wood_Beastwood_Bark"
    },
    {
      "x": -19,
      "y": 5,
      "z": 5,
      "name": "Wood_Beastwood_Bark"
    },
    {
      "x": -19,
      "y": 6,
      "z": 5,
      "name": "Wood_Beastwood_Bark"
    },
    {
      "x": -19,
      "y": 7,
      "z": 5,
      "name": "Wood_Beastwood_Bark"
    },
    {
      "x": -19,
      "y": 8,
      "z": 5,
      "name": "Wood_Beastwood_Bark"
    },
    {
      "x": -19,
      "y": 1,
      "z": 6,
      "name": "Wood_Beastwood_Bark"
    },
    {
      "x": -19,
      "y": 2,
      "z": 6,
      "name": "Wood_Beastwood_Bark"
    },
    {
      "x": -19,
      "y": 3,
      "z": 6,
      "name": "Wood_Beastwood_Bark"
    },
    {
      "x": -19,
      "y": 4,
      "z": 6,
      "name": "Wood_Beastwood_Bark"
    },
    {
      "x": -19,
      "y": 5,
      "z": 6,
      "name": "Wood_Beastwood_Bark"
    },
    {
      "x": -19,
      "y": 6,
      "z": 6,
      "name": "Wood_Beastwood_Bark"
    },
    {
      "x": -19,
      "y": 7,
      "z": 6,
      "name": "Wood_Beastwood_Bark"
    },
    {
      "x": -19,
      "y": 8,
      "z": 6,
      "name": "Wood_Beastwood_Bark"
    },
    {
      "x": -19,
      "y": 1,
      "z": 7,
      "name": "Wood_Beastwood_Bark"
    },
    {
      "x": -19,
      "y": 2,
      "z": 7,
      "name": "Wood_Beastwood_Bark"
    },
    {
      "x": -19,
      "y": 3,
      "z": 7,
      "name": "Wood_Beastwood_Bark"
    },
    {
      "x": -19,
      "y": 4,
      "z": 7,
      "name": "Wood_Beastwood_Bark"
    },
    {
      "x": -19,
      "y": 5,
      "z": 7,
      "name": "Wood_Beastwood_Bark"
    },
    {
      "x": -19,
      "y": 6,
      "z": 7,
      "name": "Wood_Beastwood_Bark"
    },
    {
      "x": -19,
      "y": 7,
      "z": 7,
      "name": "Wood_Beastwood_Bark"
    },
    {
      "x": -19,
      "y": 8,
      "z": 7,
      "name": "Wood_Beastwood_Bark"
    },
    {
      "x": -18,
      "y": 1,
      "z": -9,
      "name": "Wood_Beastwood_Bark"
    },
    {
      "x": -18,
      "y": 2,
      "z": -9,
      "name": "Wood_Beastwood_Bark"
    },
    {
      "x": -18,
      "y": 3,
      "z": -9,
      "name": "Wood_Beastwood_Bark"
    },
    {
      "x": -18,
      "y": 4,
      "z": -9,
      "name": "Wood_Beastwood_Bark"
    },
    {
      "x": -18,
      "y": 5,
      "z": -9,
      "name": "Wood_Beastwood_Bark"
    },
    {
      "x": -18,
      "y": 6,
      "z": -9,
      "name": "Wood_Beastwood_Bark"
    },
    {
      "x": -18,
      "y": 7,
      "z": -9,
      "name": "Wood_Beastwood_Bark"
    },
    {
      "x": -18,
      "y": 8,
      "z": -9,
      "name": "Wood_Beastwood_Bark"
    },
    {
      "x": -18,
      "y": 1,
      "z": -8,
      "name": "Wood_Beastwood_Bark"
    },
    {
      "x": -18,
      "y": 2,
      "z": -8,
      "name": "Wood_Beastwood_Bark"
    },
    {
      "x": -18,
      "y": 3,
      "z": -8,
      "name": "Wood_Beastwood_Bark"
    },
    {
      "x": -18,
      "y": 4,
      "z": -8,
      "name": "Wood_Beastwood_Bark"
    },
    {
      "x": -18,
      "y": 5,
      "z": -8,
      "name": "Wood_Beastwood_Bark"
    },
    {
      "x": -18,
      "y": 6,
      "z": -8,
      "name": "Wood_Beastwood_Bark"
    },
    {
      "x": -18,
      "y": 7,
      "z": -8,
      "name": "Wood_Beastwood_Bark"
    },
    {
      "x": -18,
      "y": 8,
      "z": -8,
      "name": "Wood_Beastwood_Bark"
    },
    {
      "x": -18,
      "y": 1,
      "z": -7,
      "name": "Wood_Beastwood_Bark"
    },
    {
      "x": -18,
      "y": 2,
      "z": -7,
      "name": "Wood_Beastwood_Bark"
    },
    {
      "x": -18,
      "y": 3,
      "z": -7,
      "name": "Wood_Beastwood_Bark"
    },
    {
      "x": -18,
      "y": 4,
      "z": -7,
      "name": "Wood_Beastwood_Bark"
    },
    {
      "x": -18,
      "y": 5,
      "z": -7,
      "name": "Wood_Beastwood_Bark"
    },
    {
      "x": -18,
      "y": 6,
      "z": -7,
      "name": "Wood_Beastwood_Bark"
    },
    {
      "x": -18,
      "y": 7,
      "z": -7,
      "name": "Wood_Beastwood_Bark"
    },
    {
      "x": -18,
      "y": 8,
      "z": -7,
      "name": "Wood_Beastwood_Bark"
    },
    {
      "x": -18,
      "y": 1,
      "z": -6,
      "name": "Wood_Beastwood_Bark"
    },
    {
      "x": -18,
      "y": 2,
      "z": -6,
      "name": "Wood_Beastwood_Bark"
    },
    {
      "x": -18,
      "y": 3,
      "z": -6,
      "name": "Wood_Beastwood_Bark"
    },
    {
      "x": -18,
      "y": 4,
      "z": -6,
      "name": "Wood_Beastwood_Bark"
    },
    {
      "x": -18,
      "y": 5,
      "z": -6,
      "name": "Wood_Beastwood_Bark"
    },
    {
      "x": -18,
      "y": 6,
      "z": -6,
      "name": "Wood_Beastwood_Bark"
    },
    {
      "x": -18,
      "y": 7,
      "z": -6,
      "name": "Wood_Beastwood_Bark"
    },
    {
      "x": -18,
      "y": 8,
      "z": -6,
      "name": "Wood_Beastwood_Bark"
    },
    {
      "x": -18,
      "y": 1,
      "z": -5,
      "name": "Wood_Beastwood_Bark"
    },
    {
      "x": -18,
      "y": 2,
      "z": -5,
      "name": "Wood_Beastwood_Bark"
    },
    {
      "x": -18,
      "y": 3,
      "z": -5,
      "name": "Wood_Beastwood_Bark"
    },
    {
      "x": -18,
      "y": 4,
      "z": -5,
      "name": "Wood_Beastwood_Bark"
    },
    {
      "x": -18,
      "y": 5,
      "z": -5,
      "name": "Wood_Beastwood_Bark"
    },
    {
      "x": -18,
      "y": 6,
      "z": -5,
      "name": "Wood_Beastwood_Bark"
    },
    {
      "x": -18,
      "y": 7,
      "z": -5,
      "name": "Wood_Beastwood_Bark"
    },
    {
      "x": -18,
      "y": 8,
      "z": -5,
      "name": "Wood_Beastwood_Bark"
    },
    {
      "x": -18,
      "y": 1,
      "z": -4,
      "name": "Wood_Beastwood_Bark"
    },
    {
      "x": -18,
      "y": 2,
      "z": -4,
      "name": "Wood_Beastwood_Bark"
    },
    {
      "x": -18,
      "y": 3,
      "z": -4,
      "name": "Wood_Beastwood_Bark"
    },
    {
      "x": -18,
      "y": 4,
      "z": -4,
      "name": "Wood_Beastwood_Bark"
    },
    {
      "x": -18,
      "y": 5,
      "z": -4,
      "name": "Wood_Beastwood_Bark"
    },
    {
      "x": -18,
      "y": 6,
      "z": -4,
      "name": "Wood_Beastwood_Bark"
    },
    {
      "x": -18,
      "y": 7,
      "z": -4,
      "name": "Wood_Beastwood_Bark"
    },
    {
      "x": -18,
      "y": 8,
      "z": -4,
      "name": "Wood_Beastwood_Bark"
    },
    {
      "x": -18,
      "y": 1,
      "z": -3,
      "name": "Plant_Crop_Mushroom_Block_Green"
    },
    {
      "x": -18,
      "y": 2,
      "z": -3,
      "name": "Plant_Crop_Mushroom_Block_Green"
    },
    {
      "x": -18,
      "y": 3,
      "z": -3,
      "name": "Plant_Crop_Mushroom_Block_Green"
    },
    {
      "x": -18,
      "y": 4,
      "z": -3,
      "name": "Plant_Crop_Mushroom_Block_Green"
    },
    {
      "x": -18,
      "y": 5,
      "z": -3,
      "name": "Plant_Crop_Mushroom_Block_Green"
    },
    {
      "x": -18,
      "y": 6,
      "z": -3,
      "name": "Plant_Crop_Mushroom_Block_Green"
    },
    {
      "x": -18,
      "y": 7,
      "z": -3,
      "name": "Plant_Crop_Mushroom_Block_Green"
    },
    {
      "x": -18,
      "y": 8,
      "z": -3,
      "name": "Plant_Crop_Mushroom_Block_Green"
    },
    {
      "x": -18,
      "y": 1,
      "z": -2,
      "name": "Plant_Crop_Mushroom_Block_Green"
    },
    {
      "x": -18,
      "y": 2,
      "z": -2,
      "name": "Plant_Crop_Mushroom_Block_Green"
    },
    {
      "x": -18,
      "y": 3,
      "z": -2,
      "name": "Plant_Crop_Mushroom_Block_Green"
    },
    {
      "x": -18,
      "y": 4,
      "z": -2,
      "name": "Plant_Crop_Mushroom_Block_Green"
    },
    {
      "x": -18,
      "y": 5,
      "z": -2,
      "name": "Plant_Crop_Mushroom_Block_Green"
    },
    {
      "x": -18,
      "y": 6,
      "z": -2,
      "name": "Plant_Crop_Mushroom_Block_Green"
    },
    {
      "x": -18,
      "y": 7,
      "z": -2,
      "name": "Plant_Crop_Mushroom_Block_Green"
    },
    {
      "x": -18,
      "y": 8,
      "z": -2,
      "name": "Plant_Crop_Mushroom_Block_Green"
    },
    {
      "x": -18,
      "y": 1,
      "z": -1,
      "name": "Plant_Crop_Mushroom_Block_Green"
    },
    {
      "x": -18,
      "y": 2,
      "z": -1,
      "name": "Plant_Crop_Mushroom_Block_Green"
    },
    {
      "x": -18,
      "y": 3,
      "z": -1,
      "name": "Plant_Crop_Mushroom_Block_Green"
    },
    {
      "x": -18,
      "y": 4,
      "z": -1,
      "name": "Plant_Crop_Mushroom_Block_Green"
    },
    {
      "x": -18,
      "y": 5,
      "z": -1,
      "name": "Plant_Crop_Mushroom_Block_Green"
    },
    {
      "x": -18,
      "y": 6,
      "z": -1,
      "name": "Plant_Crop_Mushroom_Block_Green"
    },
    {
      "x": -18,
      "y": 7,
      "z": -1,
      "name": "Plant_Crop_Mushroom_Block_Green"
    },
    {
      "x": -18,
      "y": 8,
      "z": -1,
      "name": "Plant_Crop_Mushroom_Block_Green"
    },
    {
      "x": -18,
      "y": 1,
      "z": 0,
      "name": "Plant_Crop_Mushroom_Block_Green"
    },
    {
      "x": -18,
      "y": 2,
      "z": 0,
      "name": "Plant_Crop_Mushroom_Block_Green"
    },
    {
      "x": -18,
      "y": 3,
      "z": 0,
      "name": "Plant_Crop_Mushroom_Block_Green"
    },
    {
      "x": -18,
      "y": 4,
      "z": 0,
      "name": "Plant_Crop_Mushroom_Block_Green"
    },
    {
      "x": -18,
      "y": 5,
      "z": 0,
      "name": "Plant_Crop_Mushroom_Block_Green"
    },
    {
      "x": -18,
      "y": 6,
      "z": 0,
      "name": "Plant_Crop_Mushroom_Block_Green"
    },
    {
      "x": -18,
      "y": 7,
      "z": 0,
      "name": "Plant_Crop_Mushroom_Block_Green"
    },
    {
      "x": -18,
      "y": 8,
      "z": 0,
      "name": "Plant_Crop_Mushroom_Block_Green"
    },
    {
      "x": -18,
      "y": 1,
      "z": 1,
      "name": "Plant_Crop_Mushroom_Block_Green"
    },
    {
      "x": -18,
      "y": 2,
      "z": 1,
      "name": "Plant_Crop_Mushroom_Block_Green"
    },
    {
      "x": -18,
      "y": 3,
      "z": 1,
      "name": "Plant_Crop_Mushroom_Block_Green"
    },
    {
      "x": -18,
      "y": 4,
      "z": 1,
      "name": "Plant_Crop_Mushroom_Block_Green"
    },
    {
      "x": -18,
      "y": 5,
      "z": 1,
      "name": "Plant_Crop_Mushroom_Block_Green"
    },
    {
      "x": -18,
      "y": 6,
      "z": 1,
      "name": "Plant_Crop_Mushroom_Block_Green"
    },
    {
      "x": -18,
      "y": 7,
      "z": 1,
      "name": "Plant_Crop_Mushroom_Block_Green"
    },
    {
      "x": -18,
      "y": 8,
      "z": 1,
      "name": "Plant_Crop_Mushroom_Block_Green"
    },
    {
      "x": -18,
      "y": 1,
      "z": 2,
      "name": "Plant_Crop_Mushroom_Block_Green"
    },
    {
      "x": -18,
      "y": 2,
      "z": 2,
      "name": "Plant_Crop_Mushroom_Block_Green"
    },
    {
      "x": -18,
      "y": 3,
      "z": 2,
      "name": "Plant_Crop_Mushroom_Block_Green"
    },
    {
      "x": -18,
      "y": 4,
      "z": 2,
      "name": "Plant_Crop_Mushroom_Block_Green"
    },
    {
      "x": -18,
      "y": 5,
      "z": 2,
      "name": "Plant_Crop_Mushroom_Block_Green"
    },
    {
      "x": -18,
      "y": 6,
      "z": 2,
      "name": "Plant_Crop_Mushroom_Block_Green"
    },
    {
      "x": -18,
      "y": 7,
      "z": 2,
      "name": "Plant_Crop_Mushroom_Block_Green"
    },
    {
      "x": -18,
      "y": 8,
      "z": 2,
      "name": "Plant_Crop_Mushroom_Block_Green"
    },
    {
      "x": -18,
      "y": 1,
      "z": 3,
      "name": "Plant_Crop_Mushroom_Block_Green"
    },
    {
      "x": -18,
      "y": 2,
      "z": 3,
      "name": "Plant_Crop_Mushroom_Block_Green"
    },
    {
      "x": -18,
      "y": 3,
      "z": 3,
      "name": "Plant_Crop_Mushroom_Block_Green"
    },
    {
      "x": -18,
      "y": 4,
      "z": 3,
      "name": "Plant_Crop_Mushroom_Block_Green"
    },
    {
      "x": -18,
      "y": 5,
      "z": 3,
      "name": "Plant_Crop_Mushroom_Block_Green"
    },
    {
      "x": -18,
      "y": 6,
      "z": 3,
      "name": "Plant_Crop_Mushroom_Block_Green"
    },
    {
      "x": -18,
      "y": 7,
      "z": 3,
      "name": "Plant_Crop_Mushroom_Block_Green"
    },
    {
      "x": -18,
      "y": 8,
      "z": 3,
      "name": "Plant_Crop_Mushroom_Block_Green"
    },
    {
      "x": -18,
      "y": 1,
      "z": 4,
      "name": "Wood_Beastwood_Bark"
    },
    {
      "x": -18,
      "y": 2,
      "z": 4,
      "name": "Wood_Beastwood_Bark"
    },
    {
      "x": -18,
      "y": 3,
      "z": 4,
      "name": "Wood_Beastwood_Bark"
    },
    {
      "x": -18,
      "y": 4,
      "z": 4,
      "name": "Wood_Beastwood_Bark"
    },
    {
      "x": -18,
      "y": 5,
      "z": 4,
      "name": "Wood_Beastwood_Bark"
    },
    {
      "x": -18,
      "y": 6,
      "z": 4,
      "name": "Wood_Beastwood_Bark"
    },
    {
      "x": -18,
      "y": 7,
      "z": 4,
      "name": "Wood_Beastwood_Bark"
    },
    {
      "x": -18,
      "y": 8,
      "z": 4,
      "name": "Wood_Beastwood_Bark"
    },
    {
      "x": -18,
      "y": 1,
      "z": 5,
      "name": "Wood_Beastwood_Bark"
    },
    {
      "x": -18,
      "y": 2,
      "z": 5,
      "name": "Wood_Beastwood_Bark"
    },
    {
      "x": -18,
      "y": 3,
      "z": 5,
      "name": "Wood_Beastwood_Bark"
    },
    {
      "x": -18,
      "y": 4,
      "z": 5,
      "name": "Wood_Beastwood_Bark"
    },
    {
      "x": -18,
      "y": 5,
      "z": 5,
      "name": "Wood_Beastwood_Bark"
    },
    {
      "x": -18,
      "y": 6,
      "z": 5,
      "name": "Wood_Beastwood_Bark"
    },
    {
      "x": -18,
      "y": 7,
      "z": 5,
      "name": "Wood_Beastwood_Bark"
    },
    {
      "x": -18,
      "y": 8,
      "z": 5,
      "name": "Wood_Beastwood_Bark"
    },
    {
      "x": -18,
      "y": 1,
      "z": 6,
      "name": "Wood_Beastwood_Bark"
    },
    {
      "x": -18,
      "y": 2,
      "z": 6,
      "name": "Wood_Beastwood_Bark"
    },
    {
      "x": -18,
      "y": 3,
      "z": 6,
      "name": "Wood_Beastwood_Bark"
    },
    {
      "x": -18,
      "y": 4,
      "z": 6,
      "name": "Wood_Beastwood_Bark"
    },
    {
      "x": -18,
      "y": 5,
      "z": 6,
      "name": "Wood_Beastwood_Bark"
    },
    {
      "x": -18,
      "y": 6,
      "z": 6,
      "name": "Wood_Beastwood_Bark"
    },
    {
      "x": -18,
      "y": 7,
      "z": 6,
      "name": "Wood_Beastwood_Bark"
    },
    {
      "x": -18,
      "y": 8,
      "z": 6,
      "name": "Wood_Beastwood_Bark"
    },
    {
      "x": -18,
      "y": 1,
      "z": 7,
      "name": "Wood_Beastwood_Bark"
    },
    {
      "x": -18,
      "y": 2,
      "z": 7,
      "name": "Wood_Beastwood_Bark"
    },
    {
      "x": -18,
      "y": 3,
      "z": 7,
      "name": "Wood_Beastwood_Bark"
    },
    {
      "x": -18,
      "y": 4,
      "z": 7,
      "name": "Wood_Beastwood_Bark"
    },
    {
      "x": -18,
      "y": 5,
      "z": 7,
      "name": "Wood_Beastwood_Bark"
    },
    {
      "x": -18,
      "y": 6,
      "z": 7,
      "name": "Wood_Beastwood_Bark"
    },
    {
      "x": -18,
      "y": 7,
      "z": 7,
      "name": "Wood_Beastwood_Bark"
    },
    {
      "x": -18,
      "y": 8,
      "z": 7,
      "name": "Wood_Beastwood_Bark"
    },
    {
      "x": -18,
      "y": 1,
      "z": 8,
      "name": "Wood_Beastwood_Bark"
    },
    {
      "x": -18,
      "y": 2,
      "z": 8,
      "name": "Wood_Beastwood_Bark"
    },
    {
      "x": -18,
      "y": 3,
      "z": 8,
      "name": "Wood_Beastwood_Bark"
    },
    {
      "x": -18,
      "y": 4,
      "z": 8,
      "name": "Wood_Beastwood_Bark"
    },
    {
      "x": -18,
      "y": 5,
      "z": 8,
      "name": "Wood_Beastwood_Bark"
    },
    {
      "x": -18,
      "y": 6,
      "z": 8,
      "name": "Wood_Beastwood_Bark"
    },
    {
      "x": -18,
      "y": 7,
      "z": 8,
      "name": "Wood_Beastwood_Bark"
    },
    {
      "x": -18,
      "y": 8,
      "z": 8,
      "name": "Wood_Beastwood_Bark"
    },
    {
      "x": -18,
      "y": 1,
      "z": 9,
      "name": "Wood_Beastwood_Bark"
    },
    {
      "x": -18,
      "y": 2,
      "z": 9,
      "name": "Wood_Beastwood_Bark"
    },
    {
      "x": -18,
      "y": 3,
      "z": 9,
      "name": "Wood_Beastwood_Bark"
    },
    {
      "x": -18,
      "y": 4,
      "z": 9,
      "name": "Wood_Beastwood_Bark"
    },
    {
      "x": -18,
      "y": 5,
      "z": 9,
      "name": "Wood_Beastwood_Bark"
    },
    {
      "x": -18,
      "y": 6,
      "z": 9,
      "name": "Wood_Beastwood_Bark"
    },
    {
      "x": -18,
      "y": 7,
      "z": 9,
      "name": "Wood_Beastwood_Bark"
    },
    {
      "x": -18,
      "y": 8,
      "z": 9,
      "name": "Wood_Beastwood_Bark"
    },
    {
      "x": -17,
      "y": 1,
      "z": -11,
      "name": "Wood_Beastwood_Bark"
    },
    {
      "x": -17,
      "y": 2,
      "z": -11,
      "name": "Wood_Beastwood_Bark"
    },
    {
      "x": -17,
      "y": 3,
      "z": -11,
      "name": "Wood_Beastwood_Bark"
    },
    {
      "x": -17,
      "y": 4,
      "z": -11,
      "name": "Wood_Beastwood_Bark"
    },
    {
      "x": -17,
      "y": 5,
      "z": -11,
      "name": "Wood_Beastwood_Bark"
    },
    {
      "x": -17,
      "y": 6,
      "z": -11,
      "name": "Wood_Beastwood_Bark"
    },
    {
      "x": -17,
      "y": 7,
      "z": -11,
      "name": "Wood_Beastwood_Bark"
    },
    {
      "x": -17,
      "y": 8,
      "z": -11,
      "name": "Wood_Beastwood_Bark"
    },
    {
      "x": -17,
      "y": 1,
      "z": -10,
      "name": "Wood_Beastwood_Bark"
    },
    {
      "x": -17,
      "y": 2,
      "z": -10,
      "name": "Wood_Beastwood_Bark"
    },
    {
      "x": -17,
      "y": 3,
      "z": -10,
      "name": "Wood_Beastwood_Bark"
    },
    {
      "x": -17,
      "y": 4,
      "z": -10,
      "name": "Wood_Beastwood_Bark"
    },
    {
      "x": -17,
      "y": 5,
      "z": -10,
      "name": "Wood_Beastwood_Bark"
    },
    {
      "x": -17,
      "y": 6,
      "z": -10,
      "name": "Wood_Beastwood_Bark"
    },
    {
      "x": -17,
      "y": 7,
      "z": -10,
      "name": "Wood_Beastwood_Bark"
    },
    {
      "x": -17,
      "y": 8,
      "z": -10,
      "name": "Wood_Beastwood_Bark"
    },
    {
      "x": -17,
      "y": 1,
      "z": -9,
      "name": "Wood_Beastwood_Bark"
    },
    {
      "x": -17,
      "y": 2,
      "z": -9,
      "name": "Wood_Beastwood_Bark"
    },
    {
      "x": -17,
      "y": 3,
      "z": -9,
      "name": "Wood_Beastwood_Bark"
    },
    {
      "x": -17,
      "y": 4,
      "z": -9,
      "name": "Wood_Beastwood_Bark"
    },
    {
      "x": -17,
      "y": 5,
      "z": -9,
      "name": "Wood_Beastwood_Bark"
    },
    {
      "x": -17,
      "y": 6,
      "z": -9,
      "name": "Wood_Beastwood_Bark"
    },
    {
      "x": -17,
      "y": 7,
      "z": -9,
      "name": "Wood_Beastwood_Bark"
    },
    {
      "x": -17,
      "y": 8,
      "z": -9,
      "name": "Wood_Beastwood_Bark"
    },
    {
      "x": -17,
      "y": 1,
      "z": -8,
      "name": "Wood_Beastwood_Bark"
    },
    {
      "x": -17,
      "y": 2,
      "z": -8,
      "name": "Wood_Beastwood_Bark"
    },
    {
      "x": -17,
      "y": 3,
      "z": -8,
      "name": "Wood_Beastwood_Bark"
    },
    {
      "x": -17,
      "y": 4,
      "z": -8,
      "name": "Wood_Beastwood_Bark"
    },
    {
      "x": -17,
      "y": 5,
      "z": -8,
      "name": "Wood_Beastwood_Bark"
    },
    {
      "x": -17,
      "y": 6,
      "z": -8,
      "name": "Wood_Beastwood_Bark"
    },
    {
      "x": -17,
      "y": 7,
      "z": -8,
      "name": "Wood_Beastwood_Bark"
    },
    {
      "x": -17,
      "y": 8,
      "z": -8,
      "name": "Wood_Beastwood_Bark"
    },
    {
      "x": -17,
      "y": 1,
      "z": -7,
      "name": "Plant_Crop_Mushroom_Block_Green"
    },
    {
      "x": -17,
      "y": 2,
      "z": -7,
      "name": "Plant_Crop_Mushroom_Block_Green"
    },
    {
      "x": -17,
      "y": 3,
      "z": -7,
      "name": "Plant_Crop_Mushroom_Block_Green"
    },
    {
      "x": -17,
      "y": 4,
      "z": -7,
      "name": "Plant_Crop_Mushroom_Block_Green"
    },
    {
      "x": -17,
      "y": 5,
      "z": -7,
      "name": "Plant_Crop_Mushroom_Block_Green"
    },
    {
      "x": -17,
      "y": 6,
      "z": -7,
      "name": "Plant_Crop_Mushroom_Block_Green"
    },
    {
      "x": -17,
      "y": 7,
      "z": -7,
      "name": "Plant_Crop_Mushroom_Block_Green"
    },
    {
      "x": -17,
      "y": 8,
      "z": -7,
      "name": "Plant_Crop_Mushroom_Block_Green"
    },
    {
      "x": -17,
      "y": 1,
      "z": -6,
      "name": "Plant_Crop_Mushroom_Block_Green"
    },
    {
      "x": -17,
      "y": 2,
      "z": -6,
      "name": "Plant_Crop_Mushroom_Block_Green"
    },
    {
      "x": -17,
      "y": 3,
      "z": -6,
      "name": "Plant_Crop_Mushroom_Block_Green"
    },
    {
      "x": -17,
      "y": 4,
      "z": -6,
      "name": "Plant_Crop_Mushroom_Block_Green"
    },
    {
      "x": -17,
      "y": 5,
      "z": -6,
      "name": "Plant_Crop_Mushroom_Block_Green"
    },
    {
      "x": -17,
      "y": 6,
      "z": -6,
      "name": "Plant_Crop_Mushroom_Block_Green"
    },
    {
      "x": -17,
      "y": 7,
      "z": -6,
      "name": "Plant_Crop_Mushroom_Block_Green"
    },
    {
      "x": -17,
      "y": 8,
      "z": -6,
      "name": "Plant_Crop_Mushroom_Block_Green"
    },
    {
      "x": -17,
      "y": 1,
      "z": -5,
      "name": "Plant_Crop_Mushroom_Block_Green"
    },
    {
      "x": -17,
      "y": 2,
      "z": -5,
      "name": "Plant_Crop_Mushroom_Block_Green"
    },
    {
      "x": -17,
      "y": 3,
      "z": -5,
      "name": "Plant_Crop_Mushroom_Block_Green"
    },
    {
      "x": -17,
      "y": 4,
      "z": -5,
      "name": "Plant_Crop_Mushroom_Block_Green"
    },
    {
      "x": -17,
      "y": 5,
      "z": -5,
      "name": "Plant_Crop_Mushroom_Block_Green"
    },
    {
      "x": -17,
      "y": 6,
      "z": -5,
      "name": "Plant_Crop_Mushroom_Block_Green"
    },
    {
      "x": -17,
      "y": 7,
      "z": -5,
      "name": "Plant_Crop_Mushroom_Block_Green"
    },
    {
      "x": -17,
      "y": 8,
      "z": -5,
      "name": "Plant_Crop_Mushroom_Block_Green"
    },
    {
      "x": -17,
      "y": 1,
      "z": -4,
      "name": "Plant_Crop_Mushroom_Block_Green"
    },
    {
      "x": -17,
      "y": 2,
      "z": -4,
      "name": "Plant_Crop_Mushroom_Block_Green"
    },
    {
      "x": -17,
      "y": 3,
      "z": -4,
      "name": "Plant_Crop_Mushroom_Block_Green"
    },
    {
      "x": -17,
      "y": 4,
      "z": -4,
      "name": "Plant_Crop_Mushroom_Block_Green"
    },
    {
      "x": -17,
      "y": 5,
      "z": -4,
      "name": "Plant_Crop_Mushroom_Block_Green"
    },
    {
      "x": -17,
      "y": 6,
      "z": -4,
      "name": "Plant_Crop_Mushroom_Block_Green"
    },
    {
      "x": -17,
      "y": 7,
      "z": -4,
      "name": "Plant_Crop_Mushroom_Block_Green"
    },
    {
      "x": -17,
      "y": 8,
      "z": -4,
      "name": "Plant_Crop_Mushroom_Block_Green"
    },
    {
      "x": -17,
      "y": 1,
      "z": -3,
      "name": "Plant_Crop_Mushroom_Block_Green"
    },
    {
      "x": -17,
      "y": 2,
      "z": -3,
      "name": "Plant_Crop_Mushroom_Block_Green"
    },
    {
      "x": -17,
      "y": 3,
      "z": -3,
      "name": "Plant_Crop_Mushroom_Block_Green"
    },
    {
      "x": -17,
      "y": 4,
      "z": -3,
      "name": "Plant_Crop_Mushroom_Block_Green"
    },
    {
      "x": -17,
      "y": 5,
      "z": -3,
      "name": "Plant_Crop_Mushroom_Block_Green"
    },
    {
      "x": -17,
      "y": 6,
      "z": -3,
      "name": "Plant_Crop_Mushroom_Block_Green"
    },
    {
      "x": -17,
      "y": 7,
      "z": -3,
      "name": "Plant_Crop_Mushroom_Block_Green"
    },
    {
      "x": -17,
      "y": 8,
      "z": -3,
      "name": "Plant_Crop_Mushroom_Block_Green"
    },
    {
      "x": -17,
      "y": 1,
      "z": -2,
      "name": "Plant_Crop_Mushroom_Block_Green"
    },
    {
      "x": -17,
      "y": 2,
      "z": -2,
      "name": "Plant_Crop_Mushroom_Block_Green"
    },
    {
      "x": -17,
      "y": 3,
      "z": -2,
      "name": "Plant_Crop_Mushroom_Block_Green"
    },
    {
      "x": -17,
      "y": 4,
      "z": -2,
      "name": "Plant_Crop_Mushroom_Block_Green"
    },
    {
      "x": -17,
      "y": 5,
      "z": -2,
      "name": "Plant_Crop_Mushroom_Block_Green"
    },
    {
      "x": -17,
      "y": 6,
      "z": -2,
      "name": "Plant_Crop_Mushroom_Block_Green"
    },
    {
      "x": -17,
      "y": 7,
      "z": -2,
      "name": "Plant_Crop_Mushroom_Block_Green"
    },
    {
      "x": -17,
      "y": 8,
      "z": -2,
      "name": "Plant_Crop_Mushroom_Block_Green"
    },
    {
      "x": -17,
      "y": 1,
      "z": -1,
      "name": "Plant_Crop_Mushroom_Block_Green"
    },
    {
      "x": -17,
      "y": 2,
      "z": -1,
      "name": "Plant_Crop_Mushroom_Block_Green"
    },
    {
      "x": -17,
      "y": 3,
      "z": -1,
      "name": "Plant_Crop_Mushroom_Block_Green"
    },
    {
      "x": -17,
      "y": 4,
      "z": -1,
      "name": "Plant_Crop_Mushroom_Block_Green"
    },
    {
      "x": -17,
      "y": 5,
      "z": -1,
      "name": "Plant_Crop_Mushroom_Block_Green"
    },
    {
      "x": -17,
      "y": 6,
      "z": -1,
      "name": "Plant_Crop_Mushroom_Block_Green"
    },
    {
      "x": -17,
      "y": 7,
      "z": -1,
      "name": "Plant_Crop_Mushroom_Block_Green"
    },
    {
      "x": -17,
      "y": 8,
      "z": -1,
      "name": "Plant_Crop_Mushroom_Block_Green"
    },
    {
      "x": -17,
      "y": 1,
      "z": 0,
      "name": "Plant_Crop_Mushroom_Block_Green"
    },
    {
      "x": -17,
      "y": 2,
      "z": 0,
      "name": "Plant_Crop_Mushroom_Block_Green"
    },
    {
      "x": -17,
      "y": 3,
      "z": 0,
      "name": "Plant_Crop_Mushroom_Block_Green"
    },
    {
      "x": -17,
      "y": 4,
      "z": 0,
      "name": "Plant_Crop_Mushroom_Block_Green"
    },
    {
      "x": -17,
      "y": 5,
      "z": 0,
      "name": "Plant_Crop_Mushroom_Block_Green"
    },
    {
      "x": -17,
      "y": 6,
      "z": 0,
      "name": "Plant_Crop_Mushroom_Block_Green"
    },
    {
      "x": -17,
      "y": 7,
      "z": 0,
      "name": "Plant_Crop_Mushroom_Block_Green"
    },
    {
      "x": -17,
      "y": 8,
      "z": 0,
      "name": "Plant_Crop_Mushroom_Block_Green"
    },
    {
      "x": -17,
      "y": 1,
      "z": 1,
      "name": "Plant_Crop_Mushroom_Block_Green"
    },
    {
      "x": -17,
      "y": 2,
      "z": 1,
      "name": "Plant_Crop_Mushroom_Block_Green"
    },
    {
      "x": -17,
      "y": 3,
      "z": 1,
      "name": "Plant_Crop_Mushroom_Block_Green"
    },
    {
      "x": -17,
      "y": 4,
      "z": 1,
      "name": "Plant_Crop_Mushroom_Block_Green"
    },
    {
      "x": -17,
      "y": 5,
      "z": 1,
      "name": "Plant_Crop_Mushroom_Block_Green"
    },
    {
      "x": -17,
      "y": 6,
      "z": 1,
      "name": "Plant_Crop_Mushroom_Block_Green"
    },
    {
      "x": -17,
      "y": 7,
      "z": 1,
      "name": "Plant_Crop_Mushroom_Block_Green"
    },
    {
      "x": -17,
      "y": 8,
      "z": 1,
      "name": "Plant_Crop_Mushroom_Block_Green"
    },
    {
      "x": -17,
      "y": 1,
      "z": 2,
      "name": "Plant_Crop_Mushroom_Block_Green"
    },
    {
      "x": -17,
      "y": 2,
      "z": 2,
      "name": "Plant_Crop_Mushroom_Block_Green"
    },
    {
      "x": -17,
      "y": 3,
      "z": 2,
      "name": "Plant_Crop_Mushroom_Block_Green"
    },
    {
      "x": -17,
      "y": 4,
      "z": 2,
      "name": "Plant_Crop_Mushroom_Block_Green"
    },
    {
      "x": -17,
      "y": 5,
      "z": 2,
      "name": "Plant_Crop_Mushroom_Block_Green"
    },
    {
      "x": -17,
      "y": 6,
      "z": 2,
      "name": "Plant_Crop_Mushroom_Block_Green"
    },
    {
      "x": -17,
      "y": 7,
      "z": 2,
      "name": "Plant_Crop_Mushroom_Block_Green"
    },
    {
      "x": -17,
      "y": 8,
      "z": 2,
      "name": "Plant_Crop_Mushroom_Block_Green"
    },
    {
      "x": -17,
      "y": 1,
      "z": 3,
      "name": "Plant_Crop_Mushroom_Block_Green"
    },
    {
      "x": -17,
      "y": 2,
      "z": 3,
      "name": "Plant_Crop_Mushroom_Block_Green"
    },
    {
      "x": -17,
      "y": 3,
      "z": 3,
      "name": "Plant_Crop_Mushroom_Block_Green"
    },
    {
      "x": -17,
      "y": 4,
      "z": 3,
      "name": "Plant_Crop_Mushroom_Block_Green"
    },
    {
      "x": -17,
      "y": 5,
      "z": 3,
      "name": "Plant_Crop_Mushroom_Block_Green"
    },
    {
      "x": -17,
      "y": 6,
      "z": 3,
      "name": "Plant_Crop_Mushroom_Block_Green"
    },
    {
      "x": -17,
      "y": 7,
      "z": 3,
      "name": "Plant_Crop_Mushroom_Block_Green"
    },
    {
      "x": -17,
      "y": 8,
      "z": 3,
      "name": "Plant_Crop_Mushroom_Block_Green"
    },
    {
      "x": -17,
      "y": 1,
      "z": 4,
      "name": "Plant_Crop_Mushroom_Block_Green"
    },
    {
      "x": -17,
      "y": 2,
      "z": 4,
      "name": "Plant_Crop_Mushroom_Block_Green"
    },
    {
      "x": -17,
      "y": 3,
      "z": 4,
      "name": "Plant_Crop_Mushroom_Block_Green"
    },
    {
      "x": -17,
      "y": 4,
      "z": 4,
      "name": "Plant_Crop_Mushroom_Block_Green"
    },
    {
      "x": -17,
      "y": 5,
      "z": 4,
      "name": "Plant_Crop_Mushroom_Block_Green"
    },
    {
      "x": -17,
      "y": 6,
      "z": 4,
      "name": "Plant_Crop_Mushroom_Block_Green"
    },
    {
      "x": -17,
      "y": 7,
      "z": 4,
      "name": "Plant_Crop_Mushroom_Block_Green"
    },
    {
      "x": -17,
      "y": 8,
      "z": 4,
      "name": "Plant_Crop_Mushroom_Block_Green"
    },
    {
      "x": -17,
      "y": 1,
      "z": 5,
      "name": "Plant_Crop_Mushroom_Block_Green"
    },
    {
      "x": -17,
      "y": 2,
      "z": 5,
      "name": "Plant_Crop_Mushroom_Block_Green"
    },
    {
      "x": -17,
      "y": 3,
      "z": 5,
      "name": "Plant_Crop_Mushroom_Block_Green"
    },
    {
      "x": -17,
      "y": 4,
      "z": 5,
      "name": "Plant_Crop_Mushroom_Block_Green"
    },
    {
      "x": -17,
      "y": 5,
      "z": 5,
      "name": "Plant_Crop_Mushroom_Block_Green"
    },
    {
      "x": -17,
      "y": 6,
      "z": 5,
      "name": "Plant_Crop_Mushroom_Block_Green"
    },
    {
      "x": -17,
      "y": 7,
      "z": 5,
      "name": "Plant_Crop_Mushroom_Block_Green"
    },
    {
      "x": -17,
      "y": 8,
      "z": 5,
      "name": "Plant_Crop_Mushroom_Block_Green"
    },
    {
      "x": -17,
      "y": 1,
      "z": 6,
      "name": "Plant_Crop_Mushroom_Block_Green"
    },
    {
      "x": -17,
      "y": 2,
      "z": 6,
      "name": "Plant_Crop_Mushroom_Block_Green"
    },
    {
      "x": -17,
      "y": 3,
      "z": 6,
      "name": "Plant_Crop_Mushroom_Block_Green"
    },
    {
      "x": -17,
      "y": 4,
      "z": 6,
      "name": "Plant_Crop_Mushroom_Block_Green"
    },
    {
      "x": -17,
      "y": 5,
      "z": 6,
      "name": "Plant_Crop_Mushroom_Block_Green"
    },
    {
      "x": -17,
      "y": 6,
      "z": 6,
      "name": "Plant_Crop_Mushroom_Block_Green"
    },
    {
      "x": -17,
      "y": 7,
      "z": 6,
      "name": "Plant_Crop_Mushroom_Block_Green"
    },
    {
      "x": -17,
      "y": 8,
      "z": 6,
      "name": "Plant_Crop_Mushroom_Block_Green"
    },
    {
      "x": -17,
      "y": 1,
      "z": 7,
      "name": "Plant_Crop_Mushroom_Block_Green"
    },
    {
      "x": -17,
      "y": 2,
      "z": 7,
      "name": "Plant_Crop_Mushroom_Block_Green"
    },
    {
      "x": -17,
      "y": 3,
      "z": 7,
      "name": "Plant_Crop_Mushroom_Block_Green"
    },
    {
      "x": -17,
      "y": 4,
      "z": 7,
      "name": "Plant_Crop_Mushroom_Block_Green"
    },
    {
      "x": -17,
      "y": 5,
      "z": 7,
      "name": "Plant_Crop_Mushroom_Block_Green"
    },
    {
      "x": -17,
      "y": 6,
      "z": 7,
      "name": "Plant_Crop_Mushroom_Block_Green"
    },
    {
      "x": -17,
      "y": 7,
      "z": 7,
      "name": "Plant_Crop_Mushroom_Block_Green"
    },
    {
      "x": -17,
      "y": 8,
      "z": 7,
      "name": "Plant_Crop_Mushroom_Block_Green"
    },
    {
      "x": -17,
      "y": 1,
      "z": 8,
      "name": "Wood_Beastwood_Bark"
    },
    {
      "x": -17,
      "y": 2,
      "z": 8,
      "name": "Wood_Beastwood_Bark"
    },
    {
      "x": -17,
      "y": 3,
      "z": 8,
      "name": "Wood_Beastwood_Bark"
    },
    {
      "x": -17,
      "y": 4,
      "z": 8,
      "name": "Wood_Beastwood_Bark"
    },
    {
      "x": -17,
      "y": 5,
      "z": 8,
      "name": "Wood_Beastwood_Bark"
    },
    {
      "x": -17,
      "y": 6,
      "z": 8,
      "name": "Wood_Beastwood_Bark"
    },
    {
      "x": -17,
      "y": 7,
      "z": 8,
      "name": "Wood_Beastwood_Bark"
    },
    {
      "x": -17,
      "y": 8,
      "z": 8,
      "name": "Wood_Beastwood_Bark"
    },
    {
      "x": -17,
      "y": 1,
      "z": 9,
      "name": "Wood_Beastwood_Bark"
    },
    {
      "x": -17,
      "y": 2,
      "z": 9,
      "name": "Wood_Beastwood_Bark"
    },
    {
      "x": -17,
      "y": 3,
      "z": 9,
      "name": "Wood_Beastwood_Bark"
    },
    {
      "x": -17,
      "y": 4,
      "z": 9,
      "name": "Wood_Beastwood_Bark"
    },
    {
      "x": -17,
      "y": 5,
      "z": 9,
      "name": "Wood_Beastwood_Bark"
    },
    {
      "x": -17,
      "y": 6,
      "z": 9,
      "name": "Wood_Beastwood_Bark"
    },
    {
      "x": -17,
      "y": 7,
      "z": 9,
      "name": "Wood_Beastwood_Bark"
    },
    {
      "x": -17,
      "y": 8,
      "z": 9,
      "name": "Wood_Beastwood_Bark"
    },
    {
      "x": -17,
      "y": 1,
      "z": 10,
      "name": "Wood_Beastwood_Bark"
    },
    {
      "x": -17,
      "y": 2,
      "z": 10,
      "name": "Wood_Beastwood_Bark"
    },
    {
      "x": -17,
      "y": 3,
      "z": 10,
      "name": "Wood_Beastwood_Bark"
    },
    {
      "x": -17,
      "y": 4,
      "z": 10,
      "name": "Wood_Beastwood_Bark"
    },
    {
      "x": -17,
      "y": 5,
      "z": 10,
      "name": "Wood_Beastwood_Bark"
    },
    {
      "x": -17,
      "y": 6,
      "z": 10,
      "name": "Wood_Beastwood_Bark"
    },
    {
      "x": -17,
      "y": 7,
      "z": 10,
      "name": "Wood_Beastwood_Bark"
    },
    {
      "x": -17,
      "y": 8,
      "z": 10,
      "name": "Wood_Beastwood_Bark"
    },
    {
      "x": -17,
      "y": 1,
      "z": 11,
      "name": "Wood_Beastwood_Bark"
    },
    {
      "x": -17,
      "y": 2,
      "z": 11,
      "name": "Wood_Beastwood_Bark"
    },
    {
      "x": -17,
      "y": 3,
      "z": 11,
      "name": "Wood_Beastwood_Bark"
    },
    {
      "x": -17,
      "y": 4,
      "z": 11,
      "name": "Wood_Beastwood_Bark"
    },
    {
      "x": -17,
      "y": 5,
      "z": 11,
      "name": "Wood_Beastwood_Bark"
    },
    {
      "x": -17,
      "y": 6,
      "z": 11,
      "name": "Wood_Beastwood_Bark"
    },
    {
      "x": -17,
      "y": 7,
      "z": 11,
      "name": "Wood_Beastwood_Bark"
    },
    {
      "x": -17,
      "y": 8,
      "z": 11,
      "name": "Wood_Beastwood_Bark"
    },
    {
      "x": -16,
      "y": 1,
      "z": -12,
      "name": "Wood_Beastwood_Bark"
    },
    {
      "x": -16,
      "y": 2,
      "z": -12,
      "name": "Wood_Beastwood_Bark"
    },
    {
      "x": -16,
      "y": 3,
      "z": -12,
      "name": "Wood_Beastwood_Bark"
    },
    {
      "x": -16,
      "y": 4,
      "z": -12,
      "name": "Wood_Beastwood_Bark"
    },
    {
      "x": -16,
      "y": 5,
      "z": -12,
      "name": "Wood_Beastwood_Bark"
    },
    {
      "x": -16,
      "y": 6,
      "z": -12,
      "name": "Wood_Beastwood_Bark"
    },
    {
      "x": -16,
      "y": 7,
      "z": -12,
      "name": "Wood_Beastwood_Bark"
    },
    {
      "x": -16,
      "y": 8,
      "z": -12,
      "name": "Wood_Beastwood_Bark"
    },
    {
      "x": -16,
      "y": 1,
      "z": -11,
      "name": "Wood_Beastwood_Bark"
    },
    {
      "x": -16,
      "y": 2,
      "z": -11,
      "name": "Wood_Beastwood_Bark"
    },
    {
      "x": -16,
      "y": 3,
      "z": -11,
      "name": "Wood_Beastwood_Bark"
    },
    {
      "x": -16,
      "y": 4,
      "z": -11,
      "name": "Wood_Beastwood_Bark"
    },
    {
      "x": -16,
      "y": 5,
      "z": -11,
      "name": "Wood_Beastwood_Bark"
    },
    {
      "x": -16,
      "y": 6,
      "z": -11,
      "name": "Wood_Beastwood_Bark"
    },
    {
      "x": -16,
      "y": 7,
      "z": -11,
      "name": "Wood_Beastwood_Bark"
    },
    {
      "x": -16,
      "y": 8,
      "z": -11,
      "name": "Wood_Beastwood_Bark"
    },
    {
      "x": -16,
      "y": 1,
      "z": -10,
      "name": "Wood_Beastwood_Bark"
    },
    {
      "x": -16,
      "y": 2,
      "z": -10,
      "name": "Wood_Beastwood_Bark"
    },
    {
      "x": -16,
      "y": 3,
      "z": -10,
      "name": "Wood_Beastwood_Bark"
    },
    {
      "x": -16,
      "y": 4,
      "z": -10,
      "name": "Wood_Beastwood_Bark"
    },
    {
      "x": -16,
      "y": 5,
      "z": -10,
      "name": "Wood_Beastwood_Bark"
    },
    {
      "x": -16,
      "y": 6,
      "z": -10,
      "name": "Wood_Beastwood_Bark"
    },
    {
      "x": -16,
      "y": 7,
      "z": -10,
      "name": "Wood_Beastwood_Bark"
    },
    {
      "x": -16,
      "y": 8,
      "z": -10,
      "name": "Wood_Beastwood_Bark"
    },
    {
      "x": -16,
      "y": 1,
      "z": -9,
      "name": "Plant_Crop_Mushroom_Block_Green"
    },
    {
      "x": -16,
      "y": 2,
      "z": -9,
      "name": "Plant_Crop_Mushroom_Block_Green"
    },
    {
      "x": -16,
      "y": 3,
      "z": -9,
      "name": "Plant_Crop_Mushroom_Block_Green"
    },
    {
      "x": -16,
      "y": 4,
      "z": -9,
      "name": "Plant_Crop_Mushroom_Block_Green"
    },
    {
      "x": -16,
      "y": 5,
      "z": -9,
      "name": "Plant_Crop_Mushroom_Block_Green"
    },
    {
      "x": -16,
      "y": 6,
      "z": -9,
      "name": "Plant_Crop_Mushroom_Block_Green"
    },
    {
      "x": -16,
      "y": 7,
      "z": -9,
      "name": "Plant_Crop_Mushroom_Block_Green"
    },
    {
      "x": -16,
      "y": 8,
      "z": -9,
      "name": "Plant_Crop_Mushroom_Block_Green"
    },
    {
      "x": -16,
      "y": 1,
      "z": -8,
      "name": "Plant_Crop_Mushroom_Block_Green"
    },
    {
      "x": -16,
      "y": 2,
      "z": -8,
      "name": "Plant_Crop_Mushroom_Block_Green"
    },
    {
      "x": -16,
      "y": 3,
      "z": -8,
      "name": "Plant_Crop_Mushroom_Block_Green"
    },
    {
      "x": -16,
      "y": 4,
      "z": -8,
      "name": "Plant_Crop_Mushroom_Block_Green"
    },
    {
      "x": -16,
      "y": 5,
      "z": -8,
      "name": "Plant_Crop_Mushroom_Block_Green"
    },
    {
      "x": -16,
      "y": 6,
      "z": -8,
      "name": "Plant_Crop_Mushroom_Block_Green"
    },
    {
      "x": -16,
      "y": 7,
      "z": -8,
      "name": "Plant_Crop_Mushroom_Block_Green"
    },
    {
      "x": -16,
      "y": 8,
      "z": -8,
      "name": "Plant_Crop_Mushroom_Block_Green"
    },
    {
      "x": -16,
      "y": 1,
      "z": -7,
      "name": "Plant_Crop_Mushroom_Block_Green"
    },
    {
      "x": -16,
      "y": 2,
      "z": -7,
      "name": "Plant_Crop_Mushroom_Block_Green"
    },
    {
      "x": -16,
      "y": 3,
      "z": -7,
      "name": "Plant_Crop_Mushroom_Block_Green"
    },
    {
      "x": -16,
      "y": 4,
      "z": -7,
      "name": "Plant_Crop_Mushroom_Block_Green"
    },
    {
      "x": -16,
      "y": 5,
      "z": -7,
      "name": "Plant_Crop_Mushroom_Block_Green"
    },
    {
      "x": -16,
      "y": 6,
      "z": -7,
      "name": "Plant_Crop_Mushroom_Block_Green"
    },
    {
      "x": -16,
      "y": 7,
      "z": -7,
      "name": "Plant_Crop_Mushroom_Block_Green"
    },
    {
      "x": -16,
      "y": 8,
      "z": -7,
      "name": "Plant_Crop_Mushroom_Block_Green"
    },
    {
      "x": -16,
      "y": 1,
      "z": -6,
      "name": "Plant_Crop_Mushroom_Block_Green"
    },
    {
      "x": -16,
      "y": 2,
      "z": -6,
      "name": "Plant_Crop_Mushroom_Block_Green"
    },
    {
      "x": -16,
      "y": 3,
      "z": -6,
      "name": "Plant_Crop_Mushroom_Block_Green"
    },
    {
      "x": -16,
      "y": 4,
      "z": -6,
      "name": "Plant_Crop_Mushroom_Block_Green"
    },
    {
      "x": -16,
      "y": 5,
      "z": -6,
      "name": "Plant_Crop_Mushroom_Block_Green"
    },
    {
      "x": -16,
      "y": 6,
      "z": -6,
      "name": "Plant_Crop_Mushroom_Block_Green"
    },
    {
      "x": -16,
      "y": 7,
      "z": -6,
      "name": "Plant_Crop_Mushroom_Block_Green"
    },
    {
      "x": -16,
      "y": 8,
      "z": -6,
      "name": "Plant_Crop_Mushroom_Block_Green"
    },
    {
      "x": -16,
      "y": 1,
      "z": -5,
      "name": "Plant_Crop_Mushroom_Block_Green"
    },
    {
      "x": -16,
      "y": 2,
      "z": -5,
      "name": "Plant_Crop_Mushroom_Block_Green"
    },
    {
      "x": -16,
      "y": 3,
      "z": -5,
      "name": "Plant_Crop_Mushroom_Block_Green"
    },
    {
      "x": -16,
      "y": 4,
      "z": -5,
      "name": "Plant_Crop_Mushroom_Block_Green"
    },
    {
      "x": -16,
      "y": 5,
      "z": -5,
      "name": "Plant_Crop_Mushroom_Block_Green"
    },
    {
      "x": -16,
      "y": 6,
      "z": -5,
      "name": "Plant_Crop_Mushroom_Block_Green"
    },
    {
      "x": -16,
      "y": 7,
      "z": -5,
      "name": "Plant_Crop_Mushroom_Block_Green"
    },
    {
      "x": -16,
      "y": 8,
      "z": -5,
      "name": "Plant_Crop_Mushroom_Block_Green"
    },
    {
      "x": -16,
      "y": 1,
      "z": -4,
      "name": "Plant_Crop_Mushroom_Block_Green"
    },
    {
      "x": -16,
      "y": 2,
      "z": -4,
      "name": "Plant_Crop_Mushroom_Block_Green"
    },
    {
      "x": -16,
      "y": 3,
      "z": -4,
      "name": "Plant_Crop_Mushroom_Block_Green"
    },
    {
      "x": -16,
      "y": 4,
      "z": -4,
      "name": "Plant_Crop_Mushroom_Block_Green"
    },
    {
      "x": -16,
      "y": 5,
      "z": -4,
      "name": "Plant_Crop_Mushroom_Block_Green"
    },
    {
      "x": -16,
      "y": 6,
      "z": -4,
      "name": "Plant_Crop_Mushroom_Block_Green"
    },
    {
      "x": -16,
      "y": 7,
      "z": -4,
      "name": "Plant_Crop_Mushroom_Block_Green"
    },
    {
      "x": -16,
      "y": 8,
      "z": -4,
      "name": "Plant_Crop_Mushroom_Block_Green"
    },
    {
      "x": -16,
      "y": 1,
      "z": -3,
      "name": "Wood_Beastwood_Sapwood"
    },
    {
      "x": -16,
      "y": 2,
      "z": -3,
      "name": "Wood_Beastwood_Sapwood"
    },
    {
      "x": -16,
      "y": 3,
      "z": -3,
      "name": "Wood_Beastwood_Sapwood"
    },
    {
      "x": -16,
      "y": 4,
      "z": -3,
      "name": "Wood_Beastwood_Sapwood"
    },
    {
      "x": -16,
      "y": 5,
      "z": -3,
      "name": "Wood_Beastwood_Sapwood"
    },
    {
      "x": -16,
      "y": 6,
      "z": -3,
      "name": "Wood_Beastwood_Sapwood"
    },
    {
      "x": -16,
      "y": 7,
      "z": -3,
      "name": "Wood_Beastwood_Sapwood"
    },
    {
      "x": -16,
      "y": 8,
      "z": -3,
      "name": "Wood_Beastwood_Sapwood"
    },
    {
      "x": -16,
      "y": 1,
      "z": -2,
      "name": "Wood_Beastwood_Sapwood"
    },
    {
      "x": -16,
      "y": 2,
      "z": -2,
      "name": "Wood_Beastwood_Sapwood"
    },
    {
      "x": -16,
      "y": 3,
      "z": -2,
      "name": "Wood_Beastwood_Sapwood"
    },
    {
      "x": -16,
      "y": 4,
      "z": -2,
      "name": "Wood_Beastwood_Sapwood"
    },
    {
      "x": -16,
      "y": 5,
      "z": -2,
      "name": "Wood_Beastwood_Sapwood"
    },
    {
      "x": -16,
      "y": 6,
      "z": -2,
      "name": "Wood_Beastwood_Sapwood"
    },
    {
      "x": -16,
      "y": 7,
      "z": -2,
      "name": "Wood_Beastwood_Sapwood"
    },
    {
      "x": -16,
      "y": 8,
      "z": -2,
      "name": "Wood_Beastwood_Sapwood"
    },
    {
      "x": -16,
      "y": 1,
      "z": -1,
      "name": "Wood_Beastwood_Sapwood"
    },
    {
      "x": -16,
      "y": 2,
      "z": -1,
      "name": "Wood_Beastwood_Sapwood"
    },
    {
      "x": -16,
      "y": 3,
      "z": -1,
      "name": "Wood_Beastwood_Sapwood"
    },
    {
      "x": -16,
      "y": 4,
      "z": -1,
      "name": "Wood_Beastwood_Sapwood"
    },
    {
      "x": -16,
      "y": 5,
      "z": -1,
      "name": "Wood_Beastwood_Sapwood"
    },
    {
      "x": -16,
      "y": 6,
      "z": -1,
      "name": "Wood_Beastwood_Sapwood"
    },
    {
      "x": -16,
      "y": 7,
      "z": -1,
      "name": "Wood_Beastwood_Sapwood"
    },
    {
      "x": -16,
      "y": 8,
      "z": -1,
      "name": "Wood_Beastwood_Sapwood"
    },
    {
      "x": -16,
      "y": 1,
      "z": 0,
      "name": "Wood_Beastwood_Sapwood"
    },
    {
      "x": -16,
      "y": 2,
      "z": 0,
      "name": "Wood_Beastwood_Sapwood"
    },
    {
      "x": -16,
      "y": 3,
      "z": 0,
      "name": "Wood_Beastwood_Sapwood"
    },
    {
      "x": -16,
      "y": 4,
      "z": 0,
      "name": "Wood_Beastwood_Sapwood"
    },
    {
      "x": -16,
      "y": 5,
      "z": 0,
      "name": "Wood_Beastwood_Sapwood"
    },
    {
      "x": -16,
      "y": 6,
      "z": 0,
      "name": "Wood_Beastwood_Sapwood"
    },
    {
      "x": -16,
      "y": 7,
      "z": 0,
      "name": "Wood_Beastwood_Sapwood"
    },
    {
      "x": -16,
      "y": 8,
      "z": 0,
      "name": "Wood_Beastwood_Sapwood"
    },
    {
      "x": -16,
      "y": 1,
      "z": 1,
      "name": "Wood_Beastwood_Sapwood"
    },
    {
      "x": -16,
      "y": 2,
      "z": 1,
      "name": "Wood_Beastwood_Sapwood"
    },
    {
      "x": -16,
      "y": 3,
      "z": 1,
      "name": "Wood_Beastwood_Sapwood"
    },
    {
      "x": -16,
      "y": 4,
      "z": 1,
      "name": "Wood_Beastwood_Sapwood"
    },
    {
      "x": -16,
      "y": 5,
      "z": 1,
      "name": "Wood_Beastwood_Sapwood"
    },
    {
      "x": -16,
      "y": 6,
      "z": 1,
      "name": "Wood_Beastwood_Sapwood"
    },
    {
      "x": -16,
      "y": 7,
      "z": 1,
      "name": "Wood_Beastwood_Sapwood"
    },
    {
      "x": -16,
      "y": 8,
      "z": 1,
      "name": "Wood_Beastwood_Sapwood"
    },
    {
      "x": -16,
      "y": 1,
      "z": 2,
      "name": "Wood_Beastwood_Sapwood"
    },
    {
      "x": -16,
      "y": 2,
      "z": 2,
      "name": "Wood_Beastwood_Sapwood"
    },
    {
      "x": -16,
      "y": 3,
      "z": 2,
      "name": "Wood_Beastwood_Sapwood"
    },
    {
      "x": -16,
      "y": 4,
      "z": 2,
      "name": "Wood_Beastwood_Sapwood"
    },
    {
      "x": -16,
      "y": 5,
      "z": 2,
      "name": "Wood_Beastwood_Sapwood"
    },
    {
      "x": -16,
      "y": 6,
      "z": 2,
      "name": "Wood_Beastwood_Sapwood"
    },
    {
      "x": -16,
      "y": 7,
      "z": 2,
      "name": "Wood_Beastwood_Sapwood"
    },
    {
      "x": -16,
      "y": 8,
      "z": 2,
      "name": "Wood_Beastwood_Sapwood"
    },
    {
      "x": -16,
      "y": 1,
      "z": 3,
      "name": "Wood_Beastwood_Sapwood"
    },
    {
      "x": -16,
      "y": 2,
      "z": 3,
      "name": "Wood_Beastwood_Sapwood"
    },
    {
      "x": -16,
      "y": 3,
      "z": 3,
      "name": "Wood_Beastwood_Sapwood"
    },
    {
      "x": -16,
      "y": 4,
      "z": 3,
      "name": "Wood_Beastwood_Sapwood"
    },
    {
      "x": -16,
      "y": 5,
      "z": 3,
      "name": "Wood_Beastwood_Sapwood"
    },
    {
      "x": -16,
      "y": 6,
      "z": 3,
      "name": "Wood_Beastwood_Sapwood"
    },
    {
      "x": -16,
      "y": 7,
      "z": 3,
      "name": "Wood_Beastwood_Sapwood"
    },
    {
      "x": -16,
      "y": 8,
      "z": 3,
      "name": "Wood_Beastwood_Sapwood"
    },
    {
      "x": -16,
      "y": 1,
      "z": 4,
      "name": "Plant_Crop_Mushroom_Block_Green"
    },
    {
      "x": -16,
      "y": 2,
      "z": 4,
      "name": "Plant_Crop_Mushroom_Block_Green"
    },
    {
      "x": -16,
      "y": 3,
      "z": 4,
      "name": "Plant_Crop_Mushroom_Block_Green"
    },
    {
      "x": -16,
      "y": 4,
      "z": 4,
      "name": "Plant_Crop_Mushroom_Block_Green"
    },
    {
      "x": -16,
      "y": 5,
      "z": 4,
      "name": "Plant_Crop_Mushroom_Block_Green"
    },
    {
      "x": -16,
      "y": 6,
      "z": 4,
      "name": "Plant_Crop_Mushroom_Block_Green"
    },
    {
      "x": -16,
      "y": 7,
      "z": 4,
      "name": "Plant_Crop_Mushroom_Block_Green"
    },
    {
      "x": -16,
      "y": 8,
      "z": 4,
      "name": "Plant_Crop_Mushroom_Block_Green"
    },
    {
      "x": -16,
      "y": 1,
      "z": 5,
      "name": "Plant_Crop_Mushroom_Block_Green"
    },
    {
      "x": -16,
      "y": 2,
      "z": 5,
      "name": "Plant_Crop_Mushroom_Block_Green"
    },
    {
      "x": -16,
      "y": 3,
      "z": 5,
      "name": "Plant_Crop_Mushroom_Block_Green"
    },
    {
      "x": -16,
      "y": 4,
      "z": 5,
      "name": "Plant_Crop_Mushroom_Block_Green"
    },
    {
      "x": -16,
      "y": 5,
      "z": 5,
      "name": "Plant_Crop_Mushroom_Block_Green"
    },
    {
      "x": -16,
      "y": 6,
      "z": 5,
      "name": "Plant_Crop_Mushroom_Block_Green"
    },
    {
      "x": -16,
      "y": 7,
      "z": 5,
      "name": "Plant_Crop_Mushroom_Block_Green"
    },
    {
      "x": -16,
      "y": 8,
      "z": 5,
      "name": "Plant_Crop_Mushroom_Block_Green"
    },
    {
      "x": -16,
      "y": 1,
      "z": 6,
      "name": "Plant_Crop_Mushroom_Block_Green"
    },
    {
      "x": -16,
      "y": 2,
      "z": 6,
      "name": "Plant_Crop_Mushroom_Block_Green"
    },
    {
      "x": -16,
      "y": 3,
      "z": 6,
      "name": "Plant_Crop_Mushroom_Block_Green"
    },
    {
      "x": -16,
      "y": 4,
      "z": 6,
      "name": "Plant_Crop_Mushroom_Block_Green"
    },
    {
      "x": -16,
      "y": 5,
      "z": 6,
      "name": "Plant_Crop_Mushroom_Block_Green"
    },
    {
      "x": -16,
      "y": 6,
      "z": 6,
      "name": "Plant_Crop_Mushroom_Block_Green"
    },
    {
      "x": -16,
      "y": 7,
      "z": 6,
      "name": "Plant_Crop_Mushroom_Block_Green"
    },
    {
      "x": -16,
      "y": 8,
      "z": 6,
      "name": "Plant_Crop_Mushroom_Block_Green"
    },
    {
      "x": -16,
      "y": 1,
      "z": 7,
      "name": "Plant_Crop_Mushroom_Block_Green"
    },
    {
      "x": -16,
      "y": 2,
      "z": 7,
      "name": "Plant_Crop_Mushroom_Block_Green"
    },
    {
      "x": -16,
      "y": 3,
      "z": 7,
      "name": "Plant_Crop_Mushroom_Block_Green"
    },
    {
      "x": -16,
      "y": 4,
      "z": 7,
      "name": "Plant_Crop_Mushroom_Block_Green"
    },
    {
      "x": -16,
      "y": 5,
      "z": 7,
      "name": "Plant_Crop_Mushroom_Block_Green"
    },
    {
      "x": -16,
      "y": 6,
      "z": 7,
      "name": "Plant_Crop_Mushroom_Block_Green"
    },
    {
      "x": -16,
      "y": 7,
      "z": 7,
      "name": "Plant_Crop_Mushroom_Block_Green"
    },
    {
      "x": -16,
      "y": 8,
      "z": 7,
      "name": "Plant_Crop_Mushroom_Block_Green"
    },
    {
      "x": -16,
      "y": 1,
      "z": 8,
      "name": "Plant_Crop_Mushroom_Block_Green"
    },
    {
      "x": -16,
      "y": 2,
      "z": 8,
      "name": "Plant_Crop_Mushroom_Block_Green"
    },
    {
      "x": -16,
      "y": 3,
      "z": 8,
      "name": "Plant_Crop_Mushroom_Block_Green"
    },
    {
      "x": -16,
      "y": 4,
      "z": 8,
      "name": "Plant_Crop_Mushroom_Block_Green"
    },
    {
      "x": -16,
      "y": 5,
      "z": 8,
      "name": "Plant_Crop_Mushroom_Block_Green"
    },
    {
      "x": -16,
      "y": 6,
      "z": 8,
      "name": "Plant_Crop_Mushroom_Block_Green"
    },
    {
      "x": -16,
      "y": 7,
      "z": 8,
      "name": "Plant_Crop_Mushroom_Block_Green"
    },
    {
      "x": -16,
      "y": 8,
      "z": 8,
      "name": "Plant_Crop_Mushroom_Block_Green"
    },
    {
      "x": -16,
      "y": 1,
      "z": 9,
      "name": "Plant_Crop_Mushroom_Block_Green"
    },
    {
      "x": -16,
      "y": 2,
      "z": 9,
      "name": "Plant_Crop_Mushroom_Block_Green"
    },
    {
      "x": -16,
      "y": 3,
      "z": 9,
      "name": "Plant_Crop_Mushroom_Block_Green"
    },
    {
      "x": -16,
      "y": 4,
      "z": 9,
      "name": "Plant_Crop_Mushroom_Block_Green"
    },
    {
      "x": -16,
      "y": 5,
      "z": 9,
      "name": "Plant_Crop_Mushroom_Block_Green"
    },
    {
      "x": -16,
      "y": 6,
      "z": 9,
      "name": "Plant_Crop_Mushroom_Block_Green"
    },
    {
      "x": -16,
      "y": 7,
      "z": 9,
      "name": "Plant_Crop_Mushroom_Block_Green"
    },
    {
      "x": -16,
      "y": 8,
      "z": 9,
      "name": "Plant_Crop_Mushroom_Block_Green"
    },
    {
      "x": -16,
      "y": 1,
      "z": 10,
      "name": "Wood_Beastwood_Bark"
    },
    {
      "x": -16,
      "y": 2,
      "z": 10,
      "name": "Wood_Beastwood_Bark"
    },
    {
      "x": -16,
      "y": 3,
      "z": 10,
      "name": "Wood_Beastwood_Bark"
    },
    {
      "x": -16,
      "y": 4,
      "z": 10,
      "name": "Wood_Beastwood_Bark"
    },
    {
      "x": -16,
      "y": 5,
      "z": 10,
      "name": "Wood_Beastwood_Bark"
    },
    {
      "x": -16,
      "y": 6,
      "z": 10,
      "name": "Wood_Beastwood_Bark"
    },
    {
      "x": -16,
      "y": 7,
      "z": 10,
      "name": "Wood_Beastwood_Bark"
    },
    {
      "x": -16,
      "y": 8,
      "z": 10,
      "name": "Wood_Beastwood_Bark"
    },
    {
      "x": -16,
      "y": 1,
      "z": 11,
      "name": "Wood_Beastwood_Bark"
    },
    {
      "x": -16,
      "y": 2,
      "z": 11,
      "name": "Wood_Beastwood_Bark"
    },
    {
      "x": -16,
      "y": 3,
      "z": 11,
      "name": "Wood_Beastwood_Bark"
    },
    {
      "x": -16,
      "y": 4,
      "z": 11,
      "name": "Wood_Beastwood_Bark"
    },
    {
      "x": -16,
      "y": 5,
      "z": 11,
      "name": "Wood_Beastwood_Bark"
    },
    {
      "x": -16,
      "y": 6,
      "z": 11,
      "name": "Wood_Beastwood_Bark"
    },
    {
      "x": -16,
      "y": 7,
      "z": 11,
      "name": "Wood_Beastwood_Bark"
    },
    {
      "x": -16,
      "y": 8,
      "z": 11,
      "name": "Wood_Beastwood_Bark"
    },
    {
      "x": -16,
      "y": 1,
      "z": 12,
      "name": "Wood_Beastwood_Bark"
    },
    {
      "x": -16,
      "y": 2,
      "z": 12,
      "name": "Wood_Beastwood_Bark"
    },
    {
      "x": -16,
      "y": 3,
      "z": 12,
      "name": "Wood_Beastwood_Bark"
    },
    {
      "x": -16,
      "y": 4,
      "z": 12,
      "name": "Wood_Beastwood_Bark"
    },
    {
      "x": -16,
      "y": 5,
      "z": 12,
      "name": "Wood_Beastwood_Bark"
    },
    {
      "x": -16,
      "y": 6,
      "z": 12,
      "name": "Wood_Beastwood_Bark"
    },
    {
      "x": -16,
      "y": 7,
      "z": 12,
      "name": "Wood_Beastwood_Bark"
    },
    {
      "x": -16,
      "y": 8,
      "z": 12,
      "name": "Wood_Beastwood_Bark"
    },
    {
      "x": -15,
      "y": 1,
      "z": -13,
      "name": "Wood_Beastwood_Bark"
    },
    {
      "x": -15,
      "y": 2,
      "z": -13,
      "name": "Wood_Beastwood_Bark"
    },
    {
      "x": -15,
      "y": 3,
      "z": -13,
      "name": "Wood_Beastwood_Bark"
    },
    {
      "x": -15,
      "y": 4,
      "z": -13,
      "name": "Wood_Beastwood_Bark"
    },
    {
      "x": -15,
      "y": 5,
      "z": -13,
      "name": "Wood_Beastwood_Bark"
    },
    {
      "x": -15,
      "y": 6,
      "z": -13,
      "name": "Wood_Beastwood_Bark"
    },
    {
      "x": -15,
      "y": 7,
      "z": -13,
      "name": "Wood_Beastwood_Bark"
    },
    {
      "x": -15,
      "y": 8,
      "z": -13,
      "name": "Wood_Beastwood_Bark"
    },
    {
      "x": -15,
      "y": 1,
      "z": -12,
      "name": "Wood_Beastwood_Bark"
    },
    {
      "x": -15,
      "y": 2,
      "z": -12,
      "name": "Wood_Beastwood_Bark"
    },
    {
      "x": -15,
      "y": 3,
      "z": -12,
      "name": "Wood_Beastwood_Bark"
    },
    {
      "x": -15,
      "y": 4,
      "z": -12,
      "name": "Wood_Beastwood_Bark"
    },
    {
      "x": -15,
      "y": 5,
      "z": -12,
      "name": "Wood_Beastwood_Bark"
    },
    {
      "x": -15,
      "y": 6,
      "z": -12,
      "name": "Wood_Beastwood_Bark"
    },
    {
      "x": -15,
      "y": 7,
      "z": -12,
      "name": "Wood_Beastwood_Bark"
    },
    {
      "x": -15,
      "y": 8,
      "z": -12,
      "name": "Wood_Beastwood_Bark"
    },
    {
      "x": -15,
      "y": 1,
      "z": -11,
      "name": "Wood_Beastwood_Bark"
    },
    {
      "x": -15,
      "y": 2,
      "z": -11,
      "name": "Wood_Beastwood_Bark"
    },
    {
      "x": -15,
      "y": 3,
      "z": -11,
      "name": "Wood_Beastwood_Bark"
    },
    {
      "x": -15,
      "y": 4,
      "z": -11,
      "name": "Wood_Beastwood_Bark"
    },
    {
      "x": -15,
      "y": 5,
      "z": -11,
      "name": "Wood_Beastwood_Bark"
    },
    {
      "x": -15,
      "y": 6,
      "z": -11,
      "name": "Wood_Beastwood_Bark"
    },
    {
      "x": -15,
      "y": 7,
      "z": -11,
      "name": "Wood_Beastwood_Bark"
    },
    {
      "x": -15,
      "y": 8,
      "z": -11,
      "name": "Wood_Beastwood_Bark"
    },
    {
      "x": -15,
      "y": 1,
      "z": -10,
      "name": "Plant_Crop_Mushroom_Block_Green"
    },
    {
      "x": -15,
      "y": 2,
      "z": -10,
      "name": "Plant_Crop_Mushroom_Block_Green"
    },
    {
      "x": -15,
      "y": 3,
      "z": -10,
      "name": "Plant_Crop_Mushroom_Block_Green"
    },
    {
      "x": -15,
      "y": 4,
      "z": -10,
      "name": "Plant_Crop_Mushroom_Block_Green"
    },
    {
      "x": -15,
      "y": 5,
      "z": -10,
      "name": "Plant_Crop_Mushroom_Block_Green"
    },
    {
      "x": -15,
      "y": 6,
      "z": -10,
      "name": "Plant_Crop_Mushroom_Block_Green"
    },
    {
      "x": -15,
      "y": 7,
      "z": -10,
      "name": "Plant_Crop_Mushroom_Block_Green"
    },
    {
      "x": -15,
      "y": 8,
      "z": -10,
      "name": "Plant_Crop_Mushroom_Block_Green"
    },
    {
      "x": -15,
      "y": 1,
      "z": -9,
      "name": "Plant_Crop_Mushroom_Block_Green"
    },
    {
      "x": -15,
      "y": 2,
      "z": -9,
      "name": "Plant_Crop_Mushroom_Block_Green"
    },
    {
      "x": -15,
      "y": 3,
      "z": -9,
      "name": "Plant_Crop_Mushroom_Block_Green"
    },
    {
      "x": -15,
      "y": 4,
      "z": -9,
      "name": "Plant_Crop_Mushroom_Block_Green"
    },
    {
      "x": -15,
      "y": 5,
      "z": -9,
      "name": "Plant_Crop_Mushroom_Block_Green"
    },
    {
      "x": -15,
      "y": 6,
      "z": -9,
      "name": "Plant_Crop_Mushroom_Block_Green"
    },
    {
      "x": -15,
      "y": 7,
      "z": -9,
      "name": "Plant_Crop_Mushroom_Block_Green"
    },
    {
      "x": -15,
      "y": 8,
      "z": -9,
      "name": "Plant_Crop_Mushroom_Block_Green"
    },
    {
      "x": -15,
      "y": 1,
      "z": -8,
      "name": "Plant_Crop_Mushroom_Block_Green"
    },
    {
      "x": -15,
      "y": 2,
      "z": -8,
      "name": "Plant_Crop_Mushroom_Block_Green"
    },
    {
      "x": -15,
      "y": 3,
      "z": -8,
      "name": "Plant_Crop_Mushroom_Block_Green"
    },
    {
      "x": -15,
      "y": 4,
      "z": -8,
      "name": "Plant_Crop_Mushroom_Block_Green"
    },
    {
      "x": -15,
      "y": 5,
      "z": -8,
      "name": "Plant_Crop_Mushroom_Block_Green"
    },
    {
      "x": -15,
      "y": 6,
      "z": -8,
      "name": "Plant_Crop_Mushroom_Block_Green"
    },
    {
      "x": -15,
      "y": 7,
      "z": -8,
      "name": "Plant_Crop_Mushroom_Block_Green"
    },
    {
      "x": -15,
      "y": 8,
      "z": -8,
      "name": "Plant_Crop_Mushroom_Block_Green"
    },
    {
      "x": -15,
      "y": 1,
      "z": -7,
      "name": "Plant_Crop_Mushroom_Block_Green"
    },
    {
      "x": -15,
      "y": 2,
      "z": -7,
      "name": "Plant_Crop_Mushroom_Block_Green"
    },
    {
      "x": -15,
      "y": 3,
      "z": -7,
      "name": "Plant_Crop_Mushroom_Block_Green"
    },
    {
      "x": -15,
      "y": 4,
      "z": -7,
      "name": "Plant_Crop_Mushroom_Block_Green"
    },
    {
      "x": -15,
      "y": 5,
      "z": -7,
      "name": "Plant_Crop_Mushroom_Block_Green"
    },
    {
      "x": -15,
      "y": 6,
      "z": -7,
      "name": "Plant_Crop_Mushroom_Block_Green"
    },
    {
      "x": -15,
      "y": 7,
      "z": -7,
      "name": "Plant_Crop_Mushroom_Block_Green"
    },
    {
      "x": -15,
      "y": 8,
      "z": -7,
      "name": "Plant_Crop_Mushroom_Block_Green"
    },
    {
      "x": -15,
      "y": 1,
      "z": -6,
      "name": "Wood_Beastwood_Sapwood"
    },
    {
      "x": -15,
      "y": 2,
      "z": -6,
      "name": "Wood_Beastwood_Sapwood"
    },
    {
      "x": -15,
      "y": 3,
      "z": -6,
      "name": "Wood_Beastwood_Sapwood"
    },
    {
      "x": -15,
      "y": 4,
      "z": -6,
      "name": "Wood_Beastwood_Sapwood"
    },
    {
      "x": -15,
      "y": 5,
      "z": -6,
      "name": "Wood_Beastwood_Sapwood"
    },
    {
      "x": -15,
      "y": 6,
      "z": -6,
      "name": "Wood_Beastwood_Sapwood"
    },
    {
      "x": -15,
      "y": 7,
      "z": -6,
      "name": "Wood_Beastwood_Sapwood"
    },
    {
      "x": -15,
      "y": 8,
      "z": -6,
      "name": "Wood_Beastwood_Sapwood"
    },
    {
      "x": -15,
      "y": 1,
      "z": -5,
      "name": "Wood_Beastwood_Sapwood"
    },
    {
      "x": -15,
      "y": 2,
      "z": -5,
      "name": "Wood_Beastwood_Sapwood"
    },
    {
      "x": -15,
      "y": 3,
      "z": -5,
      "name": "Wood_Beastwood_Sapwood"
    },
    {
      "x": -15,
      "y": 4,
      "z": -5,
      "name": "Wood_Beastwood_Sapwood"
    },
    {
      "x": -15,
      "y": 5,
      "z": -5,
      "name": "Wood_Beastwood_Sapwood"
    },
    {
      "x": -15,
      "y": 6,
      "z": -5,
      "name": "Wood_Beastwood_Sapwood"
    },
    {
      "x": -15,
      "y": 7,
      "z": -5,
      "name": "Wood_Beastwood_Sapwood"
    },
    {
      "x": -15,
      "y": 8,
      "z": -5,
      "name": "Wood_Beastwood_Sapwood"
    },
    {
      "x": -15,
      "y": 1,
      "z": -4,
      "name": "Wood_Beastwood_Sapwood"
    },
    {
      "x": -15,
      "y": 2,
      "z": -4,
      "name": "Wood_Beastwood_Sapwood"
    },
    {
      "x": -15,
      "y": 3,
      "z": -4,
      "name": "Wood_Beastwood_Sapwood"
    },
    {
      "x": -15,
      "y": 4,
      "z": -4,
      "name": "Wood_Beastwood_Sapwood"
    },
    {
      "x": -15,
      "y": 5,
      "z": -4,
      "name": "Wood_Beastwood_Sapwood"
    },
    {
      "x": -15,
      "y": 6,
      "z": -4,
      "name": "Wood_Beastwood_Sapwood"
    },
    {
      "x": -15,
      "y": 7,
      "z": -4,
      "name": "Wood_Beastwood_Sapwood"
    },
    {
      "x": -15,
      "y": 8,
      "z": -4,
      "name": "Wood_Beastwood_Sapwood"
    },
    {
      "x": -15,
      "y": 1,
      "z": -3,
      "name": "Wood_Beastwood_Sapwood"
    },
    {
      "x": -15,
      "y": 2,
      "z": -3,
      "name": "Wood_Beastwood_Sapwood"
    },
    {
      "x": -15,
      "y": 3,
      "z": -3,
      "name": "Wood_Beastwood_Sapwood"
    },
    {
      "x": -15,
      "y": 4,
      "z": -3,
      "name": "Wood_Beastwood_Sapwood"
    },
    {
      "x": -15,
      "y": 5,
      "z": -3,
      "name": "Wood_Beastwood_Sapwood"
    },
    {
      "x": -15,
      "y": 6,
      "z": -3,
      "name": "Wood_Beastwood_Sapwood"
    },
    {
      "x": -15,
      "y": 7,
      "z": -3,
      "name": "Wood_Beastwood_Sapwood"
    },
    {
      "x": -15,
      "y": 8,
      "z": -3,
      "name": "Wood_Beastwood_Sapwood"
    },
    {
      "x": -15,
      "y": 1,
      "z": -2,
      "name": "Wood_Beastwood_Sapwood"
    },
    {
      "x": -15,
      "y": 2,
      "z": -2,
      "name": "Wood_Beastwood_Sapwood"
    },
    {
      "x": -15,
      "y": 3,
      "z": -2,
      "name": "Wood_Beastwood_Sapwood"
    },
    {
      "x": -15,
      "y": 4,
      "z": -2,
      "name": "Wood_Beastwood_Sapwood"
    },
    {
      "x": -15,
      "y": 5,
      "z": -2,
      "name": "Wood_Beastwood_Sapwood"
    },
    {
      "x": -15,
      "y": 6,
      "z": -2,
      "name": "Wood_Beastwood_Sapwood"
    },
    {
      "x": -15,
      "y": 7,
      "z": -2,
      "name": "Wood_Beastwood_Sapwood"
    },
    {
      "x": -15,
      "y": 8,
      "z": -2,
      "name": "Wood_Beastwood_Sapwood"
    },
    {
      "x": -15,
      "y": 1,
      "z": -1,
      "name": "Wood_Beastwood_Sapwood"
    },
    {
      "x": -15,
      "y": 2,
      "z": -1,
      "name": "Wood_Beastwood_Sapwood"
    },
    {
      "x": -15,
      "y": 3,
      "z": -1,
      "name": "Wood_Beastwood_Sapwood"
    },
    {
      "x": -15,
      "y": 4,
      "z": -1,
      "name": "Wood_Beastwood_Sapwood"
    },
    {
      "x": -15,
      "y": 5,
      "z": -1,
      "name": "Wood_Beastwood_Sapwood"
    },
    {
      "x": -15,
      "y": 6,
      "z": -1,
      "name": "Wood_Beastwood_Sapwood"
    },
    {
      "x": -15,
      "y": 7,
      "z": -1,
      "name": "Wood_Beastwood_Sapwood"
    },
    {
      "x": -15,
      "y": 8,
      "z": -1,
      "name": "Wood_Beastwood_Sapwood"
    },
    {
      "x": -15,
      "y": 1,
      "z": 0,
      "name": "Wood_Beastwood_Sapwood"
    },
    {
      "x": -15,
      "y": 2,
      "z": 0,
      "name": "Wood_Beastwood_Sapwood"
    },
    {
      "x": -15,
      "y": 3,
      "z": 0,
      "name": "Wood_Beastwood_Sapwood"
    },
    {
      "x": -15,
      "y": 4,
      "z": 0,
      "name": "Wood_Beastwood_Sapwood"
    },
    {
      "x": -15,
      "y": 5,
      "z": 0,
      "name": "Wood_Beastwood_Sapwood"
    },
    {
      "x": -15,
      "y": 6,
      "z": 0,
      "name": "Wood_Beastwood_Sapwood"
    },
    {
      "x": -15,
      "y": 7,
      "z": 0,
      "name": "Wood_Beastwood_Sapwood"
    },
    {
      "x": -15,
      "y": 8,
      "z": 0,
      "name": "Wood_Beastwood_Sapwood"
    },
    {
      "x": -15,
      "y": 1,
      "z": 1,
      "name": "Wood_Beastwood_Sapwood"
    },
    {
      "x": -15,
      "y": 2,
      "z": 1,
      "name": "Wood_Beastwood_Sapwood"
    },
    {
      "x": -15,
      "y": 3,
      "z": 1,
      "name": "Wood_Beastwood_Sapwood"
    },
    {
      "x": -15,
      "y": 4,
      "z": 1,
      "name": "Wood_Beastwood_Sapwood"
    },
    {
      "x": -15,
      "y": 5,
      "z": 1,
      "name": "Wood_Beastwood_Sapwood"
    },
    {
      "x": -15,
      "y": 6,
      "z": 1,
      "name": "Wood_Beastwood_Sapwood"
    },
    {
      "x": -15,
      "y": 7,
      "z": 1,
      "name": "Wood_Beastwood_Sapwood"
    },
    {
      "x": -15,
      "y": 8,
      "z": 1,
      "name": "Wood_Beastwood_Sapwood"
    },
    {
      "x": -15,
      "y": 1,
      "z": 2,
      "name": "Wood_Beastwood_Sapwood"
    },
    {
      "x": -15,
      "y": 2,
      "z": 2,
      "name": "Wood_Beastwood_Sapwood"
    },
    {
      "x": -15,
      "y": 3,
      "z": 2,
      "name": "Wood_Beastwood_Sapwood"
    },
    {
      "x": -15,
      "y": 4,
      "z": 2,
      "name": "Wood_Beastwood_Sapwood"
    },
    {
      "x": -15,
      "y": 5,
      "z": 2,
      "name": "Wood_Beastwood_Sapwood"
    },
    {
      "x": -15,
      "y": 6,
      "z": 2,
      "name": "Wood_Beastwood_Sapwood"
    },
    {
      "x": -15,
      "y": 7,
      "z": 2,
      "name": "Wood_Beastwood_Sapwood"
    },
    {
      "x": -15,
      "y": 8,
      "z": 2,
      "name": "Wood_Beastwood_Sapwood"
    },
    {
      "x": -15,
      "y": 1,
      "z": 3,
      "name": "Wood_Beastwood_Sapwood"
    },
    {
      "x": -15,
      "y": 2,
      "z": 3,
      "name": "Wood_Beastwood_Sapwood"
    },
    {
      "x": -15,
      "y": 3,
      "z": 3,
      "name": "Wood_Beastwood_Sapwood"
    },
    {
      "x": -15,
      "y": 4,
      "z": 3,
      "name": "Wood_Beastwood_Sapwood"
    },
    {
      "x": -15,
      "y": 5,
      "z": 3,
      "name": "Wood_Beastwood_Sapwood"
    },
    {
      "x": -15,
      "y": 6,
      "z": 3,
      "name": "Wood_Beastwood_Sapwood"
    },
    {
      "x": -15,
      "y": 7,
      "z": 3,
      "name": "Wood_Beastwood_Sapwood"
    },
    {
      "x": -15,
      "y": 8,
      "z": 3,
      "name": "Wood_Beastwood_Sapwood"
    },
    {
      "x": -15,
      "y": 1,
      "z": 4,
      "name": "Wood_Beastwood_Sapwood"
    },
    {
      "x": -15,
      "y": 2,
      "z": 4,
      "name": "Wood_Beastwood_Sapwood"
    },
    {
      "x": -15,
      "y": 3,
      "z": 4,
      "name": "Wood_Beastwood_Sapwood"
    },
    {
      "x": -15,
      "y": 4,
      "z": 4,
      "name": "Wood_Beastwood_Sapwood"
    },
    {
      "x": -15,
      "y": 5,
      "z": 4,
      "name": "Wood_Beastwood_Sapwood"
    },
    {
      "x": -15,
      "y": 6,
      "z": 4,
      "name": "Wood_Beastwood_Sapwood"
    },
    {
      "x": -15,
      "y": 7,
      "z": 4,
      "name": "Wood_Beastwood_Sapwood"
    },
    {
      "x": -15,
      "y": 8,
      "z": 4,
      "name": "Wood_Beastwood_Sapwood"
    },
    {
      "x": -15,
      "y": 1,
      "z": 5,
      "name": "Wood_Beastwood_Sapwood"
    },
    {
      "x": -15,
      "y": 2,
      "z": 5,
      "name": "Wood_Beastwood_Sapwood"
    },
    {
      "x": -15,
      "y": 3,
      "z": 5,
      "name": "Wood_Beastwood_Sapwood"
    },
    {
      "x": -15,
      "y": 4,
      "z": 5,
      "name": "Wood_Beastwood_Sapwood"
    },
    {
      "x": -15,
      "y": 5,
      "z": 5,
      "name": "Wood_Beastwood_Sapwood"
    },
    {
      "x": -15,
      "y": 6,
      "z": 5,
      "name": "Wood_Beastwood_Sapwood"
    },
    {
      "x": -15,
      "y": 7,
      "z": 5,
      "name": "Wood_Beastwood_Sapwood"
    },
    {
      "x": -15,
      "y": 8,
      "z": 5,
      "name": "Wood_Beastwood_Sapwood"
    },
    {
      "x": -15,
      "y": 1,
      "z": 6,
      "name": "Wood_Beastwood_Sapwood"
    },
    {
      "x": -15,
      "y": 2,
      "z": 6,
      "name": "Wood_Beastwood_Sapwood"
    },
    {
      "x": -15,
      "y": 3,
      "z": 6,
      "name": "Wood_Beastwood_Sapwood"
    },
    {
      "x": -15,
      "y": 4,
      "z": 6,
      "name": "Wood_Beastwood_Sapwood"
    },
    {
      "x": -15,
      "y": 5,
      "z": 6,
      "name": "Wood_Beastwood_Sapwood"
    },
    {
      "x": -15,
      "y": 6,
      "z": 6,
      "name": "Wood_Beastwood_Sapwood"
    },
    {
      "x": -15,
      "y": 7,
      "z": 6,
      "name": "Wood_Beastwood_Sapwood"
    },
    {
      "x": -15,
      "y": 8,
      "z": 6,
      "name": "Wood_Beastwood_Sapwood"
    },
    {
      "x": -15,
      "y": 1,
      "z": 7,
      "name": "Plant_Crop_Mushroom_Block_Green"
    },
    {
      "x": -15,
      "y": 2,
      "z": 7,
      "name": "Plant_Crop_Mushroom_Block_Green"
    },
    {
      "x": -15,
      "y": 3,
      "z": 7,
      "name": "Plant_Crop_Mushroom_Block_Green"
    },
    {
      "x": -15,
      "y": 4,
      "z": 7,
      "name": "Plant_Crop_Mushroom_Block_Green"
    },
    {
      "x": -15,
      "y": 5,
      "z": 7,
      "name": "Plant_Crop_Mushroom_Block_Green"
    },
    {
      "x": -15,
      "y": 6,
      "z": 7,
      "name": "Plant_Crop_Mushroom_Block_Green"
    },
    {
      "x": -15,
      "y": 7,
      "z": 7,
      "name": "Plant_Crop_Mushroom_Block_Green"
    },
    {
      "x": -15,
      "y": 8,
      "z": 7,
      "name": "Plant_Crop_Mushroom_Block_Green"
    },
    {
      "x": -15,
      "y": 1,
      "z": 8,
      "name": "Plant_Crop_Mushroom_Block_Green"
    },
    {
      "x": -15,
      "y": 2,
      "z": 8,
      "name": "Plant_Crop_Mushroom_Block_Green"
    },
    {
      "x": -15,
      "y": 3,
      "z": 8,
      "name": "Plant_Crop_Mushroom_Block_Green"
    },
    {
      "x": -15,
      "y": 4,
      "z": 8,
      "name": "Plant_Crop_Mushroom_Block_Green"
    },
    {
      "x": -15,
      "y": 5,
      "z": 8,
      "name": "Plant_Crop_Mushroom_Block_Green"
    },
    {
      "x": -15,
      "y": 6,
      "z": 8,
      "name": "Plant_Crop_Mushroom_Block_Green"
    },
    {
      "x": -15,
      "y": 7,
      "z": 8,
      "name": "Plant_Crop_Mushroom_Block_Green"
    },
    {
      "x": -15,
      "y": 8,
      "z": 8,
      "name": "Plant_Crop_Mushroom_Block_Green"
    },
    {
      "x": -15,
      "y": 1,
      "z": 9,
      "name": "Plant_Crop_Mushroom_Block_Green"
    },
    {
      "x": -15,
      "y": 2,
      "z": 9,
      "name": "Plant_Crop_Mushroom_Block_Green"
    },
    {
      "x": -15,
      "y": 3,
      "z": 9,
      "name": "Plant_Crop_Mushroom_Block_Green"
    },
    {
      "x": -15,
      "y": 4,
      "z": 9,
      "name": "Plant_Crop_Mushroom_Block_Green"
    },
    {
      "x": -15,
      "y": 5,
      "z": 9,
      "name": "Plant_Crop_Mushroom_Block_Green"
    },
    {
      "x": -15,
      "y": 6,
      "z": 9,
      "name": "Plant_Crop_Mushroom_Block_Green"
    },
    {
      "x": -15,
      "y": 7,
      "z": 9,
      "name": "Plant_Crop_Mushroom_Block_Green"
    },
    {
      "x": -15,
      "y": 8,
      "z": 9,
      "name": "Plant_Crop_Mushroom_Block_Green"
    },
    {
      "x": -15,
      "y": 1,
      "z": 10,
      "name": "Plant_Crop_Mushroom_Block_Green"
    },
    {
      "x": -15,
      "y": 2,
      "z": 10,
      "name": "Plant_Crop_Mushroom_Block_Green"
    },
    {
      "x": -15,
      "y": 3,
      "z": 10,
      "name": "Plant_Crop_Mushroom_Block_Green"
    },
    {
      "x": -15,
      "y": 4,
      "z": 10,
      "name": "Plant_Crop_Mushroom_Block_Green"
    },
    {
      "x": -15,
      "y": 5,
      "z": 10,
      "name": "Plant_Crop_Mushroom_Block_Green"
    },
    {
      "x": -15,
      "y": 6,
      "z": 10,
      "name": "Plant_Crop_Mushroom_Block_Green"
    },
    {
      "x": -15,
      "y": 7,
      "z": 10,
      "name": "Plant_Crop_Mushroom_Block_Green"
    },
    {
      "x": -15,
      "y": 8,
      "z": 10,
      "name": "Plant_Crop_Mushroom_Block_Green"
    },
    {
      "x": -15,
      "y": 1,
      "z": 11,
      "name": "Wood_Beastwood_Bark"
    },
    {
      "x": -15,
      "y": 2,
      "z": 11,
      "name": "Wood_Beastwood_Bark"
    },
    {
      "x": -15,
      "y": 3,
      "z": 11,
      "name": "Wood_Beastwood_Bark"
    },
    {
      "x": -15,
      "y": 4,
      "z": 11,
      "name": "Wood_Beastwood_Bark"
    },
    {
      "x": -15,
      "y": 5,
      "z": 11,
      "name": "Wood_Beastwood_Bark"
    },
    {
      "x": -15,
      "y": 6,
      "z": 11,
      "name": "Wood_Beastwood_Bark"
    },
    {
      "x": -15,
      "y": 7,
      "z": 11,
      "name": "Wood_Beastwood_Bark"
    },
    {
      "x": -15,
      "y": 8,
      "z": 11,
      "name": "Wood_Beastwood_Bark"
    },
    {
      "x": -15,
      "y": 1,
      "z": 12,
      "name": "Wood_Beastwood_Bark"
    },
    {
      "x": -15,
      "y": 2,
      "z": 12,
      "name": "Wood_Beastwood_Bark"
    },
    {
      "x": -15,
      "y": 3,
      "z": 12,
      "name": "Wood_Beastwood_Bark"
    },
    {
      "x": -15,
      "y": 4,
      "z": 12,
      "name": "Wood_Beastwood_Bark"
    },
    {
      "x": -15,
      "y": 5,
      "z": 12,
      "name": "Wood_Beastwood_Bark"
    },
    {
      "x": -15,
      "y": 6,
      "z": 12,
      "name": "Wood_Beastwood_Bark"
    },
    {
      "x": -15,
      "y": 7,
      "z": 12,
      "name": "Wood_Beastwood_Bark"
    },
    {
      "x": -15,
      "y": 8,
      "z": 12,
      "name": "Wood_Beastwood_Bark"
    },
    {
      "x": -15,
      "y": 1,
      "z": 13,
      "name": "Wood_Beastwood_Bark"
    },
    {
      "x": -15,
      "y": 2,
      "z": 13,
      "name": "Wood_Beastwood_Bark"
    },
    {
      "x": -15,
      "y": 3,
      "z": 13,
      "name": "Wood_Beastwood_Bark"
    },
    {
      "x": -15,
      "y": 4,
      "z": 13,
      "name": "Wood_Beastwood_Bark"
    },
    {
      "x": -15,
      "y": 5,
      "z": 13,
      "name": "Wood_Beastwood_Bark"
    },
    {
      "x": -15,
      "y": 6,
      "z": 13,
      "name": "Wood_Beastwood_Bark"
    },
    {
      "x": -15,
      "y": 7,
      "z": 13,
      "name": "Wood_Beastwood_Bark"
    },
    {
      "x": -15,
      "y": 8,
      "z": 13,
      "name": "Wood_Beastwood_Bark"
    },
    {
      "x": -14,
      "y": 1,
      "z": -14,
      "name": "Wood_Beastwood_Bark"
    },
    {
      "x": -14,
      "y": 2,
      "z": -14,
      "name": "Wood_Beastwood_Bark"
    },
    {
      "x": -14,
      "y": 3,
      "z": -14,
      "name": "Wood_Beastwood_Bark"
    },
    {
      "x": -14,
      "y": 4,
      "z": -14,
      "name": "Wood_Beastwood_Bark"
    },
    {
      "x": -14,
      "y": 5,
      "z": -14,
      "name": "Wood_Beastwood_Bark"
    },
    {
      "x": -14,
      "y": 6,
      "z": -14,
      "name": "Wood_Beastwood_Bark"
    },
    {
      "x": -14,
      "y": 7,
      "z": -14,
      "name": "Wood_Beastwood_Bark"
    },
    {
      "x": -14,
      "y": 8,
      "z": -14,
      "name": "Wood_Beastwood_Bark"
    },
    {
      "x": -14,
      "y": 1,
      "z": -13,
      "name": "Wood_Beastwood_Bark"
    },
    {
      "x": -14,
      "y": 2,
      "z": -13,
      "name": "Wood_Beastwood_Bark"
    },
    {
      "x": -14,
      "y": 3,
      "z": -13,
      "name": "Wood_Beastwood_Bark"
    },
    {
      "x": -14,
      "y": 4,
      "z": -13,
      "name": "Wood_Beastwood_Bark"
    },
    {
      "x": -14,
      "y": 5,
      "z": -13,
      "name": "Wood_Beastwood_Bark"
    },
    {
      "x": -14,
      "y": 6,
      "z": -13,
      "name": "Wood_Beastwood_Bark"
    },
    {
      "x": -14,
      "y": 7,
      "z": -13,
      "name": "Wood_Beastwood_Bark"
    },
    {
      "x": -14,
      "y": 8,
      "z": -13,
      "name": "Wood_Beastwood_Bark"
    },
    {
      "x": -14,
      "y": 1,
      "z": -12,
      "name": "Wood_Beastwood_Bark"
    },
    {
      "x": -14,
      "y": 2,
      "z": -12,
      "name": "Wood_Beastwood_Bark"
    },
    {
      "x": -14,
      "y": 3,
      "z": -12,
      "name": "Wood_Beastwood_Bark"
    },
    {
      "x": -14,
      "y": 4,
      "z": -12,
      "name": "Wood_Beastwood_Bark"
    },
    {
      "x": -14,
      "y": 5,
      "z": -12,
      "name": "Wood_Beastwood_Bark"
    },
    {
      "x": -14,
      "y": 6,
      "z": -12,
      "name": "Wood_Beastwood_Bark"
    },
    {
      "x": -14,
      "y": 7,
      "z": -12,
      "name": "Wood_Beastwood_Bark"
    },
    {
      "x": -14,
      "y": 8,
      "z": -12,
      "name": "Wood_Beastwood_Bark"
    },
    {
      "x": -14,
      "y": 1,
      "z": -11,
      "name": "Plant_Crop_Mushroom_Block_Green"
    },
    {
      "x": -14,
      "y": 2,
      "z": -11,
      "name": "Plant_Crop_Mushroom_Block_Green"
    },
    {
      "x": -14,
      "y": 3,
      "z": -11,
      "name": "Plant_Crop_Mushroom_Block_Green"
    },
    {
      "x": -14,
      "y": 4,
      "z": -11,
      "name": "Plant_Crop_Mushroom_Block_Green"
    },
    {
      "x": -14,
      "y": 5,
      "z": -11,
      "name": "Plant_Crop_Mushroom_Block_Green"
    },
    {
      "x": -14,
      "y": 6,
      "z": -11,
      "name": "Plant_Crop_Mushroom_Block_Green"
    },
    {
      "x": -14,
      "y": 7,
      "z": -11,
      "name": "Plant_Crop_Mushroom_Block_Green"
    },
    {
      "x": -14,
      "y": 8,
      "z": -11,
      "name": "Plant_Crop_Mushroom_Block_Green"
    },
    {
      "x": -14,
      "y": 1,
      "z": -10,
      "name": "Plant_Crop_Mushroom_Block_Green"
    },
    {
      "x": -14,
      "y": 2,
      "z": -10,
      "name": "Plant_Crop_Mushroom_Block_Green"
    },
    {
      "x": -14,
      "y": 3,
      "z": -10,
      "name": "Plant_Crop_Mushroom_Block_Green"
    },
    {
      "x": -14,
      "y": 4,
      "z": -10,
      "name": "Plant_Crop_Mushroom_Block_Green"
    },
    {
      "x": -14,
      "y": 5,
      "z": -10,
      "name": "Plant_Crop_Mushroom_Block_Green"
    },
    {
      "x": -14,
      "y": 6,
      "z": -10,
      "name": "Plant_Crop_Mushroom_Block_Green"
    },
    {
      "x": -14,
      "y": 7,
      "z": -10,
      "name": "Plant_Crop_Mushroom_Block_Green"
    },
    {
      "x": -14,
      "y": 8,
      "z": -10,
      "name": "Plant_Crop_Mushroom_Block_Green"
    },
    {
      "x": -14,
      "y": 1,
      "z": -9,
      "name": "Plant_Crop_Mushroom_Block_Green"
    },
    {
      "x": -14,
      "y": 2,
      "z": -9,
      "name": "Plant_Crop_Mushroom_Block_Green"
    },
    {
      "x": -14,
      "y": 3,
      "z": -9,
      "name": "Plant_Crop_Mushroom_Block_Green"
    },
    {
      "x": -14,
      "y": 4,
      "z": -9,
      "name": "Plant_Crop_Mushroom_Block_Green"
    },
    {
      "x": -14,
      "y": 5,
      "z": -9,
      "name": "Plant_Crop_Mushroom_Block_Green"
    },
    {
      "x": -14,
      "y": 6,
      "z": -9,
      "name": "Plant_Crop_Mushroom_Block_Green"
    },
    {
      "x": -14,
      "y": 7,
      "z": -9,
      "name": "Plant_Crop_Mushroom_Block_Green"
    },
    {
      "x": -14,
      "y": 8,
      "z": -9,
      "name": "Plant_Crop_Mushroom_Block_Green"
    },
    {
      "x": -14,
      "y": 1,
      "z": -8,
      "name": "Wood_Beastwood_Sapwood"
    },
    {
      "x": -14,
      "y": 2,
      "z": -8,
      "name": "Wood_Beastwood_Sapwood"
    },
    {
      "x": -14,
      "y": 3,
      "z": -8,
      "name": "Wood_Beastwood_Sapwood"
    },
    {
      "x": -14,
      "y": 4,
      "z": -8,
      "name": "Wood_Beastwood_Sapwood"
    },
    {
      "x": -14,
      "y": 5,
      "z": -8,
      "name": "Wood_Beastwood_Sapwood"
    },
    {
      "x": -14,
      "y": 6,
      "z": -8,
      "name": "Wood_Beastwood_Sapwood"
    },
    {
      "x": -14,
      "y": 7,
      "z": -8,
      "name": "Wood_Beastwood_Sapwood"
    },
    {
      "x": -14,
      "y": 8,
      "z": -8,
      "name": "Wood_Beastwood_Sapwood"
    },
    {
      "x": -14,
      "y": 1,
      "z": -7,
      "name": "Wood_Beastwood_Sapwood"
    },
    {
      "x": -14,
      "y": 2,
      "z": -7,
      "name": "Wood_Beastwood_Sapwood"
    },
    {
      "x": -14,
      "y": 3,
      "z": -7,
      "name": "Wood_Beastwood_Sapwood"
    },
    {
      "x": -14,
      "y": 4,
      "z": -7,
      "name": "Wood_Beastwood_Sapwood"
    },
    {
      "x": -14,
      "y": 5,
      "z": -7,
      "name": "Wood_Beastwood_Sapwood"
    },
    {
      "x": -14,
      "y": 6,
      "z": -7,
      "name": "Wood_Beastwood_Sapwood"
    },
    {
      "x": -14,
      "y": 7,
      "z": -7,
      "name": "Wood_Beastwood_Sapwood"
    },
    {
      "x": -14,
      "y": 8,
      "z": -7,
      "name": "Wood_Beastwood_Sapwood"
    },
    {
      "x": -14,
      "y": 1,
      "z": -6,
      "name": "Wood_Beastwood_Sapwood"
    },
    {
      "x": -14,
      "y": 2,
      "z": -6,
      "name": "Wood_Beastwood_Sapwood"
    },
    {
      "x": -14,
      "y": 3,
      "z": -6,
      "name": "Wood_Beastwood_Sapwood"
    },
    {
      "x": -14,
      "y": 4,
      "z": -6,
      "name": "Wood_Beastwood_Sapwood"
    },
    {
      "x": -14,
      "y": 5,
      "z": -6,
      "name": "Wood_Beastwood_Sapwood"
    },
    {
      "x": -14,
      "y": 6,
      "z": -6,
      "name": "Wood_Beastwood_Sapwood"
    },
    {
      "x": -14,
