{
  "version": 8,
  "blockIdVersion": 11,
  "anchorX": 0,
  "anchorY": 0,
  "anchorZ": 0,
  "blocks": [
    {
      "x": -2,
      "y": 4,
      "z": -1,
      "name": "Plant_Leaves_Beastwood_Bright"
    },
    {
      "x": -2,
      "y": 3,
      "z": 0,
      "name": "Plant_Leaves_Beastwood_Bright"
    },
    {
      "x": -2,
      "y": 4,
      "z": 0,
      "name": "Plant_Leaves_Beastwood_Bright"
    },
    {
      "x": -2,
      "y": 5,
      "z": 0,
      "name": "Plant_Leaves_Beastwood_Dark"
    },
    {
      "x": -2,
      "y": 4,
      "z": 1,
      "name": "Plant_Leaves_Beastwood_Dark"
    },
    {
      "x": -1,
      "y": 4,
      "z": -2,
      "name": "Plant_Leaves_Beastwood_Bright"
    },
    {
      "x": -1,
      "y": 3,
      "z": -1,
      "name": "Plant_Leaves_Beastwood_Dark"
    },
    {
      "x": -1,
      "y": 4,
      "z": -1,
      "name": "Plant_Leaves_Beastwood_Dark"
    },
    {
      "x": -1,
      "y": 5,
      "z": -1,
      "name": "Plant_Leaves_Beastwood_Dark"
    },
    {
      "x": -1,
      "y": 2,
      "z": 0,
      "name": "Plant_Leaves_Beastwood_Dark"
    },
    {
      "x": -1,
      "y": 3,
      "z": 0,
      "name": "Plant_Leaves_Beastwood_Dark"
    },
    {
      "x": -1,
      "y": 4,
      "z": 0,
      "name": "Plant_Leaves_Beastwood_Dark"
    },
    {
      "x": -1,
      "y": 5,
      "z": 0,
      "name": "Plant_Leaves_Beastwood_Dark"
    },
    {
      "x": -1,
      "y": 6,
      "z": 0,
      "name": "Plant_Leaves_Beastwood_Dark"
    },
    {
      "x": -1,
      "y": 3,
      "z": 1,
      "name": "Plant_Leaves_Beastwood_Dark"
    },
    {
      "x": -1,
      "y": 4,
      "z": 1,
      "name": "Plant_Leaves_Beastwood_Bright"
    },
    {
      "x": -1,
      "y": 5,
      "z": 1,
      "name": "Plant_Leaves_Beastwood_Dark"
    },
    {
      "x": -1,
      "y": 4,
      "z": 2,
      "name": "Plant_Leaves_Beastwood_Bright"
    },
    {
      "x": 0,
      "y": 3,
      "z": -2,
      "name": "Plant_Leaves_Beastwood_Dark"
    },
    {
      "x": 0,
      "y": 4,
      "z": -2,
      "name": "Plant_Leaves_Beastwood_Dark"
    },
    {
      "x": 0,
      "y": 5,
      "z": -2,
      "name": "Plant_Leaves_Beastwood_Dark"
    },
    {
      "x": 0,
      "y": 2,
      "z": -1,
      "name": "Plant_Leaves_Beastwood_Dark"
    },
    {
      "x": 0,
      "y": 3,
      "z": -1,
      "name": "Plant_Leaves_Beastwood_Dark"
    },
    {
      "x": 0,
      "y": 4,
      "z": -1,
      "name": "Plant_Leaves_Beastwood_Bright"
    },
    {
      "x": 0,
      "y": 5,
      "z": -1,
      "name": "Plant_Leaves_Beastwood_Dark"
    },
    {
      "x": 0,
      "y": 6,
      "z": -1,
      "name": "Plant_Leaves_Beastwood_Dark"
    },
    {
      "x": 0,
      "y": 0,
      "z": 0,
      "name": "Wood_Beastwood_Bark"
    },
    {
      "x": 0,
      "y": 1,
      "z": 0,
      "name": "Wood_Redwood_Branch_Long",
      "support": 15
    },
    {
      "x": 0,
      "y": 2,
      "z": 0,
      "name": "Wood_Redwood_Branch_Long",
      "support": 15
    },
    {
      "x": 0,
      "y": 3,
      "z": 0,
      "name": "Wood_Redwood_Branch_Long",
      "support": 15
    },
    {
      "x": 0,
      "y": 4,
      "z": 0,
      "name": "Wood_Redwood_Branch_Long",
      "support": 15
    },
    {
      "x": 0,
      "y": 5,
      "z": 0,
      "name": "Plant_Leaves_Beastwood_Dark"
    },
    {
      "x": 0,
      "y": 6,
      "z": 0,
      "name": "Plant_Leaves_Beastwood_Dark"
    },
    {
      "x": 0,
      "y": 2,
      "z": 1,
      "name": "Plant_Leaves_Beastwood_Dark"
    },
    {
      "x": 0,
      "y": 3,
      "z": 1,
      "name": "Plant_Leaves_Beastwood_Dark"
    },
    {
      "x": 0,
      "y": 4,
      "z": 1,
      "name": "Plant_Leaves_Beastwood_Dark"
    },
    {
      "x": 0,
      "y": 5,
      "z": 1,
      "name": "Plant_Leaves_Beastwood_Dark"
    },
    {
      "x": 0,
      "y": 6,
      "z": 1,
      "name": "Plant_Leaves_Beastwood_Bright"
    },
    {
      "x": 0,
      "y": 3,
      "z": 2,
      "name": "Plant_Leaves_Beastwood_Dark"
    },
    {
      "x": 0,
      "y": 4,
      "z": 2,
      "name": "Plant_Leaves_Beastwood_Bright"
    },
    {
      "x": 0,
      "y": 5,
      "z": 2,
      "name": "Plant_Leaves_Beastwood_Dark"
    },
    {
      "x": 1,
      "y": 4,
      "z": -2,
      "name": "Plant_Leaves_Beastwood_Bright"
    },
    {
      "x": 1,
      "y": 3,
      "z": -1,
      "name": "Plant_Leaves_Beastwood_Dark"
    },
    {
      "x": 1,
      "y": 4,
      "z": -1,
      "name": "Plant_Leaves_Beastwood_Dark"
    },
    {
      "x": 1,
      "y": 5,
      "z": -1,
      "name": "Plant_Leaves_Beastwood_Dark"
    },
    {
      "x": 1,
      "y": 2,
      "z": 0,
      "name": "Plant_Leaves_Beastwood_Dark"
    },
    {
      "x": 1,
      "y": 3,
      "z": 0,
      "name": "Plant_Leaves_Beastwood_Dark"
    },
    {
      "x": 1,
      "y": 4,
      "z": 0,
      "name": "Plant_Leaves_Beastwood_Bright"
    },
    {
      "x": 1,
      "y": 5,
      "z": 0,
      "name": "Plant_Leaves_Beastwood_Bright"
    },
    {
      "x": 1,
      "y": 6,
      "z": 0,
      "name": "Plant_Leaves_Beastwood_Bright"
    },
    {
      "x": 1,
      "y": 3,
      "z": 1,
      "name": "Plant_Leaves_Beastwood_Dark"
    },
    {
      "x": 1,
      "y": 4,
      "z": 1,
      "name": "Plant_Leaves_Beastwood_Dark"
    },
    {
      "x": 1,
      "y": 5,
      "z": 1,
      "name": "Plant_Leaves_Beastwood_Dark"
    },
    {
      "x": 1,
      "y": 4,
      "z": 2,
      "name": "Plant_Leaves_Beastwood_Dark"
    },
    {
      "x": 2,
      "y": 4,
      "z": -1,
      "name": "Plant_Leaves_Beastwood_Dark"
    },
    {
      "x": 2,
      "y": 3,
      "z": 0,
      "name": "Plant_Leaves_Beastwood_Dark"
    },
    {
      "x": 2,
      "y": 4,
      "z": 0,
      "name": "Plant_Leaves_Beastwood_Dark"
    },
    {
      "x": 2,
      "y": 5,
      "z": 0,
      "name": "Plant_Leaves_Beastwood_Dark"
    },
    {
      "x": 2,
      "y": 4,
      "z": 1,
      "name": "Plant_Leaves_Beastwood_Dark"
    }
  ]
}