{
  "version": 8,
  "blockIdVersion": 11,
  "anchorX": 0,
  "anchorY": 0,
  "anchorZ": 0,
  "blocks": [
    {
      "x": -6,
      "y": 21,
      "z": -2,
      "name": "Empty"
    },
    {
      "x": -6,
      "y": 20,
      "z": -1,
      "name": "Empty"
    },
    {
      "x": -6,
      "y": 21,
      "z": -1,
      "name": "Empty"
    },
    {
      "x": -6,
      "y": 22,
      "z": -1,
      "name": "Empty"
    },
    {
      "x": -6,
      "y": 24,
      "z": -1,
      "name": "Empty"
    },
    {
      "x": -6,
      "y": 21,
      "z": 0,
      "name": "Empty"
    },
    {
      "x": -6,
      "y": 23,
      "z": 0,
      "name": "Empty"
    },
    {
      "x": -6,
      "y": 24,
      "z": 0,
      "name": "Empty"
    },
    {
      "x": -6,
      "y": 25,
      "z": 0,
      "name": "Empty"
    },
    {
      "x": -6,
      "y": 22,
      "z": 1,
      "name": "Empty"
    },
    {
      "x": -6,
      "y": 23,
      "z": 1,
      "name": "Empty"
    },
    {
      "x": -6,
      "y": 24,
      "z": 1,
      "name": "Empty"
    },
    {
      "x": -6,
      "y": 22,
      "z": 2,
      "name": "Empty"
    },
    {
      "x": -6,
      "y": 23,
      "z": 2,
      "name": "Empty"
    },
    {
      "x": -6,
      "y": 21,
      "z": 3,
      "name": "Empty"
    },
    {
      "x": -6,
      "y": 22,
      "z": 3,
      "name": "Empty"
    },
    {
      "x": -6,
      "y": 23,
      "z": 3,
      "name": "Empty"
    },
    {
      "x": -6,
      "y": 22,
      "z": 4,
      "name": "Empty"
    },
    {
      "x": -5,
      "y": 21,
      "z": -3,
      "name": "Empty"
    },
    {
      "x": -5,
      "y": 23,
      "z": -3,
      "name": "Empty"
    },
    {
      "x": -5,
      "y": 20,
      "z": -2,
      "name": "Empty"
    },
    {
      "x": -5,
      "y": 21,
      "z": -2,
      "name": "Empty"
    },
    {
      "x": -5,
      "y": 22,
      "z": -2,
      "name": "Empty"
    },
    {
      "x": -5,
      "y": 23,
      "z": -2,
      "name": "Empty"
    },
    {
      "x": -5,
      "y": 24,
      "z": -2,
      "name": "Empty"
    },
    {
      "x": -5,
      "y": 18,
      "z": -1,
      "name": "Empty"
    },
    {
      "x": -5,
      "y": 19,
      "z": -1,
      "name": "Empty"
    },
    {
      "x": -5,
      "y": 20,
      "z": -1,
      "name": "Empty"
    },
    {
      "x": -5,
      "y": 21,
      "z": -1,
      "name": "Empty"
    },
    {
      "x": -5,
      "y": 22,
      "z": -1,
      "name": "Empty"
    },
    {
      "x": -5,
      "y": 23,
      "z": -1,
      "name": "Empty"
    },
    {
      "x": -5,
      "y": 24,
      "z": -1,
      "name": "Empty"
    },
    {
      "x": -5,
      "y": 25,
      "z": -1,
      "name": "Empty"
    },
    {
      "x": -5,
      "y": 17,
      "z": 0,
      "name": "Empty"
    },
    {
      "x": -5,
      "y": 18,
      "z": 0,
      "name": "Empty"
    },
    {
      "x": -5,
      "y": 19,
      "z": 0,
      "name": "Empty"
    },
    {
      "x": -5,
      "y": 20,
      "z": 0,
      "name": "Empty"
    },
    {
      "x": -5,
      "y": 21,
      "z": 0,
      "name": "Empty"
    },
    {
      "x": -5,
      "y": 22,
      "z": 0,
      "name": "Empty"
    },
    {
      "x": -5,
      "y": 23,
      "z": 0,
      "name": "Empty"
    },
    {
      "x": -5,
      "y": 24,
      "z": 0,
      "name": "Empty"
    },
    {
      "x": -5,
      "y": 25,
      "z": 0,
      "name": "Empty"
    },
    {
      "x": -5,
      "y": 26,
      "z": 0,
      "name": "Empty"
    },
    {
      "x": -5,
      "y": 18,
      "z": 1,
      "name": "Empty"
    },
    {
      "x": -5,
      "y": 21,
      "z": 1,
      "name": "Empty"
    },
    {
      "x": -5,
      "y": 22,
      "z": 1,
      "name": "Empty"
    },
    {
      "x": -5,
      "y": 23,
      "z": 1,
      "name": "Empty"
    },
    {
      "x": -5,
      "y": 24,
      "z": 1,
      "name": "Empty"
    },
    {
      "x": -5,
      "y": 25,
      "z": 1,
      "name": "Empty"
    },
    {
      "x": -5,
      "y": 21,
      "z": 2,
      "name": "Empty"
    },
    {
      "x": -5,
      "y": 22,
      "z": 2,
      "name": "Empty"
    },
    {
      "x": -5,
      "y": 23,
      "z": 2,
      "name": "Empty"
    },
    {
      "x": -5,
      "y": 24,
      "z": 2,
      "name": "Empty"
    },
    {
      "x": -5,
      "y": 25,
      "z": 2,
      "name": "Empty"
    },
    {
      "x": -5,
      "y": 26,
      "z": 2,
      "name": "Empty"
    },
    {
      "x": -5,
      "y": 20,
      "z": 3,
      "name": "Empty"
    },
    {
      "x": -5,
      "y": 21,
      "z": 3,
      "name": "Empty"
    },
    {
      "x": -5,
      "y": 22,
      "z": 3,
      "name": "Empty"
    },
    {
      "x": -5,
      "y": 23,
      "z": 3,
      "name": "Empty"
    },
    {
      "x": -5,
      "y": 24,
      "z": 3,
      "name": "Empty"
    },
    {
      "x": -5,
      "y": 25,
      "z": 3,
      "name": "Empty"
    },
    {
      "x": -5,
      "y": 26,
      "z": 3,
      "name": "Empty"
    },
    {
      "x": -5,
      "y": 21,
      "z": 4,
      "name": "Empty"
    },
    {
      "x": -5,
      "y": 22,
      "z": 4,
      "name": "Empty"
    },
    {
      "x": -5,
      "y": 23,
      "z": 4,
      "name": "Empty"
    },
    {
      "x": -5,
      "y": 25,
      "z": 4,
      "name": "Empty"
    },
    {
      "x": -5,
      "y": 22,
      "z": 5,
      "name": "Empty"
    },
    {
      "x": -4,
      "y": 12,
      "z": -11,
      "name": "Empty"
    },
    {
      "x": -4,
      "y": 11,
      "z": -10,
      "name": "Empty"
    },
    {
      "x": -4,
      "y": 12,
      "z": -10,
      "name": "Empty"
    },
    {
      "x": -4,
      "y": 13,
      "z": -10,
      "name": "Empty"
    },
    {
      "x": -4,
      "y": 12,
      "z": -9,
      "name": "Empty"
    },
    {
      "x": -4,
      "y": 10,
      "z": -8,
      "name": "Empty"
    },
    {
      "x": -4,
      "y": 13,
      "z": -8,
      "name": "Empty"
    },
    {
      "x": -4,
      "y": 9,
      "z": -7,
      "name": "Empty"
    },
    {
      "x": -4,
      "y": 10,
      "z": -7,
      "name": "Empty"
    },
    {
      "x": -4,
      "y": 11,
      "z": -7,
      "name": "Empty"
    },
    {
      "x": -4,
      "y": 12,
      "z": -7,
      "name": "Empty"
    },
    {
      "x": -4,
      "y": 13,
      "z": -7,
      "name": "Empty"
    },
    {
      "x": -4,
      "y": 14,
      "z": -7,
      "name": "Empty"
    },
    {
      "x": -4,
      "y": 10,
      "z": -6,
      "name": "Empty"
    },
    {
      "x": -4,
      "y": 13,
      "z": -6,
      "name": "Empty"
    },
    {
      "x": -4,
      "y": 20,
      "z": -4,
      "name": "Empty"
    },
    {
      "x": -4,
      "y": 23,
      "z": -4,
      "name": "Empty"
    },
    {
      "x": -4,
      "y": 19,
      "z": -3,
      "name": "Empty"
    },
    {
      "x": -4,
      "y": 20,
      "z": -3,
      "name": "Empty"
    },
    {
      "x": -4,
      "y": 21,
      "z": -3,
      "name": "Empty"
    },
    {
      "x": -4,
      "y": 22,
      "z": -3,
      "name": "Empty"
    },
    {
      "x": -4,
      "y": 23,
      "z": -3,
      "name": "Empty"
    },
    {
      "x": -4,
      "y": 24,
      "z": -3,
      "name": "Empty"
    },
    {
      "x": -4,
      "y": 18,
      "z": -2,
      "name": "Empty"
    },
    {
      "x": -4,
      "y": 19,
      "z": -2,
      "name": "Empty"
    },
    {
      "x": -4,
      "y": 20,
      "z": -2,
      "name": "Empty"
    },
    {
      "x": -4,
      "y": 21,
      "z": -2,
      "name": "Empty"
    },
    {
      "x": -4,
      "y": 22,
      "z": -2,
      "name": "Plant_Leaves_Beastwood_Dark"
    },
    {
      "x": -4,
      "y": 23,
      "z": -2,
      "name": "Empty"
    },
    {
      "x": -4,
      "y": 24,
      "z": -2,
      "name": "Empty"
    },
    {
      "x": -4,
      "y": 25,
      "z": -2,
      "name": "Empty"
    },
    {
      "x": -4,
      "y": 17,
      "z": -1,
      "name": "Empty"
    },
    {
      "x": -4,
      "y": 18,
      "z": -1,
      "name": "Empty"
    },
    {
      "x": -4,
      "y": 19,
      "z": -1,
      "name": "Empty"
    },
    {
      "x": -4,
      "y": 20,
      "z": -1,
      "name": "Plant_Leaves_Beastwood_Bright"
    },
    {
      "x": -4,
      "y": 21,
      "z": -1,
      "name": "Plant_Leaves_Beastwood_Dark"
    },
    {
      "x": -4,
      "y": 22,
      "z": -1,
      "name": "Plant_Leaves_Beastwood_Dark"
    },
    {
      "x": -4,
      "y": 23,
      "z": -1,
      "name": "Plant_Leaves_Beastwood_Dark"
    },
    {
      "x": -4,
      "y": 24,
      "z": -1,
      "name": "Empty"
    },
    {
      "x": -4,
      "y": 25,
      "z": -1,
      "name": "Empty"
    },
    {
      "x": -4,
      "y": 26,
      "z": -1,
      "name": "Empty"
    },
    {
      "x": -4,
      "y": 16,
      "z": 0,
      "name": "Empty"
    },
    {
      "x": -4,
      "y": 17,
      "z": 0,
      "name": "Empty"
    },
    {
      "x": -4,
      "y": 18,
      "z": 0,
      "name": "Empty"
    },
    {
      "x": -4,
      "y": 19,
      "z": 0,
      "name": "Plant_Leaves_Beastwood_Dark"
    },
    {
      "x": -4,
      "y": 20,
      "z": 0,
      "name": "Plant_Leaves_Beastwood_Bright"
    },
    {
      "x": -4,
      "y": 21,
      "z": 0,
      "name": "Plant_Leaves_Beastwood_Dark"
    },
    {
      "x": -4,
      "y": 22,
      "z": 0,
      "name": "Plant_Leaves_Beastwood_Dark"
    },
    {
      "x": -4,
      "y": 23,
      "z": 0,
      "name": "Plant_Leaves_Beastwood_Dark"
    },
    {
      "x": -4,
      "y": 24,
      "z": 0,
      "name": "Plant_Leaves_Beastwood_Dark"
    },
    {
      "x": -4,
      "y": 25,
      "z": 0,
      "name": "Empty"
    },
    {
      "x": -4,
      "y": 26,
      "z": 0,
      "name": "Empty"
    },
    {
      "x": -4,
      "y": 17,
      "z": 1,
      "name": "Empty"
    },
    {
      "x": -4,
      "y": 18,
      "z": 1,
      "name": "Empty"
    },
    {
      "x": -4,
      "y": 19,
      "z": 1,
      "name": "Empty"
    },
    {
      "x": -4,
      "y": 20,
      "z": 1,
      "name": "Plant_Leaves_Beastwood_Dark"
    },
    {
      "x": -4,
      "y": 21,
      "z": 1,
      "name": "Plant_Leaves_Beastwood_Dark"
    },
    {
      "x": -4,
      "y": 22,
      "z": 1,
      "name": "Plant_Leaves_Beastwood_Bright"
    },
    {
      "x": -4,
      "y": 23,
      "z": 1,
      "name": "Plant_Leaves_Beastwood_Dark"
    },
    {
      "x": -4,
      "y": 24,
      "z": 1,
      "name": "Empty"
    },
    {
      "x": -4,
      "y": 25,
      "z": 1,
      "name": "Empty"
    },
    {
      "x": -4,
      "y": 26,
      "z": 1,
      "name": "Empty"
    },
    {
      "x": -4,
      "y": 18,
      "z": 2,
      "name": "Empty"
    },
    {
      "x": -4,
      "y": 19,
      "z": 2,
      "name": "Empty"
    },
    {
      "x": -4,
      "y": 20,
      "z": 2,
      "name": "Empty"
    },
    {
      "x": -4,
      "y": 21,
      "z": 2,
      "name": "Empty"
    },
    {
      "x": -4,
      "y": 22,
      "z": 2,
      "name": "Plant_Leaves_Beastwood_Dark"
    },
    {
      "x": -4,
      "y": 23,
      "z": 2,
      "name": "Plant_Leaves_Beastwood_Dark"
    },
    {
      "x": -4,
      "y": 24,
      "z": 2,
      "name": "Empty"
    },
    {
      "x": -4,
      "y": 25,
      "z": 2,
      "name": "Empty"
    },
    {
      "x": -4,
      "y": 26,
      "z": 2,
      "name": "Empty"
    },
    {
      "x": -4,
      "y": 27,
      "z": 2,
      "name": "Empty"
    },
    {
      "x": -4,
      "y": 19,
      "z": 3,
      "name": "Empty"
    },
    {
      "x": -4,
      "y": 20,
      "z": 3,
      "name": "Empty"
    },
    {
      "x": -4,
      "y": 21,
      "z": 3,
      "name": "Empty"
    },
    {
      "x": -4,
      "y": 22,
      "z": 3,
      "name": "Plant_Leaves_Beastwood_Dark"
    },
    {
      "x": -4,
      "y": 23,
      "z": 3,
      "name": "Plant_Leaves_Beastwood_Dark"
    },
    {
      "x": -4,
      "y": 24,
      "z": 3,
      "name": "Plant_Leaves_Beastwood_Bright"
    },
    {
      "x": -4,
      "y": 25,
      "z": 3,
      "name": "Empty"
    },
    {
      "x": -4,
      "y": 26,
      "z": 3,
      "name": "Empty"
    },
    {
      "x": -4,
      "y": 27,
      "z": 3,
      "name": "Empty"
    },
    {
      "x": -4,
      "y": 20,
      "z": 4,
      "name": "Empty"
    },
    {
      "x": -4,
      "y": 21,
      "z": 4,
      "name": "Empty"
    },
    {
      "x": -4,
      "y": 22,
      "z": 4,
      "name": "Empty"
    },
    {
      "x": -4,
      "y": 23,
      "z": 4,
      "name": "Plant_Leaves_Beastwood_Dark"
    },
    {
      "x": -4,
      "y": 24,
      "z": 4,
      "name": "Empty"
    },
    {
      "x": -4,
      "y": 25,
      "z": 4,
      "name": "Empty"
    },
    {
      "x": -4,
      "y": 26,
      "z": 4,
      "name": "Empty"
    },
    {
      "x": -4,
      "y": 21,
      "z": 5,
      "name": "Empty"
    },
    {
      "x": -4,
      "y": 22,
      "z": 5,
      "name": "Empty"
    },
    {
      "x": -4,
      "y": 23,
      "z": 5,
      "name": "Empty"
    },
    {
      "x": -4,
      "y": 25,
      "z": 5,
      "name": "Empty"
    },
    {
      "x": -4,
      "y": 22,
      "z": 6,
      "name": "Empty"
    },
    {
      "x": -3,
      "y": 12,
      "z": -12,
      "name": "Empty"
    },
    {
      "x": -3,
      "y": 11,
      "z": -11,
      "name": "Empty"
    },
    {
      "x": -3,
      "y": 12,
      "z": -11,
      "name": "Empty"
    },
    {
      "x": -3,
      "y": 13,
      "z": -11,
      "name": "Empty"
    },
    {
      "x": -3,
      "y": 10,
      "z": -10,
      "name": "Empty"
    },
    {
      "x": -3,
      "y": 11,
      "z": -10,
      "name": "Empty"
    },
    {
      "x": -3,
      "y": 12,
      "z": -10,
      "name": "Empty"
    },
    {
      "x": -3,
      "y": 13,
      "z": -10,
      "name": "Empty"
    },
    {
      "x": -3,
      "y": 14,
      "z": -10,
      "name": "Empty"
    },
    {
      "x": -3,
      "y": 10,
      "z": -9,
      "name": "Empty"
    },
    {
      "x": -3,
      "y": 11,
      "z": -9,
      "name": "Empty"
    },
    {
      "x": -3,
      "y": 12,
      "z": -9,
      "name": "Empty"
    },
    {
      "x": -3,
      "y": 13,
      "z": -9,
      "name": "Empty"
    },
    {
      "x": -3,
      "y": 9,
      "z": -8,
      "name": "Empty"
    },
    {
      "x": -3,
      "y": 10,
      "z": -8,
      "name": "Empty"
    },
    {
      "x": -3,
      "y": 11,
      "z": -8,
      "name": "Empty"
    },
    {
      "x": -3,
      "y": 12,
      "z": -8,
      "name": "Empty"
    },
    {
      "x": -3,
      "y": 13,
      "z": -8,
      "name": "Empty"
    },
    {
      "x": -3,
      "y": 14,
      "z": -8,
      "name": "Empty"
    },
    {
      "x": -3,
      "y": 8,
      "z": -7,
      "name": "Empty"
    },
    {
      "x": -3,
      "y": 9,
      "z": -7,
      "name": "Empty"
    },
    {
      "x": -3,
      "y": 10,
      "z": -7,
      "name": "Empty"
    },
    {
      "x": -3,
      "y": 11,
      "z": -7,
      "name": "Empty"
    },
    {
      "x": -3,
      "y": 12,
      "z": -7,
      "name": "Empty"
    },
    {
      "x": -3,
      "y": 13,
      "z": -7,
      "name": "Empty"
    },
    {
      "x": -3,
      "y": 14,
      "z": -7,
      "name": "Empty"
    },
    {
      "x": -3,
      "y": 15,
      "z": -7,
      "name": "Empty"
    },
    {
      "x": -3,
      "y": 9,
      "z": -6,
      "name": "Empty"
    },
    {
      "x": -3,
      "y": 10,
      "z": -6,
      "name": "Plant_Leaves_Beastwood_Dark"
    },
    {
      "x": -3,
      "y": 11,
      "z": -6,
      "name": "Empty"
    },
    {
      "x": -3,
      "y": 12,
      "z": -6,
      "name": "Empty"
    },
    {
      "x": -3,
      "y": 13,
      "z": -6,
      "name": "Empty"
    },
    {
      "x": -3,
      "y": 14,
      "z": -6,
      "name": "Empty"
    },
    {
      "x": -3,
      "y": 9,
      "z": -5,
      "name": "Plant_Leaves_Beastwood_Bright"
    },
    {
      "x": -3,
      "y": 10,
      "z": -5,
      "name": "Plant_Leaves_Beastwood_Dark"
    },
    {
      "x": -3,
      "y": 11,
      "z": -5,
      "name": "Plant_Leaves_Beastwood_Dark"
    },
    {
      "x": -3,
      "y": 13,
      "z": -5,
      "name": "Empty"
    },
    {
      "x": -3,
      "y": 20,
      "z": -5,
      "name": "Empty"
    },
    {
      "x": -3,
      "y": 10,
      "z": -4,
      "name": "Plant_Leaves_Beastwood_Dark"
    },
    {
      "x": -3,
      "y": 19,
      "z": -4,
      "name": "Empty"
    },
    {
      "x": -3,
      "y": 20,
      "z": -4,
      "name": "Empty"
    },
    {
      "x": -3,
      "y": 21,
      "z": -4,
      "name": "Empty"
    },
    {
      "x": -3,
      "y": 22,
      "z": -4,
      "name": "Empty"
    },
    {
      "x": -3,
      "y": 23,
      "z": -4,
      "name": "Empty"
    },
    {
      "x": -3,
      "y": 24,
      "z": -4,
      "name": "Empty"
    },
    {
      "x": -3,
      "y": 18,
      "z": -3,
      "name": "Empty"
    },
    {
      "x": -3,
      "y": 19,
      "z": -3,
      "name": "Empty"
    },
    {
      "x": -3,
      "y": 20,
      "z": -3,
      "name": "Empty"
    },
    {
      "x": -3,
      "y": 21,
      "z": -3,
      "name": "Empty"
    },
    {
      "x": -3,
      "y": 22,
      "z": -3,
      "name": "Plant_Leaves_Beastwood_Dark"
    },
    {
      "x": -3,
      "y": 23,
      "z": -3,
      "name": "Empty"
    },
    {
      "x": -3,
      "y": 24,
      "z": -3,
      "name": "Empty"
    },
    {
      "x": -3,
      "y": 25,
      "z": -3,
      "name": "Empty"
    },
    {
      "x": -3,
      "y": 17,
      "z": -2,
      "name": "Empty"
    },
    {
      "x": -3,
      "y": 18,
      "z": -2,
      "name": "Empty"
    },
    {
      "x": -3,
      "y": 19,
      "z": -2,
      "name": "Empty"
    },
    {
      "x": -3,
      "y": 20,
      "z": -2,
      "name": "Plant_Leaves_Beastwood_Bright"
    },
    {
      "x": -3,
      "y": 21,
      "z": -2,
      "name": "Plant_Leaves_Beastwood_Dark"
    },
    {
      "x": -3,
      "y": 22,
      "z": -2,
      "name": "Plant_Leaves_Beastwood_Bright"
    },
    {
      "x": -3,
      "y": 23,
      "z": -2,
      "name": "Plant_Leaves_Beastwood_Dark"
    },
    {
      "x": -3,
      "y": 24,
      "z": -2,
      "name": "Empty"
    },
    {
      "x": -3,
      "y": 25,
      "z": -2,
      "name": "Empty"
    },
    {
      "x": -3,
      "y": 16,
      "z": -1,
      "name": "Empty"
    },
    {
      "x": -3,
      "y": 17,
      "z": -1,
      "name": "Empty"
    },
    {
      "x": -3,
      "y": 18,
      "z": -1,
      "name": "Empty"
    },
    {
      "x": -3,
      "y": 19,
      "z": -1,
      "name": "Plant_Leaves_Beastwood_Dark"
    },
    {
      "x": -3,
      "y": 20,
      "z": -1,
      "name": "Plant_Leaves_Beastwood_Dark"
    },
    {
      "x": -3,
      "y": 21,
      "z": -1,
      "name": "Plant_Leaves_Beastwood_Bright"
    },
    {
      "x": -3,
      "y": 22,
      "z": -1,
      "name": "Plant_Leaves_Beastwood_Bright"
    },
    {
      "x": -3,
      "y": 23,
      "z": -1,
      "name": "Plant_Leaves_Beastwood_Dark"
    },
    {
      "x": -3,
      "y": 24,
      "z": -1,
      "name": "Plant_Leaves_Beastwood_Dark"
    },
    {
      "x": -3,
      "y": 25,
      "z": -1,
      "name": "Empty"
    },
    {
      "x": -3,
      "y": 0,
      "z": 0,
      "name": "Wood_Redwood_Trunk_Full",
      "support": 15
    },
    {
      "x": -3,
      "y": 1,
      "z": 0,
      "name": "Wood_Redwood_Trunk_Full",
      "support": 15
    },
    {
      "x": -3,
      "y": 2,
      "z": 0,
      "name": "Wood_Redwood_Trunk_Full",
      "support": 15
    },
    {
      "x": -3,
      "y": 3,
      "z": 0,
      "name": "Wood_Redwood_Trunk_Full",
      "support": 15
    },
    {
      "x": -3,
      "y": 4,
      "z": 0,
      "name": "Wood_Redwood_Trunk_Full",
      "support": 15
    },
    {
      "x": -3,
      "y": 5,
      "z": 0,
      "name": "Wood_Redwood_Trunk_Full",
      "support": 15
    },
    {
      "x": -3,
      "y": 6,
      "z": 0,
      "name": "Wood_Redwood_Trunk_Full",
      "support": 15
    },
    {
      "x": -3,
      "y": 7,
      "z": 0,
      "name": "Wood_Redwood_Trunk_Full",
      "support": 15
    },
    {
      "x": -3,
      "y": 16,
      "z": 0,
      "name": "Empty"
    },
    {
      "x": -3,
      "y": 17,
      "z": 0,
      "name": "Empty"
    },
    {
      "x": -3,
      "y": 18,
      "z": 0,
      "name": "Plant_Leaves_Beastwood_Dark"
    },
    {
      "x": -3,
      "y": 19,
      "z": 0,
      "name": "Plant_Leaves_Beastwood_Dark"
    },
    {
      "x": -3,
      "y": 20,
      "z": 0,
      "name": "Plant_Leaves_Beastwood_Bright"
    },
    {
      "x": -3,
      "y": 21,
      "z": 0,
      "name": "Plant_Leaves_Beastwood_Dark"
    },
    {
      "x": -3,
      "y": 22,
      "z": 0,
      "name": "Plant_Leaves_Beastwood_Bright"
    },
    {
      "x": -3,
      "y": 23,
      "z": 0,
      "name": "Plant_Leaves_Beastwood_Dark"
    },
    {
      "x": -3,
      "y": 24,
      "z": 0,
      "name": "Plant_Leaves_Beastwood_Dark"
    },
    {
      "x": -3,
      "y": 25,
      "z": 0,
      "name": "Empty"
    },
    {
      "x": -3,
      "y": 26,
      "z": 0,
      "name": "Empty"
    },
    {
      "x": -3,
      "y": 0,
      "z": 1,
      "name": "Wood_Redwood_Trunk_Full",
      "support": 15
    },
    {
      "x": -3,
      "y": 1,
      "z": 1,
      "name": "Wood_Redwood_Trunk_Full",
      "support": 15
    },
    {
      "x": -3,
      "y": 16,
      "z": 1,
      "name": "Empty"
    },
    {
      "x": -3,
      "y": 17,
      "z": 1,
      "name": "Empty"
    },
    {
      "x": -3,
      "y": 18,
      "z": 1,
      "name": "Empty"
    },
    {
      "x": -3,
      "y": 19,
      "z": 1,
      "name": "Plant_Leaves_Beastwood_Dark"
    },
    {
      "x": -3,
      "y": 20,
      "z": 1,
      "name": "Plant_Leaves_Beastwood_Dark"
    },
    {
      "x": -3,
      "y": 21,
      "z": 1,
      "name": "Plant_Leaves_Beastwood_Bright"
    },
    {
      "x": -3,
      "y": 22,
      "z": 1,
      "name": "Plant_Leaves_Beastwood_Bright"
    },
    {
      "x": -3,
      "y": 23,
      "z": 1,
      "name": "Plant_Leaves_Beastwood_Bright"
    },
    {
      "x": -3,
      "y": 24,
      "z": 1,
      "name": "Plant_Leaves_Beastwood_Dark"
    },
    {
      "x": -3,
      "y": 25,
      "z": 1,
      "name": "Empty"
    },
    {
      "x": -3,
      "y": 26,
      "z": 1,
      "name": "Empty"
    },
    {
      "x": -3,
      "y": 27,
      "z": 1,
      "name": "Empty"
    },
    {
      "x": -3,
      "y": 17,
      "z": 2,
      "name": "Empty"
    },
    {
      "x": -3,
      "y": 18,
      "z": 2,
      "name": "Empty"
    },
    {
      "x": -3,
      "y": 19,
      "z": 2,
      "name": "Empty"
    },
    {
      "x": -3,
      "y": 20,
      "z": 2,
      "name": "Plant_Leaves_Beastwood_Dark"
    },
    {
      "x": -3,
      "y": 21,
      "z": 2,
      "name": "Plant_Leaves_Beastwood_Bright"
    },
    {
      "x": -3,
      "y": 22,
      "z": 2,
      "name": "Plant_Leaves_Beastwood_Bright"
    },
    {
      "x": -3,
      "y": 23,
      "z": 2,
      "name": "Plant_Leaves_Beastwood_Dark"
    },
    {
      "x": -3,
      "y": 24,
      "z": 2,
      "name": "Plant_Leaves_Beastwood_Dark"
    },
    {
      "x": -3,
      "y": 25,
      "z": 2,
      "name": "Plant_Leaves_Beastwood_Dark"
    },
    {
      "x": -3,
      "y": 26,
      "z": 2,
      "name": "Empty"
    },
    {
      "x": -3,
      "y": 27,
      "z": 2,
      "name": "Empty"
    },
    {
      "x": -3,
      "y": 18,
      "z": 3,
      "name": "Empty"
    },
    {
      "x": -3,
      "y": 19,
      "z": 3,
      "name": "Empty"
    },
    {
      "x": -3,
      "y": 20,
      "z": 3,
      "name": "Empty"
    },
    {
      "x": -3,
      "y": 21,
      "z": 3,
      "name": "Plant_Leaves_Beastwood_Dark"
    },
    {
      "x": -3,
      "y": 22,
      "z": 3,
      "name": "Plant_Leaves_Beastwood_Bright"
    },
    {
      "x": -3,
      "y": 23,
      "z": 3,
      "name": "Plant_Leaves_Beastwood_Bright"
    },
    {
      "x": -3,
      "y": 24,
      "z": 3,
      "name": "Plant_Leaves_Beastwood_Dark"
    },
    {
      "x": -3,
      "y": 25,
      "z": 3,
      "name": "Plant_Leaves_Beastwood_Bright"
    },
    {
      "x": -3,
      "y": 26,
      "z": 3,
      "name": "Empty"
    },
    {
      "x": -3,
      "y": 27,
      "z": 3,
      "name": "Empty"
    },
    {
      "x": -3,
      "y": 19,
      "z": 4,
      "name": "Empty"
    },
    {
      "x": -3,
      "y": 20,
      "z": 4,
      "name": "Empty"
    },
    {
      "x": -3,
      "y": 21,
      "z": 4,
      "name": "Empty"
    },
    {
      "x": -3,
      "y": 22,
      "z": 4,
      "name": "Plant_Leaves_Beastwood_Dark"
    },
    {
      "x": -3,
      "y": 23,
      "z": 4,
      "name": "Plant_Leaves_Beastwood_Dark"
    },
    {
      "x": -3,
      "y": 24,
      "z": 4,
      "name": "Plant_Leaves_Beastwood_Bright"
    },
    {
      "x": -3,
      "y": 25,
      "z": 4,
      "name": "Empty"
    },
    {
      "x": -3,
      "y": 26,
      "z": 4,
      "name": "Empty"
    },
    {
      "x": -3,
      "y": 27,
      "z": 4,
      "name": "Empty"
    },
    {
      "x": -3,
      "y": 20,
      "z": 5,
      "name": "Empty"
    },
    {
      "x": -3,
      "y": 21,
      "z": 5,
      "name": "Empty"
    },
    {
      "x": -3,
      "y": 22,
      "z": 5,
      "name": "Empty"
    },
    {
      "x": -3,
      "y": 23,
      "z": 5,
      "name": "Plant_Leaves_Beastwood_Dark"
    },
    {
      "x": -3,
      "y": 24,
      "z": 5,
      "name": "Empty"
    },
    {
      "x": -3,
      "y": 25,
      "z": 5,
      "name": "Empty"
    },
    {
      "x": -3,
      "y": 26,
      "z": 5,
      "name": "Empty"
    },
    {
      "x": -3,
      "y": 21,
      "z": 6,
      "name": "Empty"
    },
    {
      "x": -3,
      "y": 22,
      "z": 6,
      "name": "Empty"
    },
    {
      "x": -3,
      "y": 23,
      "z": 6,
      "name": "Empty"
    },
    {
      "x": -2,
      "y": 11,
      "z": -12,
      "name": "Empty"
    },
    {
      "x": -2,
      "y": 12,
      "z": -12,
      "name": "Empty"
    },
    {
      "x": -2,
      "y": 13,
      "z": -12,
      "name": "Empty"
    },
    {
      "x": -2,
      "y": 10,
      "z": -11,
      "name": "Empty"
    },
    {
      "x": -2,
      "y": 11,
      "z": -11,
      "name": "Empty"
    },
    {
      "x": -2,
      "y": 12,
      "z": -11,
      "name": "Empty"
    },
    {
      "x": -2,
      "y": 13,
      "z": -11,
      "name": "Empty"
    },
    {
      "x": -2,
      "y": 14,
      "z": -11,
      "name": "Empty"
    },
    {
      "x": -2,
      "y": 10,
      "z": -10,
      "name": "Empty"
    },
    {
      "x": -2,
      "y": 11,
      "z": -10,
      "name": "Empty"
    },
    {
      "x": -2,
      "y": 12,
      "z": -10,
      "name": "Plant_Leaves_Beastwood_Dark"
    },
    {
      "x": -2,
      "y": 13,
      "z": -10,
      "name": "Empty"
    },
    {
      "x": -2,
      "y": 14,
      "z": -10,
      "name": "Empty"
    },
    {
      "x": -2,
      "y": 9,
      "z": -9,
      "name": "Empty"
    },
    {
      "x": -2,
      "y": 10,
      "z": -9,
      "name": "Empty"
    },
    {
      "x": -2,
      "y": 11,
      "z": -9,
      "name": "Plant_Leaves_Beastwood_Dark"
    },
    {
      "x": -2,
      "y": 12,
      "z": -9,
      "name": "Plant_Leaves_Beastwood_Dark"
    },
    {
      "x": -2,
      "y": 13,
      "z": -9,
      "name": "Plant_Leaves_Beastwood_Dark"
    },
    {
      "x": -2,
      "y": 14,
      "z": -9,
      "name": "Empty"
    },
    {
      "x": -2,
      "y": 8,
      "z": -8,
      "name": "Empty"
    },
    {
      "x": -2,
      "y": 9,
      "z": -8,
      "name": "Empty"
    },
    {
      "x": -2,
      "y": 10,
      "z": -8,
      "name": "Empty"
    },
    {
      "x": -2,
      "y": 11,
      "z": -8,
      "name": "Empty"
    },
    {
      "x": -2,
      "y": 12,
      "z": -8,
      "name": "Plant_Leaves_Beastwood_Dark"
    },
    {
      "x": -2,
      "y": 13,
      "z": -8,
      "name": "Empty"
    },
    {
      "x": -2,
      "y": 14,
      "z": -8,
      "name": "Empty"
    },
    {
      "x": -2,
      "y": 15,
      "z": -8,
      "name": "Empty"
    },
    {
      "x": -2,
      "y": 8,
      "z": -7,
      "name": "Empty"
    },
    {
      "x": -2,
      "y": 9,
      "z": -7,
      "name": "Empty"
    },
    {
      "x": -2,
      "y": 10,
      "z": -7,
      "name": "Plant_Leaves_Beastwood_Dark"
    },
    {
      "x": -2,
      "y": 11,
      "z": -7,
      "name": "Plant_Leaves_Beastwood_Dark"
    },
    {
      "x": -2,
      "y": 12,
      "z": -7,
      "name": "Plant_Leaves_Beastwood_Dark"
    },
    {
      "x": -2,
      "y": 13,
      "z": -7,
      "name": "Plant_Leaves_Beastwood_Dark"
    },
    {
      "x": -2,
      "y": 14,
      "z": -7,
      "name": "Plant_Leaves_Beastwood_Dark"
    },
    {
      "x": -2,
      "y": 15,
      "z": -7,
      "name": "Empty"
    },
    {
      "x": -2,
      "y": 16,
      "z": -7,
      "name": "Empty"
    },
    {
      "x": -2,
      "y": 8,
      "z": -6,
      "name": "Empty"
    },
    {
      "x": -2,
      "y": 9,
      "z": -6,
      "name": "Plant_Leaves_Beastwood_Dark"
    },
    {
      "x": -2,
      "y": 10,
      "z": -6,
      "name": "Plant_Leaves_Beastwood_Bright"
    },
    {
      "x": -2,
      "y": 11,
      "z": -6,
      "name": "Plant_Leaves_Beastwood_Bright"
    },
    {
      "x": -2,
      "y": 12,
      "z": -6,
      "name": "Plant_Leaves_Beastwood_Bright"
    },
    {
      "x": -2,
      "y": 13,
      "z": -6,
      "name": "Plant_Leaves_Beastwood_Dark"
    },
    {
      "x": -2,
      "y": 14,
      "z": -6,
      "name": "Empty"
    },
    {
      "x": -2,
      "y": 15,
      "z": -6,
      "name": "Empty"
    },
    {
      "x": -2,
      "y": 8,
      "z": -5,
      "name": "Plant_Leaves_Beastwood_Bright"
    },
    {
      "x": -2,
      "y": 9,
      "z": -5,
      "name": "Plant_Leaves_Beastwood_Bright"
    },
    {
      "x": -2,
      "y": 10,
      "z": -5,
      "name": "Plant_Leaves_Beastwood_Dark"
    },
    {
      "x": -2,
      "y": 11,
      "z": -5,
      "name": "Plant_Leaves_Beastwood_Dark"
    },
    {
      "x": -2,
      "y": 12,
      "z": -5,
      "name": "Plant_Leaves_Beastwood_Bright"
    },
    {
      "x": -2,
      "y": 13,
      "z": -5,
      "name": "Plant_Leaves_Beastwood_Bright"
    },
    {
      "x": -2,
      "y": 14,
      "z": -5,
      "name": "Empty"
    },
    {
      "x": -2,
      "y": 19,
      "z": -5,
      "name": "Empty"
    },
    {
      "x": -2,
      "y": 20,
      "z": -5,
      "name": "Empty"
    },
    {
      "x": -2,
      "y": 21,
      "z": -5,
      "name": "Empty"
    },
    {
      "x": -2,
      "y": 9,
      "z": -4,
      "name": "Plant_Leaves_Beastwood_Dark"
    },
    {
      "x": -2,
      "y": 10,
      "z": -4,
      "name": "Plant_Leaves_Beastwood_Dark"
    },
    {
      "x": -2,
      "y": 11,
      "z": -4,
      "name": "Plant_Leaves_Beastwood_Dark"
    },
    {
      "x": -2,
      "y": 12,
      "z": -4,
      "name": "Plant_Leaves_Beastwood_Bright"
    },
    {
      "x": -2,
      "y": 18,
      "z": -4,
      "name": "Empty"
    },
    {
      "x": -2,
      "y": 19,
      "z": -4,
      "name": "Empty"
    },
    {
      "x": -2,
      "y": 20,
      "z": -4,
      "name": "Empty"
    },
    {
      "x": -2,
      "y": 21,
      "z": -4,
      "name": "Empty"
    },
    {
      "x": -2,
      "y": 22,
      "z": -4,
      "name": "Plant_Leaves_Beastwood_Dark"
    },
    {
      "x": -2,
      "y": 23,
      "z": -4,
      "name": "Empty"
    },
    {
      "x": -2,
      "y": 25,
      "z": -4,
      "name": "Empty"
    },
    {
      "x": -2,
      "y": 10,
      "z": -3,
      "name": "Plant_Leaves_Beastwood_Bright"
    },
    {
      "x": -2,
      "y": 17,
      "z": -3,
      "name": "Empty"
    },
    {
      "x": -2,
      "y": 18,
      "z": -3,
      "name": "Empty"
    },
    {
      "x": -2,
      "y": 19,
      "z": -3,
      "name": "Empty"
    },
    {
      "x": -2,
      "y": 20,
      "z": -3,
      "name": "Plant_Leaves_Beastwood_Dark"
    },
    {
      "x": -2,
      "y": 21,
      "z": -3,
      "name": "Plant_Leaves_Beastwood_Dark"
    },
    {
      "x": -2,
      "y": 22,
      "z": -3,
      "name": "Plant_Leaves_Beastwood_Dark"
    },
    {
      "x": -2,
      "y": 23,
      "z": -3,
      "name": "Plant_Leaves_Beastwood_Dark"
    },
    {
      "x": -2,
      "y": 24,
      "z": -3,
      "name": "Empty"
    },
    {
      "x": -2,
      "y": 25,
      "z": -3,
      "name": "Empty"
    },
    {
      "x": -2,
      "y": 26,
      "z": -3,
      "name": "Empty"
    },
    {
      "x": -2,
      "y": 0,
      "z": -2,
      "name": "Wood_Redwood_Trunk_Full",
      "support": 15
    },
    {
      "x": -2,
      "y": 1,
      "z": -2,
      "name": "Wood_Redwood_Trunk_Full",
      "support": 15
    },
    {
      "x": -2,
      "y": 2,
      "z": -2,
      "name": "Wood_Redwood_Trunk_Full",
      "support": 15
    },
    {
      "x": -2,
      "y": 3,
      "z": -2,
      "name": "Wood_Redwood_Trunk_Full",
      "support": 15
    },
    {
      "x": -2,
      "y": 4,
      "z": -2,
      "name": "Wood_Redwood_Trunk_Full",
      "support": 15
    },
    {
      "x": -2,
      "y": 18,
      "z": -2,
      "name": "Empty"
    },
    {
      "x": -2,
      "y": 19,
      "z": -2,
      "name": "Plant_Leaves_Beastwood_Bright"
    },
    {
      "x": -2,
      "y": 20,
      "z": -2,
      "name": "Plant_Leaves_Beastwood_Dark"
    },
    {
      "x": -2,
      "y": 21,
      "z": -2,
      "name": "Plant_Leaves_Beastwood_Bright"
    },
    {
      "x": -2,
      "y": 22,
      "z": -2,
      "name": "Plant_Leaves_Beastwood_Bright"
    },
    {
      "x": -2,
      "y": 23,
      "z": -2,
      "name": "Plant_Leaves_Beastwood_Dark"
    },
    {
      "x": -2,
      "y": 24,
      "z": -2,
      "name": "Plant_Leaves_Beastwood_Dark"
    },
    {
      "x": -2,
      "y": 25,
      "z": -2,
      "name": "Empty"
    },
    {
      "x": -2,
      "y": 26,
      "z": -2,
      "name": "Empty"
    },
    {
      "x": -2,
      "y": 0,
      "z": -1,
      "name": "Wood_Beastwood_Bark"
    },
    {
      "x": -2,
      "y": 1,
      "z": -1,
      "name": "Wood_Beastwood_Bark"
    },
    {
      "x": -2,
      "y": 2,
      "z": -1,
      "name": "Wood_Beastwood_Bark"
    },
    {
      "x": -2,
      "y": 3,
      "z": -1,
      "name": "Wood_Beastwood_Bark"
    },
    {
      "x": -2,
      "y": 4,
      "z": -1,
      "name": "Wood_Beastwood_Bark"
    },
    {
      "x": -2,
      "y": 5,
      "z": -1,
      "name": "Wood_Beastwood_Bark"
    },
    {
      "x": -2,
      "y": 6,
      "z": -1,
      "name": "Wood_Beastwood_Bark"
    },
    {
      "x": -2,
      "y": 7,
      "z": -1,
      "name": "Wood_Beastwood_Bark"
    },
    {
      "x": -2,
      "y": 8,
      "z": -1,
      "name": "Wood_Beastwood_Bark"
    },
    {
      "x": -2,
      "y": 17,
      "z": -1,
      "name": "Empty"
    },
    {
      "x": -2,
      "y": 18,
      "z": -1,
      "name": "Plant_Leaves_Beastwood_Dark"
    },
    {
      "x": -2,
      "y": 19,
      "z": -1,
      "name": "Plant_Leaves_Beastwood_Bright"
    },
    {
      "x": -2,
      "y": 20,
      "z": -1,
      "name": "Plant_Leaves_Beastwood_Dark"
    },
    {
      "x": -2,
      "y": 21,
      "z": -1,
      "name": "Plant_Leaves_Beastwood_Bright"
    },
    {
      "x": -2,
      "y": 22,
      "z": -1,
      "name": "Plant_Leaves_Beastwood_Dark",
      "support": 2
    },
    {
      "x": -2,
      "y": 23,
      "z": -1,
      "name": "Plant_Leaves_Beastwood_Dark"
    },
    {
      "x": -2,
      "y": 24,
      "z": -1,
      "name": "Empty"
    },
    {
      "x": -2,
      "y": 25,
      "z": -1,
      "name": "Empty"
    },
    {
      "x": -2,
      "y": 26,
      "z": -1,
      "name": "Empty"
    },
    {
      "x": -2,
      "y": 0,
      "z": 0,
      "name": "Wood_Beastwood_Bark"
    },
    {
      "x": -2,
      "y": 1,
      "z": 0,
      "name": "Wood_Beastwood_Bark"
    },
    {
      "x": -2,
      "y": 2,
      "z": 0,
      "name": "Wood_Beastwood_Bark"
    },
    {
      "x": -2,
      "y": 3,
      "z": 0,
      "name": "Wood_Beastwood_Bark"
    },
    {
      "x": -2,
      "y": 4,
      "z": 0,
      "name": "Wood_Beastwood_Bark"
    },
    {
      "x": -2,
      "y": 5,
      "z": 0,
      "name": "Wood_Beastwood_Bark"
    },
    {
      "x": -2,
      "y": 6,
      "z": 0,
      "name": "Wood_Beastwood_Bark"
    },
    {
      "x": -2,
      "y": 7,
      "z": 0,
      "name": "Wood_Beastwood_Bark"
    },
    {
      "x": -2,
      "y": 8,
      "z": 0,
      "name": "Wood_Beastwood_Bark"
    },
    {
      "x": -2,
      "y": 9,
      "z": 0,
      "name": "Wood_Beastwood_Bark"
    },
    {
      "x": -2,
      "y": 10,
      "z": 0,
      "name": "Wood_Beastwood_Bark"
    },
    {
      "x": -2,
      "y": 11,
      "z": 0,
      "name": "Wood_Beastwood_Bark"
    },
    {
      "x": -2,
      "y": 16,
      "z": 0,
      "name": "Empty"
    },
    {
      "x": -2,
      "y": 17,
      "z": 0,
      "name": "Empty"
    },
    {
      "x": -2,
      "y": 18,
      "z": 0,
      "name": "Plant_Leaves_Beastwood_Dark"
    },
    {
      "x": -2,
      "y": 19,
      "z": 0,
      "name": "Empty",
      "support": 15
    },
    {
      "x": -2,
      "y": 20,
      "z": 0,
      "name": "Empty",
      "support": 15
    },
    {
      "x": -2,
      "y": 21,
      "z": 0,
      "name": "Plant_Leaves_Beastwood_Bright"
    },
    {
      "x": -2,
      "y": 22,
      "z": 0,
      "name": "Plant_Leaves_Beastwood_Dark",
      "support": 1
    },
    {
      "x": -2,
      "y": 23,
      "z": 0,
      "name": "Plant_Leaves_Beastwood_Bright",
      "support": 2
    },
    {
      "x": -2,
      "y": 24,
      "z": 0,
      "name": "Plant_Leaves_Beastwood_Dark"
    },
    {
      "x": -2,
      "y": 25,
      "z": 0,
      "name": "Empty"
    },
    {
      "x": -2,
      "y": 0,
      "z": 1,
      "name": "Wood_Beastwood_Bark"
    },
    {
      "x": -2,
      "y": 1,
      "z": 1,
      "name": "Wood_Beastwood_Bark"
    },
    {
      "x": -2,
      "y": 2,
      "z": 1,
      "name": "Wood_Beastwood_Bark"
    },
    {
      "x": -2,
      "y": 3,
      "z": 1,
      "name": "Wood_Beastwood_Bark"
    },
    {
      "x": -2,
      "y": 4,
      "z": 1,
      "name": "Wood_Beastwood_Bark"
    },
    {
      "x": -2,
      "y": 5,
      "z": 1,
      "name": "Wood_Beastwood_Bark"
    },
    {
      "x": -2,
      "y": 6,
      "z": 1,
      "name": "Wood_Beastwood_Bark"
    },
    {
      "x": -2,
      "y": 7,
      "z": 1,
      "name": "Wood_Beastwood_Bark"
    },
    {
      "x": -2,
      "y": 8,
      "z": 1,
      "name": "Wood_Beastwood_Bark"
    },
    {
      "x": -2,
      "y": 9,
      "z": 1,
      "name": "Wood_Beastwood_Bark"
    },
    {
      "x": -2,
      "y": 17,
      "z": 1,
      "name": "Empty"
    },
    {
      "x": -2,
      "y": 18,
      "z": 1,
      "name": "Plant_Leaves_Beastwood_Dark"
    },
    {
      "x": -2,
      "y": 19,
      "z": 1,
      "name": "Plant_Leaves_Beastwood_Dark"
    },
    {
      "x": -2,
      "y": 20,
      "z": 1,
      "name": "Plant_Leaves_Beastwood_Bright"
    },
    {
      "x": -2,
      "y": 21,
      "z": 1,
      "name": "Plant_Leaves_Beastwood_Dark"
    },
    {
      "x": -2,
      "y": 22,
      "z": 1,
      "name": "Plant_Leaves_Beastwood_Dark",
      "support": 2
    },
    {
      "x": -2,
      "y": 23,
      "z": 1,
      "name": "Plant_Leaves_Beastwood_Dark"
    },
    {
      "x": -2,
      "y": 24,
      "z": 1,
      "name": "Plant_Leaves_Beastwood_Dark"
    },
    {
      "x": -2,
      "y": 25,
      "z": 1,
      "name": "Plant_Leaves_Beastwood_Dark"
    },
    {
      "x": -2,
      "y": 26,
      "z": 1,
      "name": "Empty"
    },
    {
      "x": -2,
      "y": 0,
      "z": 2,
      "name": "Wood_Redwood_Trunk_Full",
      "support": 15
    },
    {
      "x": -2,
      "y": 1,
      "z": 2,
      "name": "Wood_Redwood_Trunk_Full",
      "support": 15
    },
    {
      "x": -2,
      "y": 2,
      "z": 2,
      "name": "Wood_Redwood_Trunk_Full",
      "support": 15
    },
    {
      "x": -2,
      "y": 3,
      "z": 2,
      "name": "Wood_Redwood_Trunk_Full",
      "support": 15
    },
    {
      "x": -2,
      "y": 17,
      "z": 2,
      "name": "Empty"
    },
    {
      "x": -2,
      "y": 18,
      "z": 2,
      "name": "Empty"
    },
    {
      "x": -2,
      "y": 19,
      "z": 2,
      "name": "Plant_Leaves_Beastwood_Dark"
    },
    {
      "x": -2,
      "y": 20,
      "z": 2,
      "name": "Plant_Leaves_Beastwood_Dark",
      "support": 1
    },
    {
      "x": -2,
      "y": 21,
      "z": 2,
      "name": "Plant_Leaves_Beastwood_Bright"
    },
    {
      "x": -2,
      "y": 22,
      "z": 2,
      "name": "Plant_Leaves_Beastwood_Dark"
    },
    {
      "x": -2,
      "y": 23,
      "z": 2,
      "name": "Plant_Leaves_Beastwood_Dark"
    },
    {
      "x": -2,
      "y": 24,
      "z": 2,
      "name": "Plant_Leaves_Beastwood_Dark"
    },
    {
      "x": -2,
      "y": 25,
      "z": 2,
      "name": "Plant_Leaves_Beastwood_Dark"
    },
    {
      "x": -2,
      "y": 26,
      "z": 2,
      "name": "Plant_Leaves_Beastwood_Dark"
    },
    {
      "x": -2,
      "y": 27,
      "z": 2,
      "name": "Empty"
    },
    {
      "x": -2,
      "y": 17,
      "z": 3,
      "name": "Empty"
    },
    {
      "x": -2,
      "y": 18,
      "z": 3,
      "name": "Empty"
    },
    {
      "x": -2,
      "y": 19,
      "z": 3,
      "name": "Plant_Leaves_Beastwood_Dark",
      "support": 2
    },
    {
      "x": -2,
      "y": 20,
      "z": 3,
      "name": "Plant_Leaves_Beastwood_Dark",
      "support": 1
    },
    {
      "x": -2,
      "y": 21,
      "z": 3,
      "name": "Plant_Leaves_Beastwood_Bright",
      "support": 2
    },
    {
      "x": -2,
      "y": 22,
      "z": 3,
      "name": "Plant_Leaves_Beastwood_Dark"
    },
    {
      "x": -2,
      "y": 23,
      "z": 3,
      "name": "Plant_Leaves_Beastwood_Dark"
    },
    {
      "x": -2,
      "y": 24,
      "z": 3,
      "name": "Plant_Leaves_Beastwood_Dark"
    },
    {
      "x": -2,
      "y": 25,
      "z": 3,
      "name": "Plant_Leaves_Beastwood_Dark"
    },
    {
      "x": -2,
      "y": 26,
      "z": 3,
      "name": "Empty"
    },
    {
      "x": -2,
      "y": 27,
      "z": 3,
      "name": "Empty"
    },
    {
      "x": -2,
      "y": 28,
      "z": 3,
      "name": "Empty"
    },
    {
      "x": -2,
      "y": 18,
      "z": 4,
      "name": "Empty"
    },
    {
      "x": -2,
      "y": 19,
      "z": 4,
      "name": "Empty"
    },
    {
      "x": -2,
      "y": 20,
      "z": 4,
      "name": "Plant_Leaves_Beastwood_Bright",
      "support": 2
    },
    {
      "x": -2,
      "y": 21,
      "z": 4,
      "name": "Plant_Leaves_Beastwood_Dark"
    },
    {
      "x": -2,
      "y": 22,
      "z": 4,
      "name": "Plant_Leaves_Beastwood_Dark"
    },
    {
      "x": -2,
      "y": 23,
      "z": 4,
      "name": "Plant_Leaves_Beastwood_Bright"
    },
    {
      "x": -2,
      "y": 24,
      "z": 4,
      "name": "Plant_Leaves_Beastwood_Bright"
    },
    {
      "x": -2,
      "y": 25,
      "z": 4,
      "name": "Plant_Leaves_Beastwood_Bright"
    },
    {
      "x": -2,
      "y": 26,
      "z": 4,
      "name": "Empty"
    },
    {
      "x": -2,
      "y": 27,
      "z": 4,
      "name": "Empty"
    },
    {
      "x": -2,
      "y": 20,
      "z": 5,
      "name": "Empty"
    },
    {
      "x": -2,
      "y": 21,
      "z": 5,
      "name": "Empty"
    },
    {
      "x": -2,
      "y": 22,
      "z": 5,
      "name": "Plant_Leaves_Beastwood_Bright"
    },
    {
      "x": -2,
      "y": 23,
      "z": 5,
      "name": "Plant_Leaves_Beastwood_Dark"
    },
    {
      "x": -2,
      "y": 24,
      "z": 5,
      "name": "Plant_Leaves_Beastwood_Dark"
    },
    {
      "x": -2,
      "y": 25,
      "z": 5,
      "name": "Empty"
    },
    {
      "x": -2,
      "y": 26,
      "z": 5,
      "name": "Empty"
    },
    {
      "x": -2,
      "y": 21,
      "z": 6,
      "name": "Empty"
    },
    {
      "x": -2,
      "y": 22,
      "z": 6,
      "name": "Empty"
    },
    {
      "x": -2,
      "y": 23,
      "z": 6,
      "name": "Empty"
    },
    {
      "x": -2,
      "y": 22,
      "z": 7,
      "name": "Empty"
    },
    {
      "x": -1,
      "y": 12,
      "z": -12,
      "name": "Empty"
    },
    {
      "x": -1,
      "y": 11,
      "z": -11,
      "name": "Empty"
    },
    {
      "x": -1,
      "y": 12,
      "z": -11,
      "name": "Plant_Leaves_Beastwood_Dark"
    },
    {
      "x": -1,
      "y": 13,
      "z": -11,
      "name": "Empty"
    },
    {
      "x": -1,
      "y": 10,
      "z": -10,
      "name": "Empty"
    },
    {
      "x": -1,
      "y": 11,
      "z": -10,
      "name": "Plant_Leaves_Beastwood_Dark"
    },
    {
      "x": -1,
      "y": 12,
      "z": -10,
      "name": "Plant_Leaves_Beastwood_Dark"
    },
    {
      "x": -1,
      "y": 13,
      "z": -10,
      "name": "Plant_Leaves_Beastwood_Dark"
    },
    {
      "x": -1,
      "y": 14,
      "z": -10,
      "name": "Empty"
    },
    {
      "x": -1,
      "y": 9,
      "z": -9,
      "name": "Empty"
    },
    {
      "x": -1,
      "y": 10,
      "z": -9,
      "name": "Plant_Leaves_Beastwood_Bright"
    },
    {
      "x": -1,
      "y": 11,
      "z": -9,
      "name": "Plant_Leaves_Beastwood_Dark"
    },
    {
      "x": -1,
      "y": 12,
      "z": -9,
      "name": "Plant_Leaves_Beastwood_Dark"
    },
    {
      "x": -1,
      "y": 13,
      "z": -9,
      "name": "Plant_Leaves_Beastwood_Dark"
    },
    {
      "x": -1,
      "y": 14,
      "z": -9,
      "name": "Plant_Leaves_Beastwood_Bright"
    },
    {
      "x": -1,
      "y": 15,
      "z": -9,
      "name": "Empty"
    },
    {
      "x": -1,
      "y": 8,
      "z": -8,
      "name": "Empty"
    },
    {
      "x": -1,
      "y": 9,
      "z": -8,
      "name": "Empty"
    },
    {
      "x": -1,
      "y": 10,
      "z": -8,
      "name": "Empty"
    },
    {
      "x": -1,
      "y": 11,
      "z": -8,
      "name": "Plant_Leaves_Beastwood_Bright"
    },
    {
      "x": -1,
      "y": 12,
      "z": -8,
      "name": "Plant_Leaves_Beastwood_Dark"
    },
    {
      "x": -1,
      "y": 13,
      "z": -8,
      "name": "Plant_Leaves_Beastwood_Dark"
    },
    {
      "x": -1,
      "y": 14,
      "z": -8,
      "name": "Empty"
    },
    {
      "x": -1,
      "y": 15,
      "z": -8,
      "name": "Empty"
    },
    {
      "x": -1,
      "y": 16,
      "z": -8,
      "name": "Empty"
    },
    {
      "x": -1,
      "y": 8,
      "z": -7,
      "name": "Empty"
    },
    {
      "x": -1,
      "y": 9,
      "z": -7,
      "name": "Plant_Leaves_Beastwood_Dark"
    },
    {
      "x": -1,
      "y": 10,
      "z": -7,
      "name": "Plant_Leaves_Beastwood_Dark"
    },
    {
      "x": -1,
      "y": 11,
      "z": -7,
      "name": "Plant_Leaves_Beastwood_Dark"
    },
    {
      "x": -1,
      "y": 12,
      "z": -7,
      "name": "Plant_Leaves_Beastwood_Bright"
    },
    {
      "x": -1,
      "y": 13,
      "z": -7,
      "name": "Plant_Leaves_Beastwood_Dark"
    },
    {
      "x": -1,
      "y": 14,
      "z": -7,
      "name": "Plant_Leaves_Beastwood_Dark"
    },
    {
      "x": -1,
      "y": 15,
      "z": -7,
      "name": "Plant_Leaves_Beastwood_Dark"
    },
    {
      "x": -1,
      "y": 16,
      "z": -7,
      "name": "Empty"
    },
    {
      "x": -1,
      "y": 17,
      "z": -7,
      "name": "Empty"
    },
    {
      "x": -1,
      "y": 8,
      "z": -6,
      "name": "Plant_Leaves_Beastwood_Bright"
    },
    {
      "x": -1,
      "y": 9,
      "z": -6,
      "name": "Plant_Leaves_Beastwood_Dark"
    },
    {
      "x": -1,
      "y": 10,
      "z": -6,
      "name": "Plant_Leaves_Beastwood_Dark"
    },
    {
      "x": -1,
      "y": 11,
      "z": -6,
      "name": "Plant_Leaves_Beastwood_Dark"
    },
    {
      "x": -1,
      "y": 12,
      "z": -6,
      "name": "Plant_Leaves_Beastwood_Dark"
    },
    {
      "x": -1,
      "y": 13,
      "z": -6,
      "name": "Plant_Leaves_Beastwood_Dark"
    },
    {
      "x": -1,
      "y": 14,
      "z": -6,
      "name": "Plant_Leaves_Beastwood_Bright"
    },
    {
      "x": -1,
      "y": 15,
      "z": -6,
      "name": "Empty"
    },
    {
      "x": -1,
      "y": 16,
      "z": -6,
      "name": "Empty"
    },
    {
      "x": -1,
      "y": 8,
      "z": -5,
      "name": "Plant_Leaves_Beastwood_Dark"
    },
    {
      "x": -1,
      "y": 9,
      "z": -5,
      "name": "Plant_Leaves_Beastwood_Dark"
    },
    {
      "x": -1,
      "y": 10,
      "z": -5,
      "name": "Plant_Leaves_Beastwood_Dark"
    },
    {
      "x": -1,
      "y": 11,
      "z": -5,
      "name": "Plant_Leaves_Beastwood_Dark"
    },
    {
      "x": -1,
      "y": 12,
      "z": -5,
      "name": "Plant_Leaves_Beastwood_Dark"
    },
    {
      "x": -1,
      "y": 13,
      "z": -5,
      "name": "Plant_Leaves_Beastwood_Dark"
    },
    {
      "x": -1,
      "y": 14,
      "z": -5,
      "name": "Plant_Leaves_Beastwood_Dark"
    },
    {
      "x": -1,
      "y": 15,
      "z": -5,
      "name": "Empty"
    },
    {
      "x": -1,
      "y": 18,
      "z": -5,
      "name": "Empty"
    },
    {
      "x": -1,
      "y": 20,
      "z": -5,
      "name": "Empty"
    },
    {
      "x": -1,
      "y": 23,
      "z": -5,
      "name": "Empty"
    },
    {
      "x": -1,
      "y": 25,
      "z": -5,
      "name": "Empty"
    },
    {
      "x": -1,
      "y": 8,
      "z": -4,
      "name": "Plant_Leaves_Beastwood_Bright"
    },
    {
      "x": -1,
      "y": 9,
      "z": -4,
      "name": "Plant_Leaves_Beastwood_Dark"
    },
    {
      "x": -1,
      "y": 10,
      "z": -4,
      "name": "Plant_Leaves_Beastwood_Bright"
    },
    {
      "x": -1,
      "y": 11,
      "z": -4,
      "name": "Plant_Leaves_Beastwood_Bright"
    },
    {
      "x": -1,
      "y": 12,
      "z": -4,
      "name": "Plant_Leaves_Beastwood_Bright"
    },
    {
      "x": -1,
      "y": 13,
      "z": -4,
      "name": "Plant_Leaves_Beastwood_Dark"
    },
    {
      "x": -1,
      "y": 17,
      "z": -4,
      "name": "Empty"
    },
    {
      "x": -1,
      "y": 18,
      "z": -4,
      "name": "Empty"
    },
    {
      "x": -1,
      "y": 19,
      "z": -4,
      "name": "Empty"
    },
    {
      "x": -1,
      "y": 20,
      "z": -4,
      "name": "Plant_Leaves_Beastwood_Bright"
    },
    {
      "x": -1,
      "y": 21,
      "z": -4,
      "name": "Plant_Leaves_Beastwood_Dark"
    },
    {
      "x": -1,
      "y": 22,
      "z": -4,
      "name": "Plant_Leaves_Beastwood_Dark"
    },
    {
      "x": -1,
      "y": 23,
      "z": -4,
      "name": "Plant_Leaves_Beastwood_Dark"
    },
    {
      "x": -1,
      "y": 24,
      "z": -4,
      "name": "Empty"
    },
    {
      "x": -1,
      "y": 25,
      "z": -4,
      "name": "Empty"
    },
    {
      "x": -1,
      "y": 26,
      "z": -4,
      "name": "Empty"
    },
    {
      "x": -1,
      "y": 0,
      "z": -3,
      "name": "Wood_Redwood_Trunk_Full",
      "support": 15
    },
    {
      "x": -1,
      "y": 1,
      "z": -3,
      "name": "Wood_Redwood_Trunk_Full",
      "support": 15
    },
    {
      "x": -1,
      "y": 2,
      "z": -3,
      "name": "Wood_Redwood_Trunk_Full",
      "support": 15
    },
    {
      "x": -1,
      "y": 9,
      "z": -3,
      "name": "Plant_Leaves_Beastwood_Dark"
    },
    {
      "x": -1,
      "y": 10,
      "z": -3,
      "name": "Plant_Leaves_Beastwood_Bright"
    },
    {
      "x": -1,
      "y": 11,
      "z": -3,
      "name": "Plant_Leaves_Beastwood_Dark"
    },
    {
      "x": -1,
      "y": 12,
      "z": -3,
      "name": "Plant_Leaves_Beastwood_Bright"
    },
    {
      "x": -1,
      "y": 16,
      "z": -3,
      "name": "Empty"
    },
    {
      "x": -1,
      "y": 17,
      "z": -3,
      "name": "Empty"
    },
    {
      "x": -1,
      "y": 18,
      "z": -3,
      "name": "Empty"
    },
    {
      "x": -1,
      "y": 19,
      "z": -3,
      "name": "Plant_Leaves_Beastwood_Dark"
    },
    {
      "x": -1,
      "y": 20,
      "z": -3,
      "name": "Plant_Leaves_Beastwood_Dark"
    },
    {
      "x": -1,
      "y": 21,
      "z": -3,
      "name": "Plant_Leaves_Beastwood_Dark"
    },
    {
      "x": -1,
      "y": 22,
      "z": -3,
      "name": "Plant_Leaves_Beastwood_Dark"
    },
    {
      "x": -1,
      "y": 23,
      "z": -3,
      "name": "Plant_Leaves_Beastwood_Dark"
    },
    {
      "x": -1,
      "y": 24,
      "z": -3,
      "name": "Plant_Leaves_Beastwood_Dark"
    },
    {
      "x": -1,
      "y": 25,
      "z": -3,
      "name": "Empty"
    },
    {
      "x": -1,
      "y": 26,
      "z": -3,
      "name": "Empty"
    },
    {
      "x": -1,
      "y": 27,
      "z": -3,
      "name": "Empty"
    },
    {
      "x": -1,
      "y": 0,
      "z": -2,
      "name": "Wood_Beastwood_Bark"
    },
    {
      "x": -1,
      "y": 1,
      "z": -2,
      "name": "Wood_Beastwood_Bark"
    },
    {
      "x": -1,
      "y": 2,
      "z": -2,
      "name": "Wood_Beastwood_Bark"
    },
    {
      "x": -1,
      "y": 3,
      "z": -2,
      "name": "Wood_Beastwood_Bark"
    },
    {
      "x": -1,
      "y": 4,
      "z": -2,
      "name": "Wood_Beastwood_Bark"
    },
    {
      "x": -1,
      "y": 5,
      "z": -2,
      "name": "Wood_Beastwood_Bark"
    },
    {
      "x": -1,
      "y": 6,
      "z": -2,
      "name": "Wood_Beastwood_Bark"
    },
    {
      "x": -1,
      "y": 7,
      "z": -2,
      "name": "Wood_Beastwood_Bark"
    },
    {
      "x": -1,
      "y": 8,
      "z": -2,
      "name": "Wood_Beastwood_Bark"
    },
    {
      "x": -1,
      "y": 9,
      "z": -2,
      "name": "Wood_Beastwood_Bark"
    },
    {
      "x": -1,
      "y": 17,
      "z": -2,
      "name": "Empty"
    },
    {
      "x": -1,
      "y": 18,
      "z": -2,
      "name": "Plant_Leaves_Beastwood_Bright"
    },
    {
      "x": -1,
      "y": 19,
      "z": -2,
      "name": "Plant_Leaves_Beastwood_Dark"
    },
    {
      "x": -1,
      "y": 20,
      "z": -2,
      "name": "Plant_Leaves_Beastwood_Dark"
    },
    {
      "x": -1,
      "y": 21,
      "z": -2,
      "name": "Plant_Leaves_Beastwood_Dark"
    },
    {
      "x": -1,
      "y": 22,
      "z": -2,
      "name": "Plant_Leaves_Beastwood_Dark",
      "support": 2
    },
    {
      "x": -1,
      "y": 23,
      "z": -2,
      "name": "Plant_Leaves_Beastwood_Dark"
    },
    {
      "x": -1,
      "y": 24,
      "z": -2,
      "name": "Plant_Leaves_Beastwood_Bright"
    },
    {
      "x": -1,
      "y": 25,
      "z": -2,
      "name": "Empty"
    },
    {
      "x": -1,
      "y": 26,
      "z": -2,
      "name": "Empty"
    },
    {
      "x": -1,
      "y": 27,
      "z": -2,
      "name": "Empty"
    },
    {
      "x": -1,
      "y": 0,
      "z": -1,
      "name": "Wood_Redwood_Trunk_Full",
      "support": 15
    },
    {
      "x": -1,
      "y": 1,
      "z": -1,
      "name": "Wood_Beastwood_Plhoem_Sap"
    },
    {
      "x": -1,
      "y": 2,
      "z": -1,
      "name": "Wood_Beastwood_Plhoem_Sap"
    },
    {
      "x": -1,
      "y": 3,
      "z": -1,
      "name": "Wood_Beastwood_Plhoem_Sap"
    },
    {
      "x": -1,
      "y": 4,
      "z": -1,
      "name": "Wood_Beastwood_Plhoem_Sap"
    },
    {
      "x": -1,
      "y": 5,
      "z": -1,
      "name": "Wood_Beastwood_Plhoem_Sap"
    },
    {
      "x": -1,
      "y": 6,
      "z": -1,
      "name": "Wood_Beastwood_Plhoem_Sap"
    },
    {
      "x": -1,
      "y": 7,
      "z": -1,
      "name": "Wood_Beastwood_Plhoem_Sap"
    },
    {
      "x": -1,
      "y": 8,
      "z": -1,
      "name": "Wood_Beastwood_Bark"
    },
    {
      "x": -1,
      "y": 9,
      "z": -1,
      "name": "Wood_Beastwood_Bark"
    },
    {
      "x": -1,
      "y": 10,
      "z": -1,
      "name": "Wood_Beastwood_Bark"
    },
    {
      "x": -1,
      "y": 11,
      "z": -1,
      "name": "Wood_Beastwood_Bark"
    },
    {
      "x": -1,
      "y": 12,
      "z": -1,
      "name": "Wood_Beastwood_Bark"
    },
    {
      "x": -1,
      "y": 13,
      "z": -1,
      "name": "Wood_Beastwood_Bark"
    },
    {
      "x": -1,
      "y": 18,
      "z": -1,
      "name": "Empty"
    },
    {
      "x": -1,
      "y": 19,
      "z": -1,
      "name": "Plant_Leaves_Beastwood_Dark"
    },
    {
      "x": -1,
      "y": 20,
      "z": -1,
      "name": "Plant_Leaves_Beastwood_Dark"
    },
    {
      "x": -1,
      "y": 21,
      "z": -1,
      "name": "Plant_Leaves_Beastwood_Bright",
      "support": 1
    },
    {
      "x": -1,
      "y": 22,
      "z": -1,
      "name": "Plant_Leaves_Beastwood_Dark",
      "support": 1
    },
    {
      "x": -1,
      "y": 23,
      "z": -1,
      "name": "Plant_Leaves_Beastwood_Dark",
      "support": 2
    },
    {
      "x": -1,
      "y": 24,
      "z": -1,
      "name": "Plant_Leaves_Beastwood_Dark"
    },
    {
      "x": -1,
      "y": 25,
      "z": -1,
      "name": "Empty"
    },
    {
      "x": -1,
      "y": 26,
      "z": -1,
      "name": "Empty"
    },
    {
      "x": -1,
      "y": 27,
      "z": -1,
      "name": "Empty"
    },
    {
      "x": -1,
      "y": 0,
      "z": 0,
      "name": "Wood_Redwood_Trunk_Full",
      "support": 15
    },
    {
      "x": -1,
      "y": 1,
      "z": 0,
      "name": "Wood_Beastwood_Plhoem_Sap"
    },
    {
      "x": -1,
      "y": 2,
      "z": 0,
      "name": "Wood_Beastwood_Plhoem_Sap"
    },
    {
      "x": -1,
      "y": 3,
      "z": 0,
      "name": "Wood_Beastwood_Plhoem_Sap"
    },
    {
      "x": -1,
      "y": 4,
      "z": 0,
      "name": "Wood_Beastwood_Plhoem_Sap"
    },
    {
      "x": -1,
      "y": 5,
      "z": 0,
      "name": "Wood_Beastwood_Plhoem_Sap"
    },
    {
      "x": -1,
      "y": 6,
      "z": 0,
      "name": "Wood_Beastwood_Plhoem_Sap"
    },
    {
      "x": -1,
      "y": 7,
      "z": 0,
      "name": "Wood_Beastwood_Plhoem_Sap"
    },
    {
      "x": -1,
      "y": 8,
      "z": 0,
      "name": "Wood_Beastwood_Bark"
    },
    {
      "x": -1,
      "y": 9,
      "z": 0,
      "name": "Wood_Beastwood_Bark"
    },
    {
      "x": -1,
      "y": 10,
      "z": 0,
      "name": "Wood_Beastwood_Bark"
    },
    {
      "x": -1,
      "y": 11,
      "z": 0,
      "name": "Wood_Beastwood_Bark"
    },
    {
      "x": -1,
      "y": 12,
      "z": 0,
      "name": "Wood_Beastwood_Bark"
    },
    {
      "x": -1,
      "y": 13,
      "z": 0,
      "name": "Wood_Beastwood_Bark"
    },
    {
      "x": -1,
      "y": 14,
      "z": 0,
      "name": "Wood_Beastwood_Bark"
    },
    {
      "x": -1,
      "y": 15,
      "z": 0,
      "name": "Wood_Beastwood_Bark"
    },
    {
      "x": -1,
      "y": 16,
      "z": 0,
      "name": "Wood_Beastwood_Bark"
    },
    {
      "x": -1,
      "y": 17,
      "z": 0,
      "name": "Wood_Beastwood_Bark"
    },
    {
      "x": -1,
      "y": 18,
      "z": 0,
      "name": "Empty",
      "support": 15
    },
    {
      "x": -1,
      "y": 19,
      "z": 0,
      "name": "Empty",
      "support": 15
    },
    {
      "x": -1,
      "y": 20,
      "z": 0,
      "name": "Plant_Leaves_Beastwood_Dark"
    },
    {
      "x": -1,
      "y": 21,
      "z": 0,
      "name": "Plant_Leaves_Beastwood_Bright"
    },
    {
      "x": -1,
      "y": 22,
      "z": 0,
      "name": "Plant_Leaves_Beastwood_Dark"
    },
    {
      "x": -1,
      "y": 23,
      "z": 0,
      "name": "Plant_Leaves_Beastwood_Bright",
      "support": 1
    },
    {
      "x": -1,
      "y": 24,
      "z": 0,
      "name": "Plant_Leaves_Beastwood_Dark",
      "support": 2
    },
    {
      "x": -1,
      "y": 25,
      "z": 0,
      "name": "Plant_Leaves_Beastwood_Dark"
    },
    {
      "x": -1,
      "y": 26,
      "z": 0,
      "name": "Empty"
    },
    {
      "x": -1,
      "y": 0,
      "z": 1,
      "name": "Wood_Redwood_Trunk_Full",
      "support": 15
    },
    {
      "x": -1,
      "y": 1,
      "z": 1,
      "name": "Wood_Beastwood_Plhoem_Sap"
    },
    {
      "x": -1,
      "y": 2,
      "z": 1,
      "name": "Wood_Beastwood_Plhoem_Sap"
    },
    {
      "x": -1,
      "y": 3,
      "z": 1,
      "name": "Wood_Beastwood_Plhoem_Sap"
    },
    {
      "x": -1,
      "y": 4,
      "z": 1,
      "name": "Wood_Beastwood_Plhoem_Sap"
    },
    {
      "x": -1,
      "y": 5,
      "z": 1,
      "name": "Wood_Beastwood_Plhoem_Sap"
    },
    {
      "x": -1,
      "y": 6,
      "z": 1,
      "name": "Wood_Beastwood_Plhoem_Sap"
    },
    {
      "x": -1,
      "y": 7,
      "z": 1,
      "name": "Wood_Beastwood_Plhoem_Sap"
    },
    {
      "x": -1,
      "y": 8,
      "z": 1,
      "name": "Wood_Beastwood_Bark"
    },
    {
      "x": -1,
      "y": 9,
      "z": 1,
      "name": "Wood_Beastwood_Bark"
    },
    {
      "x": -1,
      "y": 10,
      "z": 1,
      "name": "Wood_Beastwood_Bark"
    },
    {
      "x": -1,
      "y": 11,
      "z": 1,
      "name": "Wood_Beastwood_Bark"
    },
    {
      "x": -1,
      "y": 12,
      "z": 1,
      "name": "Wood_Beastwood_Bark"
    },
    {
      "x": -1,
      "y": 13,
      "z": 1,
      "name": "Wood_Beastwood_Bark"
    },
    {
      "x": -1,
      "y": 18,
      "z": 1,
      "name": "Empty"
    },
    {
      "x": -1,
      "y": 19,
      "z": 1,
      "name": "Plant_Leaves_Beastwood_Dark"
    },
    {
      "x": -1,
      "y": 20,
      "z": 1,
      "name": "Plant_Leaves_Beastwood_Dark",
      "support": 1
    },
    {
      "x": -1,
      "y": 21,
      "z": 1,
      "name": "Plant_Leaves_Beastwood_Dark",
      "support": 1
    },
    {
      "x": -1,
      "y": 22,
      "z": 1,
      "name": "Plant_Leaves_Beastwood_Dark",
      "support": 1
    },
    {
      "x": -1,
      "y": 23,
      "z": 1,
      "name": "Plant_Leaves_Beastwood_Bright",
      "support": 2
    },
    {
      "x": -1,
      "y": 24,
      "z": 1,
      "name": "Plant_Leaves_Beastwood_Bright"
    },
    {
      "x": -1,
      "y": 25,
      "z": 1,
      "name": "Plant_Leaves_Beastwood_Dark"
    },
    {
      "x": -1,
      "y": 26,
      "z": 1,
      "name": "Plant_Leaves_Beastwood_Dark"
    },
    {
      "x": -1,
      "y": 27,
      "z": 1,
      "name": "Empty"
    },
    {
      "x": -1,
      "y": 0,
      "z": 2,
      "name": "Wood_Beastwood_Bark"
    },
    {
      "x": -1,
      "y": 1,
      "z": 2,
      "name": "Wood_Beastwood_Bark"
    },
    {
      "x": -1,
      "y": 2,
      "z": 2,
      "name": "Wood_Beastwood_Bark"
    },
    {
      "x": -1,
      "y": 3,
      "z": 2,
      "name": "Wood_Beastwood_Bark"
    },
    {
      "x": -1,
      "y": 4,
      "z": 2,
      "name": "Wood_Beastwood_Bark"
    },
    {
      "x": -1,
      "y": 5,
      "z": 2,
      "name": "Wood_Beastwood_Bark"
    },
    {
      "x": -1,
      "y": 6,
      "z": 2,
      "name": "Wood_Beastwood_Bark"
    },
    {
      "x": -1,
      "y": 7,
      "z": 2,
      "name": "Wood_Redwood_Trunk_Full",
      "support": 15
    },
    {
      "x": -1,
      "y": 8,
      "z": 2,
      "name": "Wood_Redwood_Trunk_Full",
      "support": 15
    },
    {
      "x": -1,
      "y": 17,
      "z": 2,
      "name": "Empty"
    },
    {
      "x": -1,
      "y": 18,
      "z": 2,
      "name": "Empty"
    },
    {
      "x": -1,
      "y": 19,
      "z": 2,
      "name": "Plant_Leaves_Beastwood_Dark"
    },
    {
      "x": -1,
      "y": 20,
      "z": 2,
      "name": "Plant_Leaves_Beastwood_Dark"
    },
    {
      "x": -1,
      "y": 21,
      "z": 2,
      "name": "Plant_Leaves_Beastwood_Bright",
      "support": 1
    },
    {
      "x": -1,
      "y": 22,
      "z": 2,
      "name": "Plant_Leaves_Beastwood_Dark",
      "support": 2
    },
    {
      "x": -1,
      "y": 23,
      "z": 2,
      "name": "Plant_Leaves_Beastwood_Dark"
    },
    {
      "x": -1,
      "y": 24,
      "z": 2,
      "name": "Plant_Leaves_Beastwood_Dark"
    },
    {
      "x": -1,
      "y": 25,
      "z": 2,
      "name": "Plant_Leaves_Beastwood_Dark"
    },
    {
      "x": -1,
      "y": 26,
      "z": 2,
      "name": "Plant_Leaves_Beastwood_Dark"
    },
    {
      "x": -1,
      "y": 27,
      "z": 2,
      "name": "Empty"
    },
    {
      "x": -1,
      "y": 28,
      "z": 2,
      "name": "Empty"
    },
    {
      "x": -1,
      "y": 17,
      "z": 3,
      "name": "Empty"
    },
    {
      "x": -1,
      "y": 18,
      "z": 3,
      "name": "Plant_Leaves_Beastwood_Dark",
      "support": 2
    },
    {
      "x": -1,
      "y": 19,
      "z": 3,
      "name": "Plant_Leaves_Beastwood_Dark",
      "support": 1
    },
    {
      "x": -1,
      "y": 20,
      "z": 3,
      "name": "Plant_Leaves_Beastwood_Dark"
    },
    {
      "x": -1,
      "y": 21,
      "z": 3,
      "name": "Plant_Leaves_Beastwood_Bright",
      "support": 1
    },
    {
      "x": -1,
      "y": 22,
      "z": 3,
      "name": "Plant_Leaves_Beastwood_Dark",
      "support": 2
    },
    {
      "x": -1,
      "y": 23,
      "z": 3,
      "name": "Plant_Leaves_Beastwood_Bright"
    },
    {
      "x": -1,
      "y": 24,
      "z": 3,
      "name": "Plant_Leaves_Beastwood_Dark"
    },
    {
      "x": -1,
      "y": 25,
      "z": 3,
      "name": "Plant_Leaves_Beastwood_Bright"
    },
    {
      "x": -1,
      "y": 26,
      "z": 3,
      "name": "Plant_Leaves_Beastwood_Bright"
    },
    {
      "x": -1,
      "y": 27,
      "z": 3,
      "name": "Empty"
    },
    {
      "x": -1,
      "y": 28,
      "z": 3,
      "name": "Empty"
    },
    {
      "x": -1,
      "y": 18,
      "z": 4,
      "name": "Empty"
    },
    {
      "x": -1,
      "y": 19,
      "z": 4,
      "name": "Plant_Leaves_Beastwood_Dark",
      "support": 2
    },
    {
      "x": -1,
      "y": 20,
      "z": 4,
      "name": "Plant_Leaves_Beastwood_Bright",
      "support": 1
    },
    {
      "x": -1,
      "y": 21,
      "z": 4,
      "name": "Plant_Leaves_Beastwood_Dark",
      "support": 2
    },
    {
      "x": -1,
      "y": 22,
      "z": 4,
      "name": "Plant_Leaves_Beastwood_Bright"
    },
    {
      "x": -1,
      "y": 23,
      "z": 4,
      "name": "Plant_Leaves_Beastwood_Dark"
    },
    {
      "x": -1,
      "y": 24,
      "z": 4,
      "name": "Plant_Leaves_Beastwood_Bright"
    },
    {
      "x": -1,
      "y": 25,
      "z": 4,
      "name": "Plant_Leaves_Beastwood_Bright"
    },
    {
      "x": -1,
      "y": 26,
      "z": 4,
      "name": "Empty"
    },
    {
      "x": -1,
      "y": 27,
      "z": 4,
      "name": "Empty"
    },
    {
      "x": -1,
      "y": 28,
      "z": 4,
      "name": "Empty"
    },
    {
      "x": -1,
      "y": 19,
      "z": 5,
      "name": "Empty"
    },
    {
      "x": -1,
      "y": 20,
      "z": 5,
      "name": "Plant_Leaves_Beastwood_Dark",
      "support": 2
    },
    {
      "x": -1,
      "y": 21,
      "z": 5,
      "name": "Empty"
    },
    {
      "x": -1,
      "y": 22,
      "z": 5,
      "name": "Plant_Leaves_Beastwood_Dark"
    },
    {
      "x": -1,
      "y": 23,
      "z": 5,
      "name": "Plant_Leaves_Beastwood_Dark"
    },
    {
      "x": -1,
      "y": 24,
      "z": 5,
      "name": "Empty"
    },
    {
      "x": -1,
      "y": 25,
      "z": 5,
      "name": "Empty"
    },
    {
      "x": -1,
      "y": 26,
      "z": 5,
      "name": "Empty"
    },
    {
      "x": -1,
      "y": 27,
      "z": 5,
      "name": "Empty"
    },
    {
      "x": -1,
      "y": 20,
      "z": 6,
      "name": "Empty"
    },
    {
      "x": -1,
      "y": 21,
      "z": 6,
      "name": "Empty"
    },
    {
      "x": -1,
      "y": 22,
      "z": 6,
      "name": "Empty"
    },
    {
      "x": -1,
      "y": 23,
      "z": 6,
      "name": "Empty"
    },
    {
      "x": -1,
      "y": 24,
      "z": 6,
      "name": "Empty"
    },
    {
      "x": -1,
      "y": 21,
      "z": 7,
      "name": "Empty"
    },
    {
      "x": -1,
      "y": 22,
      "z": 7,
      "name": "Empty"
    },
    {
      "x": -1,
      "y": 23,
      "z": 7,
      "name": "Empty"
    },
    {
      "x": 0,
      "y": 13,
      "z": -12,
      "name": "Empty"
    },
    {
      "x": 0,
      "y": 11,
      "z": -11,
      "name": "Plant_Leaves_Beastwood_Bright"
    },
    {
      "x": 0,
      "y": 12,
      "z": -11,
      "name": "Plant_Leaves_Beastwood_Bright"
    },
    {
      "x": 0,
      "y": 13,
      "z": -11,
      "name": "Plant_Leaves_Beastwood_Dark"
    },
    {
      "x": 0,
      "y": 14,
      "z": -11,
      "name": "Empty"
    },
    {
      "x": 0,
      "y": 9,
      "z": -10,
      "name": "Empty"
    },
    {
      "x": 0,
      "y": 10,
      "z": -10,
      "name": "Plant_Leaves_Beastwood_Bright"
    },
    {
      "x": 0,
      "y": 11,
      "z": -10,
      "name": "Plant_Leaves_Beastwood_Dark"
    },
    {
      "x": 0,
      "y": 12,
      "z": -10,
      "name": "Plant_Leaves_Beastwood_Dark"
    },
    {
      "x": 0,
      "y": 13,
      "z": -10,
      "name": "Plant_Leaves_Beastwood_Dark"
    },
    {
      "x": 0,
      "y": 14,
      "z": -10,
      "name": "Plant_Leaves_Beastwood_Dark"
    },
    {
      "x": 0,
      "y": 15,
      "z": -10,
      "name": "Empty"
    },
    {
      "x": 0,
      "y": 8,
      "z": -9,
      "name": "Empty"
    },
    {
      "x": 0,
      "y": 9,
      "z": -9,
      "name": "Empty"
    },
    {
      "x": 0,
      "y": 10,
      "z": -9,
      "name": "Plant_Leaves_Beastwood_Dark"
    },
    {
      "x": 0,
      "y": 11,
      "z": -9,
      "name": "Plant_Leaves_Beastwood_Dark"
    },
    {
      "x": 0,
      "y": 12,
      "z": -9,
      "name": "Plant_Leaves_Beastwood_Dark"
    },
    {
      "x": 0,
      "y": 13,
      "z": -9,
      "name": "Plant_Leaves_Beastwood_Dark"
    },
    {
      "x": 0,
      "y": 14,
      "z": -9,
      "name": "Plant_Leaves_Beastwood_Dark"
    },
    {
      "x": 0,
      "y": 15,
      "z": -9,
      "name": "Empty"
    },
    {
      "x": 0,
      "y": 16,
      "z": -9,
      "name": "Empty"
    },
    {
      "x": 0,
      "y": 8,
      "z": -8,
      "name": "Empty"
    },
    {
      "x": 0,
      "y": 9,
      "z": -8,
      "name": "Empty"
    },
    {
      "x": 0,
      "y": 10,
      "z": -8,
      "name": "Plant_Leaves_Beastwood_Dark"
    },
    {
      "x": 0,
      "y": 11,
      "z": -8,
      "name": "Plant_Leaves_Beastwood_Bright"
    },
    {
      "x": 0,
      "y": 12,
      "z": -8,
      "name": "Plant_Leaves_Beastwood_Dark"
    },
    {
      "x": 0,
      "y": 13,
      "z": -8,
      "name": "Plant_Leaves_Beastwood_Dark"
    },
    {
      "x": 0,
      "y": 14,
      "z": -8,
      "name": "Plant_Leaves_Beastwood_Dark"
    },
    {
      "x": 0,
      "y": 15,
      "z": -8,
      "name": "Empty"
    },
    {
      "x": 0,
      "y": 16,
      "z": -8,
      "name": "Empty"
    },
    {
      "x": 0,
      "y": 17,
      "z": -8,
      "name": "Empty"
    },
    {
      "x": 0,
      "y": 8,
      "z": -7,
      "name": "Empty"
    },
    {
      "x": 0,
      "y": 9,
      "z": -7,
      "name": "Plant_Leaves_Beastwood_Bright"
    },
    {
      "x": 0,
      "y": 10,
      "z": -7,
      "name": "Plant_Leaves_Beastwood_Dark"
    },
    {
      "x": 0,
      "y": 11,
      "z": -7,
      "name": "Plant_Leaves_Beastwood_Bright"
    },
    {
      "x": 0,
      "y": 12,
      "z": -7,
      "name": "Plant_Leaves_Beastwood_Dark"
    },
    {
      "x": 0,
      "y": 13,
      "z": -7,
      "name": "Plant_Leaves_Beastwood_Bright"
    },
    {
      "x": 0,
      "y": 14,
      "z": -7,
      "name": "Plant_Leaves_Beastwood_Bright"
    },
    {
      "x": 0,
      "y": 15,
      "z": -7,
      "name": "Plant_Leaves_Beastwood_Dark"
    },
    {
      "x": 0,
      "y": 16,
      "z": -7,
      "name": "Empty"
    },
    {
      "x": 0,
      "y": 17,
      "z": -7,
      "name": "Empty"
    },
    {
      "x": 0,
      "y": 9,
      "z": -6,
      "name": "Plant_Leaves_Beastwood_Dark"
    },
    {
      "x": 0,
      "y": 10,
      "z": -6,
      "name": "Plant_Leaves_Beastwood_Dark"
    },
    {
      "x": 0,
      "y": 11,
      "z": -6,
      "name": "Plant_Leaves_Beastwood_Dark"
    },
    {
      "x": 0,
      "y": 12,
      "z": -6,
      "name": "Plant_Leaves_Beastwood_Dark"
    },
    {
      "x": 0,
      "y": 13,
      "z": -6,
      "name": "Plant_Leaves_Beastwood_Dark"
    },
    {
      "x": 0,
      "y": 14,
      "z": -6,
      "name": "Plant_Leaves_Beastwood_Dark"
    },
    {
      "x": 0,
      "y": 15,
      "z": -6,
      "name": "Plant_Leaves_Beastwood_Dark"
    },
    {
      "x": 0,
      "y": 16,
      "z": -6,
      "name": "Empty"
    },
    {
      "x": 0,
      "y": 17,
      "z": -6,
      "name": "Empty"
    },
    {
      "x": 0,
      "y": 8,
      "z": -5,
      "name": "Plant_Leaves_Beastwood_Dark"
    },
    {
      "x": 0,
      "y": 9,
      "z": -5,
      "name": "Wood_Redwood_Branch_Corner",
      "support": 15,
      "rotation": 2
    },
    {
      "x": 0,
      "y": 10,
      "z": -5,
      "name": "Wood_Redwood_Branch_Long",
      "support": 15
    },
    {
      "x": 0,
      "y": 11,
      "z": -5,
      "name": "Wood_Redwood_Branch_Long",
      "support": 15
    },
    {
      "x": 0,
      "y": 12,
      "z": -5,
      "name": "Wood_Redwood_Branch_Long",
      "support": 15
    },
    {
      "x": 0,
      "y": 13,
      "z": -5,
      "name": "Plant_Leaves_Beastwood_Dark"
    },
    {
      "x": 0,
      "y": 14,
      "z": -5,
      "name": "Plant_Leaves_Beastwood_Dark"
    },
    {
      "x": 0,
      "y": 15,
      "z": -5,
      "name": "Empty"
    },
    {
      "x": 0,
      "y": 16,
      "z": -5,
      "name": "Empty"
    },
    {
      "x": 0,
      "y": 17,
      "z": -5,
      "name": "Empty"
    },
    {
      "x": 0,
      "y": 18,
      "z": -5,
      "name": "Empty"
    },
    {
      "x": 0,
      "y": 19,
      "z": -5,
      "name": "Empty"
    },
    {
      "x": 0,
      "y": 21,
      "z": -5,
      "name": "Empty"
    },
    {
      "x": 0,
      "y": 22,
      "z": -5,
      "name": "Empty"
    },
    {
      "x": 0,
      "y": 23,
      "z": -5,
      "name": "Empty"
    },
    {
      "x": 0,
      "y": 24,
      "z": -5,
      "name": "Empty"
    },
    {
      "x": 0,
      "y": 25,
      "z": -5,
      "name": "Empty"
    },
    {
      "x": 0,
      "y": 26,
      "z": -5,
      "name": "Empty"
    },
    {
      "x": 0,
      "y": 9,
      "z": -4,
      "name": "Wood_Redwood_Branch_Long",
      "support": 15,
      "rotation": 4
    },
    {
      "x": 0,
      "y": 10,
      "z": -4,
      "name": "Plant_Leaves_Beastwood_Dark"
    },
    {
      "x": 0,
      "y": 11,
      "z": -4,
      "name": "Plant_Leaves_Beastwood_Bright"
    },
    {
      "x": 0,
      "y": 12,
      "z": -4,
      "name": "Plant_Leaves_Beastwood_Bright"
    },
    {
      "x": 0,
      "y": 13,
      "z": -4,
      "name": "Plant_Leaves_Beastwood_Dark"
    },
    {
      "x": 0,
      "y": 14,
      "z": -4,
      "name": "Plant_Leaves_Beastwood_Dark"
    },
    {
      "x": 0,
      "y": 16,
      "z": -4,
      "name": "Empty"
    },
    {
      "x": 0,
      "y": 17,
      "z": -4,
      "name": "Empty"
    },
    {
      "x": 0,
      "y": 18,
      "z": -4,
      "name": "Empty"
    },
    {
      "x": 0,
      "y": 19,
      "z": -4,
      "name": "Plant_Leaves_Beastwood_Dark"
    },
    {
      "x": 0,
      "y": 20,
      "z": -4,
      "name": "Plant_Leaves_Beastwood_Dark"
    },
    {
      "x": 0,
      "y": 21,
      "z": -4,
      "name": "Plant_Leaves_Beastwood_Bright"
    },
    {
      "x": 0,
      "y": 22,
      "z": -4,
      "name": "Plant_Leaves_Beastwood_Bright"
    },
    {
      "x": 0,
      "y": 23,
      "z": -4,
      "name": "Empty"
    },
    {
      "x": 0,
      "y": 24,
      "z": -4,
      "name": "Empty"
    },
    {
      "x": 0,
      "y": 25,
      "z": -4,
      "name": "Empty"
    },
    {
      "x": 0,
      "y": 26,
      "z": -4,
      "name": "Empty"
    },
    {
      "x": 0,
      "y": 27,
      "z": -4,
      "name": "Empty"
    },
    {
      "x": 0,
      "y": 0,
      "z": -3,
      "name": "Wood_Redwood_Trunk_Full",
      "support": 15
    },
    {
      "x": 0,
      "y": 1,
      "z": -3,
      "name": "Wood_Redwood_Trunk_Full",
      "support": 15
    },
    {
      "x": 0,
      "y": 9,
      "z": -3,
      "name": "Wood_Redwood_Branch_Long",
      "support": 15,
      "rotation": 4
    },
    {
      "x": 0,
      "y": 10,
      "z": -3,
      "name": "Plant_Leaves_Beastwood_Dark"
    },
    {
      "x": 0,
      "y": 11,
      "z": -3,
      "name": "Plant_Leaves_Beastwood_Bright"
    },
    {
      "x": 0,
      "y": 12,
      "z": -3,
      "name": "Plant_Leaves_Beastwood_Dark"
    },
    {
      "x": 0,
      "y": 13,
      "z": -3,
      "name": "Plant_Leaves_Beastwood_Dark"
    },
    {
      "x": 0,
      "y": 16,
      "z": -3,
      "name": "Empty"
    },
    {
      "x": 0,
      "y": 17,
      "z": -3,
      "name": "Empty"
    },
    {
      "x": 0,
      "y": 18,
      "z": -3,
      "name": "Plant_Leaves_Beastwood_Dark"
    },
    {
      "x": 0,
      "y": 19,
      "z": -3,
      "name": "Plant_Leaves_Beastwood_Dark"
    },
    {
      "x": 0,
      "y": 20,
      "z": -3,
      "name": "Plant_Leaves_Beastwood_Dark"
    },
    {
      "x": 0,
      "y": 21,
      "z": -3,
      "name": "Plant_Leaves_Beastwood_Dark"
    },
    {
      "x": 0,
      "y": 22,
      "z": -3,
      "name": "Plant_Leaves_Beastwood_Dark"
    },
    {
      "x": 0,
      "y": 23,
      "z": -3,
      "name": "Plant_Leaves_Beastwood_Bright"
    },
    {
      "x": 0,
      "y": 24,
      "z": -3,
      "name": "Empty"
    },
    {
      "x": 0,
      "y": 25,
      "z": -3,
      "name": "Empty"
    },
    {
      "x": 0,
      "y": 26,
      "z": -3,
      "name": "Empty"
    },
    {
      "x": 0,
      "y": 27,
      "z": -3,
      "name": "Empty"
    },
    {
      "x": 0,
      "y": 0,
      "z": -2,
      "name": "Wood_Beastwood_Bark"
    },
    {
      "x": 0,
      "y": 1,
      "z": -2,
      "name": "Wood_Beastwood_Bark"
    },
    {
      "x": 0,
      "y": 2,
      "z": -2,
      "name": "Wood_Beastwood_Bark"
    },
    {
      "x": 0,
      "y": 3,
      "z": -2,
      "name": "Wood_Beastwood_Bark"
    },
    {
      "x": 0,
      "y": 4,
      "z": -2,
      "name": "Wood_Beastwood_Bark"
    },
    {
      "x": 0,
      "y": 5,
      "z": -2,
      "name": "Wood_Beastwood_Bark"
    },
    {
      "x": 0,
      "y": 6,
      "z": -2,
      "name": "Wood_Beastwood_Bark"
    },
    {
      "x": 0,
      "y": 7,
      "z": -2,
      "name": "Wood_Beastwood_Bark"
    },
    {
      "x": 0,
      "y": 8,
      "z": -2,
      "name": "Wood_Beastwood_Bark"
    },
    {
      "x": 0,
      "y": 9,
      "z": -2,
      "name": "Wood_Beastwood_Bark"
    },
    {
      "x": 0,
      "y": 10,
      "z": -2,
      "name": "Wood_Beastwood_Bark"
    },
    {
      "x": 0,
      "y": 16,
      "z": -2,
      "name": "Empty"
    },
    {
      "x": 0,
      "y": 17,
      "z": -2,
      "name": "Empty"
    },
    {
      "x": 0,
      "y": 18,
      "z": -2,
      "name": "Plant_Leaves_Beastwood_Dark"
    },
    {
      "x": 0,
      "y": 19,
      "z": -2,
      "name": "Empty",
      "support": 15
    },
    {
      "x": 0,
      "y": 20,
      "z": -2,
      "name": "Empty",
      "support": 15
    },
    {
      "x": 0,
      "y": 21,
      "z": -2,
      "name": "Plant_Leaves_Beastwood_Dark"
    },
    {
      "x": 0,
      "y": 22,
      "z": -2,
      "name": "Plant_Leaves_Beastwood_Dark",
      "support": 1
    },
    {
      "x": 0,
      "y": 23,
      "z": -2,
      "name": "Plant_Leaves_Beastwood_Bright",
      "support": 2
    },
    {
      "x": 0,
      "y": 24,
      "z": -2,
      "name": "Plant_Leaves_Beastwood_Dark"
    },
    {
      "x": 0,
      "y": 25,
      "z": -2,
      "name": "Empty"
    },
    {
      "x": 0,
      "y": 26,
      "z": -2,
      "name": "Empty"
    },
    {
      "x": 0,
      "y": 27,
      "z": -2,
      "name": "Empty"
    },
    {
      "x": 0,
      "y": 0,
      "z": -1,
      "name": "Wood_Redwood_Trunk_Full",
      "support": 15
    },
    {
      "x": 0,
      "y": 1,
      "z": -1,
      "name": "Wood_Beastwood_Plhoem_Sap"
    },
    {
      "x": 0,
      "y": 2,
      "z": -1,
      "name": "Wood_Beastwood_Plhoem_Sap"
    },
    {
      "x": 0,
      "y": 3,
      "z": -1,
      "name": "Wood_Beastwood_Plhoem_Sap"
    },
    {
      "x": 0,
      "y": 4,
      "z": -1,
      "name": "Wood_Beastwood_Plhoem_Sap"
    },
    {
      "x": 0,
      "y": 5,
      "z": -1,
      "name": "Wood_Beastwood_Plhoem_Sap"
    },
    {
      "x": 0,
      "y": 6,
      "z": -1,
      "name": "Wood_Beastwood_Plhoem_Sap"
    },
    {
      "x": 0,
      "y": 7,
      "z": -1,
      "name": "Wood_Beastwood_Plhoem_Sap"
    },
    {
      "x": 0,
      "y": 8,
      "z": -1,
      "name": "Wood_Beastwood_Bark"
    },
    {
      "x": 0,
      "y": 9,
      "z": -1,
      "name": "Wood_Beastwood_Bark"
    },
    {
      "x": 0,
      "y": 10,
      "z": -1,
      "name": "Wood_Beastwood_Bark"
    },
    {
      "x": 0,
      "y": 11,
      "z": -1,
      "name": "Wood_Beastwood_Bark"
    },
    {
      "x": 0,
      "y": 12,
      "z": -1,
      "name": "Wood_Beastwood_Bark"
    },
    {
      "x": 0,
      "y": 13,
      "z": -1,
      "name": "Wood_Beastwood_Bark"
    },
    {
      "x": 0,
      "y": 14,
      "z": -1,
      "name": "Wood_Beastwood_Bark"
    },
    {
      "x": 0,
      "y": 15,
      "z": -1,
      "name": "Wood_Beastwood_Bark"
    },
    {
      "x": 0,
      "y": 16,
      "z": -1,
      "name": "Wood_Beastwood_Bark"
    },
    {
      "x": 0,
      "y": 17,
      "z": -1,
      "name": "Wood_Beastwood_Bark"
    },
    {
      "x": 0,
      "y": 18,
      "z": -1,
      "name": "Empty",
      "support": 15
    },
    {
      "x": 0,
      "y": 19,
      "z": -1,
      "name": "Empty",
      "support": 15
    },
    {
      "x": 0,
      "y": 20,
      "z": -1,
      "name": "Plant_Leaves_Beastwood_Dark"
    },
    {
      "x": 0,
      "y": 21,
      "z": -1,
      "name": "Plant_Leaves_Beastwood_Dark"
    },
    {
      "x": 0,
      "y": 22,
      "z": -1,
      "name": "Plant_Leaves_Beastwood_Dark"
    },
    {
      "x": 0,
      "y": 23,
      "z": -1,
      "name": "Plant_Leaves_Beastwood_Bright",
      "support": 1
    },
    {
      "x": 0,
      "y": 24,
      "z": -1,
      "name": "Plant_Leaves_Beastwood_Dark",
      "support": 2
    },
    {
      "x": 0,
      "y": 25,
      "z": -1,
      "name": "Plant_Leaves_Beastwood_Bright"
    },
    {
      "x": 0,
      "y": 26,
      "z": -1,
      "name": "Empty"
    },
    {
      "x": 0,
      "y": 27,
      "z": -1,
      "name": "Empty"
    },
    {
      "x": 0,
      "y": 0,
      "z": 0,
      "name": "Wood_Redwood_Trunk_Full",
      "support": 15
    },
    {
      "x": 0,
      "y": 1,
      "z": 0,
      "name": "Wood_Beastwood_Sapwood"
    },
    {
      "x": 0,
      "y": 2,
      "z": 0,
      "name": "Wood_Beastwood_Sapwood"
    },
    {
      "x": 0,
      "y": 3,
      "z": 0,
      "name": "Wood_Beastwood_Sapwood"
    },
    {
      "x": 0,
      "y": 4,
      "z": 0,
      "name": "Wood_Beastwood_Sapwood"
    },
    {
      "x": 0,
      "y": 5,
      "z": 0,
      "name": "Wood_Beastwood_Sapwood"
    },
    {
      "x": 0,
      "y": 6,
      "z": 0,
      "name": "Wood_Beastwood_Sapwood"
    },
    {
      "x": 0,
      "y": 7,
      "z": 0,
      "name": "Wood_Beastwood_Sapwood"
    },
    {
      "x": 0,
      "y": 8,
      "z": 0,
      "name": "Wood_Beastwood_Plhoem_Sap"
    },
    {
      "x": 0,
      "y": 9,
      "z": 0,
      "name": "Wood_Beastwood_Plhoem_Sap"
    },
    {
      "x": 0,
      "y": 10,
      "z": 0,
      "name": "Wood_Beastwood_Plhoem_Sap"
    },
    {
      "x": 0,
      "y": 11,
      "z": 0,
      "name": "Wood_Beastwood_Plhoem_Sap"
    },
    {
      "x": 0,
      "y": 12,
      "z": 0,
      "name": "Wood_Beastwood_Plhoem_Sap"
    },
    {
      "x": 0,
      "y": 13,
      "z": 0,
      "name": "Wood_Beastwood_Plhoem_Sap"
    },
    {
      "x": 0,
      "y": 14,
      "z": 0,
      "name": "Wood_Beastwood_Plhoem_Sap"
    },
    {
      "x": 0,
      "y": 15,
      "z": 0,
      "name": "Wood_Beastwood_Plhoem_Sap"
    },
    {
      "x": 0,
      "y": 16,
      "z": 0,
      "name": "Wood_Beastwood_Plhoem_Sap"
    },
    {
      "x": 0,
      "y": 17,
      "z": 0,
      "name": "Wood_Beastwood_Plhoem_Sap"
    },
    {
      "x": 0,
      "y": 18,
      "z": 0,
      "name": "Wood_Beastwood_Bark"
    },
    {
      "x": 0,
      "y": 19,
      "z": 0,
      "name": "Wood_Redwood_Branch_Long",
      "support": 15
    },
    {
      "x": 0,
      "y": 20,
      "z": 0,
      "name": "Wood_Redwood_Branch_Long",
      "support": 15
    },
    {
      "x": 0,
      "y": 21,
      "z": 0,
      "name": "Wood_Redwood_Branch_Long",
      "support": 15
    },
    {
      "x": 0,
      "y": 22,
      "z": 0,
      "name": "Wood_Redwood_Branch_Long",
      "support": 15
    },
    {
      "x": 0,
      "y": 23,
      "z": 0,
      "name": "Plant_Leaves_Beastwood_Dark"
    },
    {
      "x": 0,
      "y": 24,
      "z": 0,
      "name": "Plant_Leaves_Beastwood_Bright",
      "support": 1
    },
    {
      "x": 0,
      "y": 25,
      "z": 0,
      "name": "Plant_Leaves_Beastwood_Dark"
    },
    {
      "x": 0,
      "y": 26,
      "z": 0,
      "name": "Plant_Leaves_Beastwood_Dark"
    },
    {
      "x": 0,
      "y": 27,
      "z": 0,
      "name": "Empty"
    },
    {
      "x": 0,
      "y": 0,
      "z": 1,
      "name": "Wood_Redwood_Trunk_Full",
      "support": 15
    },
    {
      "x": 0,
      "y": 1,
      "z": 1,
      "name": "Wood_Beastwood_Plhoem_Sap"
    },
    {
      "x": 0,
      "y": 2,
      "z": 1,
      "name": "Wood_Beastwood_Plhoem_Sap"
    },
    {
      "x": 0,
      "y": 3,
      "z": 1,
      "name": "Wood_Beastwood_Plhoem_Sap"
    },
    {
      "x": 0,
      "y": 4,
      "z": 1,
      "name": "Wood_Beastwood_Plhoem_Sap"
    },
    {
      "x": 0,
      "y": 5,
      "z": 1,
      "name": "Wood_Beastwood_Plhoem_Sap"
    },
    {
      "x": 0,
      "y": 6,
      "z": 1,
      "name": "Wood_Beastwood_Plhoem_Sap"
    },
    {
      "x": 0,
      "y": 7,
      "z": 1,
      "name": "Wood_Beastwood_Plhoem_Sap"
    },
    {
      "x": 0,
      "y": 8,
      "z": 1,
      "name": "Wood_Beastwood_Bark"
    },
    {
      "x": 0,
      "y": 9,
      "z": 1,
      "name": "Wood_Beastwood_Bark"
    },
    {
      "x": 0,
      "y": 10,
      "z": 1,
      "name": "Wood_Beastwood_Bark"
    },
    {
      "x": 0,
      "y": 11,
      "z": 1,
      "name": "Wood_Beastwood_Bark"
    },
    {
      "x": 0,
      "y": 12,
      "z": 1,
      "name": "Wood_Beastwood_Bark"
    },
    {
      "x": 0,
      "y": 13,
      "z": 1,
      "name": "Wood_Beastwood_Bark"
    },
    {
      "x": 0,
      "y": 14,
      "z": 1,
      "name": "Wood_Beastwood_Bark"
    },
    {
      "x": 0,
      "y": 15,
      "z": 1,
      "name": "Wood_Beastwood_Bark"
    },
    {
      "x": 0,
      "y": 16,
      "z": 1,
      "name": "Wood_Beastwood_Bark"
    },
    {
      "x": 0,
      "y": 17,
      "z": 1,
      "name": "Wood_Beastwood_Bark"
    },
    {
      "x": 0,
      "y": 18,
      "z": 1,
      "name": "Empty",
      "support": 15
    },
    {
      "x": 0,
      "y": 19,
      "z": 1,
      "name": "Empty",
      "support": 15
    },
    {
      "x": 0,
      "y": 20,
      "z": 1,
      "name": "Plant_Leaves_Beastwood_Dark"
    },
    {
      "x": 0,
      "y": 21,
      "z": 1,
      "name": "Plant_Leaves_Beastwood_Dark"
    },
    {
      "x": 0,
      "y": 22,
      "z": 1,
      "name": "Plant_Leaves_Beastwood_Dark"
    },
    {
      "x": 0,
      "y": 23,
      "z": 1,
      "name": "Plant_Leaves_Beastwood_Bright",
      "support": 1
    },
    {
      "x": 0,
      "y": 24,
      "z": 1,
      "name": "Plant_Leaves_Beastwood_Bright",
      "support": 2
    },
    {
      "x": 0,
      "y": 25,
      "z": 1,
      "name": "Plant_Leaves_Beastwood_Dark"
    },
    {
      "x": 0,
      "y": 26,
      "z": 1,
      "name": "Empty"
    },
    {
      "x": 0,
      "y": 0,
      "z": 2,
      "name": "Wood_Beastwood_Bark"
    },
    {
      "x": 0,
      "y": 1,
      "z": 2,
      "name": "Wood_Beastwood_Bark"
    },
    {
      "x": 0,
      "y": 2,
      "z": 2,
      "name": "Wood_Beastwood_Bark"
    },
    {
      "x": 0,
      "y": 3,
      "z": 2,
      "name": "Wood_Beastwood_Bark"
    },
    {
      "x": 0,
      "y": 4,
      "z": 2,
      "name": "Wood_Beastwood_Bark"
    },
    {
      "x": 0,
      "y": 5,
      "z": 2,
      "name": "Wood_Beastwood_Bark"
    },
    {
      "x": 0,
      "y": 6,
      "z": 2,
      "name": "Wood_Beastwood_Bark"
    },
    {
      "x": 0,
      "y": 7,
      "z": 2,
      "name": "Wood_Beastwood_Bark"
    },
    {
      "x": 0,
      "y": 8,
      "z": 2,
      "name": "Wood_Beastwood_Bark"
    },
    {
      "x": 0,
      "y": 9,
      "z": 2,
      "name": "Wood_Beastwood_Bark"
    },
    {
      "x": 0,
      "y": 10,
      "z": 2,
      "name": "Wood_Beastwood_Bark"
    },
    {
      "x": 0,
      "y": 11,
      "z": 2,
      "name": "Wood_Beastwood_Bark"
    },
    {
      "x": 0,
      "y": 17,
      "z": 2,
      "name": "Empty"
    },
    {
      "x": 0,
      "y": 18,
      "z": 2,
      "name": "Plant_Leaves_Beastwood_Dark"
    },
    {
      "x": 0,
      "y": 19,
      "z": 2,
      "name": "Empty",
      "support": 15
    },
    {
      "x": 0,
      "y": 20,
      "z": 2,
      "name": "Empty",
      "support": 15
    },
    {
      "x": 0,
      "y": 21,
      "z": 2,
      "name": "Plant_Leaves_Beastwood_Bright"
    },
    {
      "x": 0,
      "y": 22,
      "z": 2,
      "name": "Plant_Leaves_Beastwood_Bright",
      "support": 1
    },
    {
      "x": 0,
      "y": 23,
      "z": 2,
      "name": "Plant_Leaves_Beastwood_Dark",
      "support": 2
    },
    {
      "x": 0,
      "y": 24,
      "z": 2,
      "name": "Plant_Leaves_Beastwood_Dark"
    },
    {
      "x": 0,
      "y": 25,
      "z": 2,
      "name": "Plant_Leaves_Beastwood_Dark"
    },
    {
      "x": 0,
      "y": 26,
      "z": 2,
      "name": "Plant_Leaves_Beastwood_Bright"
    },
    {
      "x": 0,
      "y": 27,
      "z": 2,
      "name": "Empty"
    },
    {
      "x": 0,
      "y": 0,
      "z": 3,
      "name": "Wood_Redwood_Trunk_Full",
      "support": 15
    },
    {
      "x": 0,
      "y": 1,
      "z": 3,
      "name": "Wood_Redwood_Trunk_Full",
      "support": 15
    },
    {
      "x": 0,
      "y": 2,
      "z": 3,
      "name": "Wood_Redwood_Trunk_Full",
      "support": 15
    },
    {
      "x": 0,
      "y": 3,
      "z": 3,
      "name": "Wood_Redwood_Trunk_Full",
      "support": 15
    },
    {
      "x": 0,
      "y": 4,
      "z": 3,
      "name": "Wood_Redwood_Trunk_Full",
      "support": 15
    },
    {
      "x": 0,
      "y": 5,
      "z": 3,
      "name": "Wood_Redwood_Trunk_Full",
      "support": 15
    },
    {
      "x": 0,
      "y": 6,
      "z": 3,
      "name": "Wood_Redwood_Trunk_Full",
      "support": 15
    },
    {
      "x": 0,
      "y": 16,
      "z": 3,
      "name": "Empty"
    },
    {
      "x": 0,
      "y": 17,
      "z": 3,
      "name": "Empty"
    },
    {
      "x": 0,
      "y": 18,
      "z": 3,
      "name": "Plant_Leaves_Beastwood_Bright",
      "support": 1
    },
    {
      "x": 0,
      "y": 19,
      "z": 3,
      "name": "Plant_Leaves_Beastwood_Dark"
    },
    {
      "x": 0,
      "y": 20,
      "z": 3,
      "name": "Empty",
      "support": 15
    },
    {
      "x": 0,
      "y": 21,
      "z": 3,
      "name": "Plant_Leaves_Beastwood_Dark"
    },
    {
      "x": 0,
      "y": 22,
      "z": 3,
      "name": "Plant_Leaves_Beastwood_Dark",
      "support": 1
    },
    {
      "x": 0,
      "y": 23,
      "z": 3,
      "name": "Plant_Leaves_Beastwood_Dark"
    },
    {
      "x": 0,
      "y": 24,
      "z": 3,
      "name": "Plant_Leaves_Beastwood_Dark"
    },
    {
      "x": 0,
      "y": 25,
      "z": 3,
      "name": "Plant_Leaves_Beastwood_Bright"
    },
    {
      "x": 0,
      "y": 26,
      "z": 3,
      "name": "Empty"
    },
    {
      "x": 0,
      "y": 27,
      "z": 3,
      "name": "Empty"
    },
    {
      "x": 0,
      "y": 28,
      "z": 3,
      "name": "Empty"
    },
    {
      "x": 0,
      "y": 17,
      "z": 4,
      "name": "Empty"
    },
    {
      "x": 0,
      "y": 18,
      "z": 4,
      "name": "Plant_Leaves_Beastwood_Bright",
      "support": 2
    },
    {
      "x": 0,
      "y": 19,
      "z": 4,
      "name": "Plant_Leaves_Beastwood_Dark",
      "support": 1
    },
    {
      "x": 0,
      "y": 20,
      "z": 4,
      "name": "Plant_Leaves_Beastwood_Dark"
    },
    {
      "x": 0,
      "y": 21,
      "z": 4,
      "name": "Plant_Leaves_Beastwood_Bright",
      "support": 1
    },
    {
      "x": 0,
      "y": 22,
      "z": 4,
      "name": "Plant_Leaves_Beastwood_Bright",
      "support": 2
    },
    {
      "x": 0,
      "y": 23,
      "z": 4,
      "name": "Plant_Leaves_Beastwood_Dark"
    },
    {
      "x": 0,
      "y": 24,
      "z": 4,
      "name": "Plant_Leaves_Beastwood_Bright"
    },
    {
      "x": 0,
      "y": 25,
      "z": 4,
      "name": "Empty"
    },
    {
      "x": 0,
      "y": 26,
      "z": 4,
      "name": "Empty"
    },
    {
      "x": 0,
      "y": 27,
      "z": 4,
      "name": "Empty"
    },
    {
      "x": 0,
      "y": 18,
      "z": 5,
      "name": "Empty"
    },
    {
      "x": 0,
      "y": 19,
      "z": 5,
      "name": "Plant_Leaves_Beastwood_Dark",
      "support": 2
    },
    {
      "x": 0,
      "y": 20,
      "z": 5,
      "name": "Plant_Leaves_Beastwood_Dark",
      "support": 1
    },
    {
      "x": 0,
      "y": 21,
      "z": 5,
      "name": "Plant_Leaves_Beastwood_Bright",
      "support": 2
    },
    {
      "x": 0,
      "y": 22,
      "z": 5,
      "name": "Plant_Leaves_Beastwood_Dark"
    },
    {
      "x": 0,
      "y": 23,
      "z": 5,
      "name": "Plant_Leaves_Beastwood_Dark"
    },
    {
      "x": 0,
      "y": 24,
      "z": 5,
      "name": "Empty"
    },
    {
      "x": 0,
      "y": 26,
      "z": 5,
      "name": "Empty"
    },
    {
      "x": 0,
      "y": 19,
      "z": 6,
      "name": "Empty"
    },
    {
      "x": 0,
      "y": 20,
      "z": 6,
      "name": "Empty"
    },
    {
      "x": 0,
      "y": 21,
      "z": 6,
      "name": "Empty"
    },
    {
      "x": 0,
      "y": 22,
      "z": 6,
      "name": "Empty"
    },
    {
      "x": 0,
      "y": 23,
      "z": 6,
      "name": "Empty"
    },
    {
      "x": 0,
      "y": 20,
      "z": 7,
      "name": "Empty"
    },
    {
      "x": 0,
      "y": 21,
      "z": 7,
      "name": "Empty"
    },
    {
      "x": 0,
      "y": 22,
      "z": 7,
      "name": "Empty"
    },
    {
      "x": 1,
      "y": 12,
      "z": -12,
      "name": "Empty"
    },
    {
      "x": 1,
      "y": 13,
      "z": -12,
      "name": "Empty"
    },
    {
      "x": 1,
      "y": 14,
      "z": -12,
      "name": "Empty"
    },
    {
      "x": 1,
      "y": 11,
      "z": -11,
      "name": "Empty"
    },
    {
      "x": 1,
      "y": 12,
      "z": -11,
      "name": "Plant_Leaves_Beastwood_Dark"
    },
    {
      "x": 1,
      "y": 13,
      "z": -11,
      "name": "Empty"
    },
    {
      "x": 1,
      "y": 14,
      "z": -11,
      "name": "Empty"
    },
    {
      "x": 1,
      "y": 15,
      "z": -11,
      "name": "Empty"
    },
    {
      "x": 1,
      "y": 10,
      "z": -10,
      "name": "Empty"
    },
    {
      "x": 1,
      "y": 11,
      "z": -10,
      "name": "Plant_Leaves_Beastwood_Bright"
    },
    {
      "x": 1,
      "y": 12,
      "z": -10,
      "name": "Plant_Leaves_Beastwood_Dark"
    },
    {
      "x": 1,
      "y": 13,
      "z": -10,
      "name": "Plant_Leaves_Beastwood_Dark"
    },
    {
      "x": 1,
      "y": 14,
      "z": -10,
      "name": "Empty"
    },
    {
      "x": 1,
      "y": 15,
      "z": -10,
      "name": "Empty"
    },
    {
      "x": 1,
      "y": 9,
      "z": -9,
      "name": "Empty"
    },
    {
      "x": 1,
      "y": 10,
      "z": -9,
      "name": "Plant_Leaves_Beastwood_Dark"
    },
    {
      "x": 1,
      "y": 11,
      "z": -9,
      "name": "Plant_Leaves_Beastwood_Dark"
    },
    {
      "x": 1,
      "y": 12,
      "z": -9,
      "name": "Plant_Leaves_Beastwood_Bright"
    },
    {
      "x": 1,
      "y": 13,
      "z": -9,
      "name": "Plant_Leaves_Beastwood_Bright"
    },
    {
      "x": 1,
      "y": 14,
      "z": -9,
      "name": "Plant_Leaves_Beastwood_Bright"
    },
    {
      "x": 1,
      "y": 15,
      "z": -9,
      "name": "Empty"
    },
    {
      "x": 1,
      "y": 8,
      "z": -8,
      "name": "Empty"
    },
    {
      "x": 1,
      "y": 9,
      "z": -8,
      "name": "Empty"
    },
    {
      "x": 1,
      "y": 10,
      "z": -8,
      "name": "Plant_Leaves_Beastwood_Dark"
    },
    {
      "x": 1,
      "y": 11,
      "z": -8,
      "name": "Plant_Leaves_Beastwood_Dark"
    },
    {
      "x": 1,
      "y": 12,
      "z": -8,
      "name": "Plant_Leaves_Beastwood_Dark"
    },
    {
      "x": 1,
      "y": 13,
      "z": -8,
      "name": "Plant_Leaves_Beastwood_Dark"
    },
    {
      "x": 1,
      "y": 14,
      "z": -8,
      "name": "Plant_Leaves_Beastwood_Bright"
    },
    {
      "x": 1,
      "y": 15,
      "z": -8,
      "name": "Empty"
    },
    {
      "x": 1,
      "y": 16,
      "z": -8,
      "name": "Empty"
    },
    {
      "x": 1,
      "y": 8,
      "z": -7,
      "name": "Empty"
    },
    {
      "x": 1,
      "y": 9,
      "z": -7,
      "name": "Plant_Leaves_Beastwood_Dark"
    },
    {
      "x": 1,
      "y": 10,
      "z": -7,
      "name": "Plant_Leaves_Beastwood_Bright"
    },
    {
      "x": 1,
      "y": 11,
      "z": -7,
      "name": "Plant_Leaves_Beastwood_Bright"
    },
    {
      "x": 1,
      "y": 12,
      "z": -7,
      "name": "Plant_Leaves_Beastwood_Dark"
    },
    {
      "x": 1,
      "y": 13,
      "z": -7,
      "name": "Plant_Leaves_Beastwood_Bright"
    },
    {
      "x": 1,
      "y": 14,
      "z": -7,
      "name": "Plant_Leaves_Beastwood_Dark"
    },
    {
      "x": 1,
      "y": 15,
      "z": -7,
      "name": "Plant_Leaves_Beastwood_Dark"
    },
    {
      "x": 1,
      "y": 16,
      "z": -7,
      "name": "Empty"
    },
    {
      "x": 1,
      "y": 17,
      "z": -7,
      "name": "Empty"
    },
    {
      "x": 1,
      "y": 9,
      "z": -6,
      "name": "Empty"
    },
    {
      "x": 1,
      "y": 10,
      "z": -6,
      "name": "Plant_Leaves_Beastwood_Dark"
    },
    {
      "x": 1,
      "y": 11,
      "z": -6,
      "name": "Plant_Leaves_Beastwood_Dark"
    },
    {
      "x": 1,
      "y": 12,
      "z": -6,
      "name": "Plant_Leaves_Beastwood_Dark"
    },
    {
      "x": 1,
      "y": 13,
      "z": -6,
      "name": "Plant_Leaves_Beastwood_Bright"
    },
    {
      "x": 1,
      "y": 14,
      "z": -6,
      "name": "Plant_Leaves_Beastwood_Bright"
    },
    {
      "x": 1,
      "y": 15,
      "z": -6,
      "name": "Plant_Leaves_Beastwood_Bright"
    },
    {
      "x": 1,
      "y": 16,
      "z": -6,
