{
  "version": 8,
  "blockIdVersion": 11,
  "anchorX": 0,
  "anchorY": 0,
  "anchorZ": 0,
  "blocks": [
    {
      "x": -2,
      "y": 8,
      "z": -3,
      "name": "Plant_Leaves_Beastwood_Dark"
    },
    {
      "x": -1,
      "y": 8,
      "z": -5,
      "name": "Plant_Leaves_Beastwood_Dark"
    },
    {
      "x": -1,
      "y": 9,
      "z": -5,
      "name": "Plant_Leaves_Beastwood_Dark"
    },
    {
      "x": -1,
      "y": 7,
      "z": -4,
      "name": "Plant_Leaves_Beastwood_Bright"
    },
    {
      "x": -1,
      "y": 8,
      "z": -4,
      "name": "Plant_Leaves_Beastwood_Bright"
    },
    {
      "x": -1,
      "y": 9,
      "z": -4,
      "name": "Plant_Leaves_Beastwood_Dark"
    },
    {
      "x": -1,
      "y": 7,
      "z": -3,
      "name": "Plant_Leaves_Beastwood_Bright"
    },
    {
      "x": -1,
      "y": 8,
      "z": -3,
      "name": "Plant_Leaves_Beastwood_Dark"
    },
    {
      "x": -1,
      "y": 9,
      "z": -3,
      "name": "Plant_Leaves_Beastwood_Bright"
    },
    {
      "x": -1,
      "y": 8,
      "z": -2,
      "name": "Plant_Leaves_Beastwood_Bright"
    },
    {
      "x": -1,
      "y": 15,
      "z": -1,
      "name": "Plant_Leaves_Beastwood_Dark",
      "support": 2
    },
    {
      "x": -1,
      "y": 0,
      "z": 0,
      "name": "Wood_Beastwood_Bark"
    },
    {
      "x": -1,
      "y": 1,
      "z": 0,
      "name": "Wood_Beastwood_Bark"
    },
    {
      "x": -1,
      "y": 2,
      "z": 0,
      "name": "Wood_Beastwood_Bark"
    },
    {
      "x": -1,
      "y": 3,
      "z": 0,
      "name": "Wood_Beastwood_Bark"
    },
    {
      "x": -1,
      "y": 4,
      "z": 0,
      "name": "Wood_Beastwood_Bark"
    },
    {
      "x": -1,
      "y": 5,
      "z": 0,
      "name": "Wood_Beastwood_Bark"
    },
    {
      "x": -1,
      "y": 6,
      "z": 0,
      "name": "Wood_Beastwood_Bark"
    },
    {
      "x": -1,
      "y": 7,
      "z": 0,
      "name": "Wood_Beastwood_Bark"
    },
    {
      "x": -1,
      "y": 14,
      "z": 0,
      "name": "Plant_Leaves_Beastwood_Dark",
      "support": 1
    },
    {
      "x": -1,
      "y": 15,
      "z": 0,
      "name": "Plant_Leaves_Beastwood_Dark",
      "support": 1
    },
    {
      "x": -1,
      "y": 16,
      "z": 0,
      "name": "Plant_Leaves_Beastwood_Dark",
      "support": 2
    },
    {
      "x": -1,
      "y": 9,
      "z": 1,
      "name": "Plant_Leaves_Beastwood_Bright",
      "support": 15
    },
    {
      "x": -1,
      "y": 10,
      "z": 1,
      "name": "Plant_Leaves_Beastwood_Dark",
      "support": 2
    },
    {
      "x": -1,
      "y": 15,
      "z": 1,
      "name": "Plant_Leaves_Beastwood_Dark",
      "support": 2
    },
    {
      "x": -1,
      "y": 9,
      "z": 2,
      "name": "Plant_Leaves_Beastwood_Dark",
      "support": 1
    },
    {
      "x": -1,
      "y": 10,
      "z": 2,
      "name": "Plant_Leaves_Beastwood_Bright",
      "support": 1
    },
    {
      "x": -1,
      "y": 11,
      "z": 2,
      "name": "Plant_Leaves_Beastwood_Dark",
      "support": 2
    },
    {
      "x": -1,
      "y": 10,
      "z": 3,
      "name": "Plant_Leaves_Beastwood_Bright",
      "support": 2
    },
    {
      "x": 0,
      "y": 8,
      "z": -6,
      "name": "Plant_Leaves_Beastwood_Bright"
    },
    {
      "x": 0,
      "y": 9,
      "z": -6,
      "name": "Plant_Leaves_Beastwood_Dark"
    },
    {
      "x": 0,
      "y": 7,
      "z": -5,
      "name": "Plant_Leaves_Beastwood_Bright"
    },
    {
      "x": 0,
      "y": 8,
      "z": -5,
      "name": "Plant_Leaves_Beastwood_Bright"
    },
    {
      "x": 0,
      "y": 9,
      "z": -5,
      "name": "Plant_Leaves_Beastwood_Dark"
    },
    {
      "x": 0,
      "y": 10,
      "z": -5,
      "name": "Plant_Leaves_Beastwood_Dark"
    },
    {
      "x": 0,
      "y": 6,
      "z": -4,
      "name": "Plant_Leaves_Beastwood_Dark"
    },
    {
      "x": 0,
      "y": 7,
      "z": -4,
      "name": "Wood_Redwood_Branch_Corner",
      "support": 15,
      "rotation": 2
    },
    {
      "x": 0,
      "y": 8,
      "z": -4,
      "name": "Wood_Redwood_Branch_Long",
      "support": 15
    },
    {
      "x": 0,
      "y": 9,
      "z": -4,
      "name": "Plant_Leaves_Beastwood_Dark"
    },
    {
      "x": 0,
      "y": 10,
      "z": -4,
      "name": "Plant_Leaves_Beastwood_Dark"
    },
    {
      "x": 0,
      "y": 6,
      "z": -3,
      "name": "Plant_Leaves_Beastwood_Dark"
    },
    {
      "x": 0,
      "y": 7,
      "z": -3,
      "name": "Wood_Redwood_Branch_Long",
      "support": 15,
      "rotation": 4
    },
    {
      "x": 0,
      "y": 8,
      "z": -3,
      "name": "Plant_Leaves_Beastwood_Bright"
    },
    {
      "x": 0,
      "y": 9,
      "z": -3,
      "name": "Plant_Leaves_Beastwood_Dark"
    },
    {
      "x": 0,
      "y": 10,
      "z": -3,
      "name": "Plant_Leaves_Beastwood_Dark"
    },
    {
      "x": 0,
      "y": 7,
      "z": -2,
      "name": "Wood_Redwood_Branch_Long",
      "support": 15,
      "rotation": 4
    },
    {
      "x": 0,
      "y": 8,
      "z": -2,
      "name": "Plant_Leaves_Beastwood_Bright"
    },
    {
      "x": 0,
      "y": 9,
      "z": -2,
      "name": "Plant_Leaves_Beastwood_Bright"
    },
    {
      "x": 0,
      "y": 15,
      "z": -2,
      "name": "Plant_Leaves_Beastwood_Dark",
      "support": 2
    },
    {
      "x": 0,
      "y": 0,
      "z": -1,
      "name": "Wood_Beastwood_Bark"
    },
    {
      "x": 0,
      "y": 1,
      "z": -1,
      "name": "Wood_Beastwood_Bark"
    },
    {
      "x": 0,
      "y": 2,
      "z": -1,
      "name": "Wood_Beastwood_Bark"
    },
    {
      "x": 0,
      "y": 3,
      "z": -1,
      "name": "Wood_Beastwood_Bark"
    },
    {
      "x": 0,
      "y": 4,
      "z": -1,
      "name": "Wood_Beastwood_Bark"
    },
    {
      "x": 0,
      "y": 5,
      "z": -1,
      "name": "Wood_Beastwood_Bark"
    },
    {
      "x": 0,
      "y": 6,
      "z": -1,
      "name": "Wood_Beastwood_Bark"
    },
    {
      "x": 0,
      "y": 7,
      "z": -1,
      "name": "Wood_Beastwood_Bark"
    },
    {
      "x": 0,
      "y": 14,
      "z": -1,
      "name": "Plant_Leaves_Beastwood_Dark",
      "support": 1
    },
    {
      "x": 0,
      "y": 15,
      "z": -1,
      "name": "Plant_Leaves_Beastwood_Dark",
      "support": 1
    },
    {
      "x": 0,
      "y": 16,
      "z": -1,
      "name": "Plant_Leaves_Beastwood_Bright",
      "support": 2
    },
    {
      "x": 0,
      "y": 0,
      "z": 0,
      "name": "Wood_Beastwood_Bark"
    },
    {
      "x": 0,
      "y": 1,
      "z": 0,
      "name": "Wood_Beastwood_Plhoem_Sap"
    },
    {
      "x": 0,
      "y": 2,
      "z": 0,
      "name": "Wood_Beastwood_Plhoem_Sap"
    },
    {
      "x": 0,
      "y": 3,
      "z": 0,
      "name": "Wood_Beastwood_Plhoem_Sap"
    },
    {
      "x": 0,
      "y": 4,
      "z": 0,
      "name": "Wood_Beastwood_Plhoem_Sap"
    },
    {
      "x": 0,
      "y": 5,
      "z": 0,
      "name": "Wood_Beastwood_Plhoem_Sap"
    },
    {
      "x": 0,
      "y": 6,
      "z": 0,
      "name": "Wood_Beastwood_Plhoem_Sap"
    },
    {
      "x": 0,
      "y": 7,
      "z": 0,
      "name": "Wood_Beastwood_Plhoem_Sap"
    },
    {
      "x": 0,
      "y": 8,
      "z": 0,
      "name": "Wood_Beastwood_Bark"
    },
    {
      "x": 0,
      "y": 9,
      "z": 0,
      "name": "Wood_Beastwood_Bark"
    },
    {
      "x": 0,
      "y": 10,
      "z": 0,
      "name": "Wood_Beastwood_Bark"
    },
    {
      "x": 0,
      "y": 11,
      "z": 0,
      "name": "Wood_Beastwood_Bark"
    },
    {
      "x": 0,
      "y": 13,
      "z": 0,
      "name": "Plant_Leaves_Beastwood_Dark"
    },
    {
      "x": 0,
      "y": 14,
      "z": 0,
      "name": "Plant_Leaves_Beastwood_Dark"
    },
    {
      "x": 0,
      "y": 15,
      "z": 0,
      "name": "Plant_Leaves_Beastwood_Dark"
    },
    {
      "x": 0,
      "y": 16,
      "z": 0,
      "name": "Plant_Leaves_Beastwood_Bright",
      "support": 1
    },
    {
      "x": 0,
      "y": 17,
      "z": 0,
      "name": "Plant_Leaves_Beastwood_Dark",
      "support": 2
    },
    {
      "x": 0,
      "y": 0,
      "z": 1,
      "name": "Wood_Beastwood_Bark"
    },
    {
      "x": 0,
      "y": 1,
      "z": 1,
      "name": "Wood_Beastwood_Bark"
    },
    {
      "x": 0,
      "y": 2,
      "z": 1,
      "name": "Wood_Beastwood_Bark"
    },
    {
      "x": 0,
      "y": 3,
      "z": 1,
      "name": "Wood_Beastwood_Bark"
    },
    {
      "x": 0,
      "y": 4,
      "z": 1,
      "name": "Wood_Beastwood_Bark"
    },
    {
      "x": 0,
      "y": 5,
      "z": 1,
      "name": "Wood_Beastwood_Bark"
    },
    {
      "x": 0,
      "y": 6,
      "z": 1,
      "name": "Wood_Beastwood_Bark"
    },
    {
      "x": 0,
      "y": 7,
      "z": 1,
      "name": "Wood_Beastwood_Bark"
    },
    {
      "x": 0,
      "y": 8,
      "z": 1,
      "name": "Plant_Leaves_Beastwood_Bright",
      "support": 15
    },
    {
      "x": 0,
      "y": 9,
      "z": 1,
      "name": "Plant_Leaves_Beastwood_Dark",
      "support": 15
    },
    {
      "x": 0,
      "y": 10,
      "z": 1,
      "name": "Plant_Leaves_Beastwood_Bright",
      "support": 15
    },
    {
      "x": 0,
      "y": 11,
      "z": 1,
      "name": "Plant_Leaves_Beastwood_Bright",
      "support": 15
    },
    {
      "x": 0,
      "y": 14,
      "z": 1,
      "name": "Plant_Leaves_Beastwood_Dark",
      "support": 1
    },
    {
      "x": 0,
      "y": 15,
      "z": 1,
      "name": "Plant_Leaves_Beastwood_Dark",
      "support": 1
    },
    {
      "x": 0,
      "y": 16,
      "z": 1,
      "name": "Plant_Leaves_Beastwood_Dark",
      "support": 2
    },
    {
      "x": 0,
      "y": 8,
      "z": 2,
      "name": "Plant_Leaves_Beastwood_Dark"
    },
    {
      "x": 0,
      "y": 9,
      "z": 2,
      "name": "Plant_Leaves_Beastwood_Dark"
    },
    {
      "x": 0,
      "y": 10,
      "z": 2,
      "name": "Plant_Leaves_Beastwood_Dark"
    },
    {
      "x": 0,
      "y": 11,
      "z": 2,
      "name": "Plant_Leaves_Beastwood_Dark",
      "support": 1
    },
    {
      "x": 0,
      "y": 12,
      "z": 2,
      "name": "Plant_Leaves_Beastwood_Bright",
      "support": 2
    },
    {
      "x": 0,
      "y": 15,
      "z": 2,
      "name": "Plant_Leaves_Beastwood_Dark",
      "support": 2
    },
    {
      "x": 0,
      "y": 9,
      "z": 3,
      "name": "Plant_Leaves_Beastwood_Dark",
      "support": 1
    },
    {
      "x": 0,
      "y": 10,
      "z": 3,
      "name": "Plant_Leaves_Beastwood_Bright",
      "support": 1
    },
    {
      "x": 0,
      "y": 11,
      "z": 3,
      "name": "Plant_Leaves_Beastwood_Bright",
      "support": 2
    },
    {
      "x": 0,
      "y": 10,
      "z": 4,
      "name": "Plant_Leaves_Beastwood_Dark",
      "support": 2
    },
    {
      "x": 1,
      "y": 8,
      "z": -6,
      "name": "Plant_Leaves_Beastwood_Bright"
    },
    {
      "x": 1,
      "y": 7,
      "z": -5,
      "name": "Plant_Leaves_Beastwood_Bright"
    },
    {
      "x": 1,
      "y": 8,
      "z": -5,
      "name": "Plant_Leaves_Beastwood_Dark"
    },
    {
      "x": 1,
      "y": 9,
      "z": -5,
      "name": "Plant_Leaves_Beastwood_Dark"
    },
    {
      "x": 1,
      "y": 7,
      "z": -4,
      "name": "Plant_Leaves_Beastwood_Bright"
    },
    {
      "x": 1,
      "y": 8,
      "z": -4,
      "name": "Plant_Leaves_Beastwood_Dark"
    },
    {
      "x": 1,
      "y": 9,
      "z": -4,
      "name": "Plant_Leaves_Beastwood_Dark"
    },
    {
      "x": 1,
      "y": 7,
      "z": -3,
      "name": "Plant_Leaves_Beastwood_Bright"
    },
    {
      "x": 1,
      "y": 8,
      "z": -3,
      "name": "Plant_Leaves_Beastwood_Dark"
    },
    {
      "x": 1,
      "y": 9,
      "z": -3,
      "name": "Plant_Leaves_Beastwood_Dark"
    },
    {
      "x": 1,
      "y": 14,
      "z": -2,
      "name": "Plant_Leaves_Beastwood_Bright",
      "support": 1
    },
    {
      "x": 1,
      "y": 15,
      "z": -2,
      "name": "Plant_Leaves_Beastwood_Dark",
      "support": 1
    },
    {
      "x": 1,
      "y": 16,
      "z": -2,
      "name": "Plant_Leaves_Beastwood_Dark",
      "support": 2
    },
    {
      "x": 1,
      "y": 7,
      "z": -1,
      "name": "Wood_Beastwood_Bark"
    },
    {
      "x": 1,
      "y": 8,
      "z": -1,
      "name": "Wood_Beastwood_Bark"
    },
    {
      "x": 1,
      "y": 9,
      "z": -1,
      "name": "Wood_Beastwood_Bark"
    },
    {
      "x": 1,
      "y": 10,
      "z": -1,
      "name": "Wood_Beastwood_Bark"
    },
    {
      "x": 1,
      "y": 11,
      "z": -1,
      "name": "Wood_Beastwood_Bark"
    },
    {
      "x": 1,
      "y": 13,
      "z": -1,
      "name": "Plant_Leaves_Beastwood_Bright"
    },
    {
      "x": 1,
      "y": 14,
      "z": -1,
      "name": "Plant_Leaves_Beastwood_Dark"
    },
    {
      "x": 1,
      "y": 15,
      "z": -1,
      "name": "Plant_Leaves_Beastwood_Dark"
    },
    {
      "x": 1,
      "y": 16,
      "z": -1,
      "name": "Plant_Leaves_Beastwood_Dark",
      "support": 1
    },
    {
      "x": 1,
      "y": 17,
      "z": -1,
      "name": "Plant_Leaves_Beastwood_Bright",
      "support": 2
    },
    {
      "x": 1,
      "y": 0,
      "z": 0,
      "name": "Wood_Beastwood_Bark"
    },
    {
      "x": 1,
      "y": 1,
      "z": 0,
      "name": "Wood_Beastwood_Bark"
    },
    {
      "x": 1,
      "y": 2,
      "z": 0,
      "name": "Wood_Beastwood_Bark"
    },
    {
      "x": 1,
      "y": 3,
      "z": 0,
      "name": "Wood_Beastwood_Bark"
    },
    {
      "x": 1,
      "y": 4,
      "z": 0,
      "name": "Wood_Beastwood_Bark"
    },
    {
      "x": 1,
      "y": 5,
      "z": 0,
      "name": "Wood_Beastwood_Bark"
    },
    {
      "x": 1,
      "y": 6,
      "z": 0,
      "name": "Wood_Beastwood_Bark"
    },
    {
      "x": 1,
      "y": 7,
      "z": 0,
      "name": "Wood_Beastwood_Plhoem_Sap"
    },
    {
      "x": 1,
      "y": 8,
      "z": 0,
      "name": "Wood_Beastwood_Plhoem_Sap"
    },
    {
      "x": 1,
      "y": 9,
      "z": 0,
      "name": "Wood_Beastwood_Plhoem_Sap"
    },
    {
      "x": 1,
      "y": 10,
      "z": 0,
      "name": "Wood_Beastwood_Plhoem_Sap"
    },
    {
      "x": 1,
      "y": 11,
      "z": 0,
      "name": "Wood_Beastwood_Plhoem_Sap"
    },
    {
      "x": 1,
      "y": 12,
      "z": 0,
      "name": "Wood_Beastwood_Bark"
    },
    {
      "x": 1,
      "y": 13,
      "z": 0,
      "name": "Wood_Redwood_Branch_Long",
      "support": 15
    },
    {
      "x": 1,
      "y": 14,
      "z": 0,
      "name": "Wood_Redwood_Branch_Long",
      "support": 15
    },
    {
      "x": 1,
      "y": 15,
      "z": 0,
      "name": "Wood_Redwood_Branch_Long",
      "support": 15
    },
    {
      "x": 1,
      "y": 16,
      "z": 0,
      "name": "Plant_Leaves_Beastwood_Bright"
    },
    {
      "x": 1,
      "y": 17,
      "z": 0,
      "name": "Plant_Leaves_Beastwood_Dark",
      "support": 1
    },
    {
      "x": 1,
      "y": 7,
      "z": 1,
      "name": "Wood_Beastwood_Bark"
    },
    {
      "x": 1,
      "y": 8,
      "z": 1,
      "name": "Wood_Beastwood_Bark"
    },
    {
      "x": 1,
      "y": 9,
      "z": 1,
      "name": "Wood_Beastwood_Bark"
    },
    {
      "x": 1,
      "y": 10,
      "z": 1,
      "name": "Wood_Beastwood_Bark"
    },
    {
      "x": 1,
      "y": 11,
      "z": 1,
      "name": "Wood_Beastwood_Bark"
    },
    {
      "x": 1,
      "y": 12,
      "z": 1,
      "name": "Plant_Leaves_Beastwood_Dark",
      "support": 15
    },
    {
      "x": 1,
      "y": 13,
      "z": 1,
      "name": "Plant_Leaves_Beastwood_Dark"
    },
    {
      "x": 1,
      "y": 14,
      "z": 1,
      "name": "Plant_Leaves_Beastwood_Dark"
    },
    {
      "x": 1,
      "y": 15,
      "z": 1,
      "name": "Plant_Leaves_Beastwood_Dark"
    },
    {
      "x": 1,
      "y": 16,
      "z": 1,
      "name": "Plant_Leaves_Beastwood_Dark",
      "support": 1
    },
    {
      "x": 1,
      "y": 17,
      "z": 1,
      "name": "Plant_Leaves_Beastwood_Dark",
      "support": 2
    },
    {
      "x": 1,
      "y": 7,
      "z": 2,
      "name": "Wood_Redwood_Branch_Corner",
      "support": 15
    },
    {
      "x": 1,
      "y": 8,
      "z": 2,
      "name": "Wood_Redwood_Branch_Long",
      "support": 15
    },
    {
      "x": 1,
      "y": 9,
      "z": 2,
      "name": "Wood_Redwood_Branch_Long",
      "support": 15
    },
    {
      "x": 1,
      "y": 10,
      "z": 2,
      "name": "Wood_Redwood_Branch_Long",
      "support": 15
    },
    {
      "x": 1,
      "y": 11,
      "z": 2,
      "name": "Plant_Leaves_Beastwood_Bright"
    },
    {
      "x": 1,
      "y": 12,
      "z": 2,
      "name": "Plant_Leaves_Beastwood_Dark",
      "support": 2
    },
    {
      "x": 1,
      "y": 14,
      "z": 2,
      "name": "Plant_Leaves_Beastwood_Dark",
      "support": 1
    },
    {
      "x": 1,
      "y": 15,
      "z": 2,
      "name": "Plant_Leaves_Beastwood_Bright",
      "support": 1
    },
    {
      "x": 1,
      "y": 16,
      "z": 2,
      "name": "Plant_Leaves_Beastwood_Dark",
      "support": 2
    },
    {
      "x": 1,
      "y": 8,
      "z": 3,
      "name": "Plant_Leaves_Beastwood_Bright"
    },
    {
      "x": 1,
      "y": 9,
      "z": 3,
      "name": "Plant_Leaves_Beastwood_Bright"
    },
    {
      "x": 1,
      "y": 10,
      "z": 3,
      "name": "Plant_Leaves_Beastwood_Bright"
    },
    {
      "x": 1,
      "y": 11,
      "z": 3,
      "name": "Plant_Leaves_Beastwood_Bright",
      "support": 1
    },
    {
      "x": 1,
      "y": 12,
      "z": 3,
      "name": "Plant_Leaves_Beastwood_Dark",
      "support": 2
    },
    {
      "x": 1,
      "y": 9,
      "z": 4,
      "name": "Plant_Leaves_Beastwood_Bright",
      "support": 1
    },
    {
      "x": 1,
      "y": 10,
      "z": 4,
      "name": "Plant_Leaves_Beastwood_Dark",
      "support": 1
    },
    {
      "x": 1,
      "y": 11,
      "z": 4,
      "name": "Plant_Leaves_Beastwood_Dark",
      "support": 2
    },
    {
      "x": 2,
      "y": 8,
      "z": -5,
      "name": "Plant_Leaves_Beastwood_Dark"
    },
    {
      "x": 2,
      "y": 8,
      "z": -4,
      "name": "Plant_Leaves_Beastwood_Bright"
    },
    {
      "x": 2,
      "y": 15,
      "z": -2,
      "name": "Plant_Leaves_Beastwood_Dark",
      "support": 2
    },
    {
      "x": 2,
      "y": 14,
      "z": -1,
      "name": "Plant_Leaves_Beastwood_Dark",
      "support": 1
    },
    {
      "x": 2,
      "y": 15,
      "z": -1,
      "name": "Plant_Leaves_Beastwood_Dark",
      "support": 1
    },
    {
      "x": 2,
      "y": 16,
      "z": -1,
      "name": "Plant_Leaves_Beastwood_Dark",
      "support": 2
    },
    {
      "x": 2,
      "y": 7,
      "z": 0,
      "name": "Wood_Beastwood_Bark"
    },
    {
      "x": 2,
      "y": 8,
      "z": 0,
      "name": "Wood_Beastwood_Bark"
    },
    {
      "x": 2,
      "y": 9,
      "z": 0,
      "name": "Wood_Beastwood_Bark"
    },
    {
      "x": 2,
      "y": 10,
      "z": 0,
      "name": "Wood_Beastwood_Bark"
    },
    {
      "x": 2,
      "y": 11,
      "z": 0,
      "name": "Wood_Beastwood_Bark"
    },
    {
      "x": 2,
      "y": 12,
      "z": 0,
      "name": "Wood_Redwood_Branch_Corner",
      "support": 15,
      "rotation": 9
    },
    {
      "x": 2,
      "y": 14,
      "z": 0,
      "name": "Plant_Leaves_Beastwood_Dark"
    },
    {
      "x": 2,
      "y": 15,
      "z": 0,
      "name": "Plant_Leaves_Beastwood_Dark"
    },
    {
      "x": 2,
      "y": 16,
      "z": 0,
      "name": "Plant_Leaves_Beastwood_Dark",
      "support": 1
    },
    {
      "x": 2,
      "y": 17,
      "z": 0,
      "name": "Plant_Leaves_Beastwood_Dark",
      "support": 2
    },
    {
      "x": 2,
      "y": 9,
      "z": 1,
      "name": "Plant_Leaves_Beastwood_Dark",
      "support": 1
    },
    {
      "x": 2,
      "y": 10,
      "z": 1,
      "name": "Plant_Leaves_Beastwood_Bright",
      "support": 1
    },
    {
      "x": 2,
      "y": 11,
      "z": 1,
      "name": "Plant_Leaves_Beastwood_Bright",
      "support": 2
    },
    {
      "x": 2,
      "y": 14,
      "z": 1,
      "name": "Plant_Leaves_Beastwood_Bright",
      "support": 1
    },
    {
      "x": 2,
      "y": 15,
      "z": 1,
      "name": "Plant_Leaves_Beastwood_Dark",
      "support": 1
    },
    {
      "x": 2,
      "y": 16,
      "z": 1,
      "name": "Plant_Leaves_Beastwood_Bright",
      "support": 2
    },
    {
      "x": 2,
      "y": 8,
      "z": 2,
      "name": "Plant_Leaves_Beastwood_Dark"
    },
    {
      "x": 2,
      "y": 9,
      "z": 2,
      "name": "Plant_Leaves_Beastwood_Dark"
    },
    {
      "x": 2,
      "y": 10,
      "z": 2,
      "name": "Plant_Leaves_Beastwood_Bright"
    },
    {
      "x": 2,
      "y": 11,
      "z": 2,
      "name": "Plant_Leaves_Beastwood_Dark",
      "support": 1
    },
    {
      "x": 2,
      "y": 12,
      "z": 2,
      "name": "Plant_Leaves_Beastwood_Dark",
      "support": 2
    },
    {
      "x": 2,
      "y": 15,
      "z": 2,
      "name": "Plant_Leaves_Beastwood_Dark",
      "support": 2
    },
    {
      "x": 2,
      "y": 9,
      "z": 3,
      "name": "Plant_Leaves_Beastwood_Dark",
      "support": 1
    },
    {
      "x": 2,
      "y": 10,
      "z": 3,
      "name": "Plant_Leaves_Beastwood_Dark",
      "support": 1
    },
    {
      "x": 2,
      "y": 11,
      "z": 3,
      "name": "Plant_Leaves_Beastwood_Dark",
      "support": 2
    },
    {
      "x": 2,
      "y": 10,
      "z": 4,
      "name": "Plant_Leaves_Beastwood_Dark",
      "support": 2
    },
    {
      "x": 3,
      "y": 12,
      "z": -1,
      "name": "Plant_Leaves_Beastwood_Dark"
    },
    {
      "x": 3,
      "y": 15,
      "z": -1,
      "name": "Plant_Leaves_Beastwood_Dark",
      "support": 2
    },
    {
      "x": 3,
      "y": 11,
      "z": 0,
      "name": "Plant_Leaves_Beastwood_Dark"
    },
    {
      "x": 3,
      "y": 12,
      "z": 0,
      "name": "Wood_Redwood_Branch_Long",
      "support": 15,
      "rotation": 5
    },
    {
      "x": 3,
      "y": 13,
      "z": 0,
      "name": "Plant_Leaves_Beastwood_Dark"
    },
    {
      "x": 3,
      "y": 15,
      "z": 0,
      "name": "Plant_Leaves_Beastwood_Bright",
      "support": 1
    },
    {
      "x": 3,
      "y": 16,
      "z": 0,
      "name": "Plant_Leaves_Beastwood_Dark",
      "support": 2
    },
    {
      "x": 3,
      "y": 10,
      "z": 1,
      "name": "Plant_Leaves_Beastwood_Bright",
      "support": 2
    },
    {
      "x": 3,
      "y": 12,
      "z": 1,
      "name": "Plant_Leaves_Beastwood_Bright"
    },
    {
      "x": 3,
      "y": 15,
      "z": 1,
      "name": "Plant_Leaves_Beastwood_Bright",
      "support": 2
    },
    {
      "x": 3,
      "y": 9,
      "z": 2,
      "name": "Plant_Leaves_Beastwood_Dark",
      "support": 1
    },
    {
      "x": 3,
      "y": 10,
      "z": 2,
      "name": "Plant_Leaves_Beastwood_Bright",
      "support": 1
    },
    {
      "x": 3,
      "y": 11,
      "z": 2,
      "name": "Plant_Leaves_Beastwood_Dark",
      "support": 2
    },
    {
      "x": 3,
      "y": 10,
      "z": 3,
      "name": "Plant_Leaves_Beastwood_Bright",
      "support": 2
    },
    {
      "x": 4,
      "y": 12,
      "z": -2,
      "name": "Plant_Leaves_Beastwood_Dark",
      "support": 1
    },
    {
      "x": 4,
      "y": 11,
      "z": -1,
      "name": "Plant_Leaves_Beastwood_Bright",
      "support": 1
    },
    {
      "x": 4,
      "y": 12,
      "z": -1,
      "name": "Plant_Leaves_Beastwood_Dark"
    },
    {
      "x": 4,
      "y": 13,
      "z": -1,
      "name": "Plant_Leaves_Beastwood_Dark",
      "support": 1
    },
    {
      "x": 4,
      "y": 10,
      "z": 0,
      "name": "Plant_Leaves_Beastwood_Bright",
      "support": 1
    },
    {
      "x": 4,
      "y": 11,
      "z": 0,
      "name": "Plant_Leaves_Beastwood_Bright"
    },
    {
      "x": 4,
      "y": 12,
      "z": 0,
      "name": "Wood_Redwood_Branch_Long",
      "support": 15,
      "rotation": 5
    },
    {
      "x": 4,
      "y": 13,
      "z": 0,
      "name": "Plant_Leaves_Beastwood_Dark"
    },
    {
      "x": 4,
      "y": 14,
      "z": 0,
      "name": "Plant_Leaves_Beastwood_Dark",
      "support": 1
    },
    {
      "x": 4,
      "y": 11,
      "z": 1,
      "name": "Plant_Leaves_Beastwood_Dark",
      "support": 1
    },
    {
      "x": 4,
      "y": 12,
      "z": 1,
      "name": "Plant_Leaves_Beastwood_Dark"
    },
    {
      "x": 4,
      "y": 13,
      "z": 1,
      "name": "Plant_Leaves_Beastwood_Dark",
      "support": 1
    },
    {
      "x": 4,
      "y": 12,
      "z": 2,
      "name": "Plant_Leaves_Beastwood_Dark",
      "support": 1
    },
    {
      "x": 5,
      "y": 11,
      "z": -2,
      "name": "Plant_Leaves_Beastwood_Bright",
      "support": 2
    },
    {
      "x": 5,
      "y": 12,
      "z": -2,
      "name": "Plant_Leaves_Beastwood_Bright",
      "support": 1
    },
    {
      "x": 5,
      "y": 13,
      "z": -2,
      "name": "Plant_Leaves_Beastwood_Dark",
      "support": 2
    },
    {
      "x": 5,
      "y": 10,
      "z": -1,
      "name": "Plant_Leaves_Beastwood_Dark",
      "support": 2
    },
    {
      "x": 5,
      "y": 11,
      "z": -1,
      "name": "Plant_Leaves_Beastwood_Dark",
      "support": 1
    },
    {
      "x": 5,
      "y": 12,
      "z": -1,
      "name": "Plant_Leaves_Beastwood_Dark"
    },
    {
      "x": 5,
      "y": 13,
      "z": -1,
      "name": "Plant_Leaves_Beastwood_Bright",
      "support": 1
    },
    {
      "x": 5,
      "y": 14,
      "z": -1,
      "name": "Plant_Leaves_Beastwood_Dark",
      "support": 2
    },
    {
      "x": 5,
      "y": 10,
      "z": 0,
      "name": "Plant_Leaves_Beastwood_Dark",
      "support": 1
    },
    {
      "x": 5,
      "y": 11,
      "z": 0,
      "name": "Plant_Leaves_Beastwood_Dark"
    },
    {
      "x": 5,
      "y": 12,
      "z": 0,
      "name": "Wood_Redwood_Branch_Long",
      "support": 15,
      "rotation": 5
    },
    {
      "x": 5,
      "y": 13,
      "z": 0,
      "name": "Plant_Leaves_Beastwood_Bright"
    },
    {
      "x": 5,
      "y": 14,
      "z": 0,
      "name": "Plant_Leaves_Beastwood_Dark",
      "support": 1
    },
    {
      "x": 5,
      "y": 10,
      "z": 1,
      "name": "Plant_Leaves_Beastwood_Bright",
      "support": 2
    },
    {
      "x": 5,
      "y": 11,
      "z": 1,
      "name": "Plant_Leaves_Beastwood_Bright",
      "support": 1
    },
    {
      "x": 5,
      "y": 12,
      "z": 1,
      "name": "Plant_Leaves_Beastwood_Dark"
    },
    {
      "x": 5,
      "y": 13,
      "z": 1,
      "name": "Plant_Leaves_Beastwood_Dark",
      "support": 1
    },
    {
      "x": 5,
      "y": 14,
      "z": 1,
      "name": "Plant_Leaves_Beastwood_Dark",
      "support": 2
    },
    {
      "x": 5,
      "y": 11,
      "z": 2,
      "name": "Plant_Leaves_Beastwood_Bright",
      "support": 2
    },
    {
      "x": 5,
      "y": 12,
      "z": 2,
      "name": "Plant_Leaves_Beastwood_Dark",
      "support": 1
    },
    {
      "x": 5,
      "y": 13,
      "z": 2,
      "name": "Plant_Leaves_Beastwood_Bright",
      "support": 2
    },
    {
      "x": 6,
      "y": 12,
      "z": -2,
      "name": "Plant_Leaves_Beastwood_Dark",
      "support": 2
    },
    {
      "x": 6,
      "y": 11,
      "z": -1,
      "name": "Plant_Leaves_Beastwood_Bright",
      "support": 2
    },
    {
      "x": 6,
      "y": 12,
      "z": -1,
      "name": "Plant_Leaves_Beastwood_Dark",
      "support": 1
    },
    {
      "x": 6,
      "y": 13,
      "z": -1,
      "name": "Plant_Leaves_Beastwood_Dark",
      "support": 2
    },
    {
      "x": 6,
      "y": 10,
      "z": 0,
      "name": "Plant_Leaves_Beastwood_Bright",
      "support": 2
    },
    {
      "x": 6,
      "y": 11,
      "z": 0,
      "name": "Plant_Leaves_Beastwood_Bright",
      "support": 1
    },
    {
      "x": 6,
      "y": 12,
      "z": 0,
      "name": "Plant_Leaves_Beastwood_Dark"
    },
    {
      "x": 6,
      "y": 13,
      "z": 0,
      "name": "Plant_Leaves_Beastwood_Dark",
      "support": 1
    },
    {
      "x": 6,
      "y": 14,
      "z": 0,
      "name": "Plant_Leaves_Beastwood_Bright",
      "support": 2
    },
    {
      "x": 6,
      "y": 11,
      "z": 1,
      "name": "Plant_Leaves_Beastwood_Bright",
      "support": 2
    },
    {
      "x": 6,
      "y": 12,
      "z": 1,
      "name": "Plant_Leaves_Beastwood_Bright",
      "support": 1
    },
    {
      "x": 6,
      "y": 13,
      "z": 1,
      "name": "Plant_Leaves_Beastwood_Dark",
      "support": 2
    },
    {
      "x": 6,
      "y": 12,
      "z": 2,
      "name": "Plant_Leaves_Beastwood_Bright",
      "support": 2
    },
    {
      "x": 7,
      "y": 12,
      "z": -1,
      "name": "Plant_Leaves_Beastwood_Bright",
      "support": 2
    },
    {
      "x": 7,
      "y": 11,
      "z": 0,
      "name": "Plant_Leaves_Beastwood_Bright",
      "support": 2
    },
    {
      "x": 7,
      "y": 12,
      "z": 0,
      "name": "Plant_Leaves_Beastwood_Dark",
      "support": 1
    },
    {
      "x": 7,
      "y": 13,
      "z": 0,
      "name": "Plant_Leaves_Beastwood_Dark",
      "support": 2
    },
    {
      "x": 7,
      "y": 12,
      "z": 1,
      "name": "Plant_Leaves_Beastwood_Dark",
      "support": 2
    }
  ]
}